Workbook
Name Ext._Landed_COGS: #REF!
Name Ext._Proposed_Price: #REF!
Name Ext_Landed_Rebate_COGS: #REF!
Name Ext_Landed_Rebate_Value: #REF!
Name Multiplier_from_Dashboard: #REF!

Sheet SUMMARY
A1: CATEGORY | B1: SKU COUNT | C1: BLUE TRITON EXT | D1: PA EXT | E1: DIFF $ | F1: DIFF %
A2: BEARINGS | B2: =COUNTIF('Transaction Details'!W:W,A2) -> 19 | C2: =SUMPRODUCT( --($A2='Transaction Details'!$W:$W),'Transaction Details'!AC:AC) -> 6757.9877 | D2: =SUMPRODUCT( --($A2='Transaction Details'!$W:$W),'Transaction Details'!AD:AD) -> 4460.5801 | E2: =SUMPRODUCT( --($A2='Transaction Details'!$W:$W),'Transaction Details'!AE:AE) -> 2297.4076 | F2: =E2/C2 -> 0.33995439
A3: ELECTRICAL POWER TRANSMISSION | B3: =COUNTIF('Transaction Details'!W:W,A3) -> 28 | C3: =SUMPRODUCT( --($A3='Transaction Details'!$W:$W),'Transaction Details'!AC:AC) -> 18514.595 | D3: =SUMPRODUCT( --($A3='Transaction Details'!$W:$W),'Transaction Details'!AD:AD) -> 17339.095 | E3: =SUMPRODUCT( --($A3='Transaction Details'!$W:$W),'Transaction Details'!AE:AE) -> 1175.5002 | F3: =E3/C3 -> 0.063490461
A4: FLUID POWER | B4: =COUNTIF('Transaction Details'!W:W,A4) -> 106 | C4: =SUMPRODUCT( --($A4='Transaction Details'!$W:$W),'Transaction Details'!AC:AC) -> 93319.779 | D4: =SUMPRODUCT( --($A4='Transaction Details'!$W:$W),'Transaction Details'!AD:AD) -> 90936.941 | E4: =SUMPRODUCT( --($A4='Transaction Details'!$W:$W),'Transaction Details'!AE:AE) -> 2382.838 | F4: =E4/C4 -> 0.025534116
A5: GENERAL INDUSTRIAL SUPPLY | B5: =COUNTIF('Transaction Details'!W:W,A5) -> 3 | C5: =SUMPRODUCT( --($A5='Transaction Details'!$W:$W),'Transaction Details'!AC:AC) -> 929.07 | D5: =SUMPRODUCT( --($A5='Transaction Details'!$W:$W),'Transaction Details'!AD:AD) -> 711.9 | E5: =SUMPRODUCT( --($A5='Transaction Details'!$W:$W),'Transaction Details'!AE:AE) -> 217.17 | F5: =E5/C5 -> 0.23374988
A6: LINEAR MOTION PRODUCTS | B6: =COUNTIF('Transaction Details'!W:W,A6) -> 5 | C6: =SUMPRODUCT( --($A6='Transaction Details'!$W:$W),'Transaction Details'!AC:AC) -> 846.31632 | D6: =SUMPRODUCT( --($A6='Transaction Details'!$W:$W),'Transaction Details'!AD:AD) -> 956.08522 | E6: =SUMPRODUCT( --($A6='Transaction Details'!$W:$W),'Transaction Details'!AE:AE) -> -109.7689 | F6: =E6/C6 -> -0.12970197
A7: LUBRICANT PRODUCTS | B7: =COUNTIF('Transaction Details'!W:W,A7) -> 35 | C7: =SUMPRODUCT( --($A7='Transaction Details'!$W:$W),'Transaction Details'!AC:AC) -> 9480.1464 | D7: =SUMPRODUCT( --($A7='Transaction Details'!$W:$W),'Transaction Details'!AD:AD) -> 9691.9065 | E7: =SUMPRODUCT( --($A7='Transaction Details'!$W:$W),'Transaction Details'!AE:AE) -> -211.76013 | F7: =E7/C7 -> -0.022337222
A8: MATERIAL HANDLING | B8: =COUNTIF('Transaction Details'!W:W,A8) -> 8 | C8: =SUMPRODUCT( --($A8='Transaction Details'!$W:$W),'Transaction Details'!AC:AC) -> 12323.85 | D8: =SUMPRODUCT( --($A8='Transaction Details'!$W:$W),'Transaction Details'!AD:AD) -> 11506.812 | E8: =SUMPRODUCT( --($A8='Transaction Details'!$W:$W),'Transaction Details'!AE:AE) -> 817.03788 | F8: =E8/C8 -> 0.066297292
A9: MECHANICAL POWER TRANSMISSION | B9: =COUNTIF('Transaction Details'!W:W,A9) -> 61 | C9: =SUMPRODUCT( --($A9='Transaction Details'!$W:$W),'Transaction Details'!AC:AC) -> 20458.096 | D9: =SUMPRODUCT( --($A9='Transaction Details'!$W:$W),'Transaction Details'!AD:AD) -> 18950.914 | E9: =SUMPRODUCT( --($A9='Transaction Details'!$W:$W),'Transaction Details'!AE:AE) -> 1507.1817 | F9: =E9/C9 -> 0.073671654
A10: SAFETY PRODUCTS | B10: =COUNTIF('Transaction Details'!W:W,A10) -> 3 | C10: =SUMPRODUCT( --($A10='Transaction Details'!$W:$W),'Transaction Details'!AC:AC) -> 760.36 | D10: =SUMPRODUCT( --($A10='Transaction Details'!$W:$W),'Transaction Details'!AD:AD) -> 570.48 | E10: =SUMPRODUCT( --($A10='Transaction Details'!$W:$W),'Transaction Details'!AE:AE) -> 189.88 | F10: =E10/C10 -> 0.24972382
A11: SEALS PACKING ORINGS | B11: =COUNTIF('Transaction Details'!W:W,A11) -> 2 | C11: =SUMPRODUCT( --($A11='Transaction Details'!$W:$W),'Transaction Details'!AC:AC) -> 289.86 | D11: =SUMPRODUCT( --($A11='Transaction Details'!$W:$W),'Transaction Details'!AD:AD) -> 152.85 | E11: =SUMPRODUCT( --($A11='Transaction Details'!$W:$W),'Transaction Details'!AE:AE) -> 137.01 | F11: =E11/C11 -> 0.47267646
A12: TOOLS | B12: =COUNTIF('Transaction Details'!W:W,A12) -> 6 | C12: =SUMPRODUCT( --($A12='Transaction Details'!$W:$W),'Transaction Details'!AC:AC) -> 3795.4124 | D12: =SUMPRODUCT( --($A12='Transaction Details'!$W:$W),'Transaction Details'!AD:AD) -> 3561.732 | E12: =SUMPRODUCT( --($A12='Transaction Details'!$W:$W),'Transaction Details'!AE:AE) -> 233.68038 | F12: =E12/C12 -> 0.061569168
A13: TOTAL | B13: =SUM(B2:B12) -> 276 | C13: =SUM(C2:C12) -> 167475.47 | D13: =SUM(D2:D12) -> 158839.3 | E13: =SUM(E2:E12) -> 8636.1768 | F13: =E13/C13 -> 0.051566816

Sheet Transaction Details
S1: =COUNT(S3:S29891) -> 276 | AC1: =SUBTOTAL(9,AC3:AC39910) -> 167475.47 | AD1: =SUBTOTAL(9,AD3:AD39910) -> 158839.3 | AE1: =SUBTOTAL(9,AE3:AE39910) -> 8636.1768 | AF1: =AE1/AC1 -> 0.051566816
A2: SC | B2: Billing Document Number | C2: Billing Date | D2: Master Customer (Heading) | E2: Master Customer Division (Heading) | F2: Sold-To-Party | G2: Ship-To Party | H2: Ship-To Party (Heading) | I2: Street Address | J2: City | K2: State | L2: Postal Code | M2: Customer Material Number | N2: Customer Purchase Order Number | O2: MFG Code | P2: Manufacturer Part Number | Q2: Material | R2: UOM | S2: Billing Quantity | T2: 1ST SAP MFR | U2: 1ST SAP PN | V2: 1ST SAP MATERIAL# | W2: CATEGORY | X2: 1ST SAP DESCRIPTION | Y2: 1ST SAP UOM | Z2: 1ST SAP MATERIAL STATUS | AA2: PA PRICE | AB2: BLUE TRITON Price | AC2: BLUE TRITON EXT | AD2: PA EXT | AE2: DIFF $ | AF2: DIFF % | AG2: SAVINGS CATEGORY | AH2: AIT NOTES | AI2: CSPL | AJ2: ROLLING 12 | AK2: CODE
A3: 2842 | B3: 7020969688 | C3: 44257 | D3: NESTLE | E3: NESTLE - BOTTLED WATER | F3: 0001522689 | G3: 0001622857 | H3: NESTLE WATERS NORTH AMERICA | I3: 5772 JURUPA ST | J3: ONTARIO | K3: CA | L3: 91761-3672 | M3: . | N3: 4559249513 | O3: LUBR | P3: L0945-057 | Q3: 102070387 | R3: EA | S3: 1 | T3: LUBR | U3: L0945-057 | V3: 102070387 | W3: LUBRICANT PRODUCTS | X3: LUBR_L0945-057 | Y3: EA | AA3: 26.58525 | AB3: 25.25 | AC3: =AB3*S3 -> 25.25 | AD3: =AA3*S3 -> 26.58525 | AE3: =AC3-AD3 -> -1.3352496 | AF3: =AE3/AC3 -> -0.052881173 | AG3: =IF(AF3<0,"Negative",IF(AF3=0,"Same",IF(AF3>0.3,"30+%",IF(AF3>0.2,"20-30%",IF(AF3>0.1,"10-20%",IF(AF3<=0.1,"0-10%")))))) -> Negative | AI3: NO | AJ3: 0
A4: 2756 | B4: 7020980859 | C4: 44258 | D4: NESTLE | E4: NESTLE - BOTTLED WATER | F4: 0001522689 | G4: 0001621275 | H4: NESTLE WATERS / ICE MTN | I4: 19275 8 MILE RD US PL NW | J4: STANWOOD | K4: MI | L4: 49346-8806 | M4: 104450558 | N4: 4565658877 | O4: DONA | P4: 1C220048-25 | Q4: 110988151 | R4: EA | S4: 2 | T4: DONA | U4: 1C220048-25 | V4: 110988151 | W4: FLUID POWER | X4: DONA_1C220048-25 | Y4: EA | AA4: 243.49 | AB4: 237.11 | AC4: =AB4*S4 -> 474.22 | AD4: =AA4*S4 -> 486.98 | AE4: =AC4-AD4 -> -12.76 | AF4: =AE4/AC4 -> -0.026907343 | AG4: =IF(AF4<0,"Negative",IF(AF4=0,"Same",IF(AF4>0.3,"30+%",IF(AF4>0.2,"20-30%",IF(AF4>0.1,"10-20%",IF(AF4<=0.1,"0-10%")))))) -> Negative | AH4: SPECIAL PRICING. WILL NEED TO CONFIRM MFR WILL EXTEND. | AI4: NO | AJ4: 0
A5: 2756 | B5: 7020980859 | C5: 44258 | D5: NESTLE | E5: NESTLE - BOTTLED WATER | F5: 0001522689 | G5: 0001621275 | H5: NESTLE WATERS / ICE MTN | I5: 19275 8 MILE RD US PL NW | J5: STANWOOD | K5: MI | L5: 49346-8806 | M5: 101980156 | N5: 4565658877 | O5: DONA | P5: 1C125164 | Q5: 110223931 | R5: EA | S5: 2 | T5: DONA | U5: 1C125164 | V5: 110223931 | W5: FLUID POWER | X5: DONA_1C125164 | Y5: EA | AA5: 337.03774 | AB5: 359.33333 | AC5: =AB5*S5 -> 718.66667 | AD5: =AA5*S5 -> 674.07547 | AE5: =AC5-AD5 -> 44.591195 | AF5: =AE5/AC5 -> 0.062047117 | AG5: =IF(AF5<0,"Negative",IF(AF5=0,"Same",IF(AF5>0.3,"30+%",IF(AF5>0.2,"20-30%",IF(AF5>0.1,"10-20%",IF(AF5<=0.1,"0-10%")))))) -> 0-10% | AH5: SPECIAL PRICING. WILL NEED TO CONFIRM MFR WILL EXTEND. | AI5: NO | AJ5: 0
A6: 2756 | B6: 7020980859 | C6: 44258 | D6: NESTLE | E6: NESTLE - BOTTLED WATER | F6: 0001522689 | G6: 0001621275 | H6: NESTLE WATERS / ICE MTN | I6: 19275 8 MILE RD US PL NW | J6: STANWOOD | K6: MI | L6: 49346-8806 | M6: 104333951 | N6: 4565658877 | O6: DONA | P6: 1C125764 | Q6: 110224139 | R6: EA | S6: 2 | T6: DONA | U6: 1C125764 | V6: 110224139 | W6: FLUID POWER | X6: DONA_1C125764 | Y6: EA | AA6: 381.77358 | AB6: 407 | AC6: =AB6*S6 -> 814 | AD6: =AA6*S6 -> 763.54717 | AE6: =AC6-AD6 -> 50.45283 | AF6: =AE6/AC6 -> 0.061981364 | AG6: =IF(AF6<0,"Negative",IF(AF6=0,"Same",IF(AF6>0.3,"30+%",IF(AF6>0.2,"20-30%",IF(AF6>0.1,"10-20%",IF(AF6<=0.1,"0-10%")))))) -> 0-10% | AH6: SPECIAL PRICING. WILL NEED TO CONFIRM MFR WILL EXTEND. | AI6: YES | AJ6: 4
A7: 2756 | B7: 7020980859 | C7: 44258 | D7: NESTLE | E7: NESTLE - BOTTLED WATER | F7: 0001522689 | G7: 0001621275 | H7: NESTLE WATERS / ICE MTN | I7: 19275 8 MILE RD US PL NW | J7: STANWOOD | K7: MI | L7: 49346-8806 | M7: 101131844 | N7: 4565658877 | O7: DONA | P7: 1C122164 | Q7: 103674709 | R7: EA | S7: 2 | T7: DONA | U7: 1C122164 | V7: 103674709 | W7: FLUID POWER | X7: DONA_1C122164 | Y7: EA | AA7: 378.88679 | AB7: 404.06667 | AC7: =AB7*S7 -> 808.13333 | AD7: =AA7*S7 -> 757.77358 | AE7: =AC7-AD7 -> 50.359748 | AF7: =AE7/AC7 -> 0.062316138 | AG7: =IF(AF7<0,"Negative",IF(AF7=0,"Same",IF(AF7>0.3,"30+%",IF(AF7>0.2,"20-30%",IF(AF7>0.1,"10-20%",IF(AF7<=0.1,"0-10%")))))) -> 0-10% | AH7: SPECIAL PRICING. WILL NEED TO CONFIRM MFR WILL EXTEND. | AI7: NO | AJ7: 0
A8: 2756 | B8: 7020980859 | C8: 44258 | D8: NESTLE | E8: NESTLE - BOTTLED WATER | F8: 0001522689 | G8: 0001621275 | H8: NESTLE WATERS / ICE MTN | I8: 19275 8 MILE RD US PL NW | J8: STANWOOD | K8: MI | L8: 49346-8806 | M8: 101163015 | N8: 4565658877 | O8: DONA | P8: 1C124364 | Q8: 103720400 | R8: EA | S8: 4 | T8: DONA | U8: 1C124364 | V8: 103720400 | W8: FLUID POWER | X8: DONA_1C124364 | Y8: EA | AA8: 461.16981 | AB8: 489.86667 | AC8: =AB8*S8 -> 1959.4667 | AD8: =AA8*S8 -> 1844.6792 | AE8: =AC8-AD8 -> 114.78742 | AF8: =AE8/AC8 -> 0.058580951 | AG8: =IF(AF8<0,"Negative",IF(AF8=0,"Same",IF(AF8>0.3,"30+%",IF(AF8>0.2,"20-30%",IF(AF8>0.1,"10-20%",IF(AF8<=0.1,"0-10%")))))) -> 0-10% | AH8: SPECIAL PRICING. WILL NEED TO CONFIRM MFR WILL EXTEND. | AI8: NO | AJ8: 0
A9: 2842 | B9: 7020983873 | C9: 44258 | D9: NESTLE | E9: NESTLE - BOTTLED WATER | F9: 0001522689 | G9: 0001622857 | H9: NESTLE WATERS NORTH AMERICA | I9: 5772 JURUPA ST | J9: ONTARIO | K9: CA | L9: 91761-3672 | M9: . | N9: 4559249513 | O9: LUBR | P9: L0879-057 | Q9: 101936230 | R9: EA | S9: 2 | T9: LUBR | U9: L0879-057 | V9: 101936230 | W9: LUBRICANT PRODUCTS | X9: LUBR_L0879-057 | Y9: EA | AA9: 37.99 | AB9: 37.94 | AC9: =AB9*S9 -> 75.88 | AD9: =AA9*S9 -> 75.98 | AE9: =AC9-AD9 -> -0.1 | AF9: =AE9/AC9 -> -0.0013178703 | AG9: =IF(AF9<0,"Negative",IF(AF9=0,"Same",IF(AF9>0.3,"30+%",IF(AF9>0.2,"20-30%",IF(AF9>0.1,"10-20%",IF(AF9<=0.1,"0-10%")))))) -> Negative | AI9: YES | AJ9: 24
A10: 2842 | B10: 7020983939 | C10: 44258 | D10: NESTLE | E10: NESTLE - BOTTLED WATER | F10: 0001522689 | G10: 0001622857 | H10: NESTLE WATERS NORTH AMERICA | I10: 5772 JURUPA ST | J10: ONTARIO | K10: CA | L10: 91761-3672 | M10: STOCK FONTANA | N10: 4565538859 | O10: GOLD | P10: CFK1-7/16X48 | Q10: 101718970 | R10: EA | S10: 1 | T10: GOLD | U10: CFK1-7/16X48 | V10: 101718970 | W10: LINEAR MOTION PRODUCTS | X10: GOLD_CFK1-7/16X48 | Y10: EA | AA10: 76.025038 | AB10: 67.29 | AC10: =AB10*S10 -> 67.29 | AD10: =AA10*S10 -> 76.025038 | AE10: =AC10-AD10 -> -8.7350384 | AF10: =AE10/AC10 -> -0.12981183 | AG10: =IF(AF10<0,"Negative",IF(AF10=0,"Same",IF(AF10>0.3,"30+%",IF(AF10>0.2,"20-30%",IF(AF10>0.1,"10-20%",IF(AF10<=0.1,"0-10%")))))) -> Negative | AI10: NO | AJ10: 8
A11: 2842 | B11: 7020984018 | C11: 44258 | D11: NESTLE | E11: NESTLE - BOTTLED WATER | F11: 0001522689 | G11: 0001622857 | H11: NESTLE WATERS NORTH AMERICA | I11: 5772 JURUPA ST | J11: ONTARIO | K11: CA | L11: 91761-3672 | M11: . | N11: 4559249513 | O11: LUBR | P11: L0912-063 | Q11: 102070819 | R11: EA | S11: 12 | T11: LUBR | U11: L0931-063 | V11: 118643487 | W11: LUBRICANT PRODUCTS | X11: LUBR_L0931-063 | Y11: EA | AA11: 14.829004 | AB11: 14.09 | AC11: =AB11*S11 -> 169.08 | AD11: =AA11*S11 -> 177.94805 | AE11: =AC11-AD11 -> -8.8680521 | AF11: =AE11/AC11 -> -0.052448853 | AG11: =IF(AF11<0,"Negative",IF(AF11=0,"Same",IF(AF11>0.3,"30+%",IF(AF11>0.2,"20-30%",IF(AF11>0.1,"10-20%",IF(AF11<=0.1,"0-10%")))))) -> Negative | AI11: NO | AJ11: 48
A12: 2842 | B12: 7020984018 | C12: 44258 | D12: NESTLE | E12: NESTLE - BOTTLED WATER | F12: 0001522689 | G12: 0001622857 | H12: NESTLE WATERS NORTH AMERICA | I12: 5772 JURUPA ST | J12: ONTARIO | K12: CA | L12: 91761-3672 | M12: . | N12: 4559249513 | O12: LUBR | P12: L0311-098 | Q12: 112510875 | R12: EA | S12: 4 | T12: LUBR | U12: L0311-098 | V12: 112510875 | W12: LUBRICANT PRODUCTS | X12: LUBR_L0311-098 | Y12: EA | AA12: 16.804579 | AB12: 15.97 | AC12: =AB12*S12 -> 63.88 | AD12: =AA12*S12 -> 67.218316 | AE12: =AC12-AD12 -> -3.3383157 | AF12: =AE12/AC12 -> -0.052259169 | AG12: =IF(AF12<0,"Negative",IF(AF12=0,"Same",IF(AF12>0.3,"30+%",IF(AF12>0.2,"20-30%",IF(AF12>0.1,"10-20%",IF(AF12<=0.1,"0-10%")))))) -> Negative | AI12: NO | AJ12: 0
A13: 2842 | B13: 7020989500 | C13: 44259 | D13: NESTLE | E13: NESTLE - BOTTLED WATER | F13: 0001522689 | G13: 0001622857 | H13: NESTLE WATERS NORTH AMERICA | I13: 5772 JURUPA ST | J13: ONTARIO | K13: CA | L13: 91761-3672 | M13: . | N13: 4559249513 | O13: LUBR | P13: L0917-057 | Q13: 101352292 | R13: EA | S13: 1 | T13: LUBR | U13: L0917-057 | V13: 101352292 | W13: LUBRICANT PRODUCTS | X13: LUBR_L0917-057 | Y13: EA | AA13: 59.81 | AB13: 62.08 | AC13: =AB13*S13 -> 62.08 | AD13: =AA13*S13 -> 59.81 | AE13: =AC13-AD13 -> 2.27 | AF13: =AE13/AC13 -> 0.036565722 | AG13: =IF(AF13<0,"Negative",IF(AF13=0,"Same",IF(AF13>0.3,"30+%",IF(AF13>0.2,"20-30%",IF(AF13>0.1,"10-20%",IF(AF13<=0.1,"0-10%")))))) -> 0-10% | AI13: YES | AJ13: 24
A14: 2756 | B14: 7021021723 | C14: 44264 | D14: NESTLE | E14: NESTLE - BOTTLED WATER | F14: 0001522689 | G14: 0001621275 | H14: NESTLE WATERS / ICE MTN | I14: 19275 8 MILE RD US PL NW | J14: STANWOOD | K14: MI | L14: 49346-8806 | M14: 104450558 | N14: 4565700572 | O14: DONA | P14: 1C220048-25 | Q14: 110988151 | R14: EA | S14: 2 | T14: DONA | U14: 1C220048-25 | V14: 110988151 | W14: FLUID POWER | X14: DONA_1C220048-25 | Y14: EA | AA14: 243.49 | AB14: 237.11 | AC14: =AB14*S14 -> 474.22 | AD14: =AA14*S14 -> 486.98 | AE14: =AC14-AD14 -> -12.76 | AF14: =AE14/AC14 -> -0.026907343 | AG14: =IF(AF14<0,"Negative",IF(AF14=0,"Same",IF(AF14>0.3,"30+%",IF(AF14>0.2,"20-30%",IF(AF14>0.1,"10-20%",IF(AF14<=0.1,"0-10%")))))) -> Negative | AH14: SPECIAL PRICING. WILL NEED TO CONFIRM MFR WILL EXTEND. | AI14: NO | AJ14: 0
A15: 2154 | B15: 7021031552 | C15: 44265 | D15: NESTLE | E15: NESTLE - BOTTLED WATER | F15: 0001522689 | G15: 0001602753 | H15: NESTLE WATERS NORTH AMERICA | I15: 305 NESTLE WAY | J15: BREINIGSVILLE | K15: PA | L15: 18031-1422 | M15: 103268278 | N15: 4565334831 | O15: MAGT | P15: SI-N3/V | Q15: 105081744 | R15: EA | S15: 1 | T15: MAGT | U15: SI-N3/V | V15: 105081744 | W15: ELECTRICAL POWER TRANSMISSION | X15: MAGT_SI-N3/V | Y15: EA | Z15: FPA/POR | AA15: 150.5 | AB15: 150.28758 | AC15: =AB15*S15 -> 150.28758 | AD15: =AA15*S15 -> 150.5 | AE15: =AC15-AD15 -> -0.21242077 | AF15: =AE15/AC15 -> -0.0014134286 | AG15: =IF(AF15<0,"Negative",IF(AF15=0,"Same",IF(AF15>0.3,"30+%",IF(AF15>0.2,"20-30%",IF(AF15>0.1,"10-20%",IF(AF15<=0.1,"0-10%")))))) -> Negative | AI15: NO | AJ15: 0
A16: 2842 | B16: 7021036374 | C16: 44265 | D16: NESTLE | E16: NESTLE - BOTTLED WATER | F16: 0001522689 | G16: 0001622857 | H16: NESTLE WATERS NORTH AMERICA | I16: 5772 JURUPA ST | J16: ONTARIO | K16: CA | L16: 91761-3672 | M16: 102020187 | N16: 4565728191 | O16: BALD | P16: VM3538 | Q16: 101002986 | R16: EA | S16: 1 | T16: BALD | U16: VM3538 | V16: 101002986 | W16: ELECTRICAL POWER TRANSMISSION | X16: BALD_VM3538 | Y16: EA | AA16: 276.84 | AB16: 309.08 | AC16: =AB16*S16 -> 309.08 | AD16: =AA16*S16 -> 276.84 | AE16: =AC16-AD16 -> 32.24 | AF16: =AE16/AC16 -> 0.10430956 | AG16: =IF(AF16<0,"Negative",IF(AF16=0,"Same",IF(AF16>0.3,"30+%",IF(AF16>0.2,"20-30%",IF(AF16>0.1,"10-20%",IF(AF16<=0.1,"0-10%")))))) -> 10-20% | AI16: YES | AJ16: 161
A17: 2842 | B17: 7021055909 | C17: 44267 | D17: NESTLE | E17: NESTLE - BOTTLED WATER | F17: 0001522689 | G17: 0001622857 | H17: NESTLE WATERS NORTH AMERICA | I17: 5772 JURUPA ST | J17: ONTARIO | K17: CA | L17: 91761-3672 | M17: . | N17: 4565728191 | O17: BOST | P17: HF724-50-B5-H-P23 | Q17: 110277525 | R17: EA | S17: 1 | T17: BOST | U17: HF724-50-B5-H-P23 | V17: 110277525 | W17: MECHANICAL POWER TRANSMISSION | X17: BOST_HF724-50-B5-H-P23 | Y17: EA | AA17: 862.98 | AB17: 1044.78 | AC17: =AB17*S17 -> 1044.78 | AD17: =AA17*S17 -> 862.98 | AE17: =AC17-AD17 -> 181.8 | AF17: =AE17/AC17 -> 0.17400793 | AG17: =IF(AF17<0,"Negative",IF(AF17=0,"Same",IF(AF17>0.3,"30+%",IF(AF17>0.2,"20-30%",IF(AF17>0.1,"10-20%",IF(AF17<=0.1,"0-10%")))))) -> 10-20% | AI17: NO | AJ17: 0
A18: 2258 | B18: 7021060498 | C18: 44267 | D18: NESTLE | E18: NESTLE - BOTTLED WATER | F18: 0001505447 | G18: 0001505447 | H18: ZEPHYRHILLS BOTTLED WATER | I18: 4330 20TH ST | J18: ZEPHYRHILLS | K18: FL | L18: 33542-6797 | M18: . | N18: 4565319604 | O18: RADC | P18: C09-0F | Q18: 105797530 | R18: EA | S18: 1 | T18: RADC | U18: C09-0F | V18: 105797530 | W18: MECHANICAL POWER TRANSMISSION | X18: RADC_C09-0F | Y18: EA | AA18: 447.85 | AB18: 608.00552 | AC18: =AB18*S18 -> 608.00552 | AD18: =AA18*S18 -> 447.85 | AE18: =AC18-AD18 -> 160.15552 | AF18: =AE18/AC18 -> 0.26341129 | AG18: =IF(AF18<0,"Negative",IF(AF18=0,"Same",IF(AF18>0.3,"30+%",IF(AF18>0.2,"20-30%",IF(AF18>0.1,"10-20%",IF(AF18<=0.1,"0-10%")))))) -> 20-30% | AI18: NO | AJ18: 0
A19: 2842 | B19: 7021067060 | C19: 44270 | D19: NESTLE | E19: NESTLE - BOTTLED WATER | F19: 0001522689 | G19: 0001622857 | H19: NESTLE WATERS NORTH AMERICA | I19: 5772 JURUPA ST | J19: ONTARIO | K19: CA | L19: 91761-3672 | M19: 7-10 DAYS ARO | N19: 4565641034 | O19: HYDR | P19: L2K-3648 | Q19: 118062645 | R19: EA | S19: 1 | T19: HYDR | U19: L2K-3648 | V19: 118062645 | W19: TOOLS | X19: HYDR_L2K-3648 | Y19: EA | Z19: FPA/POR | AA19: 2204.715 | AB19: 2325.3 | AC19: =AB19*S19 -> 2325.3 | AD19: =AA19*S19 -> 2204.715 | AE19: =AC19-AD19 -> 120.585 | AF19: =AE19/AC19 -> 0.051857826 | AG19: =IF(AF19<0,"Negative",IF(AF19=0,"Same",IF(AF19>0.3,"30+%",IF(AF19>0.2,"20-30%",IF(AF19>0.1,"10-20%",IF(AF19<=0.1,"0-10%")))))) -> 0-10% | AI19: NO | AJ19: 0
A20: 2842 | B20: 7021084449 | C20: 44271 | D20: NESTLE | E20: NESTLE - BOTTLED WATER | F20: 0001522689 | G20: 0001622857 | H20: NESTLE WATERS NORTH AMERICA | I20: 5772 JURUPA ST | J20: ONTARIO | K20: CA | L20: 91761-3672 | M20: . | N20: 4565788529 | O20: UST | P20: 50 2RIV | Q20: 100800671 | R20: FT | S20: 120 | T20: UST | U20: 50 2RIV | V20: 100800671 | W20: MECHANICAL POWER TRANSMISSION | X20: UST_50 2RIV | Y20: FT | AA20: 20.06 | AB20: 19.67 | AC20: =AB20*S20 -> 2360.4 | AD20: =AA20*S20 -> 2407.2 | AE20: =AC20-AD20 -> -46.8 | AF20: =AE20/AC20 -> -0.019827148 | AG20: =IF(AF20<0,"Negative",IF(AF20=0,"Same",IF(AF20>0.3,"30+%",IF(AF20>0.2,"20-30%",IF(AF20>0.1,"10-20%",IF(AF20<=0.1,"0-10%")))))) -> Negative | AI20: YES | AJ20: 570
A21: 2842 | B21: 7021084502 | C21: 44271 | D21: NESTLE | E21: NESTLE - BOTTLED WATER | F21: 0001522689 | G21: 0001622857 | H21: NESTLE WATERS NORTH AMERICA | I21: 5772 JURUPA ST | J21: ONTARIO | K21: CA | L21: 91761-3672 | M21: SUB FOR 4ZM15 | N21: 4565702409 | O21: PARK | P21: 06R218AC | Q21: 100493731 | R21: EA | S21: 2 | T21: PARK | U21: 06R218AC | V21: 100493731 | W21: FLUID POWER | X21: PARK_06R218AC | Y21: EA | AA21: 62.389966 | AB21: 60.75 | AC21: =AB21*S21 -> 121.5 | AD21: =AA21*S21 -> 124.77993 | AE21: =AC21-AD21 -> -3.2799328 | AF21: =AE21/AC21 -> -0.026995332 | AG21: =IF(AF21<0,"Negative",IF(AF21=0,"Same",IF(AF21>0.3,"30+%",IF(AF21>0.2,"20-30%",IF(AF21>0.1,"10-20%",IF(AF21<=0.1,"0-10%")))))) -> Negative | AI21: YES | AJ21: 11
A22: 2756 | B22: 7021090480 | C22: 44272 | D22: NESTLE | E22: NESTLE - BOTTLED WATER | F22: 0001522689 | G22: 0001621275 | H22: NESTLE WATERS / ICE MTN | I22: 19275 8 MILE RD US PL NW | J22: STANWOOD | K22: MI | L22: 49346-8806 | M22: 101980156 | N22: 4565764009 | O22: DONA | P22: 1C125164 | Q22: 110223931 | R22: EA | S22: 2 | T22: DONA | U22: 1C125164 | V22: 110223931 | W22: FLUID POWER | X22: DONA_1C125164 | Y22: EA | AA22: 337.03774 | AB22: 359.33333 | AC22: =AB22*S22 -> 718.66667 | AD22: =AA22*S22 -> 674.07547 | AE22: =AC22-AD22 -> 44.591195 | AF22: =AE22/AC22 -> 0.062047117 | AG22: =IF(AF22<0,"Negative",IF(AF22=0,"Same",IF(AF22>0.3,"30+%",IF(AF22>0.2,"20-30%",IF(AF22>0.1,"10-20%",IF(AF22<=0.1,"0-10%")))))) -> 0-10% | AH22: SPECIAL PRICING. WILL NEED TO CONFIRM MFR WILL EXTEND. | AI22: NO | AJ22: 0
A23: 2756 | B23: 7021090480 | C23: 44272 | D23: NESTLE | E23: NESTLE - BOTTLED WATER | F23: 0001522689 | G23: 0001621275 | H23: NESTLE WATERS / ICE MTN | I23: 19275 8 MILE RD US PL NW | J23: STANWOOD | K23: MI | L23: 49346-8806 | M23: 104333951 | N23: 4565764009 | O23: DONA | P23: 1C125764 | Q23: 110224139 | R23: EA | S23: 2 | T23: DONA | U23: 1C125764 | V23: 110224139 | W23: FLUID POWER | X23: DONA_1C125764 | Y23: EA | AA23: 381.77358 | AB23: 407 | AC23: =AB23*S23 -> 814 | AD23: =AA23*S23 -> 763.54717 | AE23: =AC23-AD23 -> 50.45283 | AF23: =AE23/AC23 -> 0.061981364 | AG23: =IF(AF23<0,"Negative",IF(AF23=0,"Same",IF(AF23>0.3,"30+%",IF(AF23>0.2,"20-30%",IF(AF23>0.1,"10-20%",IF(AF23<=0.1,"0-10%")))))) -> 0-10% | AH23: SPECIAL PRICING. WILL NEED TO CONFIRM MFR WILL EXTEND. | AI23: YES | AJ23: 4
A24: 2756 | B24: 7021090480 | C24: 44272 | D24: NESTLE | E24: NESTLE - BOTTLED WATER | F24: 0001522689 | G24: 0001621275 | H24: NESTLE WATERS / ICE MTN | I24: 19275 8 MILE RD US PL NW | J24: STANWOOD | K24: MI | L24: 49346-8806 | M24: 101131844 | N24: 4565764009 | O24: DONA | P24: 1C122164 | Q24: 103674709 | R24: EA | S24: 2 | T24: DONA | U24: 1C122164 | V24: 103674709 | W24: FLUID POWER | X24: DONA_1C122164 | Y24: EA | AA24: 378.88679 | AB24: 404.06667 | AC24: =AB24*S24 -> 808.13333 | AD24: =AA24*S24 -> 757.77358 | AE24: =AC24-AD24 -> 50.359748 | AF24: =AE24/AC24 -> 0.062316138 | AG24: =IF(AF24<0,"Negative",IF(AF24=0,"Same",IF(AF24>0.3,"30+%",IF(AF24>0.2,"20-30%",IF(AF24>0.1,"10-20%",IF(AF24<=0.1,"0-10%")))))) -> 0-10% | AH24: SPECIAL PRICING. WILL NEED TO CONFIRM MFR WILL EXTEND. | AI24: NO | AJ24: 0
A25: 2756 | B25: 7021090480 | C25: 44272 | D25: NESTLE | E25: NESTLE - BOTTLED WATER | F25: 0001522689 | G25: 0001621275 | H25: NESTLE WATERS / ICE MTN | I25: 19275 8 MILE RD US PL NW | J25: STANWOOD | K25: MI | L25: 49346-8806 | M25: 101163015 | N25: 4565764009 | O25: DONA | P25: 1C124364 | Q25: 103720400 | R25: EA | S25: 4 | T25: DONA | U25: 1C124364 | V25: 103720400 | W25: FLUID POWER | X25: DONA_1C124364 | Y25: EA | AA25: 461.16981 | AB25: 489.86667 | AC25: =AB25*S25 -> 1959.4667 | AD25: =AA25*S25 -> 1844.6792 | AE25: =AC25-AD25 -> 114.78742 | AF25: =AE25/AC25 -> 0.058580951 | AG25: =IF(AF25<0,"Negative",IF(AF25=0,"Same",IF(AF25>0.3,"30+%",IF(AF25>0.2,"20-30%",IF(AF25>0.1,"10-20%",IF(AF25<=0.1,"0-10%")))))) -> 0-10% | AH25: SPECIAL PRICING. WILL NEED TO CONFIRM MFR WILL EXTEND. | AI25: NO | AJ25: 0
A26: 2842 | B26: 7021092278 | C26: 44272 | D26: NESTLE | E26: NESTLE - BOTTLED WATER | F26: 0001522689 | G26: 0001622857 | H26: NESTLE WATERS NORTH AMERICA | I26: 5772 JURUPA ST | J26: ONTARIO | K26: CA | L26: 91761-3672 | M26: . | N26: 4559249513 | O26: LUBR | P26: L0815-057 | Q26: 101644298 | R26: EA | S26: 2 | T26: LUBR | U26: L0815-057 | V26: 101644298 | W26: LUBRICANT PRODUCTS | X26: LUBR_L0815-057 | Y26: EA | AA26: 74.073581 | AB26: 70.36 | AC26: =AB26*S26 -> 140.72 | AD26: =AA26*S26 -> 148.14716 | AE26: =AC26-AD26 -> -7.4271617 | AF26: =AE26/AC26 -> -0.052779716 | AG26: =IF(AF26<0,"Negative",IF(AF26=0,"Same",IF(AF26>0.3,"30+%",IF(AF26>0.2,"20-30%",IF(AF26>0.1,"10-20%",IF(AF26<=0.1,"0-10%")))))) -> Negative | AI26: NO | AJ26: 0
A27: 2842 | B27: 7021112279 | C27: 44274 | D27: NESTLE | E27: NESTLE - BOTTLED WATER | F27: 0001522689 | G27: 0001622857 | H27: NESTLE WATERS NORTH AMERICA | I27: 5772 JURUPA ST | J27: ONTARIO | K27: CA | L27: 91761-3672 | M27: . | N27: 4565788529 | O27: CONT | P27: 2/B173 | Q27: 100774314 | R27: EA | S27: 1 | T27: CONT | U27: 2/B173 | V27: 100774314 | W27: MECHANICAL POWER TRANSMISSION | X27: CONT_2/B173 | Y27: EA | AA27: 57.49 | AB27: 75.937774 | AC27: =AB27*S27 -> 75.937774 | AD27: =AA27*S27 -> 57.49 | AE27: =AC27-AD27 -> 18.447774 | AF27: =AE27/AC27 -> 0.24293277 | AG27: =IF(AF27<0,"Negative",IF(AF27=0,"Same",IF(AF27>0.3,"30+%",IF(AF27>0.2,"20-30%",IF(AF27>0.1,"10-20%",IF(AF27<=0.1,"0-10%")))))) -> 20-30% | AI27: NO | AJ27: 0
A28: 2842 | B28: 7021112301 | C28: 44274 | D28: NESTLE | E28: NESTLE - BOTTLED WATER | F28: 0001522689 | G28: 0001622857 | H28: NESTLE WATERS NORTH AMERICA | I28: 5772 JURUPA ST | J28: ONTARIO | K28: CA | L28: 91761-3672 | M28: . | N28: 4565338850 | O28: EURO | P28: FA47 DRN90S4/BE2HR | Q28: 117987332 | R28: EA | S28: 1 | T28: EURO | U28: FA47 DRN90S4/BE2HR | V28: 117987332 | W28: MECHANICAL POWER TRANSMISSION | X28: EURO_FA47 DRN90S4/BE2HR | Y28: EA | Z28: FPA/POR | AA28: 1062.5682 | AB28: 1128.89 | AC28: =AB28*S28 -> 1128.89 | AD28: =AA28*S28 -> 1062.5682 | AE28: =AC28-AD28 -> 66.321818 | AF28: =AE28/AC28 -> 0.058749584 | AG28: =IF(AF28<0,"Negative",IF(AF28=0,"Same",IF(AF28>0.3,"30+%",IF(AF28>0.2,"20-30%",IF(AF28>0.1,"10-20%",IF(AF28<=0.1,"0-10%")))))) -> 0-10% | AI28: NO | AJ28: 0
A29: 2842 | B29: 7021134683 | C29: 44278 | D29: NESTLE | E29: NESTLE - BOTTLED WATER | F29: 0001522689 | G29: 0001622857 | H29: NESTLE WATERS NORTH AMERICA | I29: 5772 JURUPA ST | J29: ONTARIO | K29: CA | L29: 91761-3672 | M29: . | N29: 4565788529 | O29: MART | P29: D50B18HX1 3/4W/KW | Q29: 103986911 | R29: EA | S29: 4 | T29: MART | U29: D50B18HX1 3/4W/KW | V29: 103986911 | W29: MECHANICAL POWER TRANSMISSION | X29: MART_D50B18HX1 3/4W/KW | Y29: EA | Z29: FPA/POR | AA29: 105.99953 | AB29: 94.62 | AC29: =AB29*S29 -> 378.48 | AD29: =AA29*S29 -> 423.99811 | AE29: =AC29-AD29 -> -45.518114 | AF29: =AE29/AC29 -> -0.12026557 | AG29: =IF(AF29<0,"Negative",IF(AF29=0,"Same",IF(AF29>0.3,"30+%",IF(AF29>0.2,"20-30%",IF(AF29>0.1,"10-20%",IF(AF29<=0.1,"0-10%")))))) -> Negative | AI29: NO | AJ29: 0
A30: 2842 | B30: 7021134683 | C30: 44278 | D30: NESTLE | E30: NESTLE - BOTTLED WATER | F30: 0001522689 | G30: 0001622857 | H30: NESTLE WATERS NORTH AMERICA | I30: 5772 JURUPA ST | J30: ONTARIO | K30: CA | L30: 91761-3672 | M30: . | N30: 4565788529 | O30: MART | P30: D50B15H/1 3/4"BORE | Q30: 105647539 | R30: EA | S30: 6 | T30: MART | U30: D50B15H/1 3/4"BORE | V30: 105647539 | W30: MECHANICAL POWER TRANSMISSION | X30: MART_D50B15H/1 3/4"BORE | Y30: EA | Z30: FPA/POR | AA30: 101.69467 | AB30: 90.78 | AC30: =AB30*S30 -> 544.68 | AD30: =AA30*S30 -> 610.16802 | AE30: =AC30-AD30 -> -65.488018 | AF30: =AE30/AC30 -> -0.1202321 | AG30: =IF(AF30<0,"Negative",IF(AF30=0,"Same",IF(AF30>0.3,"30+%",IF(AF30>0.2,"20-30%",IF(AF30>0.1,"10-20%",IF(AF30<=0.1,"0-10%")))))) -> Negative | AI30: NO | AJ30: 0
A31: 2842 | B31: 7021158052 | C31: 44280 | D31: NESTLE | E31: NESTLE - BOTTLED WATER | F31: 0001522689 | G31: 0001622857 | H31: NESTLE WATERS NORTH AMERICA | I31: 5772 JURUPA ST | J31: ONTARIO | K31: CA | L31: 91761-3672 | M31: . | N31: 4565472905 | O31: SKF | P31: LAPT 1000SW | Q31: 116164215 | R31: EA | S31: 1 | T31: SKF | U31: LAPT 1000SW | V31: 116164215 | W31: FLUID POWER | X31: SKF_LAPT 1000SW | Y31: EA | Z31: FPA/POR | AA31: 23.194869 | AB31: 22.59 | AC31: =AB31*S31 -> 22.59 | AD31: =AA31*S31 -> 23.194869 | AE31: =AC31-AD31 -> -0.60486928 | AF31: =AE31/AC31 -> -0.026775975 | AG31: =IF(AF31<0,"Negative",IF(AF31=0,"Same",IF(AF31>0.3,"30+%",IF(AF31>0.2,"20-30%",IF(AF31>0.1,"10-20%",IF(AF31<=0.1,"0-10%")))))) -> Negative | AI31: NO | AJ31: 0
A32: 2756 | B32: 7021158877 | C32: 44280 | D32: NESTLE | E32: NESTLE - BOTTLED WATER | F32: 0001522689 | G32: 0001621275 | H32: NESTLE WATERS / ICE MTN | I32: 19275 8 MILE RD US PL NW | J32: STANWOOD | K32: MI | L32: 49346-8806 | M32: 101163040 | N32: 4565832251 | O32: DONA | P32: 1C120032-25 | Q32: 110986844 | R32: EA | S32: 7 | T32: DONA | U32: 1C120032-25 | V32: 110986844 | W32: FLUID POWER | X32: DONA_1C120032-25 | Y32: EA | AA32: 125.01 | AB32: 121.74 | AC32: =AB32*S32 -> 852.18 | AD32: =AA32*S32 -> 875.07 | AE32: =AC32-AD32 -> -22.89 | AF32: =AE32/AC32 -> -0.026860522 | AG32: =IF(AF32<0,"Negative",IF(AF32=0,"Same",IF(AF32>0.3,"30+%",IF(AF32>0.2,"20-30%",IF(AF32>0.1,"10-20%",IF(AF32<=0.1,"0-10%")))))) -> Negative | AH32: SPECIAL PRICING. WILL NEED TO CONFIRM MFR WILL EXTEND. | AI32: NO | AJ32: 0
A33: 2756 | B33: 7021170281 | C33: 44281 | D33: NESTLE | E33: NESTLE - BOTTLED WATER | F33: 0001522689 | G33: 0001621275 | H33: NESTLE WATERS / ICE MTN | I33: 19275 8 MILE RD US PL NW | J33: STANWOOD | K33: MI | L33: 49346-8806 | M33: 104450558 | N33: 4565799568 | O33: DONA | P33: 1C220048-25 | Q33: 110988151 | R33: EA | S33: 2 | T33: DONA | U33: 1C220048-25 | V33: 110988151 | W33: FLUID POWER | X33: DONA_1C220048-25 | Y33: EA | AA33: 243.49 | AB33: 237.11 | AC33: =AB33*S33 -> 474.22 | AD33: =AA33*S33 -> 486.98 | AE33: =AC33-AD33 -> -12.76 | AF33: =AE33/AC33 -> -0.026907343 | AG33: =IF(AF33<0,"Negative",IF(AF33=0,"Same",IF(AF33>0.3,"30+%",IF(AF33>0.2,"20-30%",IF(AF33>0.1,"10-20%",IF(AF33<=0.1,"0-10%")))))) -> Negative | AH33: SPECIAL PRICING. WILL NEED TO CONFIRM MFR WILL EXTEND. | AI33: NO | AJ33: 0
A34: 2756 | B34: 7021170281 | C34: 44281 | D34: NESTLE | E34: NESTLE - BOTTLED WATER | F34: 0001522689 | G34: 0001621275 | H34: NESTLE WATERS / ICE MTN | I34: 19275 8 MILE RD US PL NW | J34: STANWOOD | K34: MI | L34: 49346-8806 | M34: 101163015 | N34: 4565799568 | O34: DONA | P34: 1C124364 | Q34: 103720400 | R34: EA | S34: 2 | T34: DONA | U34: 1C124364 | V34: 103720400 | W34: FLUID POWER | X34: DONA_1C124364 | Y34: EA | AA34: 461.16981 | AB34: 489.86667 | AC34: =AB34*S34 -> 979.73333 | AD34: =AA34*S34 -> 922.33962 | AE34: =AC34-AD34 -> 57.393711 | AF34: =AE34/AC34 -> 0.058580951 | AG34: =IF(AF34<0,"Negative",IF(AF34=0,"Same",IF(AF34>0.3,"30+%",IF(AF34>0.2,"20-30%",IF(AF34>0.1,"10-20%",IF(AF34<=0.1,"0-10%")))))) -> 0-10% | AH34: SPECIAL PRICING. WILL NEED TO CONFIRM MFR WILL EXTEND. | AI34: NO | AJ34: 0
A35: 2842 | B35: 7021181450 | C35: 44284 | D35: NESTLE | E35: NESTLE - BOTTLED WATER | F35: 0001522689 | G35: 0001622857 | H35: NESTLE WATERS NORTH AMERICA | I35: 5772 JURUPA ST | J35: ONTARIO | K35: CA | L35: 91761-3672 | M35: . | N35: 4565472905 | O35: SKF | P35: LAPF M1/8 | Q35: 101169783 | R35: EA | S35: 10 | T35: SKF | U35: LAPF M1/8 | V35: 101169783 | W35: LUBRICANT PRODUCTS | X35: SKF_LAPF M1/8 | Y35: EA | AA35: 12.268361 | AB35: 11.65 | AC35: =AB35*S35 -> 116.5 | AD35: =AA35*S35 -> 122.68361 | AE35: =AC35-AD35 -> -6.1836061 | AF35: =AE35/AC35 -> -0.053078164 | AG35: =IF(AF35<0,"Negative",IF(AF35=0,"Same",IF(AF35>0.3,"30+%",IF(AF35>0.2,"20-30%",IF(AF35>0.1,"10-20%",IF(AF35<=0.1,"0-10%")))))) -> Negative | AI35: NO | AJ35: 0
A36: 2842 | B36: 7021181450 | C36: 44284 | D36: NESTLE | E36: NESTLE - BOTTLED WATER | F36: 0001522689 | G36: 0001622857 | H36: NESTLE WATERS NORTH AMERICA | I36: 5772 JURUPA ST | J36: ONTARIO | K36: CA | L36: 91761-3672 | M36: . | N36: 4565472905 | O36: SKF | P36: LAPP 4 | Q36: 105988901 | R36: EA | S36: 4 | T36: SKF | U36: LAPP 4 | V36: 105988901 | W36: LUBRICANT PRODUCTS | X36: SKF_LAPP 4 | Y36: EA | AA36: 41.414356 | AB36: 39.33 | AC36: =AB36*S36 -> 157.32 | AD36: =AA36*S36 -> 165.65742 | AE36: =AC36-AD36 -> -8.3374237 | AF36: =AE36/AC36 -> -0.052996591 | AG36: =IF(AF36<0,"Negative",IF(AF36=0,"Same",IF(AF36>0.3,"30+%",IF(AF36>0.2,"20-30%",IF(AF36>0.1,"10-20%",IF(AF36<=0.1,"0-10%")))))) -> Negative | AI36: NO | AJ36: 0
A37: 2842 | B37: 7021181565 | C37: 44281 | D37: NESTLE | E37: NESTLE - BOTTLED WATER | F37: 0001522689 | G37: 0001622857 | H37: NESTLE WATERS NORTH AMERICA | I37: 5772 JURUPA ST | J37: ONTARIO | K37: CA | L37: 91761-3672 | M37: STOCK FONTANA | N37: 4565882360 | O37: GENE | P37: 99R10 | Q37: 102056192 | R37: EA | S37: 7 | T37: GENE | U37: 99R10 | V37: 102056192 | W37: BEARINGS | X37: GENE_99R10 | Y37: EA | AA37: 7.66 | AB37: 7.69 | AC37: =AB37*S37 -> 53.83 | AD37: =AA37*S37 -> 53.62 | AE37: =AC37-AD37 -> 0.21 | AF37: =AE37/AC37 -> 0.0039011704 | AG37: =IF(AF37<0,"Negative",IF(AF37=0,"Same",IF(AF37>0.3,"30+%",IF(AF37>0.2,"20-30%",IF(AF37>0.1,"10-20%",IF(AF37<=0.1,"0-10%")))))) -> 0-10% | AI37: NO | AJ37: 142
A38: 2842 | B38: 7021278120 | C38: 44295 | D38: NESTLE | E38: NESTLE - BOTTLED WATER | F38: 0001522689 | G38: 0001622857 | H38: NESTLE WATERS NORTH AMERICA | I38: 5772 JURUPA ST | J38: ONTARIO | K38: CA | L38: 91761-3672 | M38: . | N38: 4566035007 | O38: CHPN | P38: 2PLY BLK R/T 12" WIDE | Q38: 117560324 | R38: FT | S38: 100 | T38: CHPN | U38: 2PLY BLK R/T 12" WIDE | V38: 117560324 | W38: MATERIAL HANDLING | X38: CHPN_2PLY BLK R/T 12" WIDE | Y38: FT | Z38: FPA/POR | AA38: 3.4 | AB38: 3.5 | AC38: =AB38*S38 -> 350 | AD38: =AA38*S38 -> 340 | AE38: =AC38-AD38 -> 10 | AF38: =AE38/AC38 -> 0.028571429 | AG38: =IF(AF38<0,"Negative",IF(AF38=0,"Same",IF(AF38>0.3,"30+%",IF(AF38>0.2,"20-30%",IF(AF38>0.1,"10-20%",IF(AF38<=0.1,"0-10%")))))) -> 0-10% | AI38: NO | AJ38: 0
A39: 2154 | B39: 7021283977 | C39: 44298 | D39: NESTLE | E39: NESTLE - BOTTLED WATER | F39: 0001522689 | G39: 0001602753 | H39: NESTLE WATERS NORTH AMERICA | I39: 305 NESTLE WAY | J39: BREINIGSVILLE | K39: PA | L39: 18031-1422 | M39: 103268278 | N39: 4565894673 | O39: MAGT | P39: SI-N3/V | Q39: 105081744 | R39: EA | S39: 1 | T39: MAGT | U39: SI-N3/V | V39: 105081744 | W39: ELECTRICAL POWER TRANSMISSION | X39: MAGT_SI-N3/V | Y39: EA | Z39: FPA/POR | AA39: 150.5 | AB39: 150.28758 | AC39: =AB39*S39 -> 150.28758 | AD39: =AA39*S39 -> 150.5 | AE39: =AC39-AD39 -> -0.21242077 | AF39: =AE39/AC39 -> -0.0014134286 | AG39: =IF(AF39<0,"Negative",IF(AF39=0,"Same",IF(AF39>0.3,"30+%",IF(AF39>0.2,"20-30%",IF(AF39>0.1,"10-20%",IF(AF39<=0.1,"0-10%")))))) -> Negative | AI39: NO | AJ39: 0
A40: 2756 | B40: 7021285567 | C40: 44298 | D40: NESTLE | E40: NESTLE - BOTTLED WATER | F40: 0001522689 | G40: 0001621275 | H40: NESTLE WATERS / ICE MTN | I40: 19275 8 MILE RD US PL NW | J40: STANWOOD | K40: MI | L40: 49346-8806 | M40: 101163044 | N40: 4565933404 | O40: DONA | P40: 1C121732 | Q40: 113480827 | R40: EA | S40: 1 | T40: DONA | U40: 1C121732 | V40: 113480827 | W40: FLUID POWER | X40: DONA_1C121732 | Y40: EA | AA40: 131.34906 | AB40: 140.06667 | AC40: =AB40*S40 -> 140.06667 | AD40: =AA40*S40 -> 131.34906 | AE40: =AC40-AD40 -> 8.7176101 | AF40: =AE40/AC40 -> 0.062239006 | AG40: =IF(AF40<0,"Negative",IF(AF40=0,"Same",IF(AF40>0.3,"30+%",IF(AF40>0.2,"20-30%",IF(AF40>0.1,"10-20%",IF(AF40<=0.1,"0-10%")))))) -> 0-10% | AH40: SPECIAL PRICING. WILL NEED TO CONFIRM MFR WILL EXTEND. | AI40: NO | AJ40: 0
...
