Workbook

Sheet SUMMARY
A1: 44631
A2: CATEGORY | B2: SKU COUNT | C2: APPVION EXT | D2: PA EXT | E2: DIFF $ | F2: DIFF %
A3: BEARINGS; | B3: =COUNTIF('Transaction Details'!R:R,SUMMARY!A3) -> 225 | C3: =SUMPRODUCT( --($A3='Transaction Details'!$R:$R),'Transaction Details'!AD:AD) -> 57312.5 | D3: =SUMPRODUCT( --($A3='Transaction Details'!$R:$R),'Transaction Details'!AE:AE) -> 54302.9 | E3: =SUMPRODUCT( --($A3='Transaction Details'!$R:$R),'Transaction Details'!AF:AF) -> 3009.6 | F3: =E3/C3 -> 0.052512105
A4: CHEMICALS; | B4: =COUNTIF('Transaction Details'!R:R,SUMMARY!A4) -> 97 | C4: =SUMPRODUCT( --($A4='Transaction Details'!$R:$R),'Transaction Details'!AD:AD) -> 184354.08 | D4: =SUMPRODUCT( --($A4='Transaction Details'!$R:$R),'Transaction Details'!AE:AE) -> 184324.53 | E4: =SUMPRODUCT( --($A4='Transaction Details'!$R:$R),'Transaction Details'!AF:AF) -> 29.55 | F4: =E4/C4 -> 0.00016028937
A5: ELECTRICAL POWER TRANSMISSION; | B5: =COUNTIF('Transaction Details'!R:R,SUMMARY!A5) -> 25 | C5: =SUMPRODUCT( --($A5='Transaction Details'!$R:$R),'Transaction Details'!AD:AD) -> 21250.36 | D5: =SUMPRODUCT( --($A5='Transaction Details'!$R:$R),'Transaction Details'!AE:AE) -> 19623 | E5: =SUMPRODUCT( --($A5='Transaction Details'!$R:$R),'Transaction Details'!AF:AF) -> 1627.36 | F5: =E5/C5 -> 0.07658035
A6: FLUID POWER; | B6: =COUNTIF('Transaction Details'!R:R,SUMMARY!A6) -> 201 | C6: =SUMPRODUCT( --($A6='Transaction Details'!$R:$R),'Transaction Details'!AD:AD) -> 108966.27 | D6: =SUMPRODUCT( --($A6='Transaction Details'!$R:$R),'Transaction Details'!AE:AE) -> 105794.88 | E6: =SUMPRODUCT( --($A6='Transaction Details'!$R:$R),'Transaction Details'!AF:AF) -> 3171.39 | F6: =E6/C6 -> 0.029104327
A7: GENERAL INDUSTRIAL SUPPLY; | B7: =COUNTIF('Transaction Details'!R:R,SUMMARY!A7) -> 142 | C7: =SUMPRODUCT( --($A7='Transaction Details'!$R:$R),'Transaction Details'!AD:AD) -> 422545.62 | D7: =SUMPRODUCT( --($A7='Transaction Details'!$R:$R),'Transaction Details'!AE:AE) -> 406081.63 | E7: =SUMPRODUCT( --($A7='Transaction Details'!$R:$R),'Transaction Details'!AF:AF) -> 16463.99 | F7: =E7/C7 -> 0.038963816
A8: HOSE PRODUCTS; | B8: =COUNTIF('Transaction Details'!R:R,SUMMARY!A8) -> 26 | C8: =SUMPRODUCT( --($A8='Transaction Details'!$R:$R),'Transaction Details'!AD:AD) -> 10754.44 | D8: =SUMPRODUCT( --($A8='Transaction Details'!$R:$R),'Transaction Details'!AE:AE) -> 10269.04 | E8: =SUMPRODUCT( --($A8='Transaction Details'!$R:$R),'Transaction Details'!AF:AF) -> 485.4 | F8: =E8/C8 -> 0.045134847
A9: JANITORIAL; | B9: =COUNTIF('Transaction Details'!R:R,SUMMARY!A9) -> 54 | C9: =SUMPRODUCT( --($A9='Transaction Details'!$R:$R),'Transaction Details'!AD:AD) -> 12257.9 | D9: =SUMPRODUCT( --($A9='Transaction Details'!$R:$R),'Transaction Details'!AE:AE) -> 12705.25 | E9: =SUMPRODUCT( --($A9='Transaction Details'!$R:$R),'Transaction Details'!AF:AF) -> -447.35 | F9: =E9/C9 -> -0.036494832
A10: LINEAR MOTION PRODUCTS; | B10: =COUNTIF('Transaction Details'!R:R,SUMMARY!A10) -> 6 | C10: =SUMPRODUCT( --($A10='Transaction Details'!$R:$R),'Transaction Details'!AD:AD) -> 2442.65 | D10: =SUMPRODUCT( --($A10='Transaction Details'!$R:$R),'Transaction Details'!AE:AE) -> 2561.23 | E10: =SUMPRODUCT( --($A10='Transaction Details'!$R:$R),'Transaction Details'!AF:AF) -> -118.58 | F10: =E10/C10 -> -0.048545637
A11: LUBRICANT PRODUCTS; | B11: =COUNTIF('Transaction Details'!R:R,SUMMARY!A11) -> 45 | C11: =SUMPRODUCT( --($A11='Transaction Details'!$R:$R),'Transaction Details'!AD:AD) -> 4078.71 | D11: =SUMPRODUCT( --($A11='Transaction Details'!$R:$R),'Transaction Details'!AE:AE) -> 3929.74 | E11: =SUMPRODUCT( --($A11='Transaction Details'!$R:$R),'Transaction Details'!AF:AF) -> 148.97 | F11: =E11/C11 -> 0.036523803
A12: MATERIAL HANDLING; | B12: =COUNTIF('Transaction Details'!R:R,SUMMARY!A12) -> 19 | C12: =SUMPRODUCT( --($A12='Transaction Details'!$R:$R),'Transaction Details'!AD:AD) -> 13621.38 | D12: =SUMPRODUCT( --($A12='Transaction Details'!$R:$R),'Transaction Details'!AE:AE) -> 12513.9 | E12: =SUMPRODUCT( --($A12='Transaction Details'!$R:$R),'Transaction Details'!AF:AF) -> 1107.48 | F12: =E12/C12 -> 0.081304537
A13: MECHANICAL POWER TRANSMISSION; | B13: =COUNTIF('Transaction Details'!R:R,SUMMARY!A13) -> 223 | C13: =SUMPRODUCT( --($A13='Transaction Details'!$R:$R),'Transaction Details'!AD:AD) -> 84848.88 | D13: =SUMPRODUCT( --($A13='Transaction Details'!$R:$R),'Transaction Details'!AE:AE) -> 82111.2 | E13: =SUMPRODUCT( --($A13='Transaction Details'!$R:$R),'Transaction Details'!AF:AF) -> 2737.68 | F13: =E13/C13 -> 0.032265364
A14: SAFETY PRODUCTS; | B14: =COUNTIF('Transaction Details'!R:R,SUMMARY!A14) -> 44 | C14: =SUMPRODUCT( --($A14='Transaction Details'!$R:$R),'Transaction Details'!AD:AD) -> 6747.93 | D14: =SUMPRODUCT( --($A14='Transaction Details'!$R:$R),'Transaction Details'!AE:AE) -> 6860.5 | E14: =SUMPRODUCT( --($A14='Transaction Details'!$R:$R),'Transaction Details'!AF:AF) -> -112.57 | F14: =E14/C14 -> -0.016682153
... A16: TOOLS; | B16: =COUNTIF('Transaction Details'!R:R,SUMMARY!A16) -> 28 | C16: =SUMPRODUCT( --($A16='Transaction Details'!$R:$R),'Transaction Details'!AD:AD) -> 5884.43 | D16: =SUMPRODUCT( --($A16='Transaction Details'!$R:$R),'Transaction Details'!AE:AE) -> 5900.59 | E16: =SUMPRODUCT( --($A16='Transaction Details'!$R:$R),'Transaction Details'!AF:AF) -> -16.16 | F16: =E16/C16 -> -0.0027462303
A17: TOTAL | B17: =SUM(B3:B16) -> 1230 | C17: =SUM(C3:C16) -> 944219.43 | D17: =SUM(D3:D16) -> 915116.13 | E17: =SUM(E3:E16) -> 29103.3 | F17: =E17/C17 -> 0.030822602

Sheet Transaction Details
A2: SC | B2: Billing Document Number | C2: Billing Date | D2: Master Customer (Heading) | E2: Master Customer Division (Heading) | F2: Sold-To-Party | G2: Ship-To Party | H2: Ship-To Party (Heading) | I2: Street Address | J2: City | K2: State | L2: Postal Code | M2: Customer Material Number | N2: Customer Purchase Order Number | O2: MFG Code | P2: Manufacturer Part Number | Q2: Material | R2: Product hierarchy level 1 (Heading) | S2: UOM | T2: Billing Quantity | U2: 1ST SAP MFR | V2: 1ST SAP PN | W2: 1ST SAP MATERIAL# | X2: 1ST SAP HIERARCHY | Y2: 1ST SAP DESCRIPTION | Z2: 1ST SAP UOM | AA2: 1ST SAP MATERIAL STATUS | AB2: PA PRICE | AC2: APPVION PRICE | AD2: APPVION EXT | AE2: PA EXT | AF2: DIFF $ | AG2: DIFF % | AH2: SAVINGS CATEGORY | AI2: AIT NOTES | AJ2: CSPL | AK2: CODE
A3: 2301 | B3: 7023197619 | C3: 44558 | D3: APPVION | E3: APPVION - APPVION | F3: 0001302558 | G3: 0001607822 | H3: APPVION OPERATIONS INC | I3: 825 E WISCONSIN AVE | J3: APPLETON | K3: WI | L3: 54911-3873 | M3: 78-30-311 | N3: 652320 OH | O3: GRAC | P3: 188603 | Q3: 100332444 | R3: FLUID POWER; | S3: EA | T3: 4 | U3: GRAC | V3: 188603 | W3: 100332444 | X3: 12020301 | Y3: GRAC_188603 | Z3: EA | AB3: 2.8 | AC3: 3.08 | AD3: =AC3*T3 -> 12.32 | AE3: =AB3*T3 -> 11.2 | AF3: =AD3-AE3 -> 1.12 | AG3: =AF3/AD3 -> 0.090909091 | AH3: =IF(AG3<0,"Negative",IF(AG3=0,"Same",IF(AG3>0.3,"30+%",IF(AG3>0.2,"20-30%",IF(AG3>0.1,"10-20%",IF(AG3<=0.1,"0-10%")))))) -> 0-10% | AJ3: NO
A4: 2301 | B4: 7023019074 | C4: 44530 | D4: APPVION | E4: APPVION - APPVION | F4: 0001302558 | G4: 0001607822 | H4: APPVION OPERATIONS INC | I4: 825 E WISCONSIN AVE | J4: APPLETON | K4: WI | L4: 54911-3873 | M4: 78-30-311 | N4: 651743 OH | O4: GRAC | P4: 188603 | Q4: 100332444 | R4: FLUID POWER; | S4: EA | T4: 4 | U4: GRAC | V4: 188603 | W4: 100332444 | X4: 12020301 | Y4: GRAC_188603 | Z4: EA | AB4: 2.8 | AC4: 3.08 | AD4: =AC4*T4 -> 12.32 | AE4: =AB4*T4 -> 11.2 | AF4: =AD4-AE4 -> 1.12 | AG4: =AF4/AD4 -> 0.090909091 | AH4: =IF(AG4<0,"Negative",IF(AG4=0,"Same",IF(AG4>0.3,"30+%",IF(AG4>0.2,"20-30%",IF(AG4>0.1,"10-20%",IF(AG4<=0.1,"0-10%")))))) -> 0-10% | AJ4: NO
A5: 2301 | B5: 7022076609 | C5: 44400 | D5: APPVION | E5: APPVION - APPVION | F5: 0001302558 | G5: 0001607822 | H5: APPVION OPERATIONS INC | I5: 825 E WISCONSIN AVE | J5: APPLETON | K5: WI | L5: 54911-3873 | M5: 78-30-311 | N5: 648627 OH | O5: GRAC | P5: 188603 | Q5: 100332444 | R5: FLUID POWER; | S5: EA | T5: 8 | U5: GRAC | V5: 188603 | W5: 100332444 | X5: 12020301 | Y5: GRAC_188603 | Z5: EA | AB5: 2.8 | AC5: 3.08 | AD5: =AC5*T5 -> 24.64 | AE5: =AB5*T5 -> 22.4 | AF5: =AD5-AE5 -> 2.24 | AG5: =AF5/AD5 -> 0.090909091 | AH5: =IF(AG5<0,"Negative",IF(AG5=0,"Same",IF(AG5>0.3,"30+%",IF(AG5>0.2,"20-30%",IF(AG5>0.1,"10-20%",IF(AG5<=0.1,"0-10%")))))) -> 0-10% | AJ5: NO
A6: 2301 | B6: 7020882180 | C6: 44245 | D6: APPVION | E6: APPVION - APPVION | F6: 0001302558 | G6: 0001607822 | H6: APPVION OPERATIONS INC | I6: 825 E WISCONSIN AVE | J6: APPLETON | K6: WI | L6: 54911-3873 | M6: 50-70-045 | N6: 644864 OH | O6: MISC | P6: 7FXR80Z/196 | Q6: 112198575 | R6: JANITORIAL; | S6: EA | T6: 24 | U6: MISC | V6: 7FXR80Z/196 | W6: 112198575 | X6: 06010008 | Y6: MISC_7FXR80Z/196 | Z6: EA | AA6: FPA/POR | AB6: 2.17 | AC6: 2.09 | AD6: =AC6*T6 -> 50.16 | AE6: =AB6*T6 -> 52.08 | AF6: =AD6-AE6 -> -1.92 | AG6: =AF6/AD6 -> -0.038277512 | AH6: =IF(AG6<0,"Negative",IF(AG6=0,"Same",IF(AG6>0.3,"30+%",IF(AG6>0.2,"20-30%",IF(AG6>0.1,"10-20%",IF(AG6<=0.1,"0-10%")))))) -> Negative | AJ6: NO
A7: 2301 | B7: 7023229730 | C7: 44565 | D7: APPVION | E7: APPVION - APPVION | F7: 0001302558 | G7: 0001607822 | H7: APPVION OPERATIONS INC | I7: 825 E WISCONSIN AVE | J7: APPLETON | K7: WI | L7: 54911-3873 | M7: 50-70-045 | N7: 652420 OH | O7: MISC | P7: 7FXR80Z/196 | Q7: 112198575 | R7: JANITORIAL; | S7: EA | T7: 24 | U7: MISC | V7: 7FXR80Z/196 | W7: 112198575 | X7: 06010008 | Y7: MISC_7FXR80Z/196 | Z7: EA | AA7: FPA/POR | AB7: 2.17 | AC7: 2.09 | AD7: =AC7*T7 -> 50.16 | AE7: =AB7*T7 -> 52.08 | AF7: =AD7-AE7 -> -1.92 | AG7: =AF7/AD7 -> -0.038277512 | AH7: =IF(AG7<0,"Negative",IF(AG7=0,"Same",IF(AG7>0.3,"30+%",IF(AG7>0.2,"20-30%",IF(AG7>0.1,"10-20%",IF(AG7<=0.1,"0-10%")))))) -> Negative | AJ7: NO
A8: 2301 | B8: 7023397946 | C8: 44588 | D8: APPVION | E8: APPVION - APPVION | F8: 0001302558 | G8: 0001607822 | H8: APPVION OPERATIONS INC | I8: 825 E WISCONSIN AVE | J8: APPLETON | K8: WI | L8: 54911-3873 | M8: 12-75-400 | N8: 653147 OH | O8: KOYO | P8: BH-1616 | Q8: 101737922 | R8: BEARINGS; | S8: EA | T8: 2 | U8: KOYO | V8: BH-1616 | W8: 101737922 | X8: 01010610 | Y8: KOYO_BH-1616 | Z8: EA | AB8: 5.56 | AC8: 5.68 | AD8: =AC8*T8 -> 11.36 | AE8: =AB8*T8 -> 11.12 | AF8: =AD8-AE8 -> 0.24 | AG8: =AF8/AD8 -> 0.021126761 | AH8: =IF(AG8<0,"Negative",IF(AG8=0,"Same",IF(AG8>0.3,"30+%",IF(AG8>0.2,"20-30%",IF(AG8>0.1,"10-20%",IF(AG8<=0.1,"0-10%")))))) -> 0-10% | AJ8: NO
A9: 2301 | B9: 7023333770 | C9: 44580 | D9: APPVION | E9: APPVION - APPVION | F9: 0001302558 | G9: 0001607822 | H9: APPVION OPERATIONS INC | I9: 825 E WISCONSIN AVE | J9: APPLETON | K9: WI | L9: 54911-3873 | M9: 12-75-400 | N9: 652958 OH | O9: KOYO | P9: BH-1616 | Q9: 101737922 | R9: BEARINGS; | S9: EA | T9: 2 | U9: KOYO | V9: BH-1616 | W9: 101737922 | X9: 01010610 | Y9: KOYO_BH-1616 | Z9: EA | AB9: 5.56 | AC9: 5.68 | AD9: =AC9*T9 -> 11.36 | AE9: =AB9*T9 -> 11.12 | AF9: =AD9-AE9 -> 0.24 | AG9: =AF9/AD9 -> 0.021126761 | AH9: =IF(AG9<0,"Negative",IF(AG9=0,"Same",IF(AG9>0.3,"30+%",IF(AG9>0.2,"20-30%",IF(AG9>0.1,"10-20%",IF(AG9<=0.1,"0-10%")))))) -> 0-10% | AJ9: NO
A10: 2301 | B10: 7022939701 | C10: 44517 | D10: APPVION | E10: APPVION - APPVION | F10: 0001302558 | G10: 0001607822 | H10: APPVION OPERATIONS INC | I10: 825 E WISCONSIN AVE | J10: APPLETON | K10: WI | L10: 54911-3873 | M10: 12-75-400 | N10: 651484 OH | O10: KOYO | P10: BH-1616 | Q10: 101737922 | R10: BEARINGS; | S10: EA | T10: 2 | U10: KOYO | V10: BH-1616 | W10: 101737922 | X10: 01010610 | Y10: KOYO_BH-1616 | Z10: EA | AB10: 5.56 | AC10: 5.68 | AD10: =AC10*T10 -> 11.36 | AE10: =AB10*T10 -> 11.12 | AF10: =AD10-AE10 -> 0.24 | AG10: =AF10/AD10 -> 0.021126761 | AH10: =IF(AG10<0,"Negative",IF(AG10=0,"Same",IF(AG10>0.3,"30+%",IF(AG10>0.2,"20-30%",IF(AG10>0.1,"10-20%",IF(AG10<=0.1,"0-10%")))))) -> 0-10% | AJ10: NO
A11: 2301 | B11: 7023410145 | C11: 44589 | D11: APPVION | E11: APPVION - APPVION | F11: 0001302558 | G11: 0001222540 | H11: APPVION OPERATIONS INC (CONSIGNMENT | I11: 825 E WISCONSIN AVE | J11: APPLETON | K11: WI | L11: 54911-3873 | M11: 06-40-034 | N11: 653084 OH | O11: MSA | P11: 51910-2"X 55 EASY SPLICE FILMLINE 6RL/CA | Q11: 112227550 | R11: GENERAL INDUSTRIAL SUPPLY; | S11: EA | T11: 6 | U11: MSA | V11: 51910-2"X 55 EASY SPLICE FILMLINE 6RL/CA | W11: 112227550 | X11: 07030001 | Y11: MSA_51910-2"X 55 EASY SPLICE FILMLINE 6RL/CA | Z11: EA | AA11: FPA/POR | AB11: 139.2 | AC11: 133.84 | AD11: =AC11*T11 -> 803.04 | AE11: =AB11*T11 -> 835.2 | AF11: =AD11-AE11 -> -32.16 | AG11: =AF11/AD11 -> -0.040047818 | AH11: =IF(AG11<0,"Negative",IF(AG11=0,"Same",IF(AG11>0.3,"30+%",IF(AG11>0.2,"20-30%",IF(AG11>0.1,"10-20%",IF(AG11<=0.1,"0-10%")))))) -> Negative | AJ11: NO
A12: 2301 | B12: 7023017622 | C12: 44530 | D12: APPVION | E12: APPVION - APPVION | F12: 0001302558 | G12: 0001222540 | H12: APPVION OPERATIONS INC (CONSIGNMENT | I12: 825 E WISCONSIN AVE | J12: APPLETON | K12: WI | L12: 54911-3873 | M12: 50-50-100 | N12: 651365 | O12: 3M | P12: 50048011080043 | Q12: 101375052 | R12: TOOLS; | S12: EA | T12: 60 | U12: 3M | V12: 50048011080043 | W12: 101375052 | X12: 08100001 | Y12: 3M_50048011080043 | Z12: EA | AB12: 2.09 | AC12: 2.32 | AD12: =AC12*T12 -> 139.2 | AE12: =AB12*T12 -> 125.4 | AF12: =AD12-AE12 -> 13.8 | AG12: =AF12/AD12 -> 0.099137931 | AH12: =IF(AG12<0,"Negative",IF(AG12=0,"Same",IF(AG12>0.3,"30+%",IF(AG12>0.2,"20-30%",IF(AG12>0.1,"10-20%",IF(AG12<=0.1,"0-10%")))))) -> 0-10% | AJ12: NO
A13: 2301 | B13: 7023067242 | C13: 44537 | D13: APPVION | E13: APPVION - APPVION | F13: 0001302558 | G13: 0001222540 | H13: APPVION OPERATIONS INC (CONSIGNMENT | I13: 825 E WISCONSIN AVE | J13: APPLETON | K13: WI | L13: 54911-3873 | M13: 50-50-100 | N13: 651721 OH | O13: 3M | P13: 50048011080043 | Q13: 101375052 | R13: TOOLS; | S13: EA | T13: 60 | U13: 3M | V13: 50048011080043 | W13: 101375052 | X13: 08100001 | Y13: 3M_50048011080043 | Z13: EA | AB13: 2.09 | AC13: 2.32 | AD13: =AC13*T13 -> 139.2 | AE13: =AB13*T13 -> 125.4 | AF13: =AD13-AE13 -> 13.8 | AG13: =AF13/AD13 -> 0.099137931 | AH13: =IF(AG13<0,"Negative",IF(AG13=0,"Same",IF(AG13>0.3,"30+%",IF(AG13>0.2,"20-30%",IF(AG13>0.1,"10-20%",IF(AG13<=0.1,"0-10%")))))) -> 0-10% | AJ13: NO
A14: 2301 | B14: 7023244307 | C14: 44566 | D14: APPVION | E14: APPVION - APPVION | F14: 0001302558 | G14: 0001222540 | H14: APPVION OPERATIONS INC (CONSIGNMENT | I14: 825 E WISCONSIN AVE | J14: APPLETON | K14: WI | L14: 54911-3873 | M14: 50-50-100 | N14: 652324 OH | O14: 3M | P14: 50048011080043 | Q14: 101375052 | R14: TOOLS; | S14: EA | T14: 60 | U14: 3M | V14: 50048011080043 | W14: 101375052 | X14: 08100001 | Y14: 3M_50048011080043 | Z14: EA | AB14: 2.09 | AC14: 2.32 | AD14: =AC14*T14 -> 139.2 | AE14: =AB14*T14 -> 125.4 | AF14: =AD14-AE14 -> 13.8 | AG14: =AF14/AD14 -> 0.099137931 | AH14: =IF(AG14<0,"Negative",IF(AG14=0,"Same",IF(AG14>0.3,"30+%",IF(AG14>0.2,"20-30%",IF(AG14>0.1,"10-20%",IF(AG14<=0.1,"0-10%")))))) -> 0-10% | AJ14: NO
A15: 2301 | B15: 7021229066 | C15: 44288 | D15: APPVION | E15: APPVION - APPVION | F15: 0001302558 | G15: 0001222540 | H15: APPVION OPERATIONS INC (CONSIGNMENT | I15: 825 E WISCONSIN AVE | J15: APPLETON | K15: WI | L15: 54911-3873 | M15: 84-99-219 | N15: 645991 OH | O15: MSP | P15: 97410715 | Q15: 111732828 | R15: GENERAL INDUSTRIAL SUPPLY; | S15: EA | T15: 1 | U15: MSP | V15: 97410715 | W15: 111732828 | X15: 07030101 | Y15: MSP_97410715 | Z15: EA | AA15: FPA/POR | AB15: 159.12 | AC15: 152.99 | AD15: =AC15*T15 -> 152.99 | AE15: =AB15*T15 -> 159.12 | AF15: =AD15-AE15 -> -6.13 | AG15: =AF15/AD15 -> -0.040067978 | AH15: =IF(AG15<0,"Negative",IF(AG15=0,"Same",IF(AG15>0.3,"30+%",IF(AG15>0.2,"20-30%",IF(AG15>0.1,"10-20%",IF(AG15<=0.1,"0-10%")))))) -> Negative | AJ15: NO
A16: 2301 | B16: 7023398313 | C16: 44588 | D16: APPVION | E16: APPVION - APPVION | F16: 0001302558 | G16: 0001222540 | H16: APPVION OPERATIONS INC (CONSIGNMENT | I16: 825 E WISCONSIN AVE | J16: APPLETON | K16: WI | L16: 54911-3873 | M16: 84-99-217 | N16: 652180 OH | O16: HYDR | P16: 21744 | Q16: 112834539 | R16: FLUID POWER; | S16: EA | T16: 1 | U16: HYDR | V16: 21744 | W16: 112834539 | X16: 12030602 | Y16: HYDR_21744 | Z16: EA | AA16: FPA/POR | AB16: 21.12 | AC16: 22.02 | AD16: =AC16*T16 -> 22.02 | AE16: =AB16*T16 -> 21.12 | AF16: =AD16-AE16 -> 0.9 | AG16: =AF16/AD16 -> 0.040871935 | AH16: =IF(AG16<0,"Negative",IF(AG16=0,"Same",IF(AG16>0.3,"30+%",IF(AG16>0.2,"20-30%",IF(AG16>0.1,"10-20%",IF(AG16<=0.1,"0-10%")))))) -> 0-10% | AJ16: NO
A17: 2301 | B17: 7021358102 | C17: 44306 | D17: APPVION | E17: APPVION - APPVION | F17: 0001302558 | G17: 0001607822 | H17: APPVION OPERATIONS INC | I17: 825 E WISCONSIN AVE | J17: APPLETON | K17: WI | L17: 54911-3873 | M17: 84-10-186 | N17: 646498 OH | O17: MISC | P17: R24287D1 | Q17: 105360060 | R17: GENERAL INDUSTRIAL SUPPLY; | S17: EA | T17: 2 | U17: MISC | V17: R24287D1 | W17: 105360060 | X17: 0706 | Y17: MISC_R24287D1 | Z17: EA | AA17: FPA/POR | AB17: 134.64 | AC17: 129.46 | AD17: =AC17*T17 -> 258.92 | AE17: =AB17*T17 -> 269.28 | AF17: =AD17-AE17 -> -10.36 | AG17: =AF17/AD17 -> -0.040012359 | AH17: =IF(AG17<0,"Negative",IF(AG17=0,"Same",IF(AG17>0.3,"30+%",IF(AG17>0.2,"20-30%",IF(AG17>0.1,"10-20%",IF(AG17<=0.1,"0-10%")))))) -> Negative | AJ17: NO
A18: 2301 | B18: 7020962740 | C18: 44256 | D18: APPVION | E18: APPVION - APPVION | F18: 0001302558 | G18: 0001607822 | H18: APPVION OPERATIONS INC | I18: 825 E WISCONSIN AVE | J18: APPLETON | K18: WI | L18: 54911-3873 | M18: 97-90-042 | N18: 644898 OH | O18: MCT | P18: N32-4-IRB | Q18: 105974075 | R18: MATERIAL HANDLING; | S18: EA | T18: 3 | U18: MCT | V18: N32-4-IRB | W18: 105974075 | X18: 1305 | Y18: MCT_N32-4-IRB | Z18: EA | AA18: FPA/POR | AB18: 16.69 | AC18: 18.17 | AD18: =AC18*T18 -> 54.51 | AE18: =AB18*T18 -> 50.07 | AF18: =AD18-AE18 -> 4.44 | AG18: =AF18/AD18 -> 0.081452944 | AH18: =IF(AG18<0,"Negative",IF(AG18=0,"Same",IF(AG18>0.3,"30+%",IF(AG18>0.2,"20-30%",IF(AG18>0.1,"10-20%",IF(AG18<=0.1,"0-10%")))))) -> 0-10% | AJ18: NO
A19: 2301 | B19: 7022077398 | C19: 44400 | D19: APPVION | E19: APPVION - APPVION | F19: 0001302558 | G19: 0001607822 | H19: APPVION OPERATIONS INC | I19: 825 E WISCONSIN AVE | J19: APPLETON | K19: WI | L19: 54911-3873 | M19: 06-40-028 | N19: 648765 OH | O19: 3M | P19: 0-00-21200-38934-4 | Q19: 112038900 | R19: GENERAL INDUSTRIAL SUPPLY; | S19: EA | T19: 24 | U19: 3M | V19: 0-00-21200-38934-4 | W19: 112038900 | X19: 07040602 | Y19: 3M_0-00-21200-38934-4 | Z19: EA | AA19: FPA/POR | AB19: 60.84 | AC19: 61.01 | AD19: =AC19*T19 -> 1464.24 | AE19: =AB19*T19 -> 1460.16 | AF19: =AD19-AE19 -> 4.08 | AG19: =AF19/AD19 -> 0.0027864285 | AH19: =IF(AG19<0,"Negative",IF(AG19=0,"Same",IF(AG19>0.3,"30+%",IF(AG19>0.2,"20-30%",IF(AG19>0.1,"10-20%",IF(AG19<=0.1,"0-10%")))))) -> 0-10% | AJ19: NO
A20: 2301 | B20: 7023315579 | C20: 44578 | D20: APPVION | E20: APPVION - APPVION | F20: 0001302558 | G20: 0001222540 | H20: APPVION OPERATIONS INC (CONSIGNMENT | I20: 825 E WISCONSIN AVE | J20: APPLETON | K20: WI | L20: 54911-3873 | M20: 50-50-111 | N20: 652759 OH | O20: MISC | P20: 5016-C 1/2" GALV WIDE CROWN | Q20: 118889585 | R20: GENERAL INDUSTRIAL SUPPLY; | S20: BX | T20: 5 | U20: MISC | V20: 5016-C 1/2" GALV WIDE CROWN | W20: 118889585 | X20: 07030001 | Y20: MISC_5016-C 1/2" GALV WIDE CROWN | Z20: BX | AA20: FPA/POR | AB20: 16.73 | AC20: 16.09 | AD20: =AC20*T20 -> 80.45 | AE20: =AB20*T20 -> 83.65 | AF20: =AD20-AE20 -> -3.2 | AG20: =AF20/AD20 -> -0.039776259 | AH20: =IF(AG20<0,"Negative",IF(AG20=0,"Same",IF(AG20>0.3,"30+%",IF(AG20>0.2,"20-30%",IF(AG20>0.1,"10-20%",IF(AG20<=0.1,"0-10%")))))) -> Negative | AJ20: NO
A21: 2301 | B21: 7023409333 | C21: 44589 | D21: APPVION | E21: APPVION - APPVION | F21: 0001302558 | G21: 0001607822 | H21: APPVION OPERATIONS INC | I21: 825 E WISCONSIN AVE | J21: APPLETON | K21: WI | L21: 54911-3873 | M21: 60-60-720 | N21: 653147 OH | O21: PBP | P21: 42360 | Q21: 100848729 | R21: GENERAL INDUSTRIAL SUPPLY; | S21: EA | T21: 1 | U21: PBP | V21: 42360 | W21: 100848729 | X21: 07090002 | Y21: PBP_42360 | Z21: EA | AB21: 18.49 | AC21: 17.78 | AD21: =AC21*T21 -> 17.78 | AE21: =AB21*T21 -> 18.49 | AF21: =AD21-AE21 -> -0.71 | AG21: =AF21/AD21 -> -0.039932508 | AH21: =IF(AG21<0,"Negative",IF(AG21=0,"Same",IF(AG21>0.3,"30+%",IF(AG21>0.2,"20-30%",IF(AG21>0.1,"10-20%",IF(AG21<=0.1,"0-10%")))))) -> Negative | AJ21: YES
A22: 2301 | B22: 7022898454 | C22: 44511 | D22: APPVION | E22: APPVION - APPVION | F22: 0001302558 | G22: 0001607822 | H22: APPVION OPERATIONS INC | I22: 825 E WISCONSIN AVE | J22: APPLETON | K22: WI | L22: 54911-3873 | M22: 12-89-700 | N22: 651342 OH | O22: AKRO | P22: 30235STONE | Q22: 101766641 | R22: GENERAL INDUSTRIAL SUPPLY; | S22: EA | T22: 12 | U22: AKRO | V22: 30235STONE | W22: 101766641 | X22: 07040104 | Y22: AKRO_30235STONE | Z22: EA | AB22: 9.45 | AC22: 9.09 | AD22: =AC22*T22 -> 109.08 | AE22: =AB22*T22 -> 113.4 | AF22: =AD22-AE22 -> -4.32 | AG22: =AF22/AD22 -> -0.03960396 | AH22: =IF(AG22<0,"Negative",IF(AG22=0,"Same",IF(AG22>0.3,"30+%",IF(AG22>0.2,"20-30%",IF(AG22>0.1,"10-20%",IF(AG22<=0.1,"0-10%")))))) -> Negative | AJ22: NO
A23: 2301 | B23: 7022574136 | C23: 44468 | D23: APPVION | E23: APPVION - APPVION | F23: 0001302558 | G23: 0001607822 | H23: APPVION OPERATIONS INC | I23: 825 E WISCONSIN AVE | J23: APPLETON | K23: WI | L23: 54911-3873 | M23: 06-45-005* | N23: 650251 OH | O23: MSA | P23: 60404 1.5"X 72YDS RED PVC S/S | Q23: 118712038 | R23: GENERAL INDUSTRIAL SUPPLY; | S23: EA | T23: 48 | U23: MSA | V23: 60404 1.5"X 72YDS RED PVC S/S | W23: 118712038 | X23: 07030001 | Y23: MSA_60404 1.5"X 72YDS RED PVC S/S | Z23: EA | AA23: FPA/POR | AB23: 6.07 | AC23: 5.83 | AD23: =AC23*T23 -> 279.84 | AE23: =AB23*T23 -> 291.36 | AF23: =AD23-AE23 -> -11.52 | AG23: =AF23/AD23 -> -0.041166381 | AH23: =IF(AG23<0,"Negative",IF(AG23=0,"Same",IF(AG23>0.3,"30+%",IF(AG23>0.2,"20-30%",IF(AG23>0.1,"10-20%",IF(AG23<=0.1,"0-10%")))))) -> Negative | AJ23: NO
A24: 2301 | B24: 7021247824 | C24: 44292 | D24: APPVION | E24: APPVION - APPVION | F24: 0001302558 | G24: 0001607822 | H24: APPVION OPERATIONS INC | I24: 825 E WISCONSIN AVE | J24: APPLETON | K24: WI | L24: 54911-3873 | M24: 06-10-020 | N24: 646194 OH | O24: IPG | P24: K2800/RL | Q24: 112777281 | R24: GENERAL INDUSTRIAL SUPPLY; | S24: EA | T24: 10 | U24: IPG | V24: K2800/RL | W24: 112777281 | X24: 07040602 | Y24: IPG_K2800/RL | Z24: EA | AA24: FPA/POR | AB24: 7.33 | AC24: 7.05 | AD24: =AC24*T24 -> 70.5 | AE24: =AB24*T24 -> 73.3 | AF24: =AD24-AE24 -> -2.8 | AG24: =AF24/AD24 -> -0.039716312 | AH24: =IF(AG24<0,"Negative",IF(AG24=0,"Same",IF(AG24>0.3,"30+%",IF(AG24>0.2,"20-30%",IF(AG24>0.1,"10-20%",IF(AG24<=0.1,"0-10%")))))) -> Negative | AJ24: NO
A25: 2301 | B25: 7023398315 | C25: 44588 | D25: APPVION | E25: APPVION - APPVION | F25: 0001302558 | G25: 0001607822 | H25: APPVION OPERATIONS INC | I25: 825 E WISCONSIN AVE | J25: APPLETON | K25: WI | L25: 54911-3873 | M25: 29-29-229 | N25: 653153 OH | O25: LGAS | P25: CLO15949CT | Q25: 101680797 | R25: JANITORIAL; | S25: EA | T25: 2 | U25: LGAS | V25: CLO15949CT | W25: 101680797 | X25: 06020007 | Y25: LGAS_CLO15949CT | Z25: EA | AB25: 36.24 | AC25: 36.84 | AD25: =AC25*T25 -> 73.68 | AE25: =AB25*T25 -> 72.48 | AF25: =AD25-AE25 -> 1.2 | AG25: =AF25/AD25 -> 0.016286645 | AH25: =IF(AG25<0,"Negative",IF(AG25=0,"Same",IF(AG25>0.3,"30+%",IF(AG25>0.2,"20-30%",IF(AG25>0.1,"10-20%",IF(AG25<=0.1,"0-10%")))))) -> 0-10% | AJ25: YES
A26: 2301 | B26: 7023284936 | C26: 44573 | D26: APPVION | E26: APPVION - APPVION | F26: 0001302558 | G26: 0001607822 | H26: APPVION OPERATIONS INC | I26: 825 E WISCONSIN AVE | J26: APPLETON | K26: WI | L26: 54911-3873 | M26: 34-45-190 | N26: 652755 OH | O26: LN | P26: KM8 | Q26: 102195383 | R26: BEARINGS; | S26: EA | T26: 1 | U26: LN | V26: KM8 | W26: 102195383 | X26: 0102030402 | Y26: LN_KM8 | Z26: EA | AB26: 13.4 | AC26: 14.11 | AD26: =AC26*T26 -> 14.11 | AE26: =AB26*T26 -> 13.4 | AF26: =AD26-AE26 -> 0.71 | AG26: =AF26/AD26 -> 0.050318923 | AH26: =IF(AG26<0,"Negative",IF(AG26=0,"Same",IF(AG26>0.3,"30+%",IF(AG26>0.2,"20-30%",IF(AG26>0.1,"10-20%",IF(AG26<=0.1,"0-10%")))))) -> 0-10% | AJ26: NO
A27: 2301 | B27: 7023248434 | C27: 44567 | D27: APPVION | E27: APPVION - APPVION | F27: 0001302558 | G27: 0001607822 | H27: APPVION OPERATIONS INC | I27: 825 E WISCONSIN AVE | J27: APPLETON | K27: WI | L27: 54911-3873 | M27: 34-45-190 | N27: 652558 OH | O27: LN | P27: KM8 | Q27: 102195383 | R27: BEARINGS; | S27: EA | T27: 1 | U27: LN | V27: KM8 | W27: 102195383 | X27: 0102030402 | Y27: LN_KM8 | Z27: EA | AB27: 13.4 | AC27: 14.11 | AD27: =AC27*T27 -> 14.11 | AE27: =AB27*T27 -> 13.4 | AF27: =AD27-AE27 -> 0.71 | AG27: =AF27/AD27 -> 0.050318923 | AH27: =IF(AG27<0,"Negative",IF(AG27=0,"Same",IF(AG27>0.3,"30+%",IF(AG27>0.2,"20-30%",IF(AG27>0.1,"10-20%",IF(AG27<=0.1,"0-10%")))))) -> 0-10% | AJ27: NO
A28: 2301 | B28: 7023274983 | C28: 44572 | D28: APPVION | E28: APPVION - APPVION | F28: 0001302558 | G28: 0001607822 | H28: APPVION OPERATIONS INC | I28: 825 E WISCONSIN AVE | J28: APPLETON | K28: WI | L28: 54911-3873 | M28: 16-10-107 | N28: 652360 OH | O28: MRUP | P28: APPVION-16-10-107 | Q28: 113362541 | R28: MATERIAL HANDLING; | S28: EA | T28: 1 | U28: MRUP | V28: APPVION-16-10-107 | W28: 113362541 | X28: 130303 | Y28: MRUP_APPVION-16-10-107 | Z28: EA | AA28: FPA/POR | AB28: 67.28 | AC28: 73.25 | AD28: =AC28*T28 -> 73.25 | AE28: =AB28*T28 -> 67.28 | AF28: =AD28-AE28 -> 5.97 | AG28: =AF28/AD28 -> 0.081501706 | AH28: =IF(AG28<0,"Negative",IF(AG28=0,"Same",IF(AG28>0.3,"30+%",IF(AG28>0.2,"20-30%",IF(AG28>0.1,"10-20%",IF(AG28<=0.1,"0-10%")))))) -> 0-10% | AJ28: NO
A29: 2301 | B29: 7023323042 | C29: 44579 | D29: APPVION | E29: APPVION - APPVION | F29: 0001302558 | G29: 0001607822 | H29: APPVION OPERATIONS INC | I29: 825 E WISCONSIN AVE | J29: APPLETON | K29: WI | L29: 54911-3873 | M29: 16-60-575 | N29: 652874 OH | O29: CONT | P29: 5VX1120 | Q29: 100772650 | R29: MECHANICAL POWER TRANSMISSION; | S29: EA | T29: 8 | U29: CONT | V29: 5VX1120 | W29: 100772650 | X29: 1001010602 | Y29: CONT_5VX1120 | Z29: EA | AB29: 34.64 | AC29: 38.21 | AD29: =AC29*T29 -> 305.68 | AE29: =AB29*T29 -> 277.12 | AF29: =AD29-AE29 -> 28.56 | AG29: =AF29/AD29 -> 0.093431039 | AH29: =IF(AG29<0,"Negative",IF(AG29=0,"Same",IF(AG29>0.3,"30+%",IF(AG29>0.2,"20-30%",IF(AG29>0.1,"10-20%",IF(AG29<=0.1,"0-10%")))))) -> 0-10% | AJ29: YES
A30: 2301 | B30: 7023397946 | C30: 44588 | D30: APPVION | E30: APPVION - APPVION | F30: 0001302558 | G30: 0001607822 | H30: APPVION OPERATIONS INC | I30: 825 E WISCONSIN AVE | J30: APPLETON | K30: WI | L30: 54911-3873 | M30: 16-90-520 | N30: 653147 OH | O30: CONT | P30: 3/3VX630 | Q30: 100775432 | R30: MECHANICAL POWER TRANSMISSION; | S30: EA | T30: 1 | U30: CONT | V30: 3/3VX630 | W30: 100775432 | X30: 1001010204 | Y30: CONT_3/3VX630 | Z30: EA | AB30: 36.33 | AC30: 37.97 | AD30: =AC30*T30 -> 37.97 | AE30: =AB30*T30 -> 36.33 | AF30: =AD30-AE30 -> 1.64 | AG30: =AF30/AD30 -> 0.043191994 | AH30: =IF(AG30<0,"Negative",IF(AG30=0,"Same",IF(AG30>0.3,"30+%",IF(AG30>0.2,"20-30%",IF(AG30>0.1,"10-20%",IF(AG30<=0.1,"0-10%")))))) -> 0-10% | AJ30: NO
A31: 2301 | B31: 7020814680 | C31: 44236 | D31: APPVION | E31: APPVION - APPVION | F31: 0001302558 | G31: 0001607822 | H31: APPVION OPERATIONS INC | I31: 825 E WISCONSIN AVE | J31: APPLETON | K31: WI | L31: 54911-3873 | M31: 12-99-191 | N31: 644184 OH | O31: BBB | P31: FFM012018020 | Q31: 101466178 | R31: BEARINGS; | S31: EA | T31: 50 | U31: BBB | V31: FFM012018020 | W31: 101466178 | X31: 0103050104 | Y31: BBB_FFM012018020 | Z31: EA | AA31: FPA/POR | AB31: 2.75 | AC31: 2.46 | AD31: =AC31*T31 -> 123 | AE31: =AB31*T31 -> 137.5 | AF31: =AD31-AE31 -> -14.5 | AG31: =AF31/AD31 -> -0.11788618 | AH31: =IF(AG31<0,"Negative",IF(AG31=0,"Same",IF(AG31>0.3,"30+%",IF(AG31>0.2,"20-30%",IF(AG31>0.1,"10-20%",IF(AG31<=0.1,"0-10%")))))) -> Negative | AJ31: NO
A32: 2301 | B32: 7021098812 | C32: 44273 | D32: APPVION | E32: APPVION - APPVION | F32: 0001302558 | G32: 0001607822 | H32: APPVION OPERATIONS INC | I32: 825 E WISCONSIN AVE | J32: APPLETON | K32: WI | L32: 54911-3873 | M32: . | N32: 2100309 | O32: MCT | P32: 9.06002.03 | Q32: 115737392 | R32: MATERIAL HANDLING; | S32: EA | T32: 6 | U32: MCT | V32: 9.06002.03 | W32: 115737392 | X32: 1303020702 | Y32: MCT_9.06002.03 | Z32: EA | AA32: FPA/POR | AB32: 37.92 | AC32: 41.28 | AD32: =AC32*T32 -> 247.68 | AE32: =AB32*T32 -> 227.52 | AF32: =AD32-AE32 -> 20.16 | AG32: =AF32/AD32 -> 0.081395349 | AH32: =IF(AG32<0,"Negative",IF(AG32=0,"Same",IF(AG32>0.3,"30+%",IF(AG32>0.2,"20-30%",IF(AG32>0.1,"10-20%",IF(AG32<=0.1,"0-10%")))))) -> 0-10% | AJ32: NO
A33: 2301 | B33: 7023410548 | C33: 44589 | D33: APPVION | E33: APPVION - APPVION | F33: 0001302558 | G33: 0001607822 | H33: APPVION OPERATIONS INC | I33: 825 E WISCONSIN AVE | J33: APPLETON | K33: WI | L33: 54911-3873 | M33: 84-99-212 | N33: 653047 OH | O33: MSP | P33: 410718 | Q33: 110914564 | R33: GENERAL INDUSTRIAL SUPPLY; | S33: EA | T33: 1 | U33: MSP | V33: 410718 | W33: 110914564 | X33: 07030101 | Y33: MSP_410718 | Z33: EA | AA33: FPA/POR | AB33: 183.79 | AC33: 176.71 | AD33: =AC33*T33 -> 176.71 | AE33: =AB33*T33 -> 183.79 | AF33: =AD33-AE33 -> -7.08 | AG33: =AF33/AD33 -> -0.040065644 | AH33: =IF(AG33<0,"Negative",IF(AG33=0,"Same",IF(AG33>0.3,"30+%",IF(AG33>0.2,"20-30%",IF(AG33>0.1,"10-20%",IF(AG33<=0.1,"0-10%")))))) -> Negative | AJ33: NO
A34: 2301 | B34: 7023248435 | C34: 44567 | D34: APPVION | E34: APPVION - APPVION | F34: 0001302558 | G34: 0001607822 | H34: APPVION OPERATIONS INC | I34: 825 E WISCONSIN AVE | J34: APPLETON | K34: WI | L34: 54911-3873 | M34: 16-60-797 | N34: 652485 OH | O34: CONT | P34: 5VX1700 | Q34: 100772667 | R34: MECHANICAL POWER TRANSMISSION; | S34: EA | T34: 5 | U34: CONT | V34: 5VX1700 | W34: 100772667 | X34: 1001010602 | Y34: CONT_5VX1700 | Z34: EA | AB34: 52.72 | AC34: 58.13 | AD34: =AC34*T34 -> 290.65 | AE34: =AB34*T34 -> 263.6 | AF34: =AD34-AE34 -> 27.05 | AG34: =AF34/AD34 -> 0.093067263 | AH34: =IF(AG34<0,"Negative",IF(AG34=0,"Same",IF(AG34>0.3,"30+%",IF(AG34>0.2,"20-30%",IF(AG34>0.1,"10-20%",IF(AG34<=0.1,"0-10%")))))) -> 0-10% | AJ34: YES
A35: 2301 | B35: 7020793268 | C35: 44232 | D35: APPVION | E35: APPVION - APPVION | F35: 0001302558 | G35: 0001222540 | H35: APPVION OPERATIONS INC (CONSIGNMENT | I35: 825 E WISCONSIN AVE | J35: APPLETON | K35: WI | L35: 54911-3873 | M35: 78-99-103 | N35: 643996 OH | O35: GAST | P35: AV469B | Q35: 105695206 | R35: FLUID POWER; | S35: EA | T35: 12 | U35: GAST | V35: AV469B | W35: 105695206 | X35: 12020202 | Y35: GAST_AV469B | Z35: EA | AA35: FPA/POR | AB35: 4.68 | AC35: 6.36 | AD35: =AC35*T35 -> 76.32 | AE35: =AB35*T35 -> 56.16 | AF35: =AD35-AE35 -> 20.16 | AG35: =AF35/AD35 -> 0.26415094 | AH35: =IF(AG35<0,"Negative",IF(AG35=0,"Same",IF(AG35>0.3,"30+%",IF(AG35>0.2,"20-30%",IF(AG35>0.1,"10-20%",IF(AG35<=0.1,"0-10%")))))) -> 20-30% | AJ35: NO
A36: 2301 | B36: 7023224021 | C36: 44564 | D36: APPVION | E36: APPVION - APPVION | F36: 0001302558 | G36: 0001607822 | H36: APPVION OPERATIONS INC | I36: 825 E WISCONSIN AVE | J36: APPLETON | K36: WI | L36: 54911-3873 | M36: 50-70-065 | N36: 652451 OH | O36: KC | P36: 21400 | Q36: 111890497 | R36: JANITORIAL; | S36: CS | T36: 2 | U36: KC | V36: 21400 | W36: 111890497 | X36: 06020007 | Y36: KC_21400 | Z36: CS | AB36: 65.12 | AC36: 63.69 | AD36: =AC36*T36 -> 127.38 | AE36: =AB36*T36 -> 130.24 | AF36: =AD36-AE36 -> -2.86 | AG36: =AF36/AD36 -> -0.022452504 | AH36: =IF(AG36<0,"Negative",IF(AG36=0,"Same",IF(AG36>0.3,"30+%",IF(AG36>0.2,"20-30%",IF(AG36>0.1,"10-20%",IF(AG36<=0.1,"0-10%")))))) -> Negative | AJ36: NO
A37: 2301 | B37: 7023296269 | C37: 44574 | D37: APPVION | E37: APPVION - APPVION | F37: 0001302558 | G37: 0001607822 | H37: APPVION OPERATIONS INC | I37: 825 E WISCONSIN AVE | J37: APPLETON | K37: WI | L37: 54911-3873 | M37: 50-70-065 | N37: 652880 OH | O37: KC | P37: 21400 | Q37: 111890497 | R37: JANITORIAL; | S37: CS | T37: 1 | U37: KC | V37: 21400 | W37: 111890497 | X37: 06020007 | Y37: KC_21400 | Z37: CS | AB37: 65.12 | AC37: 63.69 | AD37: =AC37*T37 -> 63.69 | AE37: =AB37*T37 -> 65.12 | AF37: =AD37-AE37 -> -1.43 | AG37: =AF37/AD37 -> -0.022452504 | AH37: =IF(AG37<0,"Negative",IF(AG37=0,"Same",IF(AG37>0.3,"30+%",IF(AG37>0.2,"20-30%",IF(AG37>0.1,"10-20%",IF(AG37<=0.1,"0-10%")))))) -> Negative | AJ37: NO
A38: 2301 | B38: 7023047635 | C38: 44533 | D38: APPVION | E38: APPVION - APPVION | F38: 0001302558 | G38: 0001222540 | H38: APPVION OPERATIONS INC (CONSIGNMENT | I38: 825 E WISCONSIN AVE | J38: APPLETON | K38: WI | L38: 54911-3873 | M38: 12-99-050 | N38: 651630 OH | O38: THK | P38: SRS9XMUU+55LM-11 | Q38: 110914132 | R38: LINEAR MOTION PRODUCTS; | S38: EA | T38: 5 | U38: THK | V38: SRS9XMUU+55LM-11 | W38: 110914132 | X38: 02030101 | Y38: THK_SRS9XMUU+55LM-11 | Z38: EA | AA38: FPA/POR | AB38: 59.61 | AC38: 54.3 | AD38: =AC38*T38 -> 271.5 | AE38: =AB38*T38 -> 298.05 | AF38: =AD38-AE38 -> -26.55 | AG38: =AF38/AD38 -> -0.097790055 | AH38: =IF(AG38<0,"Negative",IF(AG38=0,"Same",IF(AG38>0.3,"30+%",IF(AG38>0.2,"20-30%",IF(AG38>0.1,"10-20%",IF(AG38<=0.1,"0-10%")))))) -> Negative | AJ38: NO
A39: 2301 | B39: 7022338861 | C39: 44435 | D39: APPVION | E39: APPVION - APPVION | F39: 0001302558 | G39: 0001222540 | H39: APPVION OPERATIONS INC (CONSIGNMENT | I39: 825 E WISCONSIN AVE | J39: APPLETON | K39: WI | L39: 54911-3873 | M39: 12-99-050 | N39: 647618 OH | O39: THK | P39: SRS9XMUU+55LM-11 | Q39: 110914132 | R39: LINEAR MOTION PRODUCTS; | S39: EA | T39: 4 | U39: THK | V39: SRS9XMUU+55LM-11 | W39: 110914132 | X39: 02030101 | Y39: THK_SRS9XMUU+55LM-11 | Z39: EA | AA39: FPA/POR | AB39: 59.61 | AC39: 54.3 | AD39: =AC39*T39 -> 217.2 | AE39: =AB39*T39 -> 238.44 | AF39: =AD39-AE39 -> -21.24 | AG39: =AF39/AD39 -> -0.097790055 | AH39: =IF(AG39<0,"Negative",IF(AG39=0,"Same",IF(AG39>0.3,"30+%",IF(AG39>0.2,"20-30%",IF(AG39>0.1,"10-20%",IF(AG39<=0.1,"0-10%")))))) -> Negative | AJ39: NO
A40: 2301 | B40: 7021229066 | C40: 44288 | D40: APPVION | E40: APPVION - APPVION | F40: 0001302558 | G40: 0001222540 | H40: APPVION OPERATIONS INC (CONSIGNMENT | I40: 825 E WISCONSIN AVE | J40: APPLETON | K40: WI | L40: 54911-3873 | M40: 12-99-050 | N40: 645991 OH | O40: THK | P40: SRS9XMUU+55LM-11 | Q40: 110914132 | R40: LINEAR MOTION PRODUCTS; | S40: EA | T40: 1 | U40: THK | V40: SRS9XMUU+55LM-11 | W40: 110914132 | X40: 02030101 | Y40: THK_SRS9XMUU+55LM-11 | Z40: EA | AA40: FPA/POR | AB40: 59.61 | AC40: 54.3 | AD40: =AC40*T40 -> 54.3 | AE40: =AB40*T40 -> 59.61 | AF40: =AD40-AE40 -> -5.31 | AG40: =AF40/AD40 -> -0.097790055 | AH40: =IF(AG40<0,"Negative",IF(AG40=0,"Same",IF(AG40>0.3,"30+%",IF(AG40>0.2,"20-30%",IF(AG40>0.1,"10-20%",IF(AG40<=0.1,"0-10%")))))) -> Negative | AJ40: NO
A41: 2301 | B41: 7021439697 | C41: 44315 | D41: APPVION | E41: APPVION - APPVION | F41: 0001302558 | G41: 0001607822 | H41: APPVION OPERATIONS INC | I41: 825 E WISCONSIN AVE | J41: APPLETON | K41: WI | L41: 54911-3873 | M41: 16-10-009 | N41: 643533 OH | O41: SIEG | P41: E5/2 0/V3 MT-NA 8"IN X 108"IN LG "KS" | Q41: 110964191 | R41: MATERIAL HANDLING; | S41: EA | T41: 1 | U41: SIEG | V41: E5/2 0/V3 MT-NA 8"IN X 108"IN LG "KS" | W41: 110964191 | X41: 1303020401 | Y41: SIEG_E5/2 0/V3 MT-NA 8"IN X 108"IN LG "KS" | Z41: EA | AA41: FPA/POR | AB41: 201.27 | AC41: 219.13 | AD41: =AC41*T41 -> 219.13 | AE41: =AB41*T41 -> 201.27 | AF41: =AD41-AE41 -> 17.86 | AG41: =AF41/AD41 -> 0.08150413 | AH41: =IF(AG41<0,"Negative",IF(AG41=0,"Same",IF(AG41>0.3,"30+%",IF(AG41>0.2,"20-30%",IF(AG41>0.1,"10-20%",IF(AG41<=0.1,"0-10%")))))) -> 0-10% | AJ41: NO
...

Sheet OBSOLETE
A1: SC | B1: Billing Document Number | C1: Billing Date | D1: Master Customer (Heading) | E1: Master Customer Division (Heading) | F1: Sold-To-Party | G1: Ship-To Party | H1: Ship-To Party (Heading) | I1: Street Address | J1: City | K1: State | L1: Postal Code | M1: Customer Material Number | N1: Customer Purchase Order Number | O1: MFG Code | P1: Manufacturer Part Number | Q1: Material | R1: Product hierarchy level 1 (Heading) | S1: UOM | T1: Billing Quantity | U1: Unit Sale Price | V1: Extended Sale Price | W1: 1ST SAP MFR | X1: 1ST SAP PN | Y1: 1ST SAP MATERIAL# | Z1: 1ST SAP DESCRIPTION | AA1: 1ST SAP UOM | AB1: 1ST SAP MATERIAL STATUS | AC1: AIT NOTES | AD1: CSPL | AE1: CODE
A2: 2301 | B2: 7022806962 | C2: 44498 | D2: APPVION | E2: APPVION - APPVION | F2: 0001302558 | G2: 0001222540 | H2: APPVION OPERATIONS INC (CONSIGNMENT | I2: 825 E WISCONSIN AVE | J2: APPLETON | K2: WI | L2: 54911-3873 | M2: 53-20-037 | N2: 650989 OH | O2: KANO | P2: AEROKROIL | Q2: 102212930 | R2: LUBRICANT PRODUCTS; | S2: EA | T2: 12 | U2: 14.05 | V2: 168.6 | W2: KANO | X2: AEROKROIL | Y2: 102212930 | Z2: KANO_AEROKROIL | AA2: EA | AB2: Z4_Pending Obsolete-Warning | AC2: OBSOLETE | AD2: NO
A3: 2301 | B3: 7021124817 | C3: 44277 | D3: APPVION | E3: APPVION - APPVION | F3: 0001302558 | G3: 0001607822 | H3: APPVION OPERATIONS INC | I3: 825 E WISCONSIN AVE | J3: APPLETON | K3: WI | L3: 54911-3873 | M3: . | N3: 645681 ON | O3: PHC | P3: 0683720000 | Q3: 111529129 | R3: FLUID POWER; | S3: EA | T3: 2 | U3: 41.38 | V3: 82.76 | W3: PHC | X3: 0683720000 | Y3: 111529129 | Z3: PHC_0683720000 | AA3: EA | AB3: Z4_Pending Obsolete-Warning | AC3: OBSOLETE | AD3: NO
A4: 2301 | B4: 7021159747 | C4: 44280 | D4: APPVION | E4: APPVION - APPVION | F4: 0001302558 | G4: 0001607822 | H4: APPVION OPERATIONS INC | I4: 825 E WISCONSIN AVE | J4: APPLETON | K4: WI | L4: 54911-3873 | M4: . | N4: 645681 ON | O4: PHC | P4: 0959810175 | Q4: 111540435 | R4: HOSE PRODUCTS; | S4: EA | T4: 2 | U4: 368.58 | V4: 737.16 | W4: PHC | X4: 0959810175 | Y4: 111540435 | Z4: PHC_0959810175 | AA4: EA | AB4: Z4_Pending Obsolete-Warning | AC4: OBSOLETE | AD4: NO
A5: 2301 | B5: 7021005702 | C5: 44260 | D5: APPVION | E5: APPVION - APPVION | F5: 0001302558 | G5: 0001222540 | H5: APPVION OPERATIONS INC (CONSIGNMENT | I5: 825 E WISCONSIN AVE | J5: APPLETON | K5: WI | L5: 54911-3873 | M5: 53-40-101 | N5: 645162 OH | O5: LGAS | P5: SCCLPH416 | Q5: 112520194 | R5: JANITORIAL; | S5: CS | T5: 1 | U5: 139.75 | V5: 139.75 | W5: LGAS | X5: SCCLPH416 | Y5: 112520194 | Z5: LGAS_SCCLPH416 | AA5: CS | AB5: Z4_Pending Obsolete-Warning | AC5: OBSOLETE | AD5: NO
A6: 2301 | B6: 7021672124 | C6: 44344 | D6: APPVION | E6: APPVION - APPVION | F6: 0001302558 | G6: 0001222540 | H6: APPVION OPERATIONS INC (CONSIGNMENT | I6: 825 E WISCONSIN AVE | J6: APPLETON | K6: WI | L6: 54911-3873 | M6: 53-40-101 | N6: 647339 OH | O6: LGAS | P6: SCCLPH416 | Q6: 112520194 | R6: JANITORIAL; | S6: CS | T6: 1 | U6: 139.75 | V6: 139.75 | W6: LGAS | X6: SCCLPH416 | Y6: 112520194 | Z6: LGAS_SCCLPH416 | AA6: CS | AB6: Z4_Pending Obsolete-Warning | AC6: OBSOLETE | AD6: NO
A7: 2301 | B7: 7022087391 | C7: 44403 | D7: APPVION | E7: APPVION - APPVION | F7: 0001302558 | G7: 0001222540 | H7: APPVION OPERATIONS INC (CONSIGNMENT | I7: 825 E WISCONSIN AVE | J7: APPLETON | K7: WI | L7: 54911-3873 | M7: 53-40-101 | N7: 468688 OH | O7: LGAS | P7: SCCLPH416 | Q7: 112520194 | R7: JANITORIAL; | S7: CS | T7: 1 | U7: 139.75 | V7: 139.75 | W7: LGAS | X7: SCCLPH416 | Y7: 112520194 | Z7: LGAS_SCCLPH416 | AA7: CS | AB7: Z4_Pending Obsolete-Warning | AC7: OBSOLETE | AD7: NO
A8: 2301 | B8: 7022233804 | C8: 44421 | D8: APPVION | E8: APPVION - APPVION | F8: 0001302558 | G8: 0001222540 | H8: APPVION OPERATIONS INC (CONSIGNMENT | I8: 825 E WISCONSIN AVE | J8: APPLETON | K8: WI | L8: 54911-3873 | M8: 53-40-101 | N8: 649179 OH | O8: LGAS | P8: SCCLPH416 | Q8: 112520194 | R8: JANITORIAL; | S8: CS | T8: 2 | U8: 139.75 | V8: 279.5 | W8: LGAS | X8: SCCLPH416 | Y8: 112520194 | Z8: LGAS_SCCLPH416 | AA8: CS | AB8: Z4_Pending Obsolete-Warning | AC8: OBSOLETE | AD8: NO
A9: 2301 | B9: 7022729057 | C9: 44489 | D9: APPVION | E9: APPVION - APPVION | F9: 0001302558 | G9: 0001607822 | H9: APPVION OPERATIONS INC | I9: 825 E WISCONSIN AVE | J9: APPLETON | K9: WI | L9: 54911-3873 | M9: 12-99-103 | N9: 649038 OH | O9: THK | P9: HSR25LA1SS | Q9: 102200110 | R9: LINEAR MOTION PRODUCTS; | S9: EA | T9: 2 | U9: 104.98 | V9: 209.96 | W9: THK | X9: HSR25LA1SS | Y9: 102200110 | Z9: THK_HSR25LA1SS | AA9: EA | AB9: Z4_Pending Obsolete-Warning | AC9: OBSOLETE | AD9: NO
A10: 2301 | B10: 7022845714 | C10: 44504 | D10: APPVION | E10: APPVION - APPVION | F10: 0001302558 | G10: 0001607822 | H10: APPVION OPERATIONS INC | I10: 825 E WISCONSIN AVE | J10: APPLETON | K10: WI | L10: 54911-3873 | M10: 12-99-103 | N10: 649038 OH | O10: THK | P10: HSR25LA1SS | Q10: 102200110 | R10: LINEAR MOTION PRODUCTS; | S10: EA | T10: 2 | U10: 104.98 | V10: 209.96 | W10: THK | X10: HSR25LA1SS | Y10: 102200110 | Z10: THK_HSR25LA1SS | AA10: EA | AB10: Z4_Pending Obsolete-Warning | AC10: OBSOLETE | AD10: NO
A11: 2301 | B11: 7022528857 | C11: 44462 | D11: APPVION | E11: APPVION - APPVION | F11: 0001302558 | G11: 0001607822 | H11: APPVION OPERATIONS INC | I11: 825 E WISCONSIN AVE | J11: APPLETON | K11: WI | L11: 54911-3873 | M11: 26-40-564 | N11: 650030 OH | O11: SUMI | P11: CNVMS02-6100YA-119 | Q11: 105198145 | R11: MECHANICAL POWER TRANSMISSION; | S11: EA | T11: 1 | U11: 1247.67 | V11: 1247.67 | W11: SUMI | X11: CNVMS02-6100YA-119 | Y11: 105198145 | Z11: SUMI_CNVMS02-6100YA-119 | AA11: EA | AB11: Z4_Pending Obsolete-Warning | AC11: OBSOLETE | AD11: NO
A12: 2301 | B12: 7020891949 | C12: 44246 | D12: APPVION | E12: APPVION - APPVION | F12: 0001302558 | G12: 0001222540 | H12: APPVION OPERATIONS INC (CONSIGNMENT | I12: 825 E WISCONSIN AVE | J12: APPLETON | K12: WI | L12: 54911-3873 | M12: 53-20-037 | N12: 644186 OH | O12: KANO | P12: AEROKROIL | Q12: 102212930 | R12: LUBRICANT PRODUCTS; | S12: EA | T12: 12 | U12: 14.05 | V12: 168.6 | W12: KANO | X12: AEROKROIL | Y12: 102212930 | Z12: KANO_AEROKROIL | AA12: EA | AB12: Z4_Pending Obsolete-Warning | AC12: OBSOLETE | AD12: NO
A13: 2301 | B13: 7021118950 | C13: 44274 | D13: APPVION | E13: APPVION - APPVION | F13: 0001302558 | G13: 0001222540 | H13: APPVION OPERATIONS INC (CONSIGNMENT | I13: 825 E WISCONSIN AVE | J13: APPLETON | K13: WI | L13: 54911-3873 | M13: 53-20-037 | N13: 645577 OH | O13: KANO | P13: AEROKROIL | Q13: 102212930 | R13: LUBRICANT PRODUCTS; | S13: EA | T13: 12 | U13: 14.05 | V13: 168.6 | W13: KANO | X13: AEROKROIL | Y13: 102212930 | Z13: KANO_AEROKROIL | AA13: EA | AB13: Z4_Pending Obsolete-Warning | AC13: OBSOLETE | AD13: NO
... A17: 2301 | B17: 7023257664 | C17: 44568 | D17: APPVION | E17: APPVION - APPVION | F17: 0001302558 | G17: 0001222540 | H17: APPVION OPERATIONS INC (CONSIGNMENT | I17: 825 E WISCONSIN AVE | J17: APPLETON | K17: WI | L17: 54911-3873 | M17: 53-20-037 | N17: 652425 OH | O17: KANO | P17: AEROKROIL | Q17: 102212930 | R17: LUBRICANT PRODUCTS; | S17: EA | T17: 12 | U17: 15.17 | V17: 182.04 | W17: KANO | X17: AEROKROIL | Y17: 102212930 | Z17: KANO_AEROKROIL | AA17: EA | AB17: Z4_Pending Obsolete-Warning | AC17: OBSOLETE | AD17: NO
