Workbook

Sheet Data
S1: =SUBTOTAL(2,S3:S540) -> 538 | T1: =SUBTOTAL(9,T3:T1048576) -> 48540.57 | U1: =SUBTOTAL(9,U3:U1048576) -> 11416.384 | V1: =U1/T1 -> 0.23519262 | X1: =SUBTOTAL(9,X3:X1048576) -> 7718.1963 | AL1: =SUBTOTAL(9,AL3:AL1048576) -> 2216.4069 | AM1: =AL1/T1 -> 0.045660916 | AO1: =SUBTOTAL(9,AO3:AO1048576) -> 841.12312 | BC1: =SUBTOTAL(9,BC3:BC1048576) -> 12492.062 | BD1: =BC1/T1 -> 0.25735302 | BF1: =SUBTOTAL(9,BF3:BF1048576) -> 6642.5178
A2: Project Name | B2: Sequence Number | C2: Location | D2: Transaction Date | E2: Customer Internal Part number | F2: Distributor Name | G2: Distributor Part Number | H2: Item Description | I2: Manufacturer | J2: Manufacturer Part Number | K2: Other Notes 1 | L2: Other Notes 2 | M2: Other Notes 3 | N2: Unit of Measure (UoM) | O2: UoM Quantity | P2: Incumbent Pack Price | Q2: Quantity | R2: Unit price | S2: Total baseline units | T2: CURRENT EXT | U2: Savings $ | V2: Savings % | W2: Savings cat. | X2: PA EXT | Y2: UNIT PRICE | Z2: PA PRICE | AA2: Fastenal UOM | AB2: Fastenal UNITS/ PACK | AC2: NOTES | AD2: Fastenal MANUFACTURER NAME | AE2: Fastenal MANUFACTURER PART NUMBER | AF2: Fastenal SKU | AG2: CATEGORY | AH2: PRODUCT DESCRIPTION | AI2: MATCH TYPE | AJ2: PA CORE | AK2: PA NOTES | AL2: Savings $ | AM2: Savings % | AN2: Savings cat. | AO2: PA EXT | AP2: UNIT PRICE | AQ2: PA PRICE | AR2: Fastenal UOM | AS2: Fastenal UNITS/ PACK | AT2: NOTES | AU2: Fastenal MANUFACTURER NAME | AV2: Fastenal MANUFACTURER PART NUMBER | AW2: Fastenal SKU | AX2: CATEGORY | AY2: PRODUCT DESCRIPTION | AZ2: MATCH TYPE | BA2: CSPL | BB2: PA NOTES | BC2: Savings $ | BD2: Savings % | BE2: Savings cat. | BF2: PA EXT | BG2: UNIT PRICE | BH2: PA PRICE | BI2: Fastenal UOM | BJ2: Fastenal UNITS/ PACK | BK2: NOTES | BL2: Fastenal MANUFACTURER NAME | BM2: Fastenal MANUFACTURER PART NUMBER | BN2: Fastenal SKU | BO2: CATEGORY | BP2: PRODUCT DESCRIPTION | BQ2: MATCH TYPE | BR2: PA Core | BS2: PA NOTES
A3: VRC_Cascadia Multiple Suppliers | B3: 1 | F3: McMaster-Carr | G3: COM-0567 | H3: P900-00616 | N3: EA | O3: 1 | P3: 1238.06 | Q3: 5 | R3: =P3/O3 -> 1238.06 | S3: =Q3*O3 -> 5 | T3: =S3*R3 -> 6190.3 | AI3: Not Enough Product Data | BQ3: =IF(BS3="Original",AI3,AZ3) -> Not Enough Product Data | BS3: =IF(AQ3="","Original",IF(AP3<Y3,"Alternate","Original")) -> Original
A4: VRC_Cascadia Multiple Suppliers | B4: 2 | F4: McMaster-Carr | G4: COM-0456 | H4: 96697A500 SPRING STEEL WAVE WASHER .43" OD | N4: EA | O4: 1 | P4: 1388.16 | Q4: 1 | R4: =P4/O4 -> 1388.16 | S4: =Q4*O4 -> 1 | T4: =S4*R4 -> 1388.16 | AI4: Not Enough Product Data | BQ4: =IF(BS4="Original",AI4,AZ4) -> Not Enough Product Data | BS4: =IF(AQ4="","Original",IF(AP4<Y4,"Alternate","Original")) -> Original
A5: VRC_Cascadia Multiple Suppliers | B5: 3 | F5: McMaster-Carr | G5: COM-0453 | H5: 96562A146 6-32 X 3/8 SS SCREW | N5: EA | O5: 1 | P5: 1242.63 | Q5: 1 | R5: =P5/O5 -> 1242.63 | S5: =Q5*O5 -> 1 | T5: =S5*R5 -> 1242.63 | AI5: Not Enough Product Data | BQ5: =IF(BS5="Original",AI5,AZ5) -> Not Enough Product Data | BS5: =IF(AQ5="","Original",IF(AP5<Y5,"Alternate","Original")) -> Original
A6: VRC_Cascadia Multiple Suppliers | B6: 4 | F6: MSC | G6: 73039844 | H6: 14" Cable ties 100/pk | N6: EA | O6: 1 | P6: 273.7 | Q6: 3 | R6: =P6/O6 -> 273.7 | S6: =Q6*O6 -> 3 | T6: =S6*R6 -> 821.1 | U6: =IFERROR(T6-X6,0) -> 820.95384 | V6: =IFERROR(U6/T6,0) -> 0.99982199 | W6: =IF($V6<0,"Negative",IF($V6=0,"Same",IF($V6>0.3,"30+%",IF($V6>0.2,"20-30%",IF($V6>0.1,"10-20%",IF($V6<=0.1,"0-10%")))))) -> 30+% | X6: =IFERROR(Y6*S6,0) -> 0.14616 | Y6: =IFERROR(Z6/AB6,0) -> 0.04872 | Z6: 4.872 | AA6: Pack | AB6: 100 | AC6: Possible UOM or LPP issue. | AD6: Power Phase[REG] | AE6: 0775548 | AF6: 0775548 | AG6: Electrical | AH6: 14.6" 50lb Tensile Blue Nylon 6.6 Power Phase[REG] Colored Cable Tie Pkg | AI6: Similar Match | AJ6: No | BC6: =T6-BF6 -> 820.95384 | BD6: =BC6/T6 -> 0.99982199 | BE6: =IF(BD6<0,"Negative",IF(BD6=0,"Same",IF(BD6>0.3,"30+%",IF(BD6>0.2,"20-30%",IF(BD6>0.1,"10-20%",IF(BD6<=0.1,"0-10%")))))) -> 30+% | BF6: =BG6*S6 -> 0.14616 | BG6: =BH6/BJ6 -> 0.04872 | BH6: =IF(BS6="Original",Z6,AQ6) -> 4.872 | BI6: =IF(BS6="Original",AA6,AR6) -> Pack | BJ6: =IF(BS6="Original",AB6,AS6) -> 100 | BK6: =IF(BS6="Original",AC6,AT6) -> Possible UOM or LPP issue. | BL6: =IF(BS6="Original",AD6,AU6) -> Power Phase[REG] | BM6: =IF(BS6="Original",AE6,AV6) -> 0775548 | BN6: =IF(BS6="Original",AF6,AW6) -> 0775548 | BO6: =IF(BS6="Original",AG6,AX6) -> Electrical | BP6: =IF(BS6="Original",AH6,AY6) -> 14.6" 50lb Tensile Blue Nylon 6.6 Power Phase[REG] Colored Cable Tie Pkg | BQ6: =IF(BS6="Original",AI6,AZ6) -> Similar Match | BR6: =IF(BS6="Original",AJ6,BA6) -> No | BS6: =IF(AQ6="","Original",IF(AP6<Y6,"Alternate","Original")) -> Original
A7: VRC_Cascadia Multiple Suppliers | B7: 5 | F7: Grainger | G7: 1YND9 | H7: 30 Gal flammable cabinet. | N7: EA | O7: 1 | P7: 796.82 | Q7: 1 | R7: =P7/O7 -> 796.82 | S7: =Q7*O7 -> 1 | T7: =S7*R7 -> 796.82 | U7: =IFERROR(T7-X7,0) -> -209.0863 | V7: =IFERROR(U7/T7,0) -> -0.26240092 | W7: =IF($V7<0,"Negative",IF($V7=0,"Same",IF($V7>0.3,"30+%",IF($V7>0.2,"20-30%",IF($V7>0.1,"10-20%",IF($V7<=0.1,"0-10%")))))) -> Negative | X7: =IFERROR(Y7*S7,0) -> 1005.9063 | Y7: =IFERROR(Z7/AB7,0) -> 1005.9063 | Z7: 1005.9063 | AA7: Piece | AB7: 1 | AD7: JUSTRITE MANUFACTURING COMPANY | AE7: 893000 | AF7: 1018401 | AG7: Safety | AH7: 30 Gallon 44"Hx43"Wx18"D Yellow Steel 1-Shelf 2-Door Manual Close Safety Cabinet | AI7: Exact Match | AJ7: No | AL7: =IF(AQ7="","",T7-AO7) -> 188.5369 | AM7: =IFERROR(AL7/T7,"") -> 0.23661166 | AN7: =IF(AM7="","",IF(AM7<0,"Negative",IF(AM7=0,"Same",IF(AM7>0.3,"30+%",IF(AM7>0.2,"20-30%",IF(AM7>0.1,"10-20%",IF(AM7<=0.1,"0-10%"))))))) -> 20-30% | AO7: =IFERROR(AP7*S7,"") -> 608.2831 | AP7: =IFERROR(AQ7/AS7,"") -> 608.2831 | AQ7: 608.2831 | AR7: Piece | AS7: 1 | AU7: Agent[REG] | AV7: 1068342 | AW7: 1068342 | AX7: Safety | AY7: 30gal Capacity Yellow Steel Agent[REG] 1-Shelf Manual Close Standard Flammable Storage Cabinet | AZ7: Similar Match | BA7: Yes | BC7: =T7-BF7 -> 188.5369 | BD7: =BC7/T7 -> 0.23661166 | BE7: =IF(BD7<0,"Negative",IF(BD7=0,"Same",IF(BD7>0.3,"30+%",IF(BD7>0.2,"20-30%",IF(BD7>0.1,"10-20%",IF(BD7<=0.1,"0-10%")))))) -> 20-30% | BF7: =BG7*S7 -> 608.2831 | BG7: =BH7/BJ7 -> 608.2831 | BH7: =IF(BS7="Original",Z7,AQ7) -> 608.2831 | BI7: =IF(BS7="Original",AA7,AR7) -> Piece | BJ7: =IF(BS7="Original",AB7,AS7) -> 1 | BL7: =IF(BS7="Original",AD7,AU7) -> Agent[REG] | BM7: =IF(BS7="Original",AE7,AV7) -> 1068342 | BN7: =IF(BS7="Original",AF7,AW7) -> 1068342 | BO7: =IF(BS7="Original",AG7,AX7) -> Safety | BP7: =IF(BS7="Original",AH7,AY7) -> 30gal Capacity Yellow Steel Agent[REG] 1-Shelf Manual Close Standard Flammable Storage Cabinet | BQ7: =IF(BS7="Original",AI7,AZ7) -> Similar Match | BR7: =IF(BS7="Original",AJ7,BA7) -> Yes | BS7: =IF(AQ7="","Original",IF(AP7<Y7,"Alternate","Original")) -> Alternate
A8: VRC_Cascadia Multiple Suppliers | B8: 6 | F8: MSC | G8: 73125288 | H8: 14" CABLE TIES 100/PK | N8: EA | O8: 1 | P8: 347.86 | Q8: 2 | R8: =P8/O8 -> 347.86 | S8: =Q8*O8 -> 2 | T8: =S8*R8 -> 695.72 | U8: =IFERROR(T8-X8,0) -> 695.6486 | V8: =IFERROR(U8/T8,0) -> 0.99989737 | W8: =IF($V8<0,"Negative",IF($V8=0,"Same",IF($V8>0.3,"30+%",IF($V8>0.2,"20-30%",IF($V8>0.1,"10-20%",IF($V8<=0.1,"0-10%")))))) -> 30+% | X8: =IFERROR(Y8*S8,0) -> 0.0714 | Y8: =IFERROR(Z8/AB8,0) -> 0.0357 | Z8: 3.57 | AA8: Pack | AB8: 100 | AC8: Possible UOM or LPP issue. | AD8: Carlon[REG] | AE8: L-14-50-9-C | AF8: 0719823 | AG8: Electrical | AH8: 14.1" 50lb Tensile Natural Nylon 6.6 Cable Tie | AI8: Exact Match | AJ8: No | BC8: =T8-BF8 -> 695.6486 | BD8: =BC8/T8 -> 0.99989737 | BE8: =IF(BD8<0,"Negative",IF(BD8=0,"Same",IF(BD8>0.3,"30+%",IF(BD8>0.2,"20-30%",IF(BD8>0.1,"10-20%",IF(BD8<=0.1,"0-10%")))))) -> 30+% | BF8: =BG8*S8 -> 0.0714 | BG8: =BH8/BJ8 -> 0.0357 | BH8: =IF(BS8="Original",Z8,AQ8) -> 3.57 | BI8: =IF(BS8="Original",AA8,AR8) -> Pack | BJ8: =IF(BS8="Original",AB8,AS8) -> 100 | BK8: =IF(BS8="Original",AC8,AT8) -> Possible UOM or LPP issue. | BL8: =IF(BS8="Original",AD8,AU8) -> Carlon[REG] | BM8: =IF(BS8="Original",AE8,AV8) -> L-14-50-9-C | BN8: =IF(BS8="Original",AF8,AW8) -> 0719823 | BO8: =IF(BS8="Original",AG8,AX8) -> Electrical | BP8: =IF(BS8="Original",AH8,AY8) -> 14.1" 50lb Tensile Natural Nylon 6.6 Cable Tie | BQ8: =IF(BS8="Original",AI8,AZ8) -> Exact Match | BR8: =IF(BS8="Original",AJ8,BA8) -> No | BS8: =IF(AQ8="","Original",IF(AP8<Y8,"Alternate","Original")) -> Original
A9: VRC_Cascadia Multiple Suppliers | B9: 7 | F9: McMaster-Carr | G9: 4587t73 | H9: cabinet | N9: EA | O9: 1 | P9: 669.77 | Q9: 1 | R9: =P9/O9 -> 669.77 | S9: =Q9*O9 -> 1 | T9: =S9*R9 -> 669.77 | AC9: Need color of cabinet. | AI9: Not Enough Product Data | BK9: =IF(BS9="Original",AC9,AT9) -> Need color of cabinet. | BQ9: =IF(BS9="Original",AI9,AZ9) -> Not Enough Product Data | BS9: =IF(AQ9="","Original",IF(AP9<Y9,"Alternate","Original")) -> Original
A10: VRC_Cascadia Multiple Suppliers | B10: 8 | F10: McMaster-Carr | G10: COM-0454 | H10: 99461A130/0408LPP188 SS4 X 1/2 TRI HD | N10: EA | O10: 1 | P10: 575.23 | Q10: 1 | R10: =P10/O10 -> 575.23 | S10: =Q10*O10 -> 1 | T10: =S10*R10 -> 575.23 | AI10: Not Enough Product Data | BQ10: =IF(BS10="Original",AI10,AZ10) -> Not Enough Product Data | BS10: =IF(AQ10="","Original",IF(AP10<Y10,"Alternate","Original")) -> Original
A11: VRC_Cascadia Multiple Suppliers | B11: 9 | F11: Grainger | G11: 4YV87 | H11: fluke thermometer w/certificate | N11: EA | O11: 1 | P11: 534.48 | Q11: 1 | R11: =P11/O11 -> 534.48 | S11: =Q11*O11 -> 1 | T11: =S11*R11 -> 534.48 | U11: =IFERROR(T11-X11,0) -> 152.5005 | V11: =IFERROR(U11/T11,0) -> 0.28532499 | W11: =IF($V11<0,"Negative",IF($V11=0,"Same",IF($V11>0.3,"30+%",IF($V11>0.2,"20-30%",IF($V11>0.1,"10-20%",IF($V11<=0.1,"0-10%")))))) -> 20-30% | X11: =IFERROR(Y11*S11,0) -> 381.9795 | Y11: =IFERROR(Z11/AB11,0) -> 381.9795 | Z11: 381.9795 | AA11: Piece | AB11: 1 | AD11: Fluke Corp | AE11: 674686 | AF11: 0712562 | AG11: Test and Measurement | AH11: Fluke-51-2 Single Input Thermometer | AI11: Exact Match | AJ11: No | BC11: =T11-BF11 -> 152.5005 | BD11: =BC11/T11 -> 0.28532499 | BE11: =IF(BD11<0,"Negative",IF(BD11=0,"Same",IF(BD11>0.3,"30+%",IF(BD11>0.2,"20-30%",IF(BD11>0.1,"10-20%",IF(BD11<=0.1,"0-10%")))))) -> 20-30% | BF11: =BG11*S11 -> 381.9795 | BG11: =BH11/BJ11 -> 381.9795 | BH11: =IF(BS11="Original",Z11,AQ11) -> 381.9795 | BI11: =IF(BS11="Original",AA11,AR11) -> Piece | BJ11: =IF(BS11="Original",AB11,AS11) -> 1 | BL11: =IF(BS11="Original",AD11,AU11) -> Fluke Corp | BM11: =IF(BS11="Original",AE11,AV11) -> 674686 | BN11: =IF(BS11="Original",AF11,AW11) -> 0712562 | BO11: =IF(BS11="Original",AG11,AX11) -> Test and Measurement | BP11: =IF(BS11="Original",AH11,AY11) -> Fluke-51-2 Single Input Thermometer | BQ11: =IF(BS11="Original",AI11,AZ11) -> Exact Match | BR11: =IF(BS11="Original",AJ11,BA11) -> No | BS11: =IF(AQ11="","Original",IF(AP11<Y11,"Alternate","Original")) -> Original
A12: VRC_Cascadia Multiple Suppliers | B12: 10 | F12: McMaster-Carr | G12: COM-0555 | H12: SCREWS - P900-00684 | N12: EA | O12: 1 | P12: 131.6 | Q12: 4 | R12: =P12/O12 -> 131.6 | S12: =Q12*O12 -> 4 | T12: =S12*R12 -> 526.4 | AI12: Not Enough Product Data | BQ12: =IF(BS12="Original",AI12,AZ12) -> Not Enough Product Data | BS12: =IF(AQ12="","Original",IF(AP12<Y12,"Alternate","Original")) -> Original
A13: VRC_Cascadia Multiple Suppliers | B13: 11 | F13: MSC | G13: 61843553 | H13: Granular Ice & Snow Melter & De-Icer | N13: EA | O13: 1 | P13: 460.99 | Q13: 1 | R13: =P13/O13 -> 460.99 | S13: =Q13*O13 -> 1 | T13: =S13*R13 -> 460.99 | U13: =IFERROR(T13-X13,0) -> 453.2908 | V13: =IFERROR(U13/T13,0) -> 0.98329855 | W13: =IF($V13<0,"Negative",IF($V13=0,"Same",IF($V13>0.3,"30+%",IF($V13>0.2,"20-30%",IF($V13>0.1,"10-20%",IF($V13<=0.1,"0-10%")))))) -> 30+% | X13: =IFERROR(Y13*S13,0) -> 7.6992 | Y13: =IFERROR(Z13/AB13,0) -> 7.6992 | Z13: 7.6992 | AA13: Bag | AB13: 1 | AC13: Possible UOM or LPP issue. | AD13: TILLSON BRANDS INC | AE13: TB-ECO-SALT227KG | AF13: 0610682 | AG13: Outdoor Products and Equipment | AH13: 50lb Bag Eco Salt Ice Melter | AI13: Similar Match | AJ13: No | BC13: =T13-BF13 -> 453.2908 | BD13: =BC13/T13 -> 0.98329855 | BE13: =IF(BD13<0,"Negative",IF(BD13=0,"Same",IF(BD13>0.3,"30+%",IF(BD13>0.2,"20-30%",IF(BD13>0.1,"10-20%",IF(BD13<=0.1,"0-10%")))))) -> 30+% | BF13: =BG13*S13 -> 7.6992 | BG13: =BH13/BJ13 -> 7.6992 | BH13: =IF(BS13="Original",Z13,AQ13) -> 7.6992 | BI13: =IF(BS13="Original",AA13,AR13) -> Bag | BJ13: =IF(BS13="Original",AB13,AS13) -> 1 | BK13: =IF(BS13="Original",AC13,AT13) -> Possible UOM or LPP issue. | BL13: =IF(BS13="Original",AD13,AU13) -> TILLSON BRANDS INC | BM13: =IF(BS13="Original",AE13,AV13) -> TB-ECO-SALT227KG | BN13: =IF(BS13="Original",AF13,AW13) -> 0610682 | BO13: =IF(BS13="Original",AG13,AX13) -> Outdoor Products and Equipment | BP13: =IF(BS13="Original",AH13,AY13) -> 50lb Bag Eco Salt Ice Melter | BQ13: =IF(BS13="Original",AI13,AZ13) -> Similar Match | BR13: =IF(BS13="Original",AJ13,BA13) -> No | BS13: =IF(AQ13="","Original",IF(AP13<Y13,"Alternate","Original")) -> Original
A14: VRC_Cascadia Multiple Suppliers | B14: 12 | F14: McMaster-Carr | G14: 8975k426 | H14: 3/8 by 4 by 6 foot aluminum, shop ,dovetails | N14: EA | O14: 1 | P14: 226.89 | Q14: 2 | R14: =P14/O14 -> 226.89 | S14: =Q14*O14 -> 2 | T14: =S14*R14 -> 453.78 | U14: =IFERROR(T14-X14,0) -> 378.7512 | V14: =IFERROR(U14/T14,0) -> 0.8346582 | W14: =IF($V14<0,"Negative",IF($V14=0,"Same",IF($V14>0.3,"30+%",IF($V14>0.2,"20-30%",IF($V14>0.1,"10-20%",IF($V14<=0.1,"0-10%")))))) -> 30+% | X14: =IFERROR(Y14*S14,0) -> 75.0288 | Y14: =IFERROR(Z14/AB14,0) -> 37.5144 | Z14: 37.5144 | AA14: Piece | AB14: 1 | AC14: Possible UOM or LPP issue. | AD14: Fastenal Approved Vendor | AE14: 1161_36_0 | AF14: 0963984 | AG14: Raw Materials | AH14: 3/8" Thick x 4" Width x 3' Long ASTM B221 6061 Aluminum Flat Bar | AI14: Similar Match | AJ14: No | BC14: =T14-BF14 -> 378.7512 | BD14: =BC14/T14 -> 0.8346582 | BE14: =IF(BD14<0,"Negative",IF(BD14=0,"Same",IF(BD14>0.3,"30+%",IF(BD14>0.2,"20-30%",IF(BD14>0.1,"10-20%",IF(BD14<=0.1,"0-10%")))))) -> 30+% | BF14: =BG14*S14 -> 75.0288 | BG14: =BH14/BJ14 -> 37.5144 | BH14: =IF(BS14="Original",Z14,AQ14) -> 37.5144 | BI14: =IF(BS14="Original",AA14,AR14) -> Piece | BJ14: =IF(BS14="Original",AB14,AS14) -> 1 | BK14: =IF(BS14="Original",AC14,AT14) -> Possible UOM or LPP issue. | BL14: =IF(BS14="Original",AD14,AU14) -> Fastenal Approved Vendor | BM14: =IF(BS14="Original",AE14,AV14) -> 1161_36_0 | BN14: =IF(BS14="Original",AF14,AW14) -> 0963984 | BO14: =IF(BS14="Original",AG14,AX14) -> Raw Materials | BP14: =IF(BS14="Original",AH14,AY14) -> 3/8" Thick x 4" Width x 3' Long ASTM B221 6061 Aluminum Flat Bar | BQ14: =IF(BS14="Original",AI14,AZ14) -> Similar Match | BR14: =IF(BS14="Original",AJ14,BA14) -> No | BS14: =IF(AQ14="","Original",IF(AP14<Y14,"Alternate","Original")) -> Original
A15: VRC_Cascadia Multiple Suppliers | B15: 13 | F15: Grainger | G15: 2F625 | H15: hydraulic quick connect | N15: EA | O15: 1 | P15: 150.67 | Q15: 3 | R15: =P15/O15 -> 150.67 | S15: =Q15*O15 -> 3 | T15: =S15*R15 -> 452.01 | U15: =IFERROR(T15-X15,0) -> 415.5852 | V15: =IFERROR(U15/T15,0) -> 0.91941594 | W15: =IF($V15<0,"Negative",IF($V15=0,"Same",IF($V15>0.3,"30+%",IF($V15>0.2,"20-30%",IF($V15>0.1,"10-20%",IF($V15<=0.1,"0-10%")))))) -> 30+% | X15: =IFERROR(Y15*S15,0) -> 36.4248 | Y15: =IFERROR(Z15/AB15,0) -> 12.1416 | Z15: 12.1416 | AA15: Piece | AB15: 1 | AC15: Possible UOM or LPP issue. | AD15: Eaton/Hansen | AE15: 2H16 | AF15: 0482607 | AG15: Hydraulics | AH15: 1/4" Plug x 1/4" Female NPT Steel Double Shut-Off Hydraulic Coupler | AI15: Similar Match | AJ15: No | BC15: =T15-BF15 -> 415.5852 | BD15: =BC15/T15 -> 0.91941594 | BE15: =IF(BD15<0,"Negative",IF(BD15=0,"Same",IF(BD15>0.3,"30+%",IF(BD15>0.2,"20-30%",IF(BD15>0.1,"10-20%",IF(BD15<=0.1,"0-10%")))))) -> 30+% | BF15: =BG15*S15 -> 36.4248 | BG15: =BH15/BJ15 -> 12.1416 | BH15: =IF(BS15="Original",Z15,AQ15) -> 12.1416 | BI15: =IF(BS15="Original",AA15,AR15) -> Piece | BJ15: =IF(BS15="Original",AB15,AS15) -> 1 | BK15: =IF(BS15="Original",AC15,AT15) -> Possible UOM or LPP issue. | BL15: =IF(BS15="Original",AD15,AU15) -> Eaton/Hansen | BM15: =IF(BS15="Original",AE15,AV15) -> 2H16 | BN15: =IF(BS15="Original",AF15,AW15) -> 0482607 | BO15: =IF(BS15="Original",AG15,AX15) -> Hydraulics | BP15: =IF(BS15="Original",AH15,AY15) -> 1/4" Plug x 1/4" Female NPT Steel Double Shut-Off Hydraulic Coupler | BQ15: =IF(BS15="Original",AI15,AZ15) -> Similar Match | BR15: =IF(BS15="Original",AJ15,BA15) -> No | BS15: =IF(AQ15="","Original",IF(AP15<Y15,"Alternate","Original")) -> Original
A16: VRC_Cascadia Multiple Suppliers | B16: 14 | F16: Grainger | G16: 11Z107 | H16: Floor Marking Tape, Pattern Solid, Yellow, Width 3 in, Roll Length 100 ft | N16: EA | O16: 1 | P16: 146.26 | Q16: 3 | R16: =P16/O16 -> 146.26 | S16: =Q16*O16 -> 3 | T16: =S16*R16 -> 438.78 | U16: =IFERROR(T16-X16,0) -> 257.91 | V16: =IFERROR(U16/T16,0) -> 0.58778887 | W16: =IF($V16<0,"Negative",IF($V16=0,"Same",IF($V16>0.3,"30+%",IF($V16>0.2,"20-30%",IF($V16>0.1,"10-20%",IF($V16<=0.1,"0-10%")))))) -> 30+% | X16: =IFERROR(Y16*S16,0) -> 180.87 | Y16: =IFERROR(Z16/AB16,0) -> 60.29 | Z16: 60.29 | AA16: Roll | AB16: 1 | AD16: Toughstripe[TM] | AE16: 104342 | AF16: 1031850 | AG16: Safety | AH16: 33 yd (100') L X 3" W 8 mil Toughstripe[TM] Yellow General Purpose Floor Marking Tape Blank | AI16: Exact Match | AJ16: No | AL16: =IF(AQ16="","",T16-AO16) -> 414.3087 | AM16: =IFERROR(AL16/T16,"") -> 0.94422877 | AN16: =IF(AM16="","",IF(AM16<0,"Negative",IF(AM16=0,"Same",IF(AM16>0.3,"30+%",IF(AM16>0.2,"20-30%",IF(AM16>0.1,"10-20%",IF(AM16<=0.1,"0-10%"))))))) -> 30+% | AO16: =IFERROR(AP16*S16,"") -> 24.4713 | AP16: =IFERROR(AQ16/AS16,"") -> 8.1571 | AQ16: 8.1571 | AR16: Roll | AS16: 1 | AT16: Possible UOM or LPP issue. | AU16: Agent[REG] | AV16: 1054438 | AW16: 1054438 | AX16: Safety | AY16: 36 yd (108') L X 3" W 6 mil Yellow General Purpose Aisle Marking Tape Blank | AZ16: Similar Match | BA16: No | BC16: =T16-BF16 -> 414.3087 | BD16: =BC16/T16 -> 0.94422877 | BE16: =IF(BD16<0,"Negative",IF(BD16=0,"Same",IF(BD16>0.3,"30+%",IF(BD16>0.2,"20-30%",IF(BD16>0.1,"10-20%",IF(BD16<=0.1,"0-10%")))))) -> 30+% | BF16: =BG16*S16 -> 24.4713 | BG16: =BH16/BJ16 -> 8.1571 | BH16: =IF(BS16="Original",Z16,AQ16) -> 8.1571 | BI16: =IF(BS16="Original",AA16,AR16) -> Roll | BJ16: =IF(BS16="Original",AB16,AS16) -> 1 | BK16: =IF(BS16="Original",AC16,AT16) -> Possible UOM or LPP issue. | BL16: =IF(BS16="Original",AD16,AU16) -> Agent[REG] | BM16: =IF(BS16="Original",AE16,AV16) -> 1054438 | BN16: =IF(BS16="Original",AF16,AW16) -> 1054438 | BO16: =IF(BS16="Original",AG16,AX16) -> Safety | BP16: =IF(BS16="Original",AH16,AY16) -> 36 yd (108') L X 3" W 6 mil Yellow General Purpose Aisle Marking Tape Blank | BQ16: =IF(BS16="Original",AI16,AZ16) -> Similar Match | BR16: =IF(BS16="Original",AJ16,BA16) -> No | BS16: =IF(AQ16="","Original",IF(AP16<Y16,"Alternate","Original")) -> Alternate
A17: VRC_Cascadia Multiple Suppliers | B17: 15 | F17: McMaster-Carr | G17: COM-0403 | H17: 91755A205 RETAINER | N17: EA | O17: 1 | P17: 71.14 | Q17: 6 | R17: =P17/O17 -> 71.14 | S17: =Q17*O17 -> 6 | T17: =S17*R17 -> 426.84 | AI17: Not Enough Product Data | BQ17: =IF(BS17="Original",AI17,AZ17) -> Not Enough Product Data | BS17: =IF(AQ17="","Original",IF(AP17<Y17,"Alternate","Original")) -> Original
A18: VRC_Cascadia Multiple Suppliers | B18: 16 | F18: MSC | G18: MSC # 37997988 | H18: 0-1" range, 0.0005" Graduation, electonic Drop Indicator | N18: EA | O18: 1 | P18: 407.74 | Q18: 1 | R18: =P18/O18 -> 407.74 | S18: =Q18*O18 -> 1 | T18: =S18*R18 -> 407.74 | AI18: Non-Supported Product | BQ18: =IF(BS18="Original",AI18,AZ18) -> Non-Supported Product | BS18: =IF(AQ18="","Original",IF(AP18<Y18,"Alternate","Original")) -> Original
A19: VRC_Cascadia Multiple Suppliers | B19: 17 | F19: McMaster-Carr | G19: 50215A3 | H19: Auto-Adjusting Heavy Duty Hold-Down Toggle Clamps | N19: EA | O19: 1 | P19: 400.51 | Q19: 1 | R19: =P19/O19 -> 400.51 | S19: =Q19*O19 -> 1 | T19: =S19*R19 -> 400.51 | U19: =IFERROR(T19-X19,0) -> 270.6943 | V19: =IFERROR(U19/T19,0) -> 0.67587401 | W19: =IF($V19<0,"Negative",IF($V19=0,"Same",IF($V19>0.3,"30+%",IF($V19>0.2,"20-30%",IF($V19>0.1,"10-20%",IF($V19<=0.1,"0-10%")))))) -> 30+% | X19: =IFERROR(Y19*S19,0) -> 129.8157 | Y19: =IFERROR(Z19/AB19,0) -> 129.8157 | Z19: 129.8157 | AA19: Piece | AB19: 1 | AC19: Possible UOM or LPP issue. | AD19: DESTACO | AE19: 7-101 | AF19: 03054785 | AG19: Cutting Tools and Metalworking | AH19: 7-101 Cam-Action Clamp | AI19: Similar Match | AJ19: No | BC19: =T19-BF19 -> 270.6943 | BD19: =BC19/T19 -> 0.67587401 | BE19: =IF(BD19<0,"Negative",IF(BD19=0,"Same",IF(BD19>0.3,"30+%",IF(BD19>0.2,"20-30%",IF(BD19>0.1,"10-20%",IF(BD19<=0.1,"0-10%")))))) -> 30+% | BF19: =BG19*S19 -> 129.8157 | BG19: =BH19/BJ19 -> 129.8157 | BH19: =IF(BS19="Original",Z19,AQ19) -> 129.8157 | BI19: =IF(BS19="Original",AA19,AR19) -> Piece | BJ19: =IF(BS19="Original",AB19,AS19) -> 1 | BK19: =IF(BS19="Original",AC19,AT19) -> Possible UOM or LPP issue. | BL19: =IF(BS19="Original",AD19,AU19) -> DESTACO | BM19: =IF(BS19="Original",AE19,AV19) -> 7-101 | BN19: =IF(BS19="Original",AF19,AW19) -> 03054785 | BO19: =IF(BS19="Original",AG19,AX19) -> Cutting Tools and Metalworking | BP19: =IF(BS19="Original",AH19,AY19) -> 7-101 Cam-Action Clamp | BQ19: =IF(BS19="Original",AI19,AZ19) -> Similar Match | BR19: =IF(BS19="Original",AJ19,BA19) -> No | BS19: =IF(AQ19="","Original",IF(AP19<Y19,"Alternate","Original")) -> Original
A20: VRC_Cascadia Multiple Suppliers | B20: 18 | F20: McMaster-Carr | G20: 8975k224 | H20: 5/8 by6 by 6 foot aluminum pry bars | N20: EA | O20: 1 | P20: 395.74 | Q20: 1 | R20: =P20/O20 -> 395.74 | S20: =Q20*O20 -> 1 | T20: =S20*R20 -> 395.74 | AI20: Non-Supported Product | BQ20: =IF(BS20="Original",AI20,AZ20) -> Non-Supported Product | BS20: =IF(AQ20="","Original",IF(AP20<Y20,"Alternate","Original")) -> Original
A21: VRC_Cascadia Multiple Suppliers | B21: 19 | F21: MSC | G21: 75638437 | H21: Mitutoyo 1/4" range 0-50-0 dial reading 0.001" Graduation Dial Drop Indicator | N21: EA | O21: 1 | P21: 391.73 | Q21: 1 | R21: =P21/O21 -> 391.73 | S21: =Q21*O21 -> 1 | T21: =S21*R21 -> 391.73 | U21: =IFERROR(T21-X21,0) -> 279.5112 | V21: =IFERROR(U21/T21,0) -> 0.71353024 | W21: =IF($V21<0,"Negative",IF($V21=0,"Same",IF($V21>0.3,"30+%",IF($V21>0.2,"20-30%",IF($V21>0.1,"10-20%",IF($V21<=0.1,"0-10%")))))) -> 30+% | X21: =IFERROR(Y21*S21,0) -> 112.2188 | Y21: =IFERROR(Z21/AB21,0) -> 112.2188 | Z21: 112.2188 | AA21: Piece | AB21: 1 | AC21: Possible UOM or LPP issue. | AD21: MITUTOYO AMERICA CORPORATION | AE21: 1411S | AF21: 99029064 | AG21: Test and Measurement | AH21: 1411S DIAL INDICATOR, .001-.25" | AI21: Exact Match | AJ21: No | BC21: =T21-BF21 -> 279.5112 | BD21: =BC21/T21 -> 0.71353024 | BE21: =IF(BD21<0,"Negative",IF(BD21=0,"Same",IF(BD21>0.3,"30+%",IF(BD21>0.2,"20-30%",IF(BD21>0.1,"10-20%",IF(BD21<=0.1,"0-10%")))))) -> 30+% | BF21: =BG21*S21 -> 112.2188 | BG21: =BH21/BJ21 -> 112.2188 | BH21: =IF(BS21="Original",Z21,AQ21) -> 112.2188 | BI21: =IF(BS21="Original",AA21,AR21) -> Piece | BJ21: =IF(BS21="Original",AB21,AS21) -> 1 | BK21: =IF(BS21="Original",AC21,AT21) -> Possible UOM or LPP issue. | BL21: =IF(BS21="Original",AD21,AU21) -> MITUTOYO AMERICA CORPORATION | BM21: =IF(BS21="Original",AE21,AV21) -> 1411S | BN21: =IF(BS21="Original",AF21,AW21) -> 99029064 | BO21: =IF(BS21="Original",AG21,AX21) -> Test and Measurement | BP21: =IF(BS21="Original",AH21,AY21) -> 1411S DIAL INDICATOR, .001-.25" | BQ21: =IF(BS21="Original",AI21,AZ21) -> Exact Match | BR21: =IF(BS21="Original",AJ21,BA21) -> No | BS21: =IF(AQ21="","Original",IF(AP21<Y21,"Alternate","Original")) -> Original
A22: VRC_Cascadia Multiple Suppliers | B22: 20 | F22: McMaster-Carr | G22: 2547k43 | H22: 1/2 by 39 by 39 garolite welder table | N22: EA | O22: 1 | P22: 382.16 | Q22: 1 | R22: =P22/O22 -> 382.16 | S22: =Q22*O22 -> 1 | T22: =S22*R22 -> 382.16 | AI22: Non-Supported Product | BQ22: =IF(BS22="Original",AI22,AZ22) -> Non-Supported Product | BS22: =IF(AQ22="","Original",IF(AP22<Y22,"Alternate","Original")) -> Original
A23: VRC_Cascadia Multiple Suppliers | B23: 21 | F23: MSC | G23: 84540673 | H23: tool wrap | N23: EA | O23: 1 | P23: 374.42 | Q23: 1 | R23: =P23/O23 -> 374.42 | S23: =Q23*O23 -> 1 | T23: =S23*R23 -> 374.42 | U23: =IFERROR(T23-X23,0) -> 225.2615 | V23: =IFERROR(U23/T23,0) -> 0.60162785 | W23: =IF($V23<0,"Negative",IF($V23=0,"Same",IF($V23>0.3,"30+%",IF($V23>0.2,"20-30%",IF($V23>0.1,"10-20%",IF($V23<=0.1,"0-10%")))))) -> 30+% | X23: =IFERROR(Y23*S23,0) -> 149.1585 | Y23: =IFERROR(Z23/AB23,0) -> 149.1585 | Z23: 149.1585 | AA23: Piece | AB23: 1 | AC23: Possible UOM or LPP issue. | AD23: PRECISION BRAND PRODUCTS, INC. | AE23: 20310 | AF23: 7041389 | AG23: Raw Materials | AH23: 12" x 50' x .002" Type 321 Stainless Steel Tool Wrap/Foil | AI23: Exact Match | AJ23: No | AL23: =IF(AQ23="","",T23-AO23) -> 261.965 | AM23: =IFERROR(AL23/T23,"") -> 0.69965547 | AN23: =IF(AM23="","",IF(AM23<0,"Negative",IF(AM23=0,"Same",IF(AM23>0.3,"30+%",IF(AM23>0.2,"20-30%",IF(AM23>0.1,"10-20%",IF(AM23<=0.1,"0-10%"))))))) -> 30+% | AO23: =IFERROR(AP23*S23,"") -> 112.455 | AP23: =IFERROR(AQ23/AS23,"") -> 112.455 | AQ23: 449.82 | AR23: Pack | AS23: 4 | AT23: Possible UOM or LPP issue. | AU23: Fastenal Approved Vendor | AV23: 0993323 | AW23: 0993323 | AX23: Raw Materials | AY23: 12" x .002" x 50' 321 Stainless Steel Foil | AZ23: Similar Match | BA23: No | BC23: =T23-BF23 -> 261.965 | BD23: =BC23/T23 -> 0.69965547 | BE23: =IF(BD23<0,"Negative",IF(BD23=0,"Same",IF(BD23>0.3,"30+%",IF(BD23>0.2,"20-30%",IF(BD23>0.1,"10-20%",IF(BD23<=0.1,"0-10%")))))) -> 30+% | BF23: =BG23*S23 -> 112.455 | BG23: =BH23/BJ23 -> 112.455 | BH23: =IF(BS23="Original",Z23,AQ23) -> 449.82 | BI23: =IF(BS23="Original",AA23,AR23) -> Pack | BJ23: =IF(BS23="Original",AB23,AS23) -> 4 | BK23: =IF(BS23="Original",AC23,AT23) -> Possible UOM or LPP issue. | BL23: =IF(BS23="Original",AD23,AU23) -> Fastenal Approved Vendor | BM23: =IF(BS23="Original",AE23,AV23) -> 0993323 | BN23: =IF(BS23="Original",AF23,AW23) -> 0993323 | BO23: =IF(BS23="Original",AG23,AX23) -> Raw Materials | BP23: =IF(BS23="Original",AH23,AY23) -> 12" x .002" x 50' 321 Stainless Steel Foil | BQ23: =IF(BS23="Original",AI23,AZ23) -> Similar Match | BR23: =IF(BS23="Original",AJ23,BA23) -> No | BS23: =IF(AQ23="","Original",IF(AP23<Y23,"Alternate","Original")) -> Alternate
A24: VRC_Cascadia Multiple Suppliers | B24: 22 | F24: Grainger | G24: 11C909 | H24: pistol grip air impact | N24: EA | O24: 1 | P24: 365.59 | Q24: 1 | R24: =P24/O24 -> 365.59 | S24: =Q24*O24 -> 1 | T24: =S24*R24 -> 365.59 | U24: =IFERROR(T24-X24,0) -> -20.4862 | V24: =IFERROR(U24/T24,0) -> -0.056035997 | W24: =IF($V24<0,"Negative",IF($V24=0,"Same",IF($V24>0.3,"30+%",IF($V24>0.2,"20-30%",IF($V24>0.1,"10-20%",IF($V24<=0.1,"0-10%")))))) -> Negative | X24: =IFERROR(Y24*S24,0) -> 386.0762 | Y24: =IFERROR(Z24/AB24,0) -> 386.0762 | Z24: 386.0762 | AA24: Piece | AB24: 1 | AD24: CHICAGO PNEUMATIC TOOL COMPANY | AE24: T025214 | AF24: 2183431 | AG24: Tools and Equipment | AH24: 1/2" 6400rpm Square Heavy Duty Air Impact Wrench 96 dBA Pistol Grip | AI24: Exact Match | AJ24: No | BC24: =T24-BF24 -> -20.4862 | BD24: =BC24/T24 -> -0.056035997 | BE24: =IF(BD24<0,"Negative",IF(BD24=0,"Same",IF(BD24>0.3,"30+%",IF(BD24>0.2,"20-30%",IF(BD24>0.1,"10-20%",IF(BD24<=0.1,"0-10%")))))) -> Negative | BF24: =BG24*S24 -> 386.0762 | BG24: =BH24/BJ24 -> 386.0762 | BH24: =IF(BS24="Original",Z24,AQ24) -> 386.0762 | BI24: =IF(BS24="Original",AA24,AR24) -> Piece | BJ24: =IF(BS24="Original",AB24,AS24) -> 1 | BL24: =IF(BS24="Original",AD24,AU24) -> CHICAGO PNEUMATIC TOOL COMPANY | BM24: =IF(BS24="Original",AE24,AV24) -> T025214 | BN24: =IF(BS24="Original",AF24,AW24) -> 2183431 | BO24: =IF(BS24="Original",AG24,AX24) -> Tools and Equipment | BP24: =IF(BS24="Original",AH24,AY24) -> 1/2" 6400rpm Square Heavy Duty Air Impact Wrench 96 dBA Pistol Grip | BQ24: =IF(BS24="Original",AI24,AZ24) -> Exact Match | BR24: =IF(BS24="Original",AJ24,BA24) -> No | BS24: =IF(AQ24="","Original",IF(AP24<Y24,"Alternate","Original")) -> Original
A25: VRC_Cascadia Multiple Suppliers | B25: 23 | F25: Grainger | G25: 46Z647 | H25: 24VDC Air Valve | N25: EA | O25: 1 | P25: 354.47 | Q25: 1 | R25: =P25/O25 -> 354.47 | S25: =Q25*O25 -> 1 | T25: =S25*R25 -> 354.47 | U25: =IFERROR(T25-X25,0) -> 143.0399 | V25: =IFERROR(U25/T25,0) -> 0.40353175 | W25: =IF($V25<0,"Negative",IF($V25=0,"Same",IF($V25>0.3,"30+%",IF($V25>0.2,"20-30%",IF($V25>0.1,"10-20%",IF($V25<=0.1,"0-10%")))))) -> 30+% | X25: =IFERROR(Y25*S25,0) -> 211.4301 | Y25: =IFERROR(Z25/AB25,0) -> 211.4301 | Z25: 211.4301 | AA25: Piece | AB25: 1 | AD25: Dynaquip | AE25: 145855.03 | AF25: BSS | AG25: Pneumatics | AH25: Air Vaulve | AI25: Exact Match | AJ25: No | BC25: =T25-BF25 -> 143.0399 | BD25: =BC25/T25 -> 0.40353175 | BE25: =IF(BD25<0,"Negative",IF(BD25=0,"Same",IF(BD25>0.3,"30+%",IF(BD25>0.2,"20-30%",IF(BD25>0.1,"10-20%",IF(BD25<=0.1,"0-10%")))))) -> 30+% | BF25: =BG25*S25 -> 211.4301 | BG25: =BH25/BJ25 -> 211.4301 | BH25: =IF(BS25="Original",Z25,AQ25) -> 211.4301 | BI25: =IF(BS25="Original",AA25,AR25) -> Piece | BJ25: =IF(BS25="Original",AB25,AS25) -> 1 | BL25: =IF(BS25="Original",AD25,AU25) -> Dynaquip | BM25: =IF(BS25="Original",AE25,AV25) -> 145855.03 | BN25: =IF(BS25="Original",AF25,AW25) -> BSS | BO25: =IF(BS25="Original",AG25,AX25) -> Pneumatics | BP25: =IF(BS25="Original",AH25,AY25) -> Air Vaulve | BQ25: =IF(BS25="Original",AI25,AZ25) -> Exact Match | BR25: =IF(BS25="Original",AJ25,BA25) -> No | BS25: =IF(AQ25="","Original",IF(AP25<Y25,"Alternate","Original")) -> Original
A26: VRC_Cascadia Multiple Suppliers | B26: 24 | F26: MSC | G26: 09413121 | H26: kool mister | N26: EA | O26: 1 | P26: 160.63 | Q26: 2 | R26: =P26/O26 -> 160.63 | S26: =Q26*O26 -> 2 | T26: =S26*R26 -> 321.26 | U26: =IFERROR(T26-X26,0) -> 93.704 | V26: =IFERROR(U26/T26,0) -> 0.29167652 | W26: =IF($V26<0,"Negative",IF($V26=0,"Same",IF($V26>0.3,"30+%",IF($V26>0.2,"20-30%",IF($V26>0.1,"10-20%",IF($V26<=0.1,"0-10%")))))) -> 20-30% | X26: =IFERROR(Y26*S26,0) -> 227.556 | Y26: =IFERROR(Z26/AB26,0) -> 113.778 | Z26: 113.778 | AA26: Piece | AB26: 1 | AD26: Lennox | AE26: 60M12 | AF26: 922890735 | AG26: Safety | AH26: 60M12 24v Coil 3P 25AMP W/AUX CONT | AI26: Exact Match | AJ26: No | BC26: =T26-BF26 -> 93.704 | BD26: =BC26/T26 -> 0.29167652 | BE26: =IF(BD26<0,"Negative",IF(BD26=0,"Same",IF(BD26>0.3,"30+%",IF(BD26>0.2,"20-30%",IF(BD26>0.1,"10-20%",IF(BD26<=0.1,"0-10%")))))) -> 20-30% | BF26: =BG26*S26 -> 227.556 | BG26: =BH26/BJ26 -> 113.778 | BH26: =IF(BS26="Original",Z26,AQ26) -> 113.778 | BI26: =IF(BS26="Original",AA26,AR26) -> Piece | BJ26: =IF(BS26="Original",AB26,AS26) -> 1 | BL26: =IF(BS26="Original",AD26,AU26) -> Lennox | BM26: =IF(BS26="Original",AE26,AV26) -> 60M12 | BN26: =IF(BS26="Original",AF26,AW26) -> 922890735 | BO26: =IF(BS26="Original",AG26,AX26) -> Safety | BP26: =IF(BS26="Original",AH26,AY26) -> 60M12 24v Coil 3P 25AMP W/AUX CONT | BQ26: =IF(BS26="Original",AI26,AZ26) -> Exact Match | BR26: =IF(BS26="Original",AJ26,BA26) -> No | BS26: =IF(AQ26="","Original",IF(AP26<Y26,"Alternate","Original")) -> Original
A27: VRC_Cascadia Multiple Suppliers | B27: 25 | F27: Grainger | G27: 4YTG5 | H27: 3 Way/2 Position, 24VDC Air Valve | N27: EA | O27: 1 | P27: 318.65 | Q27: 1 | R27: =P27/O27 -> 318.65 | S27: =Q27*O27 -> 1 | T27: =S27*R27 -> 318.65 | U27: =IFERROR(T27-X27,0) -> 221.8579 | V27: =IFERROR(U27/T27,0) -> 0.69624321 | W27: =IF($V27<0,"Negative",IF($V27=0,"Same",IF($V27>0.3,"30+%",IF($V27>0.2,"20-30%",IF($V27>0.1,"10-20%",IF($V27<=0.1,"0-10%")))))) -> 30+% | X27: =IFERROR(Y27*S27,0) -> 96.7921 | Y27: =IFERROR(Z27/AB27,0) -> 96.7921 | Z27: 96.7921 | AA27: Piece | AB27: 1 | AC27: Possible UOM or LPP issue. | AD27: Ingersoll Rand[REG] | AE27: M253SS-024-D | AF27: 921107524 | AG27: Pneumatics | AH27: ARO Solenoid Air Control Valve 3-Way/2-Position Voltage 24Vdc Valve Actuator/Return Solenoid/Spring Pipe Size 3/8" Max. Cfm Valves 61.00 Pressure Range 45 To 115 Psi Temp Range 15 - 122 Degrees | AI27: Exact Match | AJ27: No | BC27: =T27-BF27 -> 221.8579 | BD27: =BC27/T27 -> 0.69624321 | BE27: =IF(BD27<0,"Negative",IF(BD27=0,"Same",IF(BD27>0.3,"30+%",IF(BD27>0.2,"20-30%",IF(BD27>0.1,"10-20%",IF(BD27<=0.1,"0-10%")))))) -> 30+% | BF27: =BG27*S27 -> 96.7921 | BG27: =BH27/BJ27 -> 96.7921 | BH27: =IF(BS27="Original",Z27,AQ27) -> 96.7921 | BI27: =IF(BS27="Original",AA27,AR27) -> Piece | BJ27: =IF(BS27="Original",AB27,AS27) -> 1 | BK27: =IF(BS27="Original",AC27,AT27) -> Possible UOM or LPP issue. | BL27: =IF(BS27="Original",AD27,AU27) -> Ingersoll Rand[REG] | BM27: =IF(BS27="Original",AE27,AV27) -> M253SS-024-D | BN27: =IF(BS27="Original",AF27,AW27) -> 921107524 | BO27: =IF(BS27="Original",AG27,AX27) -> Pneumatics | BP27: =IF(BS27="Original",AH27,AY27) -> ARO Solenoid Air Control Valve 3-Way/2-Position Voltage 24Vdc Valve Actuator/Return Solenoid/Spring Pipe Size 3/8" Max. Cfm Valves 61.00 Pressure Range 45 To 115 Psi Temp Range 15 - 122 Degrees | BQ27: =IF(BS27="Original",AI27,AZ27) -> Exact Match | BR27: =IF(BS27="Original",AJ27,BA27) -> No | BS27: =IF(AQ27="","Original",IF(AP27<Y27,"Alternate","Original")) -> Original
A28: VRC_Cascadia Multiple Suppliers | B28: 26 | F28: McMaster-Carr | G28: 9246k564 | H28: 3/4 alu by 6 by 48 inches shop | N28: EA | O28: 1 | P28: 157.13 | Q28: 2 | R28: =P28/O28 -> 157.13 | S28: =Q28*O28 -> 2 | T28: =S28*R28 -> 314.26 | U28: =IFERROR(T28-X28,0) -> -121.2296 | V28: =IFERROR(U28/T28,0) -> -0.38576211 | W28: =IF($V28<0,"Negative",IF($V28=0,"Same",IF($V28>0.3,"30+%",IF($V28>0.2,"20-30%",IF($V28>0.1,"10-20%",IF($V28<=0.1,"0-10%")))))) -> Negative | X28: =IFERROR(Y28*S28,0) -> 435.4896 | Y28: =IFERROR(Z28/AB28,0) -> 217.7448 | Z28: 217.7448 | AA28: Piece | AB28: 1 | AD28: Fastenal Approved Vendor | AE28: 1184_144_0 | AF28: 0964089 | AG28: Raw Materials | AH28: 3/4" Thick x 6" Width x 12' Long ASTM B221 6061 Aluminum Flat Bar | AI28: Exact Match | AJ28: No | BC28: =T28-BF28 -> -121.2296 | BD28: =BC28/T28 -> -0.38576211 | BE28: =IF(BD28<0,"Negative",IF(BD28=0,"Same",IF(BD28>0.3,"30+%",IF(BD28>0.2,"20-30%",IF(BD28>0.1,"10-20%",IF(BD28<=0.1,"0-10%")))))) -> Negative | BF28: =BG28*S28 -> 435.4896 | BG28: =BH28/BJ28 -> 217.7448 | BH28: =IF(BS28="Original",Z28,AQ28) -> 217.7448 | BI28: =IF(BS28="Original",AA28,AR28) -> Piece | BJ28: =IF(BS28="Original",AB28,AS28) -> 1 | BL28: =IF(BS28="Original",AD28,AU28) -> Fastenal Approved Vendor | BM28: =IF(BS28="Original",AE28,AV28) -> 1184_144_0 | BN28: =IF(BS28="Original",AF28,AW28) -> 0964089 | BO28: =IF(BS28="Original",AG28,AX28) -> Raw Materials | BP28: =IF(BS28="Original",AH28,AY28) -> 3/4" Thick x 6" Width x 12' Long ASTM B221 6061 Aluminum Flat Bar | BQ28: =IF(BS28="Original",AI28,AZ28) -> Exact Match | BR28: =IF(BS28="Original",AJ28,BA28) -> No | BS28: =IF(AQ28="","Original",IF(AP28<Y28,"Alternate","Original")) -> Original
A29: VRC_Cascadia Multiple Suppliers | B29: 27 | F29: Grainger | G29: 31AX37 | H29: Indoor convex mirror | N29: EA | O29: 1 | P29: 308.28 | Q29: 1 | R29: =P29/O29 -> 308.28 | S29: =Q29*O29 -> 1 | T29: =S29*R29 -> 308.28 | AI29: Non-Supported Product | BQ29: =IF(BS29="Original",AI29,AZ29) -> Non-Supported Product | BS29: =IF(AQ29="","Original",IF(AP29<Y29,"Alternate","Original")) -> Original
A30: VRC_Cascadia Multiple Suppliers | B30: 28 | F30: Grainger | G30: COM-0440 | H30: BRT DK2214 LABEL FOR VIEWER | N30: EA | O30: 1 | P30: 153.15 | Q30: 2 | R30: =P30/O30 -> 153.15 | S30: =Q30*O30 -> 2 | T30: =S30*R30 -> 306.3 | AI30: Not Enough Product Data | BQ30: =IF(BS30="Original",AI30,AZ30) -> Not Enough Product Data | BS30: =IF(AQ30="","Original",IF(AP30<Y30,"Alternate","Original")) -> Original
A31: VRC_Cascadia Multiple Suppliers | B31: 29 | F31: McMaster-Carr | G31: 88915k21 | H31: ss rod | N31: EA | O31: 1 | P31: 279.88 | Q31: 1 | R31: =P31/O31 -> 279.88 | S31: =Q31*O31 -> 1 | T31: =S31*R31 -> 279.88 | U31: =IFERROR(T31-X31,0) -> 263.9305 | V31: =IFERROR(U31/T31,0) -> 0.94301308 | W31: =IF($V31<0,"Negative",IF($V31=0,"Same",IF($V31>0.3,"30+%",IF($V31>0.2,"20-30%",IF($V31>0.1,"10-20%",IF($V31<=0.1,"0-10%")))))) -> 30+% | X31: =IFERROR(Y31*S31,0) -> 15.9495 | Y31: =IFERROR(Z31/AB31,0) -> 15.9495 | Z31: 15.9495 | AA31: Piece | AB31: 1 | AC31: Possible UOM or LPP issue. | AD31: Fastenal Approved Vendor | AE31: 2014_72_0 | AF31: 0964653 | AG31: Raw Materials | AH31: 3/8" Dia x 6' Long ASTM A582 303 Stainless Steel Round Stock | AI31: Similar Match | AJ31: No | BC31: =T31-BF31 -> 263.9305 | BD31: =BC31/T31 -> 0.94301308 | BE31: =IF(BD31<0,"Negative",IF(BD31=0,"Same",IF(BD31>0.3,"30+%",IF(BD31>0.2,"20-30%",IF(BD31>0.1,"10-20%",IF(BD31<=0.1,"0-10%")))))) -> 30+% | BF31: =BG31*S31 -> 15.9495 | BG31: =BH31/BJ31 -> 15.9495 | BH31: =IF(BS31="Original",Z31,AQ31) -> 15.9495 | BI31: =IF(BS31="Original",AA31,AR31) -> Piece | BJ31: =IF(BS31="Original",AB31,AS31) -> 1 | BK31: =IF(BS31="Original",AC31,AT31) -> Possible UOM or LPP issue. | BL31: =IF(BS31="Original",AD31,AU31) -> Fastenal Approved Vendor | BM31: =IF(BS31="Original",AE31,AV31) -> 2014_72_0 | BN31: =IF(BS31="Original",AF31,AW31) -> 0964653 | BO31: =IF(BS31="Original",AG31,AX31) -> Raw Materials | BP31: =IF(BS31="Original",AH31,AY31) -> 3/8" Dia x 6' Long ASTM A582 303 Stainless Steel Round Stock | BQ31: =IF(BS31="Original",AI31,AZ31) -> Similar Match | BR31: =IF(BS31="Original",AJ31,BA31) -> No | BS31: =IF(AQ31="","Original",IF(AP31<Y31,"Alternate","Original")) -> Original
A32: VRC_Cascadia Multiple Suppliers | B32: 30 | F32: McMaster-Carr | G32: 2547k52 | H32: 3/4 by 18 by 39 Garolite | N32: EA | O32: 1 | P32: 277.87 | Q32: 1 | R32: =P32/O32 -> 277.87 | S32: =Q32*O32 -> 1 | T32: =S32*R32 -> 277.87 | AI32: Non-Supported Product | BQ32: =IF(BS32="Original",AI32,AZ32) -> Non-Supported Product | BS32: =IF(AQ32="","Original",IF(AP32<Y32,"Alternate","Original")) -> Original
A33: VRC_Cascadia Multiple Suppliers | B33: 31 | F33: McMaster-Carr | G33: 8975k446 | H33: alu plate by 3 feet | N33: EA | O33: 1 | P33: 138.72 | Q33: 2 | R33: =P33/O33 -> 138.72 | S33: =Q33*O33 -> 2 | T33: =S33*R33 -> 277.44 | AI33: Non-Supported Product | BQ33: =IF(BS33="Original",AI33,AZ33) -> Non-Supported Product | BS33: =IF(AQ33="","Original",IF(AP33<Y33,"Alternate","Original")) -> Original
A34: VRC_Cascadia Multiple Suppliers | B34: 32 | F34: Grainger | G34: 1ETT9 | H34: Polycarbonate sheet stock, 48"x96" | N34: EA | O34: 1 | P34: 276.22 | Q34: 1 | R34: =P34/O34 -> 276.22 | S34: =Q34*O34 -> 1 | T34: =S34*R34 -> 276.22 | U34: =IFERROR(T34-X34,0) -> 42.1628 | V34: =IFERROR(U34/T34,0) -> 0.1526421 | W34: =IF($V34<0,"Negative",IF($V34=0,"Same",IF($V34>0.3,"30+%",IF($V34>0.2,"20-30%",IF($V34>0.1,"10-20%",IF($V34<=0.1,"0-10%")))))) -> 10-20% | X34: =IFERROR(Y34*S34,0) -> 234.0572 | Y34: =IFERROR(Z34/AB34,0) -> 234.0572 | Z34: 234.0572 | AA34: Piece | AB34: 1 | AD34: Fastenal Approved Vendor | AE34: 11328101 | AF34: 0954800 | AG34: Raw Materials | AH34: 0.236" x 48" x 96" Clear Polycarbonate Sheet | AI34: Exact Match | AJ34: Yes | BC34: =T34-BF34 -> 42.1628 | BD34: =BC34/T34 -> 0.1526421 | BE34: =IF(BD34<0,"Negative",IF(BD34=0,"Same",IF(BD34>0.3,"30+%",IF(BD34>0.2,"20-30%",IF(BD34>0.1,"10-20%",IF(BD34<=0.1,"0-10%")))))) -> 10-20% | BF34: =BG34*S34 -> 234.0572 | BG34: =BH34/BJ34 -> 234.0572 | BH34: =IF(BS34="Original",Z34,AQ34) -> 234.0572 | BI34: =IF(BS34="Original",AA34,AR34) -> Piece | BJ34: =IF(BS34="Original",AB34,AS34) -> 1 | BL34: =IF(BS34="Original",AD34,AU34) -> Fastenal Approved Vendor | BM34: =IF(BS34="Original",AE34,AV34) -> 11328101 | BN34: =IF(BS34="Original",AF34,AW34) -> 0954800 | BO34: =IF(BS34="Original",AG34,AX34) -> Raw Materials | BP34: =IF(BS34="Original",AH34,AY34) -> 0.236" x 48" x 96" Clear Polycarbonate Sheet | BQ34: =IF(BS34="Original",AI34,AZ34) -> Exact Match | BR34: =IF(BS34="Original",AJ34,BA34) -> Yes | BS34: =IF(AQ34="","Original",IF(AP34<Y34,"Alternate","Original")) -> Original
A35: VRC_Cascadia Multiple Suppliers | B35: 33 | F35: McMaster-Carr | G35: 8975k244 | H35: 1 by 6 inches by 3 feet alu F6815 | N35: EA | O35: 1 | P35: 133.45 | Q35: 2 | R35: =P35/O35 -> 133.45 | S35: =Q35*O35 -> 2 | T35: =S35*R35 -> 266.9 | AI35: Potential Sourcing | BQ35: =IF(BS35="Original",AI35,AZ35) -> Potential Sourcing | BS35: =IF(AQ35="","Original",IF(AP35<Y35,"Alternate","Original")) -> Original
A36: VRC_Cascadia Multiple Suppliers | B36: 34 | F36: Grainger | G36: ADH-0039 | H36: EPX Plus II Mixing Nozzle | N36: EA | O36: 1 | P36: 131.69 | Q36: 2 | R36: =P36/O36 -> 131.69 | S36: =Q36*O36 -> 2 | T36: =S36*R36 -> 263.38 | U36: =IFERROR(T36-X36,0) -> 256.3682 | V36: =IFERROR(U36/T36,0) -> 0.97337763 | W36: =IF($V36<0,"Negative",IF($V36=0,"Same",IF($V36>0.3,"30+%",IF($V36>0.2,"20-30%",IF($V36>0.1,"10-20%",IF($V36<=0.1,"0-10%")))))) -> 30+% | X36: =IFERROR(Y36*S36,0) -> 7.0118 | Y36: =IFERROR(Z36/AB36,0) -> 3.5059 | Z36: 3.5059 | AA36: Piece | AB36: 1 | AC36: Possible UOM or LPP issue. | AD36: 3M PRODUCTS | AE36: 00076308864347 | AF36: 0626172 | AG36: Adhesives, Sealants, and Tape | AH36: 48.5mL & 50mL EPX Mixing Nozzle | AI36: Similar Match | AJ36: Yes | BC36: =T36-BF36 -> 256.3682 | BD36: =BC36/T36 -> 0.97337763 | BE36: =IF(BD36<0,"Negative",IF(BD36=0,"Same",IF(BD36>0.3,"30+%",IF(BD36>0.2,"20-30%",IF(BD36>0.1,"10-20%",IF(BD36<=0.1,"0-10%")))))) -> 30+% | BF36: =BG36*S36 -> 7.0118 | BG36: =BH36/BJ36 -> 3.5059 | BH36: =IF(BS36="Original",Z36,AQ36) -> 3.5059 | BI36: =IF(BS36="Original",AA36,AR36) -> Piece | BJ36: =IF(BS36="Original",AB36,AS36) -> 1 | BK36: =IF(BS36="Original",AC36,AT36) -> Possible UOM or LPP issue. | BL36: =IF(BS36="Original",AD36,AU36) -> 3M PRODUCTS | BM36: =IF(BS36="Original",AE36,AV36) -> 00076308864347 | BN36: =IF(BS36="Original",AF36,AW36) -> 0626172 | BO36: =IF(BS36="Original",AG36,AX36) -> Adhesives, Sealants, and Tape | BP36: =IF(BS36="Original",AH36,AY36) -> 48.5mL & 50mL EPX Mixing Nozzle | BQ36: =IF(BS36="Original",AI36,AZ36) -> Similar Match | BR36: =IF(BS36="Original",AJ36,BA36) -> Yes | BS36: =IF(AQ36="","Original",IF(AP36<Y36,"Alternate","Original")) -> Original
A37: VRC_Cascadia Multiple Suppliers | B37: 35 | F37: Grainger | G37: 11Z095 | H37: Floor Marking Tape, Pattern Solid, White, Width 2 in, Roll Length 100 ft | N37: EA | O37: 1 | P37: 64.38 | Q37: 4 | R37: =P37/O37 -> 64.38 | S37: =Q37*O37 -> 4 | T37: =S37*R37 -> 257.52 | U37: =IFERROR(T37-X37,0) -> 92.8436 | V37: =IFERROR(U37/T37,0) -> 0.36052967 | W37: =IF($V37<0,"Negative",IF($V37=0,"Same",IF($V37>0.3,"30+%",IF($V37>0.2,"20-30%",IF($V37>0.1,"10-20%",IF($V37<=0.1,"0-10%")))))) -> 30+% | X37: =IFERROR(Y37*S37,0) -> 164.6764 | Y37: =IFERROR(Z37/AB37,0) -> 41.1691 | Z37: 41.1691 | AA37: Roll | AB37: 1 | AD37: Toughstripe[TM] | AE37: 104311 | AF37: 1031839 | AG37: Safety | AH37: 33 yd (100') L X 2" W 8 mil White General Purpose Floor Marking Tape Blank | AI37: Exact Match | AJ37: No | AL37: =IF(AQ37="","",T37-AO37) -> 228.738 | AM37: =IFERROR(AL37/T37,"") -> 0.88823392 | AN37: =IF(AM37="","",IF(AM37<0,"Negative",IF(AM37=0,"Same",IF(AM37>0.3,"30+%",IF(AM37>0.2,"20-30%",IF(AM37>0.1,"10-20%",IF(AM37<=0.1,"0-10%"))))))) -> 30+% | AO37: =IFERROR(AP37*S37,"") -> 28.782 | AP37: =IFERROR(AQ37/AS37,"") -> 7.1955 | AQ37: 7.1955 | AR37: Roll | AS37: 1 | AT37: Possible UOM or LPP issue. | AU37: Agent[REG] | AV37: 1014655 | AW37: 1014655 | AX37: Safety | AY37: 36 yd (108') L X 2" W 6 mil White General Purpose Aisle Marking Tape Blank | AZ37: Similar Match | BA37: Yes | BC37: =T37-BF37 -> 228.738 | BD37: =BC37/T37 -> 0.88823392 | BE37: =IF(BD37<0,"Negative",IF(BD37=0,"Same",IF(BD37>0.3,"30+%",IF(BD37>0.2,"20-30%",IF(BD37>0.1,"10-20%",IF(BD37<=0.1,"0-10%")))))) -> 30+% | BF37: =BG37*S37 -> 28.782 | BG37: =BH37/BJ37 -> 7.1955 | BH37: =IF(BS37="Original",Z37,AQ37) -> 7.1955 | BI37: =IF(BS37="Original",AA37,AR37) -> Roll | BJ37: =IF(BS37="Original",AB37,AS37) -> 1 | BK37: =IF(BS37="Original",AC37,AT37) -> Possible UOM or LPP issue. | BL37: =IF(BS37="Original",AD37,AU37) -> Agent[REG] | BM37: =IF(BS37="Original",AE37,AV37) -> 1014655 | BN37: =IF(BS37="Original",AF37,AW37) -> 1014655 | BO37: =IF(BS37="Original",AG37,AX37) -> Safety | BP37: =IF(BS37="Original",AH37,AY37) -> 36 yd (108') L X 2" W 6 mil White General Purpose Aisle Marking Tape Blank | BQ37: =IF(BS37="Original",AI37,AZ37) -> Similar Match | BR37: =IF(BS37="Original",AJ37,BA37) -> Yes | BS37: =IF(AQ37="","Original",IF(AP37<Y37,"Alternate","Original")) -> Alternate
A38: VRC_Cascadia Multiple Suppliers | B38: 36 | F38: MSC | G38: 65590697 | H38: Large nitrile gloves | N38: EA | O38: 1 | P38: 83.36 | Q38: 3 | R38: =P38/O38 -> 83.36 | S38: =Q38*O38 -> 3 | T38: =S38*R38 -> 250.08 | U38: =IFERROR(T38-X38,0) -> 249.69948 | V38: =IFERROR(U38/T38,0) -> 0.99847841 | W38: =IF($V38<0,"Negative",IF($V38=0,"Same",IF($V38>0.3,"30+%",IF($V38>0.2,"20-30%",IF($V38>0.1,"10-20%",IF($V38<=0.1,"0-10%")))))) -> 30+% | X38: =IFERROR(Y38*S38,0) -> 0.38052 | Y38: =IFERROR(Z38/AB38,0) -> 0.12684 | Z38: 12.684 | AA38: Pack | AB38: 100 | AC38: Possible UOM or LPP issue. | AD38: Body Guard[REG] | AE38: 1334819 | AF38: 1334819 | AG38: Safety | AH38: L Series 816BK 6 mil Black Nitrile Industrial Powder Free Body Guard[REG] Disposable Glove | AI38: Similar Match | AJ38: No | BC38: =T38-BF38 -> 249.69948 | BD38: =BC38/T38 -> 0.99847841 | BE38: =IF(BD38<0,"Negative",IF(BD38=0,"Same",IF(BD38>0.3,"30+%",IF(BD38>0.2,"20-30%",IF(BD38>0.1,"10-20%",IF(BD38<=0.1,"0-10%")))))) -> 30+% | BF38: =BG38*S38 -> 0.38052 | BG38: =BH38/BJ38 -> 0.12684 | BH38: =IF(BS38="Original",Z38,AQ38) -> 12.684 | BI38: =IF(BS38="Original",AA38,AR38) -> Pack | BJ38: =IF(BS38="Original",AB38,AS38) -> 100 | BK38: =IF(BS38="Original",AC38,AT38) -> Possible UOM or LPP issue. | BL38: =IF(BS38="Original",AD38,AU38) -> Body Guard[REG] | BM38: =IF(BS38="Original",AE38,AV38) -> 1334819 | BN38: =IF(BS38="Original",AF38,AW38) -> 1334819 | BO38: =IF(BS38="Original",AG38,AX38) -> Safety | BP38: =IF(BS38="Original",AH38,AY38) -> L Series 816BK 6 mil Black Nitrile Industrial Powder Free Body Guard[REG] Disposable Glove | BQ38: =IF(BS38="Original",AI38,AZ38) -> Similar Match | BR38: =IF(BS38="Original",AJ38,BA38) -> No | BS38: =IF(AQ38="","Original",IF(AP38<Y38,"Alternate","Original")) -> Original
A39: VRC_Cascadia Multiple Suppliers | B39: 37 | F39: MSC | G39: 56484967 | H39: tool wrap | N39: EA | O39: 1 | P39: 249.76 | Q39: 1 | R39: =P39/O39 -> 249.76 | S39: =Q39*O39 -> 1 | T39: =S39*R39 -> 249.76 | U39: =IFERROR(T39-X39,0) -> 154.2614 | V39: =IFERROR(U39/T39,0) -> 0.61763853 | W39: =IF($V39<0,"Negative",IF($V39=0,"Same",IF($V39>0.3,"30+%",IF($V39>0.2,"20-30%",IF($V39>0.1,"10-20%",IF($V39<=0.1,"0-10%")))))) -> 30+% | X39: =IFERROR(Y39*S39,0) -> 95.4986 | Y39: =IFERROR(Z39/AB39,0) -> 95.4986 | Z39: 95.4986 | AA39: Roll | AB39: 1 | AC39: Possible UOM or LPP issue. | AD39: MAUDLIN & SON MFG. CO., INC. | AE39: SSFW309-20-25 | AF39: 4135004 | AG39: Raw Materials | AH39: 0.002" x 20" x 25' 309 Stainless Steel Tool Wrap | AI39: Exact Match | AJ39: No | BC39: =T39-BF39 -> 154.2614 | BD39: =BC39/T39 -> 0.61763853 | BE39: =IF(BD39<0,"Negative",IF(BD39=0,"Same",IF(BD39>0.3,"30+%",IF(BD39>0.2,"20-30%",IF(BD39>0.1,"10-20%",IF(BD39<=0.1,"0-10%")))))) -> 30+% | BF39: =BG39*S39 -> 95.4986 | BG39: =BH39/BJ39 -> 95.4986 | BH39: =IF(BS39="Original",Z39,AQ39) -> 95.4986 | BI39: =IF(BS39="Original",AA39,AR39) -> Roll | BJ39: =IF(BS39="Original",AB39,AS39) -> 1 | BK39: =IF(BS39="Original",AC39,AT39) -> Possible UOM or LPP issue. | BL39: =IF(BS39="Original",AD39,AU39) -> MAUDLIN & SON MFG. CO., INC. | BM39: =IF(BS39="Original",AE39,AV39) -> SSFW309-20-25 | BN39: =IF(BS39="Original",AF39,AW39) -> 4135004 | BO39: =IF(BS39="Original",AG39,AX39) -> Raw Materials | BP39: =IF(BS39="Original",AH39,AY39) -> 0.002" x 20" x 25' 309 Stainless Steel Tool Wrap | BQ39: =IF(BS39="Original",AI39,AZ39) -> Exact Match | BR39: =IF(BS39="Original",AJ39,BA39) -> No | BS39: =IF(AQ39="","Original",IF(AP39<Y39,"Alternate","Original")) -> Original
A40: VRC_Cascadia Multiple Suppliers | B40: 38 | F40: MSC | G40: 65590713 | H40: Medium nitrile gloves | N40: EA | O40: 1 | P40: 82.57 | Q40: 3 | R40: =P40/O40 -> 82.57 | S40: =Q40*O40 -> 3 | T40: =S40*R40 -> 247.71 | U40: =IFERROR(T40-X40,0) -> 247.3341 | V40: =IFERROR(U40/T40,0) -> 0.9984825 | W40: =IF($V40<0,"Negative",IF($V40=0,"Same",IF($V40>0.3,"30+%",IF($V40>0.2,"20-30%",IF($V40>0.1,"10-20%",IF($V40<=0.1,"0-10%")))))) -> 30+% | X40: =IFERROR(Y40*S40,0) -> 0.3759 | Y40: =IFERROR(Z40/AB40,0) -> 0.1253 | Z40: 12.53 | AA40: Pack | AB40: 100 | AC40: Possible UOM or LPP issue. | AD40: Body Guard[REG] | AE40: 1334818 | AF40: 1334818 | AG40: Safety | AH40: M Series 816BK 6 mil Black Nitrile Industrial Powder Free Body Guard[REG]Disposable Glove | AI40: Similar Match | AJ40: No | BC40: =T40-BF40 -> 247.3341 | BD40: =BC40/T40 -> 0.9984825 | BE40: =IF(BD40<0,"Negative",IF(BD40=0,"Same",IF(BD40>0.3,"30+%",IF(BD40>0.2,"20-30%",IF(BD40>0.1,"10-20%",IF(BD40<=0.1,"0-10%")))))) -> 30+% | BF40: =BG40*S40 -> 0.3759 | BG40: =BH40/BJ40 -> 0.1253 | BH40: =IF(BS40="Original",Z40,AQ40) -> 12.53 | BI40: =IF(BS40="Original",AA40,AR40) -> Pack | BJ40: =IF(BS40="Original",AB40,AS40) -> 100 | BK40: =IF(BS40="Original",AC40,AT40) -> Possible UOM or LPP issue. | BL40: =IF(BS40="Original",AD40,AU40) -> Body Guard[REG] | BM40: =IF(BS40="Original",AE40,AV40) -> 1334818 | BN40: =IF(BS40="Original",AF40,AW40) -> 1334818 | BO40: =IF(BS40="Original",AG40,AX40) -> Safety | BP40: =IF(BS40="Original",AH40,AY40) -> M Series 816BK 6 mil Black Nitrile Industrial Powder Free Body Guard[REG]Disposable Glove | BQ40: =IF(BS40="Original",AI40,AZ40) -> Similar Match | BR40: =IF(BS40="Original",AJ40,BA40) -> No | BS40: =IF(AQ40="","Original",IF(AP40<Y40,"Alternate","Original")) -> Original
...

Sheet Guideline
C4: Color Code Legend | D4: Columns Found | E4: Notes
C5: Customer Data | D5: A-T | E5: Member data provided by PA team in columns "A-T". No changes should be made to these columns, sequence numbers must remain in tact
C6: Savings Calculations Formulas | D6: U-W, AL-AN, BC-BE | E6: Formulas should be copied down to review file savings. Use savings categories to aid in UoM and match checks
C7: PA Formula Fields | D7: X-Y, AO-AP, BF-BS | E7: No changes to be made, copy down formulas to aid in savings calculation
C8: Fastenal Product Input | D8: Z-AJ | E8: Provide product crosses that are exact or the closest possible match based on function and quality
C9: PA Notes | D9: AK, BB | E9: Used by PA to provide notes to Vendor
C10: Fastenal Alternate Solution | D10: AQ-BA | E10: Provide alternate products when possible with goal of maximizing savings
B12: Pricing Validation | D12: Notes
C13: PA PRICE | D13: PA pricing per pack should be entered into Columns Z and AQ (as applicable). An example is Blue Nitrile Gloves - $8.95/ PK100. Please provide $8.95 in this cell
C14: Fastenal UOM | D14: Unit of Measure to be provided in column AA and AR (as applicable). e.g. EA and PK.
C15: Fastenal UNITS/ PACK | D15: Number of items in pack entered into column AB and AS (as applicable). Based on our example on Nitrile Gloves please provide 100 in this cell
C16: Final File Check | D16: Outliers that are either +60% savings or -80% should have a note that the SKU has been confirmed
B19: File Checks | D19: Notes | E19: Validation
C20: Match Type (Column AI) | D20: Should be provided for all lines | E20: =IF((COUNTIF(Data!A:A,"<>")-COUNTIF(Data!AI:AI,"<>"))=0,"Complete","Insert Match Types") -> Complete
C21: CATEGORY | D21: Provided for all SKU crosses | E21: =IF((COUNTIF(Data!AG:AG,"<>")-COUNTIF(Data!AF:AF,"<>"))=0,"Complete","Update Category Info") -> Complete
C22: PRODUCT DESCRIPTION | D22: Provided for all SKU crosses | E22: =IF((COUNTIF(Data!AH:AH,"<>")-COUNTIF(Data!AF:AF,"<>"))=0,"Complete","Update Product Description") -> Complete
C23: PA CORE | D23: Provided for all SKU crosses | E23: =IF((COUNTIF(Data!AJ:AJ,"<>")-COUNTIF(Data!AF:AF,"<>"))=0,"Complete","Update PA Core") -> Complete
C24: Fastenal UOM | D24: Provided for all SKU crosses | E24: =IF((COUNTIF(Data!AA:AA,"<>")-COUNTIF(Data!AF:AF,"<>"))=0,"Complete","Update FNL UoM") -> Complete
C25: Fastenal UNITS/ PACK | D25: Provided for all SKU crosses | E25: =IF((COUNTIF(Data!AB:AB,"<>")-COUNTIF(Data!AF:AF,"<>"))=0,"Complete","Update Units per Pack") -> Complete

Sheet Match Types
C3: Match Type | D3: Code | E3: Definition
C4: Exact Match | D4: E | E4: Item matches the Mfg/Vendor Name and Mfg/Vendor Part Number provided by Member
C5: Similar Match | D5: SM | E5: Similar product related to form, fit, function based on Mfg/Vendor Name, Mfg/Vendor Part Number and/or Detailed Item Description provided by Member
C6: Potential Sourcing | D6: O | E6: Products are not available through the primary product offering. They would be sourced upon request for convienance.
C7: Not Enough Product Data | D7: X | E7: Unable to process due to: missing or incomplete Mfg/Vendor Name, Mfg/Vendor Part Number, incomplete detailed item descriptions and/or poor data quality in original Member data
C8: Metalworking Program | D8: MW | E8: Item would fall under Metalworking Program which is based on Total Cost of Ownership (TCO) savings
C9: Low Threshold Spend | D9: TAIL | E9: Items with low usage and/ or low spend (less than $100)
C10: Not Product Data | D10: NPD | E10: Lines representing non-product related data i.e. service fees, instruction manuals, quotes, repair services, calibration services, etc.
C11: Non-Supported Product | D11: NSP | E11: Products that are not supported by Fastenal
