Workbook

Sheet Summary
C1: Procurement Advisors
C2: BlueScope Steel | H2: 46000
A4: Incumbent | B4: Total Eligible Spend | C4: Benchmarked Spend | D4: Benchmarked % of Total | E4: PA Pricing | F4: Savings $ | G4: Savings | H4: Comments
A5: Airgas | B5: =C37 -> 1180039.5 | C5: =SUM('Item Detail'!O:O) -> 407377.1 | D5: =C5/B5 -> 0.34522328 | E5: =SUM('Item Detail'!S:S) -> 393855.52 | F5: =C5-E5 -> 13521.58 | G5: =SUM(1-(E5/C5)) -> 0.033191802 | H5: Like-to-like SKU benchmarking
A7: No. of SKUs | B7: Negative | C7: Same | D7: 0-10% | E7: 10-20% | F7: 20-30% | G7: 30+% | H7: Total
A8: Total SKUs | B8: =COUNTIF('Item Detail'!$R:$R,"Negative") -> 55 | C8: =COUNTIF('Item Detail'!$R:$R,"Same") -> 1 | D8: =COUNTIF('Item Detail'!$R:$R,"0-10%") -> 26 | E8: =COUNTIF('Item Detail'!$R:$R,"10-20%") -> 8 | F8: =COUNTIF('Item Detail'!$R:$R,"20-30%") -> 3 | G8: =COUNTIF('Item Detail'!$R:$R,"30+%") -> 9 | H8: =SUM(B8:G8) -> 102
A10: $ Spend | B10: Negative | C10: Same | D10: 0-10% | E10: 10-20% | F10: 20-30% | G10: 30+% | H10: Total
A11: =A5 -> Airgas | B11: =SUMIF('Item Detail'!$R:$R,"Negative",'Item Detail'!$O:$O) -> 78082.72 | C11: =SUMIF('Item Detail'!$R:$R,"Same",'Item Detail'!$O:$O) -> 16531.32 | D11: =SUMIF('Item Detail'!$R:$R,"0-10%",'Item Detail'!$O:$O) -> 146054.15 | E11: =SUMIF('Item Detail'!$R:$R,"10-20%",'Item Detail'!$O:$O) -> 113700.91 | F11: =SUMIF('Item Detail'!$R:$R,"20-30%",'Item Detail'!$O:$O) -> 15400.61 | G11: =SUMIF('Item Detail'!$R:$R,"30+%",'Item Detail'!$O:$O) -> 37607.39 | H11: =SUM(B11:G11) -> 407377.1
A12: WWG-PA | B12: =SUMIF('Item Detail'!$R:$R,"Negative",'Item Detail'!$S:$S) -> 106802.58 | C12: =SUMIF('Item Detail'!$R:$R,"Same",'Item Detail'!$S:$S) -> 16531.32 | D12: =SUMIF('Item Detail'!$R:$R,"0-10%",'Item Detail'!$S:$S) -> 140775.73 | E12: =SUMIF('Item Detail'!$R:$R,"10-20%",'Item Detail'!$S:$S) -> 97353.69 | F12: =SUMIF('Item Detail'!$R:$R,"20-30%",'Item Detail'!$S:$S) -> 11275.63 | G12: =SUMIF('Item Detail'!$R:$R,"30+%",'Item Detail'!$S:$S) -> 21116.57 | H12: =SUM(B12:G12) -> 393855.52
A13: SKU Level Savings | B13: =B11-B12 -> -28719.86 | C13: =C11-C12 -> 0 | D13: =D11-D12 -> 5278.42 | E13: =E11-E12 -> 16347.22 | F13: =F11-F12 -> 4124.98 | G13: =G11-G12 -> 16490.82 | H13: =H11-H12 -> 13521.58
A15: CSPL breakdown | B15: SKUs | C15: % | D15: $ | E15: PA $ | F15: Savings % | G15: Savings $
A16: CSPL Skus | B16: =COUNTIF('Item Detail'!AI:AI,"*True")+COUNTIF('Item Detail'!AI:AI,"TRUEA") -> 18 | C16: =B16/H8 -> 0.17647059 | D16: =SUMIF('Item Detail'!$AI:$AI,"*True",'Item Detail'!$O:$O)+SUMIF('Item Detail'!$AI:$AI,"TrueA",'Item Detail'!$O:$O) -> 63533.95 | E16: =SUMIF('Item Detail'!$AI:$AI,"*True",'Item Detail'!$S:$S)+SUMIF('Item Detail'!$AI:$AI,"TrueA",'Item Detail'!$S:$S) -> 63372.54 | F16: =1-E16/D16 -> 0.0025405315 | G16: =D16-E16 -> 161.41
A17: Non-CSPL Skus | B17: =COUNTA('Item Detail'!B:B)-Summary!B16-1 -> 84 | C17: =B17/H8 -> 0.82352941 | D17: =SUMIF('Item Detail'!$AI:$AI,"",'Item Detail'!$O:$O) -> 343843.15 | E17: =SUMIF('Item Detail'!$AI:$AI,"",'Item Detail'!$S:$S) -> 330482.98 | F17: =1-E17/D17 -> 0.03885542 | G17: =D17-E17 -> 13360.17
A18: Total | B18: =SUM(B16:B17) -> 102 | C18: =SUM(C16:C17) -> 1 | D18: =SUM(D16:D17) -> 407377.1 | E18: =SUM(E16:E17) -> 393855.52 | F18: =1-E18/D18 -> 0.033191802 | G18: =SUM(G16:G17) -> 13521.58
A20: SKUs Submitted for Conditional CSP | B20: =COUNTIF('Item Detail'!$AI:$AI,"TRUEA") -> 0
A22: Note:
A23: (1) Total eligible spend is the full data provided by the customer
A24: (2) Benchmarked active Redbook SKUs
A25: (3) Savings do not reflect A) volume and manufacturer rebates, B) future CSPL adds, C) freight savings
A26: (4) Benchmark files are a preliminary assessment and valid for 30 days. Final SKU review will occur at time of affiliation.
A28: Product cross-reference comparisons do not imply that products are available or perfectly comparable. Cross-referenced products are not represented or warranted as functional or performance equivalents. Each Member shall review all cross-referenced product specifications prior to purchase and use to determine suitability of the product for the Member's intended use. Savings $ and % presented is based on these products alone. Changes in the product mix will result is a different savings calculation.
A30: File Summary
B31: # SKU | C31: Spend $
A32: Total Provided | B32: =COUNTA('Cust File'!B:B)-1 -> 620 | C32: =SUM('Cust File'!T:T) -> 1256069
A33: SKUs not meeting threshold | B33: =B32-B34 -> 370 | C33: =C32-C34 -> 76029.495
A34: SKUs reviewed for benchmarking | B34: =B37 -> 250 | C34: =C37 -> 1180039.5
A36: Benchmarking Summary
A37: Total Eligible Spend | B37: =COUNTA('Item Detail'!B:B)-1+COUNTA(Excluded!B:B)-1 -> 250 | C37: =SUM('Item Detail'!O:O)+SUM(Excluded!O:O) -> 1180039.5
A39: Items Benchmarked (Item Detail) | B39: =B37-B41 -> 230 | C39: =C37-C41 -> 1101376.4
A41: Total Excluded (Excluded Tab) | B41: =SUM(B42:B48) -> 20 | C41: =SUM(C42:C48) -> 78663.08
A42: Non-MRO spend (DNC) | B42: =COUNTIF(Excluded!$V:$V,"DNC") -> 0 | C42: =SUMIF(Excluded!$V:$V,"DNC",Excluded!$O:$O) -> 0
A43: Need more information (X) | B43: =COUNTIF(Excluded!$V:$V,"X") -> 0 | C43: =SUMIF(Excluded!$V:$V,"X",Excluded!$O:$O) -> 0
A44: Items with zero spend (ZERO) | B44: =COUNTIF(Excluded!$V:$V,"ZERO") -> 0 | C44: =SUMIF(Excluded!$V:$V,"ZERO",Excluded!$O:$O) -> 0
A45: UOM issues (UOM) | B45: =COUNTIF(Excluded!$V:$V,"UOM") -> 0 | C45: =SUMIF(Excluded!$V:$V,"UOM",Excluded!$O:$O) -> 0
A46: WWG potential sourcing (O) | B46: =COUNTIF(Excluded!$V:$V,"O") -> 18 | C46: =SUMIF(Excluded!$V:$V,"O",Excluded!$O:$O) -> 77028.53
A47: Non Product Data (NPD) | B47: =COUNTIF(Excluded!$V:$V,"NPD") -> 0 | C47: =SUMIF(Excluded!$V:$V,"NPD",Excluded!$O:$O) -> 0
A48: Duplicates (DUP) | B48: =COUNTIF(Excluded!$V:$V,"DUP") -> 2 | C48: =SUMIF(Excluded!$V:$V,"DUP",Excluded!$O:$O) -> 1634.55

Sheet Item Detail
A1: Xsort | B1: Sequence # | C1: Customer product # | D1: Distributor name | E1: Distributor # | F1: Description | G1: Manufacturer name | H1: Manufacturer number | I1: Unit of measure | J1: Units/pack | K1: Pack price | L1: Total packs | M1: Unit price | N1: Total baseline units | O1: Total incumbent spend | P1: Savings $ | Q1: Savings % | R1: Savings cat. | S1: WWG extended price | T1: WWG unit price | U1: WWG item # | V1: Code | W1: Status (in/out) | X1: Act price | Y1: Notes | Z1: Xref Notes | AA1: WWG unit of measure | AB1: WWG unit/pack | AC1: WWG Manufacturer name | AD1: WWG Manufacturer number | AE1: WWG Description | AF1: Product segment | AG1: Product category | AH1: Product family | AI1: CSP | AJ1: Flag | AK1: Note
A2: 1 | B2: 125 | F2: [DS] CHICAGO PROTECTIVE APPAREL/CPA | G2: AIRGAS | H2: CB2GENERIC | I2: FALSE | J2: 1 | K2: 601.90 | L2: 144 | M2: =IFERROR(IF(A2="","",K2/J2)," ") -> 601.9 | N2: =IFERROR(IF(A2="","",J2*L2)," ") -> 144 | O2: =IFERROR(M2*N2," ") -> 86673.6 | P2: =IFERROR(IF(A2="","",O2-S2)," ") -> 11666.88 | Q2: =IFERROR(IF(A2="","",P2/O2)," ") -> 0.13460708 | R2: =IFERROR(IF(A2="","",(IF(Q2<0,"Negative",IF(Q2=0,"Same",IF(Q2>0.3,"30+%",IF(Q2>0.2,"20-30%",IF(Q2>0.1,"10-20%",IF(Q2<=0.1,"0-10%"))))))))," ") -> 10-20% | S2: =IFERROR(IF(A2="","",T2*N2)," ") -> 75006.72 | T2: =IFERROR(IF(A2="","",X2/AB2)," ") -> 520.88 | U2: 5PGX2 | V2: FE | X2: 520.88 | Z2: 0 | AA2: EA | AB2: 1 | AC2: HI TEMP | AD2: R51-36X36X1-P | AE2: Welding Pad, 3 ft W, 3 ft L, Red | AF2: Welding | AG2: Welding Blankets, Pads, Wraps and Rolls | AH2: Welding Safety Equipment | AJ2: Exact Match | AK2: Savings
A3: 5 | B3: 527 | F3: RESP Z-LINK & RESP INCL 16-810 SFTY LENS | G3: AIRGAS | H3: RPB16-078-21-FR | I3: FALSE | J3: 1 | K3: 2547.85 | L3: 14 | M3: =IFERROR(IF(A3="","",K3/J3)," ") -> 2547.85 | N3: =IFERROR(IF(A3="","",J3*L3)," ") -> 14 | O3: =IFERROR(M3*N3," ") -> 35669.9 | P3: =IFERROR(IF(A3="","",O3-S3)," ") -> 1783.46 | Q3: =IFERROR(IF(A3="","",P3/O3)," ") -> 0.049999019 | R3: =IFERROR(IF(A3="","",(IF(Q3<0,"Negative",IF(Q3=0,"Same",IF(Q3>0.3,"30+%",IF(Q3>0.2,"20-30%",IF(Q3>0.1,"10-20%",IF(Q3<=0.1,"0-10%"))))))))," ") -> 0-10% | S3: =IFERROR(IF(A3="","",T3*N3)," ") -> 33886.44 | T3: =IFERROR(IF(A3="","",X3/AB3)," ") -> 2420.46 | U3: 61CX77 | V3: E | X3: 2420.46 | Z3: 0 | AA3: EA | AB3: 1 | AC3: RPB SAFETY | AD3: 16-078-21-FR | AE3: Z-Link Helmet | AF3: Safety | AG3: Powered Air-Purifying Respirators | AH3: Respiratory | AJ3: Exact Match | AK3: Savings
A4: 9 | B4: 461 | F4: GLV DRVR LG GN CWHD HIVIS IMPRINTED | G4: AIRGAS | H4: RAD64057044 | I4: FALSE | J4: 1 | K4: 4.96 | L4: 3504 | M4: =IFERROR(IF(A4="","",K4/J4)," ") -> 4.96 | N4: =IFERROR(IF(A4="","",J4*L4)," ") -> 3504 | O4: =IFERROR(M4*N4," ") -> 17379.84 | P4: =IFERROR(IF(A4="","",O4-S4)," ") -> 840.96 | Q4: =IFERROR(IF(A4="","",P4/O4)," ") -> 0.048387097 | R4: =IFERROR(IF(A4="","",(IF(Q4<0,"Negative",IF(Q4=0,"Same",IF(Q4>0.3,"30+%",IF(Q4>0.2,"20-30%",IF(Q4>0.1,"10-20%",IF(Q4<=0.1,"0-10%"))))))))," ") -> 0-10% | S4: =IFERROR(IF(A4="","",T4*N4)," ") -> 16538.88 | T4: =IFERROR(IF(A4="","",X4/AB4)," ") -> 4.72 | U4: 3ZL50 | V4: FE | X4: 4.72 | Z4: 0 | AA4: PR | AB4: 1 | AC4: CONDOR | AD4: 3ZL50 | AE4: Leather Gloves,White,L,PR | AF4: Safety | AG4: Leather Gloves and Mitts | AH4: Gloves and Hand Protection | AI4: TRUE | AJ4: Exact Match | AK4: Savings
A5: 10 | B5: 108 | F5: MNTR SNGL GAS BW CLP CO 35-200PPM RTD 2Y | G5: AIRGAS | H5: B86BWC2RM | I5: FALSE | J5: 1 | K5: 211.94 | L5: 78 | M5: =IFERROR(IF(A5="","",K5/J5)," ") -> 211.94 | N5: =IFERROR(IF(A5="","",J5*L5)," ") -> 78 | O5: =IFERROR(M5*N5," ") -> 16531.32 | P5: =IFERROR(IF(A5="","",O5-S5)," ") -> 0 | Q5: =IFERROR(IF(A5="","",P5/O5)," ") -> 0 | R5: =IFERROR(IF(A5="","",(IF(Q5<0,"Negative",IF(Q5=0,"Same",IF(Q5>0.3,"30+%",IF(Q5>0.2,"20-30%",IF(Q5>0.1,"10-20%",IF(Q5<=0.1,"0-10%"))))))))," ") -> Same | S5: =IFERROR(IF(A5="","",T5*N5)," ") -> 16531.32 | T5: =IFERROR(IF(A5="","",X5/AB5)," ") -> 211.94 | U5: 41HG96 | V5: FE | X5: 211.94 | Z5: 0 | AA5: EA | AB5: 1 | AC5: HONEYWELL | AD5: BWC2-M | AE5: Single Gas Detectr,CO,Yllw,2yr. Battery | AF5: Safety | AG5: Portable Single- and Multi-Gas Detectors | AH5: Gas Detection | AJ5: Exact Match | AK5: Savings
A6: 15 | B6: 295 | F6: CT HT RES XL 12OZ OPF BLND FLCE CLTH | G6: AIRGAS | H6: N33C22CWXL48179 | I6: FALSE | J6: 1 | K6: 539.50 | L6: 24 | M6: =IFERROR(IF(A6="","",K6/J6)," ") -> 539.5 | N6: =IFERROR(IF(A6="","",J6*L6)," ") -> 24 | O6: =IFERROR(M6*N6," ") -> 12948 | P6: =IFERROR(IF(A6="","",O6-S6)," ") -> 2247.6 | Q6: =IFERROR(IF(A6="","",P6/O6)," ") -> 0.17358665 | R6: =IFERROR(IF(A6="","",(IF(Q6<0,"Negative",IF(Q6=0,"Same",IF(Q6>0.3,"30+%",IF(Q6>0.2,"20-30%",IF(Q6>0.1,"10-20%",IF(Q6<=0.1,"0-10%"))))))))," ") -> 10-20% | S6: =IFERROR(IF(A6="","",T6*N6)," ") -> 10700.4 | T6: =IFERROR(IF(A6="","",X6/AB6)," ") -> 445.85 | U6: 8AAR2 | V6: PS-NMI | X6: 445.85 | Z6: 0 | AA6: EA | AB6: 1 | AC6: KAREWEAR | AD6: 714ACKXL | AE6: Aluminized Jacket,XL,Carbon Kevlar(R) | AF6: Safety | AG6: Aluminized Jackets and Coats | AH6: Flame Resistant and Arc Flash Clothing | AJ6: Exact Match | AK6: Savings
A7: 17 | B7: 329 | F7: TALLYHOOD 8.6OZ OPF BLND RPSP TWLL | G7: AIRGAS | H7: N33H74H3001 | I7: FALSE | J7: 1 | K7: 83.81 | L7: 144 | M7: =IFERROR(IF(A7="","",K7/J7)," ") -> 83.81 | N7: =IFERROR(IF(A7="","",J7*L7)," ") -> 144 | O7: =IFERROR(M7*N7," ") -> 12068.64 | P7: =IFERROR(IF(A7="","",O7-S7)," ") -> 4060.8 | Q7: =IFERROR(IF(A7="","",P7/O7)," ") -> 0.33647536 | R7: =IFERROR(IF(A7="","",(IF(Q7<0,"Negative",IF(Q7=0,"Same",IF(Q7>0.3,"30+%",IF(Q7>0.2,"20-30%",IF(Q7>0.1,"10-20%",IF(Q7<=0.1,"0-10%"))))))))," ") -> 30+% | S7: =IFERROR(IF(A7="","",T7*N7)," ") -> 8007.84 | T7: =IFERROR(IF(A7="","",X7/AB7)," ") -> 55.61 | U7: 61RN10 | V7: PS-PLG | X7: 55.61 | Z7: 0 | AA7: EA | AB7: 1 | AC7: ARIAT | AD7: 10018116 | AE7: FR Balaclava,Black | AF7: Safety | AG7: Flame Resistant and Arc Flash Hats and Caps | AH7: Flame Resistant and Arc Flash Clothing | AJ7: Exact Match | AK7: Savings
A8: 18 | B8: 291 | F8: CT HT RES 3X 12OZ OPF BLND FLCE CLTH | G8: AIRGAS | H8: N33C22CW3X48179 | I8: FALSE | J8: 1 | K8: 593.43 | L8: 20 | M8: =IFERROR(IF(A8="","",K8/J8)," ") -> 593.43 | N8: =IFERROR(IF(A8="","",J8*L8)," ") -> 20 | O8: =IFERROR(M8*N8," ") -> 11868.6 | P8: =IFERROR(IF(A8="","",O8-S8)," ") -> 3240 | Q8: =IFERROR(IF(A8="","",P8/O8)," ") -> 0.27298923 | R8: =IFERROR(IF(A8="","",(IF(Q8<0,"Negative",IF(Q8=0,"Same",IF(Q8>0.3,"30+%",IF(Q8>0.2,"20-30%",IF(Q8>0.1,"10-20%",IF(Q8<=0.1,"0-10%"))))))))," ") -> 20-30% | S8: =IFERROR(IF(A8="","",T8*N8)," ") -> 8628.6 | T8: =IFERROR(IF(A8="","",X8/AB8)," ") -> 431.43 | U8: 8DN27 | V8: PS-NMI | X8: 431.43 | Z8: 0 | AA8: EA | AB8: 1 | AC8: KAREWEAR | AD8: 714ACK3XL | AE8: Aluminized Jacket,3XL,Carbon Kevlar(R) | AF8: Safety | AG8: Aluminized Jackets and Coats | AH8: Flame Resistant and Arc Flash Clothing | AJ8: Exact Match | AK8: Savings
A9: 20 | B9: 511 | F9: FAN HSNG | G9: AIRGAS | H9: RPB03-810 | I9: FALSE | J9: 1 | K9: 867.98 | L9: 13 | M9: =IFERROR(IF(A9="","",K9/J9)," ") -> 867.98 | N9: =IFERROR(IF(A9="","",J9*L9)," ") -> 13 | O9: =IFERROR(M9*N9," ") -> 11283.74 | P9: =IFERROR(IF(A9="","",O9-S9)," ") -> 221 | Q9: =IFERROR(IF(A9="","",P9/O9)," ") -> 0.019585705 | R9: =IFERROR(IF(A9="","",(IF(Q9<0,"Negative",IF(Q9=0,"Same",IF(Q9>0.3,"30+%",IF(Q9>0.2,"20-30%",IF(Q9>0.1,"10-20%",IF(Q9<=0.1,"0-10%"))))))))," ") -> 0-10% | S9: =IFERROR(IF(A9="","",T9*N9)," ") -> 11062.74 | T9: =IFERROR(IF(A9="","",X9/AB9)," ") -> 850.98 | U9: 382WZ4 | V9: E | X9: 850.98 | Z9: 0 | AA9: EA | AB9: 1 | AC9: RPB SAFETY | AD9: 03-810 | AE9: PX5 Fan Housing | AF9: Safety | AG9: Powered Air-Purifying Respirator PAPR System Components and Accessories | AH9: Respiratory | AJ9: Exact Match | AK9: Savings
A10: 22 | B10: 290 | F10: CT ALUMZD 2X 48" LNG 14OZ CARBON-X | G10: AIRGAS | H10: N33C22CW2X48179 | I10: FALSE | J10: 1 | K10: 595.37 | L10: 18 | M10: =IFERROR(IF(A10="","",K10/J10)," ") -> 595.37 | N10: =IFERROR(IF(A10="","",J10*L10)," ") -> 18 | O10: =IFERROR(M10*N10," ") -> 10716.66 | P10: =IFERROR(IF(A10="","",O10-S10)," ") -> 200.52 | Q10: =IFERROR(IF(A10="","",P10/O10)," ") -> 0.018711054 | R10: =IFERROR(IF(A10="","",(IF(Q10<0,"Negative",IF(Q10=0,"Same",IF(Q10>0.3,"30+%",IF(Q10>0.2,"20-30%",IF(Q10>0.1,"10-20%",IF(Q10<=0.1,"0-10%"))))))))," ") -> 0-10% | S10: =IFERROR(IF(A10="","",T10*N10)," ") -> 10516.14 | T10: =IFERROR(IF(A10="","",X10/AB10)," ") -> 584.23 | U10: 2YRK4 | V10: FE | X10: 584.23 | Z10: 0 | AA10: EA | AB10: 1 | AC10: NATIONAL SAFETY APPAREL | AD10: C22NL2X45 | AE10: Aluminized Coat,2XL,Carbon Kevlar(R) | AF10: Safety | AG10: Aluminized Jackets and Coats | AH10: Flame Resistant and Arc Flash Clothing | AJ10: Exact Match | AK10: Savings
A11: 31 | B11: 98 | F11: GLV CUT RES PU CTD MD WHT 13 GA HPPE | G11: AIRGAS | H11: B13540-M | I11: FALSE | J11: 1 | K11: 6.26 | L11: 1584 | M11: =IFERROR(IF(A11="","",K11/J11)," ") -> 6.26 | N11: =IFERROR(IF(A11="","",J11*L11)," ") -> 1584 | O11: =IFERROR(M11*N11," ") -> 9915.84 | P11: =IFERROR(IF(A11="","",O11-S11)," ") -> 15.84 | Q11: =IFERROR(IF(A11="","",P11/O11)," ") -> 0.0015974441 | R11: =IFERROR(IF(A11="","",(IF(Q11<0,"Negative",IF(Q11=0,"Same",IF(Q11>0.3,"30+%",IF(Q11>0.2,"20-30%",IF(Q11>0.1,"10-20%",IF(Q11<=0.1,"0-10%"))))))))," ") -> 0-10% | S11: =IFERROR(IF(A11="","",T11*N11)," ") -> 9900 | T11: =IFERROR(IF(A11="","",X11/AB11)," ") -> 6.25 | U11: 24L254 | V11: FE | X11: 6.25 | Z11: 0 | AA11: PR | AB11: 1 | AC11: HYFLEX | AD11: 11-644 | AE11: PR,Cut Resistant Gloves,Lgt Gry,8 | AF11: Safety | AG11: Knit Gloves and Mitts | AH11: Gloves and Hand Protection | AI11: TRUE | AJ11: Exact Match | AK11: Savings
A12: 38 | B12: 462 | F12: GLV DRVR XL GN CWHD UNL KYSTN THMB HIVIS | G12: AIRGAS | H12: RAD64057045 | I12: FALSE | J12: 1 | K12: 4.99 | L12: 1632 | M12: =IFERROR(IF(A12="","",K12/J12)," ") -> 4.99 | N12: =IFERROR(IF(A12="","",J12*L12)," ") -> 1632 | O12: =IFERROR(M12*N12," ") -> 8143.68 | P12: =IFERROR(IF(A12="","",O12-S12)," ") -> 391.68 | Q12: =IFERROR(IF(A12="","",P12/O12)," ") -> 0.048096192 | R12: =IFERROR(IF(A12="","",(IF(Q12<0,"Negative",IF(Q12=0,"Same",IF(Q12>0.3,"30+%",IF(Q12>0.2,"20-30%",IF(Q12>0.1,"10-20%",IF(Q12<=0.1,"0-10%"))))))))," ") -> 0-10% | S12: =IFERROR(IF(A12="","",T12*N12)," ") -> 7752 | T12: =IFERROR(IF(A12="","",X12/AB12)," ") -> 4.75 | U12: 3ZL49 | V12: FE | X12: 4.75 | Z12: 0 | AA12: PR | AB12: 1 | AC12: CONDOR | AD12: 3ZL49 | AE12: Leather Gloves,Beige,XL,PR | AF12: Safety | AG12: Leather Gloves and Mitts | AH12: Gloves and Hand Protection | AI12: TRUE | AJ12: Exact Match | AK12: Savings
A13: 42 | B13: 608 | F13: GLV MIG XL TOP GN CWHD FLCE LND PLM | G13: AIRGAS | H13: TIL50XL | I13: FALSE | J13: 1 | K13: 26.50 | L13: 289 | M13: =IFERROR(IF(A13="","",K13/J13)," ") -> 26.5 | N13: =IFERROR(IF(A13="","",J13*L13)," ") -> 289 | O13: =IFERROR(M13*N13," ") -> 7658.5 | P13: =IFERROR(IF(A13="","",O13-S13)," ") -> 118.49 | Q13: =IFERROR(IF(A13="","",P13/O13)," ") -> 0.015471698 | R13: =IFERROR(IF(A13="","",(IF(Q13<0,"Negative",IF(Q13=0,"Same",IF(Q13>0.3,"30+%",IF(Q13>0.2,"20-30%",IF(Q13>0.1,"10-20%",IF(Q13<=0.1,"0-10%"))))))))," ") -> 0-10% | S13: =IFERROR(IF(A13="","",T13*N13)," ") -> 7540.01 | T13: =IFERROR(IF(A13="","",X13/AB13)," ") -> 26.09 | U13: 5UPC8 | V13: FE | X13: 26.09 | Z13: 0 | AA13: PR | AB13: 1 | AC13: TILLMAN | AD13: 50XL | AE13: Welding Gloves,MIG,XL/10,PR | AF13: Safety | AG13: Welding Gloves | AH13: Gloves and Hand Protection | AJ13: Exact Match | AK13: Savings
A14: 46 | B14: 604 | F14: GLV MIG LG TOP GN CWHD FLCE LND PLM | G14: AIRGAS | H14: TIL50L | I14: FALSE | J14: 1 | K14: 26.51 | L14: 272 | M14: =IFERROR(IF(A14="","",K14/J14)," ") -> 26.51 | N14: =IFERROR(IF(A14="","",J14*L14)," ") -> 272 | O14: =IFERROR(M14*N14," ") -> 7210.72 | P14: =IFERROR(IF(A14="","",O14-S14)," ") -> 114.24 | Q14: =IFERROR(IF(A14="","",P14/O14)," ") -> 0.015843078 | R14: =IFERROR(IF(A14="","",(IF(Q14<0,"Negative",IF(Q14=0,"Same",IF(Q14>0.3,"30+%",IF(Q14>0.2,"20-30%",IF(Q14>0.1,"10-20%",IF(Q14<=0.1,"0-10%"))))))))," ") -> 0-10% | S14: =IFERROR(IF(A14="","",T14*N14)," ") -> 7096.48 | T14: =IFERROR(IF(A14="","",X14/AB14)," ") -> 26.09 | U14: 5UPC7 | V14: FE | X14: 26.09 | Z14: 0 | AA14: PR | AB14: 1 | AC14: TILLMAN | AD14: 50L | AE14: Welding Gloves,MIG,L/9,PR | AF14: Safety | AG14: Welding Gloves | AH14: Gloves and Hand Protection | AJ14: Exact Match | AK14: Savings
A15: 53 | B15: 218 | F15: LCKR CYL FOR 12 HRZNL 20/33LB LPG CYL | G15: AIRGAS | H15: JTR23004 | I15: FALSE | J15: 1 | K15: 2796.23 | L15: 2 | M15: =IFERROR(IF(A15="","",K15/J15)," ") -> 2796.23 | N15: =IFERROR(IF(A15="","",J15*L15)," ") -> 2 | O15: =IFERROR(M15*N15," ") -> 5592.46 | P15: =IFERROR(IF(A15="","",O15-S15)," ") -> 3467.26 | Q15: =IFERROR(IF(A15="","",P15/O15)," ") -> 0.61998834 | R15: =IFERROR(IF(A15="","",(IF(Q15<0,"Negative",IF(Q15=0,"Same",IF(Q15>0.3,"30+%",IF(Q15>0.2,"20-30%",IF(Q15>0.1,"10-20%",IF(Q15<=0.1,"0-10%"))))))))," ") -> 30+% | S15: =IFERROR(IF(A15="","",T15*N15)," ") -> 2125.2 | T15: =IFERROR(IF(A15="","",X15/AB15)," ") -> 1062.6 | U15: 6HCA2 | V15: FE | X15: 1062.6 | Z15: 0 | AA15: EA | AB15: 1 | AC15: VESTIL | AD15: CYL-EX-12-S | AE15: Cylinder Storage Cabinet, White, Steel | AF15: Safety | AG15: Cylinder Storage Cabinets and Lockers | AH15: Safety Storage | AJ15: Exact Match | AK15: Savings
A16: 55 | B16: 325 | F16: HDGR 13OZ DLX ALUMZD W/ RTCHT HDGR | G16: AIRGAS | H16: N33H15NJGOLD | I16: FALSE | J16: 1 | K16: 424.79 | L16: 12 | M16: =IFERROR(IF(A16="","",K16/J16)," ") -> 424.79 | N16: =IFERROR(IF(A16="","",J16*L16)," ") -> 12 | O16: =IFERROR(M16*N16," ") -> 5097.48 | P16: =IFERROR(IF(A16="","",O16-S16)," ") -> -803.76 | Q16: =IFERROR(IF(A16="","",P16/O16)," ") -> -0.15767791 | R16: =IFERROR(IF(A16="","",(IF(Q16<0,"Negative",IF(Q16=0,"Same",IF(Q16>0.3,"30+%",IF(Q16>0.2,"20-30%",IF(Q16>0.1,"10-20%",IF(Q16<=0.1,"0-10%"))))))))," ") -> Negative | S16: =IFERROR(IF(A16="","",T16*N16)," ") -> 5901.24 | T16: =IFERROR(IF(A16="","",X16/AB16)," ") -> 491.77 | U16: 2YRL4 | V16: FE | X16: 491.77 | Z16: 0 | AA16: EA | AB16: 1 | AC16: NATIONAL SAFETY APPAREL | AD16: H58NLHG | AE16: Hood,Aluminized Carbon Kevlar(R) | AF16: Safety | AG16: Aluminized Hoods | AH16: Flame Resistant and Arc Flash Clothing | AJ16: Exact Match | AK16: Current Price
A17: 61 | B17: 409 | F17: GLV CLD WTHR DRVR GN PIG LTHR LG TAN | G17: AIRGAS | H17: PIP994KOTP/L | I17: FALSE | J17: 1 | K17: 7.49 | L17: 576 | M17: =IFERROR(IF(A17="","",K17/J17)," ") -> 7.49 | N17: =IFERROR(IF(A17="","",J17*L17)," ") -> 576 | O17: =IFERROR(M17*N17," ") -> 4314.24 | P17: =IFERROR(IF(A17="","",O17-S17)," ") -> 213.12 | Q17: =IFERROR(IF(A17="","",P17/O17)," ") -> 0.049399199 | R17: =IFERROR(IF(A17="","",(IF(Q17<0,"Negative",IF(Q17=0,"Same",IF(Q17>0.3,"30+%",IF(Q17>0.2,"20-30%",IF(Q17>0.1,"10-20%",IF(Q17<=0.1,"0-10%"))))))))," ") -> 0-10% | S17: =IFERROR(IF(A17="","",T17*N17)," ") -> 4101.12 | T17: =IFERROR(IF(A17="","",X17/AB17)," ") -> 7.12 | U17: 25D570 | V17: FE | X17: 7.12 | Z17: 0 | AA17: PR | AB17: 1 | AC17: MCR SAFETY | AD17: 3213HVIL | AE17: Leather Gloves,Beige,L,PR | AF17: Safety | AG17: Leather Gloves and Mitts | AH17: Gloves and Hand Protection | AJ17: Exact Match | AK17: Savings
A18: 64 | B18: 562 | F18: FCSHD PN 9"X15.5"X.060" CLR UBD | G18: AIRGAS | H18: SEL29084 | I18: FALSE | J18: 1 | K18: 9.06 | L18: 456 | M18: =IFERROR(IF(A18="","",K18/J18)," ") -> 9.06 | N18: =IFERROR(IF(A18="","",J18*L18)," ") -> 456 | O18: =IFERROR(M18*N18," ") -> 4131.36 | P18: =IFERROR(IF(A18="","",O18-S18)," ") -> 109.44 | Q18: =IFERROR(IF(A18="","",P18/O18)," ") -> 0.026490066 | R18: =IFERROR(IF(A18="","",(IF(Q18<0,"Negative",IF(Q18=0,"Same",IF(Q18>0.3,"30+%",IF(Q18>0.2,"20-30%",IF(Q18>0.1,"10-20%",IF(Q18<=0.1,"0-10%"))))))))," ") -> 0-10% | S18: =IFERROR(IF(A18="","",T18*N18)," ") -> 4021.92 | T18: =IFERROR(IF(A18="","",X18/AB18)," ") -> 8.82 | U18: 33VA20 | V18: E | X18: 8.82 | Z18: 0 | AA18: EA | AB18: 1 | AC18: JACKSON SAFETY | AD18: 29084 | AE18: FaceShieldVisor,Clr,Uncoated,PC | AF18: Safety | AG18: Face Shield Replacement Visors and Lenses | AH18: Face Protection | AJ18: Exact Match | AK18: Savings
A19: 67 | B19: 35 | F19: CRTDG ORGC VPR RESPY PRTN 6001 | G19: AIRGAS | H19: 3MR6001 | I19: FALSE | J19: 1 | K19: 13.81 | L19: 288 | M19: =IFERROR(IF(A19="","",K19/J19)," ") -> 13.81 | N19: =IFERROR(IF(A19="","",J19*L19)," ") -> 288 | O19: =IFERROR(M19*N19," ") -> 3977.28 | P19: =IFERROR(IF(A19="","",O19-S19)," ") -> 1375.2 | Q19: =IFERROR(IF(A19="","",P19/O19)," ") -> 0.34576394 | R19: =IFERROR(IF(A19="","",(IF(Q19<0,"Negative",IF(Q19=0,"Same",IF(Q19>0.3,"30+%",IF(Q19>0.2,"20-30%",IF(Q19>0.1,"10-20%",IF(Q19<=0.1,"0-10%"))))))))," ") -> 30+% | S19: =IFERROR(IF(A19="","",T19*N19)," ") -> 2602.08 | T19: =IFERROR(IF(A19="","",X19/AB19)," ") -> 9.035 | U19: 6AM37 | V19: E | X19: 18.07 | Z19: 0 | AA19: PK | AB19: 2 | AC19: 3M | AD19: 6001 | AE19: Cartridge,Black,Bayonet,PK2 | AF19: Safety | AG19: Respirator Cartridges and Filters | AH19: Respiratory | AI19: TRUE | AJ19: Exact Match | AK19: Savings
A20: 69 | B20: 320 | F20: \\ TSHT LNG SLV FR XL 8.75OZ PRFRMN DES | G20: AIRGAS | H20: N33DF2CM265ALSDSXL | I20: FALSE | J20: 1 | K20: 86.89 | L20: 45 | M20: =IFERROR(IF(A20="","",K20/J20)," ") -> 86.89 | N20: =IFERROR(IF(A20="","",J20*L20)," ") -> 45 | O20: =IFERROR(M20*N20," ") -> 3910.05 | P20: =IFERROR(IF(A20="","",O20-S20)," ") -> 684.45 | Q20: =IFERROR(IF(A20="","",P20/O20)," ") -> 0.17504891 | R20: =IFERROR(IF(A20="","",(IF(Q20<0,"Negative",IF(Q20=0,"Same",IF(Q20>0.3,"30+%",IF(Q20>0.2,"20-30%",IF(Q20>0.1,"10-20%",IF(Q20<=0.1,"0-10%"))))))))," ") -> 10-20% | S20: =IFERROR(IF(A20="","",T20*N20)," ") -> 3225.6 | T20: =IFERROR(IF(A20="","",X20/AB20)," ") -> 71.68 | U20: 61RJ24 | V20: FE | X20: 71.68 | Z20: 0 | AA20: EA | AB20: 1 | AC20: ARIAT | AD20: 10022328 | AE20: FR Crew Longsleeve Tee,Tan,XL | AF20: Safety | AG20: Flame-Resistant and Arc Flash Shirts | AH20: Flame Resistant and Arc Flash Clothing | AJ20: Exact Match | AK20: Savings
A21: 70 | B21: 292 | F21: CT HT RES 4X 12OZ OPF BLND FLCE CLTH | G21: AIRGAS | H21: N33C22CW4X48179 | I21: FALSE | J21: 1 | K21: 650.14 | L21: 6 | M21: =IFERROR(IF(A21="","",K21/J21)," ") -> 650.14 | N21: =IFERROR(IF(A21="","",J21*L21)," ") -> 6 | O21: =IFERROR(M21*N21," ") -> 3900.84 | P21: =IFERROR(IF(A21="","",O21-S21)," ") -> 1312.26 | Q21: =IFERROR(IF(A21="","",P21/O21)," ") -> 0.33640447 | R21: =IFERROR(IF(A21="","",(IF(Q21<0,"Negative",IF(Q21=0,"Same",IF(Q21>0.3,"30+%",IF(Q21>0.2,"20-30%",IF(Q21>0.1,"10-20%",IF(Q21<=0.1,"0-10%"))))))))," ") -> 30+% | S21: =IFERROR(IF(A21="","",T21*N21)," ") -> 2588.58 | T21: =IFERROR(IF(A21="","",X21/AB21)," ") -> 431.43 | U21: 8DN27 | V21: PS-PLG | X21: 431.43 | Z21: 0 | AA21: EA | AB21: 1 | AC21: KAREWEAR | AD21: 714ACK3XL | AE21: Aluminized Jacket,3XL,Carbon Kevlar(R) | AF21: Safety | AG21: Aluminized Jackets and Coats | AH21: Flame Resistant and Arc Flash Clothing | AJ21: Exact Match | AK21: Savings
A22: 71 | B22: 476 | F22: GLV WLDG SPLT CWHD CSHN COR LND LG | G22: AIRGAS | H22: REV320L | I22: FALSE | J22: 1 | K22: 12.36 | L22: 312 | M22: =IFERROR(IF(A22="","",K22/J22)," ") -> 12.36 | N22: =IFERROR(IF(A22="","",J22*L22)," ") -> 312 | O22: =IFERROR(M22*N22," ") -> 3856.32 | P22: =IFERROR(IF(A22="","",O22-S22)," ") -> 190.32 | Q22: =IFERROR(IF(A22="","",P22/O22)," ") -> 0.049352751 | R22: =IFERROR(IF(A22="","",(IF(Q22<0,"Negative",IF(Q22=0,"Same",IF(Q22>0.3,"30+%",IF(Q22>0.2,"20-30%",IF(Q22>0.1,"10-20%",IF(Q22<=0.1,"0-10%"))))))))," ") -> 0-10% | S22: =IFERROR(IF(A22="","",T22*N22)," ") -> 3666 | T22: =IFERROR(IF(A22="","",X22/AB22)," ") -> 11.75 | U22: 4TJX5 | V22: FE | X22: 11.75 | Z22: 0 | AA22: PR | AB22: 1 | AC22: CONDOR | AD22: 4TJX5 | AE22: Welding Gloves,Stick,L/9,PR | AF22: Safety | AG22: Welding Gloves | AH22: Gloves and Hand Protection | AI22: TRUE | AJ22: Exact Match | AK22: Savings
A23: 78 | B23: 412 | F23: GLV CLD WTHR DRVR GN PIG LTHR XL TAN | G23: AIRGAS | H23: PIP994KOTP/XL | I23: FALSE | J23: 1 | K23: 7.51 | L23: 480 | M23: =IFERROR(IF(A23="","",K23/J23)," ") -> 7.51 | N23: =IFERROR(IF(A23="","",J23*L23)," ") -> 480 | O23: =IFERROR(M23*N23," ") -> 3604.8 | P23: =IFERROR(IF(A23="","",O23-S23)," ") -> 177.6 | Q23: =IFERROR(IF(A23="","",P23/O23)," ") -> 0.049267643 | R23: =IFERROR(IF(A23="","",(IF(Q23<0,"Negative",IF(Q23=0,"Same",IF(Q23>0.3,"30+%",IF(Q23>0.2,"20-30%",IF(Q23>0.1,"10-20%",IF(Q23<=0.1,"0-10%"))))))))," ") -> 0-10% | S23: =IFERROR(IF(A23="","",T23*N23)," ") -> 3427.2 | T23: =IFERROR(IF(A23="","",X23/AB23)," ") -> 7.14 | U23: 25D573 | V23: FE | X23: 7.14 | Z23: 0 | AA23: PR | AB23: 1 | AC23: MCR SAFETY | AD23: 3213HVIXL | AE23: Leather Gloves,Beige,XL,PR | AF23: Safety | AG23: Leather Gloves and Mitts | AH23: Gloves and Hand Protection | AJ23: Exact Match | AK23: Savings
A24: 81 | B24: 318 | F24: \\ TSHT LNG SLV FR LG 8.75OZ PRFRMN DES | G24: AIRGAS | H24: N33DF2CM265ALSDSLG | I24: FALSE | J24: 1 | K24: 87.37 | L24: 39 | M24: =IFERROR(IF(A24="","",K24/J24)," ") -> 87.37 | N24: =IFERROR(IF(A24="","",J24*L24)," ") -> 39 | O24: =IFERROR(M24*N24," ") -> 3407.43 | P24: =IFERROR(IF(A24="","",O24-S24)," ") -> 611.91 | Q24: =IFERROR(IF(A24="","",P24/O24)," ") -> 0.17958109 | R24: =IFERROR(IF(A24="","",(IF(Q24<0,"Negative",IF(Q24=0,"Same",IF(Q24>0.3,"30+%",IF(Q24>0.2,"20-30%",IF(Q24>0.1,"10-20%",IF(Q24<=0.1,"0-10%"))))))))," ") -> 10-20% | S24: =IFERROR(IF(A24="","",T24*N24)," ") -> 2795.52 | T24: =IFERROR(IF(A24="","",X24/AB24)," ") -> 71.68 | U24: 61RJ23 | V24: FE | X24: 71.68 | Z24: 0 | AA24: EA | AB24: 1 | AC24: ARIAT | AD24: 10022328 | AE24: FR Crew Longsleeve Tee,Tan,L | AF24: Safety | AG24: Flame-Resistant and Arc Flash Shirts | AH24: Flame Resistant and Arc Flash Clothing | AJ24: Exact Match | AK24: Savings
A25: 82 | B25: 543 | F25: VSN LNK LED LGHT BDY ASSY | G25: AIRGAS | H25: RPB16-910 | I25: FALSE | J25: 1 | K25: 224.74 | L25: 15 | M25: =IFERROR(IF(A25="","",K25/J25)," ") -> 224.74 | N25: =IFERROR(IF(A25="","",J25*L25)," ") -> 15 | O25: =IFERROR(M25*N25," ") -> 3371.1 | P25: =IFERROR(IF(A25="","",O25-S25)," ") -> 2568.3 | Q25: =IFERROR(IF(A25="","",P25/O25)," ") -> 0.76185815 | R25: =IFERROR(IF(A25="","",(IF(Q25<0,"Negative",IF(Q25=0,"Same",IF(Q25>0.3,"30+%",IF(Q25>0.2,"20-30%",IF(Q25>0.1,"10-20%",IF(Q25<=0.1,"0-10%"))))))))," ") -> 30+% | S25: =IFERROR(IF(A25="","",T25*N25)," ") -> 802.8 | T25: =IFERROR(IF(A25="","",X25/AB25)," ") -> 53.52 | U25: 43MJ59 | V25: PS-PLG | X25: 53.52 | Z25: 0 | AA25: EA | AB25: 1 | AC25: PELICAN | AD25: 2760C | AE25: Headlamp,Polycarbonate,Black,289lm | AF25: Lighting | AG25: Headlamps and Headgear Mounted Lights | AH25: Flashlights | AJ25: Exact Match | AK25: Savings
A26: 85 | B26: 460 | F26: GLV DRVR MD GN CWHD HIVIS IMPRINTED | G26: AIRGAS | H26: RAD64057043 | I26: FALSE | J26: 1 | K26: 4.99 | L26: 648 | M26: =IFERROR(IF(A26="","",K26/J26)," ") -> 4.99 | N26: =IFERROR(IF(A26="","",J26*L26)," ") -> 648 | O26: =IFERROR(M26*N26," ") -> 3233.52 | P26: =IFERROR(IF(A26="","",O26-S26)," ") -> 155.52 | Q26: =IFERROR(IF(A26="","",P26/O26)," ") -> 0.048096192 | R26: =IFERROR(IF(A26="","",(IF(Q26<0,"Negative",IF(Q26=0,"Same",IF(Q26>0.3,"30+%",IF(Q26>0.2,"20-30%",IF(Q26>0.1,"10-20%",IF(Q26<=0.1,"0-10%"))))))))," ") -> 0-10% | S26: =IFERROR(IF(A26="","",T26*N26)," ") -> 3078 | T26: =IFERROR(IF(A26="","",X26/AB26)," ") -> 4.75 | U26: 3ZL51 | V26: FE | X26: 4.75 | Z26: 0 | AA26: PR | AB26: 1 | AC26: CONDOR | AD26: 3ZL51 | AE26: Leather Gloves,Beige,M,PR | AF26: Safety | AG26: Leather Gloves and Mitts | AH26: Gloves and Hand Protection | AI26: TRUE | AJ26: Exact Match | AK26: Savings
A27: 92 | B27: 147 | F27: LFLN SLF RTRCTG 9' 3M DBI-SALA NANO-L | G27: AIRGAS | H27: D623101366 | I27: FALSE | J27: 1 | K27: 273.74 | L27: 11 | M27: =IFERROR(IF(A27="","",K27/J27)," ") -> 273.74 | N27: =IFERROR(IF(A27="","",J27*L27)," ") -> 11 | O27: =IFERROR(M27*N27," ") -> 3011.14 | P27: =IFERROR(IF(A27="","",O27-S27)," ") -> -882.09 | Q27: =IFERROR(IF(A27="","",P27/O27)," ") -> -0.29294221 | R27: =IFERROR(IF(A27="","",(IF(Q27<0,"Negative",IF(Q27=0,"Same",IF(Q27>0.3,"30+%",IF(Q27>0.2,"20-30%",IF(Q27>0.1,"10-20%",IF(Q27<=0.1,"0-10%"))))))))," ") -> Negative | S27: =IFERROR(IF(A27="","",T27*N27)," ") -> 3893.23 | T27: =IFERROR(IF(A27="","",X27/AB27)," ") -> 353.93 | U27: 46W460 | V27: FE | X27: 353.93 | Z27: 0 | AA27: EA | AB27: 1 | AC27: 3M DBI-SALA | AD27: 3101366 | AE27: Self-Retracting Lifeline,9 ft L,1Leg | AF27: Safety | AG27: Self-Retracting Lifelines | AH27: Fall Protection | AJ27: Exact Match | AK27: Current Price
A28: 97 | B28: 13 | F28: EYEWR PROTV W/FM GSKT CLR AF LENS | G28: AIRGAS | H28: 3MR11872-00000 | I28: FALSE | J28: 1 | K28: 8.08 | L28: 360 | M28: =IFERROR(IF(A28="","",K28/J28)," ") -> 8.08 | N28: =IFERROR(IF(A28="","",J28*L28)," ") -> 360 | O28: =IFERROR(M28*N28," ") -> 2908.8 | P28: =IFERROR(IF(A28="","",O28-S28)," ") -> -284.4 | Q28: =IFERROR(IF(A28="","",P28/O28)," ") -> -0.097772277 | R28: =IFERROR(IF(A28="","",(IF(Q28<0,"Negative",IF(Q28=0,"Same",IF(Q28>0.3,"30+%",IF(Q28>0.2,"20-30%",IF(Q28>0.1,"10-20%",IF(Q28<=0.1,"0-10%"))))))))," ") -> Negative | S28: =IFERROR(IF(A28="","",T28*N28)," ") -> 3193.2 | T28: =IFERROR(IF(A28="","",X28/AB28)," ") -> 8.87 | U28: 46F390 | V28: FE | X28: 8.87 | Z28: 0 | AA28: EA | AB28: 1 | AC28: 3M | AD28: 11872 | AE28: Safety Glasses, Clear, Anti-Fog, Clear | AF28: Safety | AG28: Safety Glasses | AH28: Eye Protection and Accessories | AI28: TRUE | AJ28: Exact Match | AK28: Current Price
A29: 99 | B29: 293 | F29: CT HT RES 5X 12OZ OPF BLND FLCE CLTH | G29: AIRGAS | H29: N33C22CW5X48179 | I29: FALSE | J29: 1 | K29: 721.91 | L29: 4 | M29: =IFERROR(IF(A29="","",K29/J29)," ") -> 721.91 | N29: =IFERROR(IF(A29="","",J29*L29)," ") -> 4 | O29: =IFERROR(M29*N29," ") -> 2887.64 | P29: =IFERROR(IF(A29="","",O29-S29)," ") -> 1161.92 | Q29: =IFERROR(IF(A29="","",P29/O29)," ") -> 0.40237703 | R29: =IFERROR(IF(A29="","",(IF(Q29<0,"Negative",IF(Q29=0,"Same",IF(Q29>0.3,"30+%",IF(Q29>0.2,"20-30%",IF(Q29>0.1,"10-20%",IF(Q29<=0.1,"0-10%"))))))))," ") -> 30+% | S29: =IFERROR(IF(A29="","",T29*N29)," ") -> 1725.72 | T29: =IFERROR(IF(A29="","",X29/AB29)," ") -> 431.43 | U29: 8DN27 | V29: PS-PLG | X29: 431.43 | Z29: 0 | AA29: EA | AB29: 1 | AC29: KAREWEAR | AD29: 714ACK3XL | AE29: Aluminized Jacket,3XL,Carbon Kevlar(R) | AF29: Safety | AG29: Aluminized Jackets and Coats | AH29: Flame Resistant and Arc Flash Clothing | AJ29: Exact Match | AK29: Savings
A30: 104 | B30: 205 | F30: TP BARICD 3"X500' RED DNGR RFRCD GRDE | G30: AIRGAS | H30: ICMREBT2057 | I30: FALSE | J30: 1 | K30: 20.85 | L30: 132 | M30: =IFERROR(IF(A30="","",K30/J30)," ") -> 20.85 | N30: =IFERROR(IF(A30="","",J30*L30)," ") -> 132 | O30: =IFERROR(M30*N30," ") -> 2752.2 | P30: =IFERROR(IF(A30="","",O30-S30)," ") -> 137.28 | Q30: =IFERROR(IF(A30="","",P30/O30)," ") -> 0.049880096 | R30: =IFERROR(IF(A30="","",(IF(Q30<0,"Negative",IF(Q30=0,"Same",IF(Q30>0.3,"30+%",IF(Q30>0.2,"20-30%",IF(Q30>0.1,"10-20%",IF(Q30<=0.1,"0-10%"))))))))," ") -> 0-10% | S30: =IFERROR(IF(A30="","",T30*N30)," ") -> 2614.92 | T30: =IFERROR(IF(A30="","",X30/AB30)," ") -> 19.81 | U30: 30WU19 | V30: DR | X30: 19.81 | Z30: 0 | AA30: EA | AB30: 1 | AC30: APPROVED VENDOR | AD30: BR35XR21-200 | AE30: Barricade Tape, Red, 500 ft L, 3 in | AF30: Security | AG30: Barrier, Flagging and Underground Marking Tapes | AH30: Access Barriers and Crowd Control | AJ30: Exact Match | AK30: Savings
A31: 106 | B31: 316 | F31: \\ TSHT LNG SLV FR 2X 8.75OZ PRFRMN DES | G31: AIRGAS | H31: N33DF2CM265ALSDS2X | I31: FALSE | J31: 1 | K31: 96.17 | L31: 28 | M31: =IFERROR(IF(A31="","",K31/J31)," ") -> 96.17 | N31: =IFERROR(IF(A31="","",J31*L31)," ") -> 28 | O31: =IFERROR(M31*N31," ") -> 2692.76 | P31: =IFERROR(IF(A31="","",O31-S31)," ") -> 685.72 | Q31: =IFERROR(IF(A31="","",P31/O31)," ") -> 0.25465322 | R31: =IFERROR(IF(A31="","",(IF(Q31<0,"Negative",IF(Q31=0,"Same",IF(Q31>0.3,"30+%",IF(Q31>0.2,"20-30%",IF(Q31>0.1,"10-20%",IF(Q31<=0.1,"0-10%"))))))))," ") -> 20-30% | S31: =IFERROR(IF(A31="","",T31*N31)," ") -> 2007.04 | T31: =IFERROR(IF(A31="","",X31/AB31)," ") -> 71.68 | U31: 61RJ25 | V31: FE | X31: 71.68 | Z31: 0 | AA31: EA | AB31: 1 | AC31: ARIAT | AD31: 10022328 | AE31: FR Crew Longsleeve Tee,Tan,2XL | AF31: Safety | AG31: Flame-Resistant and Arc Flash Shirts | AH31: Flame Resistant and Arc Flash Clothing | AJ31: Exact Match | AK31: Savings
A32: 110 | B32: 299 | F32: CT HT RES 4X 13OZ ALUMZD CARBON | G32: AIRGAS | H32: N33C22NU4X48018 | I32: FALSE | J32: 1 | K32: 431.70 | L32: 6 | M32: =IFERROR(IF(A32="","",K32/J32)," ") -> 431.7 | N32: =IFERROR(IF(A32="","",J32*L32)," ") -> 6 | O32: =IFERROR(M32*N32," ") -> 2590.2 | P32: =IFERROR(IF(A32="","",O32-S32)," ") -> 1.62 | Q32: =IFERROR(IF(A32="","",P32/O32)," ") -> 0.00062543433 | R32: =IFERROR(IF(A32="","",(IF(Q32<0,"Negative",IF(Q32=0,"Same",IF(Q32>0.3,"30+%",IF(Q32>0.2,"20-30%",IF(Q32>0.1,"10-20%",IF(Q32<=0.1,"0-10%"))))))))," ") -> 0-10% | S32: =IFERROR(IF(A32="","",T32*N32)," ") -> 2588.58 | T32: =IFERROR(IF(A32="","",X32/AB32)," ") -> 431.43 | U32: 8DN27 | V32: PS-PLG | X32: 431.43 | Z32: 0 | AA32: EA | AB32: 1 | AC32: KAREWEAR | AD32: 714ACK3XL | AE32: Aluminized Jacket,3XL,Carbon Kevlar(R) | AF32: Safety | AG32: Aluminized Jackets and Coats | AH32: Flame Resistant and Arc Flash Clothing | AJ32: Exact Match | AK32: Savings
A33: 111 | B33: 481 | F33: GLV SZ LG WLDG CWHD BCK PRM MIG GN | G33: AIRGAS | H33: REVBM88-LG | I33: FALSE | J33: 1 | K33: 17.83 | L33: 144 | M33: =IFERROR(IF(A33="","",K33/J33)," ") -> 17.83 | N33: =IFERROR(IF(A33="","",J33*L33)," ") -> 144 | O33: =IFERROR(M33*N33," ") -> 2567.52 | P33: =IFERROR(IF(A33="","",O33-S33)," ") -> 875.52 | Q33: =IFERROR(IF(A33="","",P33/O33)," ") -> 0.34099832 | R33: =IFERROR(IF(A33="","",(IF(Q33<0,"Negative",IF(Q33=0,"Same",IF(Q33>0.3,"30+%",IF(Q33>0.2,"20-30%",IF(Q33>0.1,"10-20%",IF(Q33<=0.1,"0-10%"))))))))," ") -> 30+% | S33: =IFERROR(IF(A33="","",T33*N33)," ") -> 1692 | T33: =IFERROR(IF(A33="","",X33/AB33)," ") -> 11.75 | U33: 4TJX5 | V33: FE | X33: 11.75 | Z33: 0 | AA33: PR | AB33: 1 | AC33: CONDOR | AD33: 4TJX5 | AE33: Welding Gloves,Stick,L/9,PR | AF33: Safety | AG33: Welding Gloves | AH33: Gloves and Hand Protection | AI33: TRUE | AJ33: Exact Match | AK33: Savings
A34: 113 | B34: 119 | F34: GATE SFTY 27" SELF-CLOSING | G34: AIRGAS | H34: BWA500367 | I34: FALSE | J34: 1 | K34: 315.28 | L34: 8 | M34: =IFERROR(IF(A34="","",K34/J34)," ") -> 315.28 | N34: =IFERROR(IF(A34="","",J34*L34)," ") -> 8 | O34: =IFERROR(M34*N34," ") -> 2522.24 | P34: =IFERROR(IF(A34="","",O34-S34)," ") -> 1151.6 | Q34: =IFERROR(IF(A34="","",P34/O34)," ") -> 0.45657828 | R34: =IFERROR(IF(A34="","",(IF(Q34<0,"Negative",IF(Q34=0,"Same",IF(Q34>0.3,"30+%",IF(Q34>0.2,"20-30%",IF(Q34>0.1,"10-20%",IF(Q34<=0.1,"0-10%"))))))))," ") -> 30+% | S34: =IFERROR(IF(A34="","",T34*N34)," ") -> 1370.64 | T34: =IFERROR(IF(A34="","",X34/AB34)," ") -> 171.33 | U34: 31TT69 | V34: FE | X34: 171.33 | Z34: 0 | AA34: EA | AB34: 1 | AC34: CONDOR | AD34: 31TT69 | AE34: Single-Door,11 3/4 in,Yellow | AF34: Material Handling | AG34: Self-Closing Safety Gates | AH34: Structures and Storage Buildings | AJ34: Exact Match | AK34: Savings
A35: 115 | B35: 540 | F35: LENS IMPCT WLDG ADF | G35: AIRGAS | H35: RPB16-872 | I35: FALSE | J35: 1 | K35: 1.77 | L35: 1350 | M35: =IFERROR(IF(A35="","",K35/J35)," ") -> 1.77 | N35: =IFERROR(IF(A35="","",J35*L35)," ") -> 1350 | O35: =IFERROR(M35*N35," ") -> 2389.5 | P35: =IFERROR(IF(A35="","",O35-S35)," ") -> -720.9 | Q35: =IFERROR(IF(A35="","",P35/O35)," ") -> -0.30169492 | R35: =IFERROR(IF(A35="","",(IF(Q35<0,"Negative",IF(Q35=0,"Same",IF(Q35>0.3,"30+%",IF(Q35>0.2,"20-30%",IF(Q35>0.1,"10-20%",IF(Q35<=0.1,"0-10%"))))))))," ") -> Negative | S35: =IFERROR(IF(A35="","",T35*N35)," ") -> 3110.4 | T35: =IFERROR(IF(A35="","",X35/AB35)," ") -> 2.304 | U35: 61CX89 | V35: E | X35: 23.04 | Z35: 0 | AA35: PK | AB35: 10 | AC35: RPB SAFETY | AD35: 16-872 | AE35: ADF Impact Lens,Clear,PK 10 | AF35: Safety | AG35: Powered Air-Purifying Respirators | AH35: Respiratory | AJ35: Exact Match | AK35: Current Price
A36: 117 | B36: 15 | F36: PFLTR WLDG SFTY 15-0099-99X12 12 PER CA | G36: AIRGAS | H36: 3MR15009999X12 | I36: FALSE | J36: 1 | K36: 3.03 | L36: 780 | M36: =IFERROR(IF(A36="","",K36/J36)," ") -> 3.03 | N36: =IFERROR(IF(A36="","",J36*L36)," ") -> 780 | O36: =IFERROR(M36*N36," ") -> 2363.4 | P36: =IFERROR(IF(A36="","",O36-S36)," ") -> -967.2 | Q36: =IFERROR(IF(A36="","",P36/O36)," ") -> -0.40924092 | R36: =IFERROR(IF(A36="","",(IF(Q36<0,"Negative",IF(Q36=0,"Same",IF(Q36>0.3,"30+%",IF(Q36>0.2,"20-30%",IF(Q36>0.1,"10-20%",IF(Q36<=0.1,"0-10%"))))))))," ") -> Negative | S36: =IFERROR(IF(A36="","",T36*N36)," ") -> 3330.6 | T36: =IFERROR(IF(A36="","",X36/AB36)," ") -> 4.27 | U36: 32V222 | V36: E | X36: 51.24 | Z36: 0 | AA36: PK | AB36: 12 | AC36: SPEEDGLAS | AD36: 15-0099-99X12 | AE36: PAPR Prefilter,PK12 | AF36: Safety | AG36: Respirator Parts and Accessories | AH36: Respiratory | AJ36: Exact Match | AK36: Current Price
A37: 118 | B37: 319 | F37: \\ TSHT LNG SLV FR MD 8.75OZ PRFRMN DES | G37: AIRGAS | H37: N33DF2CM265ALSDSMD | I37: FALSE | J37: 1 | K37: 86.97 | L37: 27 | M37: =IFERROR(IF(A37="","",K37/J37)," ") -> 86.97 | N37: =IFERROR(IF(A37="","",J37*L37)," ") -> 27 | O37: =IFERROR(M37*N37," ") -> 2348.19 | P37: =IFERROR(IF(A37="","",O37-S37)," ") -> 412.83 | Q37: =IFERROR(IF(A37="","",P37/O37)," ") -> 0.17580775 | R37: =IFERROR(IF(A37="","",(IF(Q37<0,"Negative",IF(Q37=0,"Same",IF(Q37>0.3,"30+%",IF(Q37>0.2,"20-30%",IF(Q37>0.1,"10-20%",IF(Q37<=0.1,"0-10%"))))))))," ") -> 10-20% | S37: =IFERROR(IF(A37="","",T37*N37)," ") -> 1935.36 | T37: =IFERROR(IF(A37="","",X37/AB37)," ") -> 71.68 | U37: 61RJ22 | V37: FE | X37: 71.68 | Z37: 0 | AA37: EA | AB37: 1 | AC37: ARIAT | AD37: 10022328 | AE37: FR Crew Longsleeve Tee,Tan,M | AF37: Safety | AG37: Flame-Resistant and Arc Flash Shirts | AH37: Flame Resistant and Arc Flash Clothing | AJ37: Exact Match | AK37: Savings
A38: 119 | B38: 298 | F38: CT HT RES 3X 13OZ ALUMZD CARBON | G38: AIRGAS | H38: N33C22NU3X48018 | I38: FALSE | J38: 1 | K38: 391.18 | L38: 6 | M38: =IFERROR(IF(A38="","",K38/J38)," ") -> 391.18 | N38: =IFERROR(IF(A38="","",J38*L38)," ") -> 6 | O38: =IFERROR(M38*N38," ") -> 2347.08 | P38: =IFERROR(IF(A38="","",O38-S38)," ") -> -241.5 | Q38: =IFERROR(IF(A38="","",P38/O38)," ") -> -0.10289381 | R38: =IFERROR(IF(A38="","",(IF(Q38<0,"Negative",IF(Q38=0,"Same",IF(Q38>0.3,"30+%",IF(Q38>0.2,"20-30%",IF(Q38>0.1,"10-20%",IF(Q38<=0.1,"0-10%"))))))))," ") -> Negative | S38: =IFERROR(IF(A38="","",T38*N38)," ") -> 2588.58 | T38: =IFERROR(IF(A38="","",X38/AB38)," ") -> 431.43 | U38: 8DN27 | V38: FE | X38: 431.43 | Z38: 0 | AA38: EA | AB38: 1 | AC38: KAREWEAR | AD38: 714ACK3XL | AE38: Aluminized Jacket,3XL,Carbon Kevlar(R) | AF38: Safety | AG38: Aluminized Jackets and Coats | AH38: Flame Resistant and Arc Flash Clothing | AJ38: Exact Match | AK38: Current Price
A39: 120 | B39: 297 | F39: CT HT RES 2X 13OZ ALUMZD CARBON | G39: AIRGAS | H39: N33C22NU2X48018 | I39: FALSE | J39: 1 | K39: 390.45 | L39: 6 | M39: =IFERROR(IF(A39="","",K39/J39)," ") -> 390.45 | N39: =IFERROR(IF(A39="","",J39*L39)," ") -> 6 | O39: =IFERROR(M39*N39," ") -> 2342.7 | P39: =IFERROR(IF(A39="","",O39-S39)," ") -> -520.38 | Q39: =IFERROR(IF(A39="","",P39/O39)," ") -> -0.22212831 | R39: =IFERROR(IF(A39="","",(IF(Q39<0,"Negative",IF(Q39=0,"Same",IF(Q39>0.3,"30+%",IF(Q39>0.2,"20-30%",IF(Q39>0.1,"10-20%",IF(Q39<=0.1,"0-10%"))))))))," ") -> Negative | S39: =IFERROR(IF(A39="","",T39*N39)," ") -> 2863.08 | T39: =IFERROR(IF(A39="","",X39/AB39)," ") -> 477.18 | U39: 9NN05 | V39: FE | X39: 477.18 | Z39: 0 | AA39: EA | AB39: 1 | AC39: KAREWEAR | AD39: 714ACK2XL | AE39: Aluminized Jacket,2XL,Carbon Kevlar(R) | AF39: Safety | AG39: Aluminized Jackets and Coats | AH39: Flame Resistant and Arc Flash Clothing | AJ39: Exact Match | AK39: Current Price
A40: 126 | B40: 241 | F40: GLV DRVR PRM GRDE LTHR GTSN LG WHT | G40: AIRGAS | H40: MEG3601KL | I40: FALSE | J40: 1 | K40: 12.14 | L40: 181 | M40: =IFERROR(IF(A40="","",K40/J40)," ") -> 12.14 | N40: =IFERROR(IF(A40="","",J40*L40)," ") -> 181 | O40: =IFERROR(M40*N40," ") -> 2197.34 | P40: =IFERROR(IF(A40="","",O40-S40)," ") -> -680.56 | Q40: =IFERROR(IF(A40="","",P40/O40)," ") -> -0.30971993 | R40: =IFERROR(IF(A40="","",(IF(Q40<0,"Negative",IF(Q40=0,"Same",IF(Q40>0.3,"30+%",IF(Q40>0.2,"20-30%",IF(Q40>0.1,"10-20%",IF(Q40<=0.1,"0-10%"))))))))," ") -> Negative | S40: =IFERROR(IF(A40="","",T40*N40)," ") -> 2877.9 | T40: =IFERROR(IF(A40="","",X40/AB40)," ") -> 15.9 | U40: 21NM43 | V40: E | X40: 15.9 | Z40: 0 | AA40: PR | AB40: 1 | AC40: MCR SAFETY | AD40: 3601KL | AE40: Leather Gloves,White,L,PR | AF40: Safety | AG40: Leather Gloves and Mitts | AH40: Gloves and Hand Protection | AI40: TRUE | AJ40: Exact Match | AK40: Current Price
...

Sheet Excluded
A1: Xsort | B1: Sequence # | C1: Customer product # | D1: Distributor name | E1: Distributor # | F1: Description | G1: Manufacturer name | H1: Manufacturer number | I1: Unit of measure | J1: Units/pack | K1: Pack price | L1: Total packs | M1: Unit price | N1: Total baseline units | O1: Total incumbent spend | P1: Savings $ | Q1: Savings % | R1: Savings cat. | S1: WWG extended price | T1: WWG unit price | U1: WWG item # | V1: Code | W1: Status (in/out) | X1: Act price | Y1: Notes | Z1: Xref Notes | AA1: WWG unit of measure | AB1: WWG unit/pack | AC1: WWG Manufacturer name | AD1: WWG Manufacturer number | AE1: WWG Description | AF1: Product segment | AG1: Product category | AH1: Product family | AI1: CSP | AJ1: Exclusion Reason
A2: 4 | B2: 322 | F2: [DS] NATIONAL SAFETY APPAREL INC | G2: AIRGAS | H2: N33GENERIC | I2: FALSE | J2: 1 | K2: 373.25 | L2: 115 | M2: =IFERROR(IF(A2="","",K2/J2)," ") -> 373.25 | N2: =IFERROR(IF(A2="","",J2*L2)," ") -> 115 | O2: =IFERROR(M2*N2," ") -> 42923.75 | P2: =IFERROR(IF(A2="","",O2-S2)," ") | Q2: =IFERROR(IF(A2="","",P2/O2)," ") | R2: =IFERROR(IF(A2="","",(IF(Q2<0,"Negative",IF(Q2=0,"Same",IF(Q2>0.3,"30+%",IF(Q2>0.2,"20-30%",IF(Q2>0.1,"10-20%",IF(Q2<=0.1,"0-10%"))))))))," ") -> 30+% | S2: =IFERROR(IF(A2="","",T2*N2)," ") | T2: =IFERROR(IF(A2="","",X2/AB2)," ") | U2: 0 | V2: NCI | X2: 0 | Z2: 0 | AJ2: No Match
A3: 8 | B3: 565 | F3: FCSHD CLR GLD HT REFLV A/FG | G3: AIRGAS | H3: SEL4125AFB | I3: FALSE | J3: 1 | K3: 147.39 | L3: 120 | M3: =IFERROR(IF(A3="","",K3/J3)," ") -> 147.39 | N3: =IFERROR(IF(A3="","",J3*L3)," ") -> 120 | O3: =IFERROR(M3*N3," ") -> 17686.8 | P3: =IFERROR(IF(A3="","",O3-S3)," ") | Q3: =IFERROR(IF(A3="","",P3/O3)," ") | R3: =IFERROR(IF(A3="","",(IF(Q3<0,"Negative",IF(Q3=0,"Same",IF(Q3>0.3,"30+%",IF(Q3>0.2,"20-30%",IF(Q3>0.1,"10-20%",IF(Q3<=0.1,"0-10%"))))))))," ") -> 30+% | S3: =IFERROR(IF(A3="","",T3*N3)," ") | T3: =IFERROR(IF(A3="","",X3/AB3)," ") | U3: 0 | V3: O | X3: 0 | Z3: 0 | AJ3: No Match
A4: 21 | B4: 560 | F4: FACESHIELD ASSEMBLY | G4: AIRGAS | H4: SEL24125AFB | I4: FALSE | J4: 1 | K4: 160.33 | L4: 70 | M4: =IFERROR(IF(A4="","",K4/J4)," ") -> 160.33 | N4: =IFERROR(IF(A4="","",J4*L4)," ") -> 70 | O4: =IFERROR(M4*N4," ") -> 11223.1 | P4: =IFERROR(IF(A4="","",O4-S4)," ") | Q4: =IFERROR(IF(A4="","",P4/O4)," ") | R4: =IFERROR(IF(A4="","",(IF(Q4<0,"Negative",IF(Q4=0,"Same",IF(Q4>0.3,"30+%",IF(Q4>0.2,"20-30%",IF(Q4>0.1,"10-20%",IF(Q4<=0.1,"0-10%"))))))))," ") -> 30+% | S4: =IFERROR(IF(A4="","",T4*N4)," ") | T4: =IFERROR(IF(A4="","",X4/AB4)," ") | U4: 0 | V4: O | X4: 0 | Z4: 0 | AJ4: No Match
A5: 24 | B5: 621 | F5: [DS] WILSON BOHANNAN COMPANY | G5: AIRGAS | H5: W67GENERIC | I5: FALSE | J5: 1 | K5: 23.09 | L5: 454 | M5: =IFERROR(IF(A5="","",K5/J5)," ") -> 23.09 | N5: =IFERROR(IF(A5="","",J5*L5)," ") -> 454 | O5: =IFERROR(M5*N5," ") -> 10482.86 | P5: =IFERROR(IF(A5="","",O5-S5)," ") | Q5: =IFERROR(IF(A5="","",P5/O5)," ") | R5: =IFERROR(IF(A5="","",(IF(Q5<0,"Negative",IF(Q5=0,"Same",IF(Q5>0.3,"30+%",IF(Q5>0.2,"20-30%",IF(Q5>0.1,"10-20%",IF(Q5<=0.1,"0-10%"))))))))," ") -> 30+% | S5: =IFERROR(IF(A5="","",T5*N5)," ") | T5: =IFERROR(IF(A5="","",X5/AB5)," ") | U5: 0 | V5: NCI | X5: 0 | Z5: 0 | AJ5: No Match
A6: 36 | B6: 209 | F6: FLTR ESM WLDG HLMT HI EFNC | G6: AIRGAS | H6: IS6PR02026SP | I6: FALSE | J6: 1 | K6: 108.30 | L6: 76 | M6: =IFERROR(IF(A6="","",K6/J6)," ") -> 108.3 | N6: =IFERROR(IF(A6="","",J6*L6)," ") -> 76 | O6: =IFERROR(M6*N6," ") -> 8230.8 | P6: =IFERROR(IF(A6="","",O6-S6)," ") | Q6: =IFERROR(IF(A6="","",P6/O6)," ") | R6: =IFERROR(IF(A6="","",(IF(Q6<0,"Negative",IF(Q6=0,"Same",IF(Q6>0.3,"30+%",IF(Q6>0.2,"20-30%",IF(Q6>0.1,"10-20%",IF(Q6<=0.1,"0-10%"))))))))," ") -> 30+% | S6: =IFERROR(IF(A6="","",T6*N6)," ") | T6: =IFERROR(IF(A6="","",X6/AB6)," ") | U6: 0 | V6: O | X6: 0 | Z6: 0 | AJ6: No Match
A7: 49 | B7: 313 | F7: \\ LONGJOHN FR PNTS HVYWT DRIFIRE | G7: AIRGAS | H7: N33DF2CM265ALPDSLG | I7: FALSE | J7: 1 | K7: 87.39 | L7: 71 | M7: =IFERROR(IF(A7="","",K7/J7)," ") -> 87.39 | N7: =IFERROR(IF(A7="","",J7*L7)," ") -> 71 | O7: =IFERROR(M7*N7," ") -> 6204.69 | P7: =IFERROR(IF(A7="","",O7-S7)," ") | Q7: =IFERROR(IF(A7="","",P7/O7)," ") | R7: =IFERROR(IF(A7="","",(IF(Q7<0,"Negative",IF(Q7=0,"Same",IF(Q7>0.3,"30+%",IF(Q7>0.2,"20-30%",IF(Q7>0.1,"10-20%",IF(Q7<=0.1,"0-10%"))))))))," ") -> 30+% | S7: =IFERROR(IF(A7="","",T7*N7)," ") | T7: =IFERROR(IF(A7="","",X7/AB7)," ") | U7: 0 | V7: O | X7: 0 | Z7: 0 | AJ7: No Match
A8: 50 | B8: 339 | F8: UNWR LNG FR CTRL 2.0 LG 5.5OZ SND 4CAL | G8: AIRGAS | H8: N33U52JKSRLG | I8: FALSE | J8: 1 | K8: 79.04 | L8: 78 | M8: =IFERROR(IF(A8="","",K8/J8)," ") -> 79.04 | N8: =IFERROR(IF(A8="","",J8*L8)," ") -> 78 | O8: =IFERROR(M8*N8," ") -> 6165.12 | P8: =IFERROR(IF(A8="","",O8-S8)," ") | Q8: =IFERROR(IF(A8="","",P8/O8)," ") | R8: =IFERROR(IF(A8="","",(IF(Q8<0,"Negative",IF(Q8=0,"Same",IF(Q8>0.3,"30+%",IF(Q8>0.2,"20-30%",IF(Q8>0.1,"10-20%",IF(Q8<=0.1,"0-10%"))))))))," ") -> 30+% | S8: =IFERROR(IF(A8="","",T8*N8)," ") | T8: =IFERROR(IF(A8="","",X8/AB8)," ") | U8: 0 | V8: O | X8: 0 | Z8: 0 | AJ8: No Match
A9: 58 | B9: 568 | F9: [DS] STRONG HOLD PRODUCTS | G9: AIRGAS | H9: SHPGENERIC | I9: FALSE | J9: 1 | K9: 4905.74 | L9: 1 | M9: =IFERROR(IF(A9="","",K9/J9)," ") -> 4905.74 | N9: =IFERROR(IF(A9="","",J9*L9)," ") -> 1 | O9: =IFERROR(M9*N9," ") -> 4905.74 | P9: =IFERROR(IF(A9="","",O9-S9)," ") | Q9: =IFERROR(IF(A9="","",P9/O9)," ") | R9: =IFERROR(IF(A9="","",(IF(Q9<0,"Negative",IF(Q9=0,"Same",IF(Q9>0.3,"30+%",IF(Q9>0.2,"20-30%",IF(Q9>0.1,"10-20%",IF(Q9<=0.1,"0-10%"))))))))," ") -> 30+% | S9: =IFERROR(IF(A9="","",T9*N9)," ") | T9: =IFERROR(IF(A9="","",X9/AB9)," ") | U9: 0 | V9: NCI | X9: 0 | Z9: 0 | AJ9: No Match
A10: 68 | B10: 167 | F10: [DS] EBEL IMPRINTS | G10: AIRGAS | H10: EA4GENERIC | I10: FALSE | J10: 1 | K10: 83.52 | L10: 47 | M10: =IFERROR(IF(A10="","",K10/J10)," ") -> 83.52 | N10: =IFERROR(IF(A10="","",J10*L10)," ") -> 47 | O10: =IFERROR(M10*N10," ") -> 3925.44 | P10: =IFERROR(IF(A10="","",O10-S10)," ") | Q10: =IFERROR(IF(A10="","",P10/O10)," ") | R10: =IFERROR(IF(A10="","",(IF(Q10<0,"Negative",IF(Q10=0,"Same",IF(Q10>0.3,"30+%",IF(Q10>0.2,"20-30%",IF(Q10>0.1,"10-20%",IF(Q10<=0.1,"0-10%"))))))))," ") -> 30+% | S10: =IFERROR(IF(A10="","",T10*N10)," ") | T10: =IFERROR(IF(A10="","",X10/AB10)," ") | U10: 0 | V10: NCI | X10: 0 | Z10: 0 | AJ10: No Match
A11: 73 | B11: 564 | F11: FCSHD GLD HT REFLV W/ ALUM BRCKT | G11: AIRGAS | H11: SEL3165B | I11: FALSE | J11: 1 | K11: 159.20 | L11: 24 | M11: =IFERROR(IF(A11="","",K11/J11)," ") -> 159.2 | N11: =IFERROR(IF(A11="","",J11*L11)," ") -> 24 | O11: =IFERROR(M11*N11," ") -> 3820.8 | P11: =IFERROR(IF(A11="","",O11-S11)," ") | Q11: =IFERROR(IF(A11="","",P11/O11)," ") | R11: =IFERROR(IF(A11="","",(IF(Q11<0,"Negative",IF(Q11=0,"Same",IF(Q11>0.3,"30+%",IF(Q11>0.2,"20-30%",IF(Q11>0.1,"10-20%",IF(Q11<=0.1,"0-10%"))))))))," ") -> 30+% | S11: =IFERROR(IF(A11="","",T11*N11)," ") | T11: =IFERROR(IF(A11="","",X11/AB11)," ") | U11: 0 | V11: O | X11: 0 | Z11: 0 | AJ11: No Match
A12: 91 | B12: 215 | F12: CAPE NCK FR 4 INTERACTIVE SFTY PUREFLO | G12: AIRGAS | H12: IS6PR02475SP | I12: FALSE | J12: 1 | K12: 217.46 | L12: 14 | M12: =IFERROR(IF(A12="","",K12/J12)," ") -> 217.46 | N12: =IFERROR(IF(A12="","",J12*L12)," ") -> 14 | O12: =IFERROR(M12*N12," ") -> 3044.44 | P12: =IFERROR(IF(A12="","",O12-S12)," ") | Q12: =IFERROR(IF(A12="","",P12/O12)," ") | R12: =IFERROR(IF(A12="","",(IF(Q12<0,"Negative",IF(Q12=0,"Same",IF(Q12>0.3,"30+%",IF(Q12>0.2,"20-30%",IF(Q12>0.1,"10-20%",IF(Q12<=0.1,"0-10%"))))))))," ") -> 30+% | S12: =IFERROR(IF(A12="","",T12*N12)," ") | T12: =IFERROR(IF(A12="","",X12/AB12)," ") | U12: 0 | V12: O | X12: 0 | Z12: 0 | AJ12: No Match
A13: 93 | B13: 212 | F13: VSR ASSY HI IMPCT PUREFLO W/ ATCHMT KT | G13: AIRGAS | H13: IS6PR02050SP | I13: FALSE | J13: 1 | K13: 148.80 | L13: 20 | M13: =IFERROR(IF(A13="","",K13/J13)," ") -> 148.8 | N13: =IFERROR(IF(A13="","",J13*L13)," ") -> 20 | O13: =IFERROR(M13*N13," ") -> 2976 | P13: =IFERROR(IF(A13="","",O13-S13)," ") | Q13: =IFERROR(IF(A13="","",P13/O13)," ") | R13: =IFERROR(IF(A13="","",(IF(Q13<0,"Negative",IF(Q13=0,"Same",IF(Q13>0.3,"30+%",IF(Q13>0.2,"20-30%",IF(Q13>0.1,"10-20%",IF(Q13<=0.1,"0-10%"))))))))," ") -> 30+% | S13: =IFERROR(IF(A13="","",T13*N13)," ") | T13: =IFERROR(IF(A13="","",X13/AB13)," ") | U13: 0 | V13: O | X13: 0 | Z13: 0 | AJ13: No Match
... A29: 241 | B29: 211 | F29: VSR ASSY HI IMPCT PUREFLO W/ ATCHMT KT | G29: AIRGAS | H29: IS6PR02050SP | I29: FALSE | J29: 1 | K29: 653.75 | L29: 1 | M29: =IFERROR(IF(A29="","",K29/J29)," ") -> 653.75 | N29: =IFERROR(IF(A29="","",J29*L29)," ") -> 1 | O29: =IFERROR(M29*N29," ") -> 653.75 | P29: =IFERROR(IF(A29="","",O29-S29)," ") | Q29: =IFERROR(IF(A29="","",P29/O29)," ") | R29: =IFERROR(IF(A29="","",(IF(Q29<0,"Negative",IF(Q29=0,"Same",IF(Q29>0.3,"30+%",IF(Q29>0.2,"20-30%",IF(Q29>0.1,"10-20%",IF(Q29<=0.1,"0-10%"))))))))," ") -> 30+% | S29: =IFERROR(IF(A29="","",T29*N29)," ") | T29: =IFERROR(IF(A29="","",X29/AB29)," ") | U29: 0 | V29: DUP | X29: 0 | Z29: 0 | AJ29: No Match
A30: 2 | B30: 515 | F30: FLTR HI EFNC (HE) PX5 | G30: AIRGAS | H30: RPB03-892 | I30: FALSE | J30: 1 | K30: 54.75 | L30: 1010 | M30: =IFERROR(IF(A30="","",K30/J30)," ") -> 54.75 | N30: =IFERROR(IF(A30="","",J30*L30)," ") -> 1010 | O30: =IFERROR(M30*N30," ") -> 55297.5 | P30: =IFERROR(IF(A30="","",O30-S30)," ") -> -14867.2 | Q30: =IFERROR(IF(A30="","",P30/O30)," ") -> -0.26885845 | R30: =IFERROR(IF(A30="","",(IF(Q30<0,"Negative",IF(Q30=0,"Same",IF(Q30>0.3,"30+%",IF(Q30>0.2,"20-30%",IF(Q30>0.1,"10-20%",IF(Q30<=0.1,"0-10%"))))))))," ") -> Negative | S30: =IFERROR(IF(A30="","",T30*N30)," ") -> 70164.7 | T30: =IFERROR(IF(A30="","",X30/AB30)," ") -> 69.47 | U30: 61CX03 | V30: E | X30: 69.47 | Z30: 0 | AA30: EA | AB30: 1 | AC30: RPB SAFETY | AD30: 03-892 | AE30: Hepa Filter | AF30: Safety | AG30: Powered Air-Purifying Respirators | AH30: Respiratory | AJ30: UOM Issue
A31: 3 | B31: 216 | F31: HRDHT BLK NCK CAPE HE FLTR INT&EXT SWCH | G31: AIRGAS | H31: IS6PR05814B0A1 | I31: FALSE | J31: 1 | K31: 1758.51 | L31: 26 | M31: =IFERROR(IF(A31="","",K31/J31)," ") -> 1758.51 | N31: =IFERROR(IF(A31="","",J31*L31)," ") -> 26 | O31: =IFERROR(M31*N31," ") -> 45721.26 | P31: =IFERROR(IF(A31="","",O31-S31)," ") -> 45719.835 | Q31: =IFERROR(IF(A31="","",P31/O31)," ") -> 0.99996884 | R31: =IFERROR(IF(A31="","",(IF(Q31<0,"Negative",IF(Q31=0,"Same",IF(Q31>0.3,"30+%",IF(Q31>0.2,"20-30%",IF(Q31>0.1,"10-20%",IF(Q31<=0.1,"0-10%"))))))))," ") -> 30+% | S31: =IFERROR(IF(A31="","",T31*N31)," ") -> 1.4248 | T31: =IFERROR(IF(A31="","",X31/AB31)," ") -> 0.0548 | U31: 1TTU9 | V31: FE | X31: 5.48 | Z31: 0 | AA31: PK | AB31: 100 | AC31: CONDOR | AD31: 1TTU9 | AE31: Bouffant Cap,PP,White,21 in,PK100 | AF31: Safety | AG31: Hairnets and Bouffants | AH31: Chemical and Particulate Protective Clothing | AI31: TRUE | AJ31: UOM Issue
A32: 6 | B32: 16 | F32: FLTR PAPR HI EFNC PRTCLT ADFLO 20/CA | G32: AIRGAS | H32: 3MR15-0299-99X20 | I32: FALSE | J32: 1 | K32: 58.32 | L32: 600 | M32: =IFERROR(IF(A32="","",K32/J32)," ") -> 58.32 | N32: =IFERROR(IF(A32="","",J32*L32)," ") -> 600 | O32: =IFERROR(M32*N32," ") -> 34992 | P32: =IFERROR(IF(A32="","",O32-S32)," ") -> -8730.6 | Q32: =IFERROR(IF(A32="","",P32/O32)," ") -> -0.24950274 | R32: =IFERROR(IF(A32="","",(IF(Q32<0,"Negative",IF(Q32=0,"Same",IF(Q32>0.3,"30+%",IF(Q32>0.2,"20-30%",IF(Q32>0.1,"10-20%",IF(Q32<=0.1,"0-10%"))))))))," ") -> Negative | S32: =IFERROR(IF(A32="","",T32*N32)," ") -> 43722.6 | T32: =IFERROR(IF(A32="","",X32/AB32)," ") -> 72.871 | U32: 785WP9 | V32: E | X32: 1457.42 | Z32: 0 | AA32: PK | AB32: 20 | AC32: 3M | AD32: 15-0299- 99X20 | AE32: HE Filter,Pink,PAPR System,PK20 | AF32: Safety | AG32: Powered Air-Purifying Respirator PAPR System Components and Accessories | AH32: Respiratory | AJ32: UOM Issue
A33: 7 | B33: 33 | F33: >> PAPR SYS W/WLDG HLMT HE L-ION BAT | G33: AIRGAS | H33: 3MR37-1101-30ISW | I33: FALSE | J33: 1 | K33: 1672.63 | L33: 18 | M33: =IFERROR(IF(A33="","",K33/J33)," ") -> 1672.63 | N33: =IFERROR(IF(A33="","",J33*L33)," ") -> 18 | O33: =IFERROR(M33*N33," ") -> 30107.34 | P33: =IFERROR(IF(A33="","",O33-S33)," ") -> -21551.94 | Q33: =IFERROR(IF(A33="","",P33/O33)," ") -> -0.71583674 | R33: =IFERROR(IF(A33="","",(IF(Q33<0,"Negative",IF(Q33=0,"Same",IF(Q33>0.3,"30+%",IF(Q33>0.2,"20-30%",IF(Q33>0.1,"10-20%",IF(Q33<=0.1,"0-10%"))))))))," ") -> Negative | S33: =IFERROR(IF(A33="","",T33*N33)," ") -> 51659.28 | T33: =IFERROR(IF(A33="","",X33/AB33)," ") -> 2869.96 | U33: 446M10 | V33: E | X33: 2869.96 | Z33: 0 | AA33: EA | AB33: 1 | AC33: 3M SPEEDGLAS | AD33: 37-1101-30ISW | AE33: Welding PAPR System,Helmet,Belt-Mount | AF33: Safety | AG33: Powered Air-Purifying Respirators | AH33: Respiratory | AJ33: UOM Issue
A34: 11 | B34: 266 | F34: DSPR FOR FM ERPG PLUGSTATION 500 PAIRS | G34: AIRGAS | H34: MOL6645 | I34: FALSE | J34: 1 | K34: 69.16 | L34: 232 | M34: =IFERROR(IF(A34="","",K34/J34)," ") -> 69.16 | N34: =IFERROR(IF(A34="","",J34*L34)," ") -> 232 | O34: =IFERROR(M34*N34," ") -> 16045.12 | P34: =IFERROR(IF(A34="","",O34-S34)," ") -> -7688.48 | Q34: =IFERROR(IF(A34="","",P34/O34)," ") -> -0.47917872 | R34: =IFERROR(IF(A34="","",(IF(Q34<0,"Negative",IF(Q34=0,"Same",IF(Q34>0.3,"30+%",IF(Q34>0.2,"20-30%",IF(Q34>0.1,"10-20%",IF(Q34<=0.1,"0-10%"))))))))," ") -> Negative | S34: =IFERROR(IF(A34="","",T34*N34)," ") -> 23733.6 | T34: =IFERROR(IF(A34="","",X34/AB34)," ") -> 102.3 | U34: 2FLL1 | V34: FE | X34: 102.3 | Z34: 0 | AA34: EA | AB34: 1 | AC34: MOLDEX | AD34: 6645 | AE34: Ear Plug Dispensing System,33dB | AF34: Safety | AG34: Filled Earplug Dispensers | AH34: Hearing Protection | AI34: TRUE | AJ34: UOM Issue
A35: 12 | B35: 282 | F35: HDCP SKLGD WHT FAS-TRAC SUSP | G35: AIRGAS | H35: MSA475396 | I35: FALSE | J35: 1 | K35: 114.10 | L35: 140 | M35: =IFERROR(IF(A35="","",K35/J35)," ") -> 114.1 | N35: =IFERROR(IF(A35="","",J35*L35)," ") -> 140 | O35: =IFERROR(M35*N35," ") -> 15974 | P35: =IFERROR(IF(A35="","",O35-S35)," ") -> -11264.4 | Q35: =IFERROR(IF(A35="","",P35/O35)," ") -> -0.7051709 | R35: =IFERROR(IF(A35="","",(IF(Q35<0,"Negative",IF(Q35=0,"Same",IF(Q35>0.3,"30+%",IF(Q35>0.2,"20-30%",IF(Q35>0.1,"10-20%",IF(Q35<=0.1,"0-10%"))))))))," ") -> Negative | S35: =IFERROR(IF(A35="","",T35*N35)," ") -> 27238.4 | T35: =IFERROR(IF(A35="","",X35/AB35)," ") -> 194.56 | U35: 4MD41 | V35: FE | X35: 194.56 | Z35: 0 | AA35: EA | AB35: 1 | AC35: MSA | AD35: 475396 | AE35: Hard Hat,Type 1, Class G,Ratchet,White | AF35: Safety | AG35: Hard Hats | AH35: Head Protection | AJ35: UOM Issue
A36: 13 | B36: 321 | F36: GLV 18.5" XL ALUMZD LTHR PLM PTCH CTTN | G36: AIRGAS | H36: N33DJXG705185XL | I36: FALSE | J36: 1 | K36: 80.73 | L36: 192 | M36: =IFERROR(IF(A36="","",K36/J36)," ") -> 80.73 | N36: =IFERROR(IF(A36="","",J36*L36)," ") -> 192 | O36: =IFERROR(M36*N36," ") -> 15500.16 | P36: =IFERROR(IF(A36="","",O36-S36)," ") -> -13242.24 | Q36: =IFERROR(IF(A36="","",P36/O36)," ") -> -0.85432925 | R36: =IFERROR(IF(A36="","",(IF(Q36<0,"Negative",IF(Q36=0,"Same",IF(Q36>0.3,"30+%",IF(Q36>0.2,"20-30%",IF(Q36>0.1,"10-20%",IF(Q36<=0.1,"0-10%"))))))))," ") -> Negative | S36: =IFERROR(IF(A36="","",T36*N36)," ") -> 28742.4 | T36: =IFERROR(IF(A36="","",X36/AB36)," ") -> 149.7 | U36: 56XM45 | V36: FE | X36: 149.7 | Z36: 0 | AA36: PR | AB36: 1 | AC36: NATIONAL SAFETY APPAREL | AD36: DJXG705165XL | AE36: Aluminized Gloves,1,000F,16-1/2",PR | AF36: Safety | AG36: Aluminized Gloves | AH36: Gloves and Hand Protection | AJ36: UOM Issue
A37: 14 | B37: 51 | F37: GLS KT FM STRP CLR A/FG LENS GRN/BLK FRM | G37: AIRGAS | H37: 3MRS1201SGAF-KT | I37: FALSE | J37: 1 | K37: 14.36 | L37: 1040 | M37: =IFERROR(IF(A37="","",K37/J37)," ") -> 14.36 | N37: =IFERROR(IF(A37="","",J37*L37)," ") -> 1040 | O37: =IFERROR(M37*N37," ") -> 14934.4 | P37: =IFERROR(IF(A37="","",O37-S37)," ") -> -1019.2 | Q37: =IFERROR(IF(A37="","",P37/O37)," ") -> -0.068245125 | R37: =IFERROR(IF(A37="","",(IF(Q37<0,"Negative",IF(Q37=0,"Same",IF(Q37>0.3,"30+%",IF(Q37>0.2,"20-30%",IF(Q37>0.1,"10-20%",IF(Q37<=0.1,"0-10%"))))))))," ") -> Negative | S37: =IFERROR(IF(A37="","",T37*N37)," ") -> 15953.6 | T37: =IFERROR(IF(A37="","",X37/AB37)," ") -> 15.34 | U37: 48TK84 | V37: E | X37: 15.34 | Z37: 0 | AA37: EA | AB37: 1 | AC37: 3M | AD37: S1201SGAF-KT | AE37: SafetyGlasses,Clear,AntiFog,Blk/Grn | AF37: Safety | AG37: Safety Glasses | AH37: Eye Protection and Accessories | AI37: TRUE | AJ37: UOM Issue
