Workbook
Name ExternalData_1: 'Cust File'!#REF!

Sheet Summary
C1: Procure Analytics
C2: Benchmarking Summary - Pactiv
C3: 44641
A5: Incumbent | B5: Total Eligible Spend | C5: Benchmarked Spend | D5: Benchmarked % of Total | E5: PA Pricing | F5: Savings $ | G5: Savings | H5: Comments
A6: Various | B6: =C33-C35-C36-C43-C45-C47 -> 16604.96 | C6: =SUM('Item Detail'!V:V) -> 11142.6 | D6: =C6/B6 -> 0.67104046 | E6: =SUM('Item Detail'!AC:AC) -> 8329.5322 | F6: =C6-E6 -> 2813.0678 | G6: =SUM(1-(E6/C6)) -> 0.25246063 | H6: Like-to-like SKU benchmarking
A8: No. of SKUs | B8: Negative | C8: Same | D8: 0-10% | E8: 10-20% | F8: 20-30% | G8: 30+% | H8: Total | I8: Wtd. Avg.
A9: Total SKUs | B9: =COUNTIF('Item Detail'!$Z:$Z,"Negative") -> 28 | C9: =COUNTIF('Item Detail'!$Z:$Z,"Same") -> 0 | D9: =COUNTIF('Item Detail'!$Z:$Z,"0-10%") -> 3 | E9: =COUNTIF('Item Detail'!$Z:$Z,"10-20%") -> 3 | F9: =COUNTIF('Item Detail'!$Z:$Z,"20-30%") -> 4 | G9: =COUNTIF('Item Detail'!$Z:$Z,"30+%") -> 28 | H9: =SUM(B9:G9) -> 66 | I9: =G6 -> 0.25246063
A11: $ Spend | B11: Negative | C11: Same | D11: 0-10% | E11: 10-20% | F11: 20-30% | G11: 30+% | H11: Total
A12: =A6 -> Various | B12: =SUMIF('Item Detail'!$Z:$Z,"Negative",'Item Detail'!$V:$V) -> 3945.06 | C12: =SUMIF('Item Detail'!$Z:$Z,"Same",'Item Detail'!$V:$V) -> 0 | D12: =SUMIF('Item Detail'!$Z:$Z,"0-10%",'Item Detail'!$V:$V) -> 115.47 | E12: =SUMIF('Item Detail'!$Z:$Z,"10-20%",'Item Detail'!$V:$V) -> 1408.89 | F12: =SUMIF('Item Detail'!$Z:$Z,"20-30%",'Item Detail'!$V:$V) -> 213.88 | G12: =SUMIF('Item Detail'!$Z:$Z,"30+%",'Item Detail'!$V:$V) -> 5459.3 | H12: =SUM(B12:G12) -> 11142.6
A13: Graybar-PA | B13: =SUMIF('Item Detail'!$Z:$Z,"Negative",'Item Detail'!$AC:$AC) -> 5156.2988 | C13: =SUMIF('Item Detail'!$Z:$Z,"Same",'Item Detail'!$AC:$AC) -> 0 | D13: =SUMIF('Item Detail'!$Z:$Z,"0-10%",'Item Detail'!$AC:$AC) -> 105.0106 | E13: =SUMIF('Item Detail'!$Z:$Z,"10-20%",'Item Detail'!$AC:$AC) -> 1255.4049 | F13: =SUMIF('Item Detail'!$Z:$Z,"20-30%",'Item Detail'!$AC:$AC) -> 165.9089 | G13: =SUMIF('Item Detail'!$Z:$Z,"30+%",'Item Detail'!$AC:$AC) -> 1646.909 | H13: =SUM(B13:G13) -> 8329.5322
A14: SKU Level Savings | B14: =B12-B13 -> -1211.2388 | C14: =C12-C13 -> 0 | D14: =D12-D13 -> 10.4594 | E14: =E12-E13 -> 153.4851 | F14: =F12-F13 -> 47.971102 | G14: =G12-G13 -> 3812.391 | H14: =H12-H13 -> 2813.0678
A16: Core Item Breakdown | B16: SKUs | C16: % | D16: $ | E16: PA $ | F16: Savings % | G16: Savings $
A17: Core Skus | B17: =COUNTIF('Item Detail'!AR:AR,"core") -> 15 | C17: =B17/H9 -> 0.22727273 | D17: =SUMIF('Item Detail'!$AR:$AR,"core",'Item Detail'!$V:$V) -> 1562.75 | E17: =SUMIF('Item Detail'!$AR:$AR,"core",'Item Detail'!$AC:$AC) -> 1396.9422 | F17: =1-E17/D17 -> 0.10610004 | G17: =D17-E17 -> 165.80784
A18: Non-Core Skus | B18: =H9-B17 -> 51 | C18: =B18/H9 -> 0.77272727 | D18: =SUMIF('Item Detail'!$AR:$AR,"",'Item Detail'!$V:$V) -> 9579.85 | E18: =SUMIF('Item Detail'!$AR:$AR,"",'Item Detail'!$AC:$AC) -> 6932.5901 | F18: =1-E18/D18 -> 0.27633626 | G18: =D18-E18 -> 2647.2599
A19: Total | B19: =SUM(B17:B18) -> 66 | C19: =SUM(C17:C18) -> 1 | D19: =SUM(D17:D18) -> 11142.6 | E19: =SUM(E17:E18) -> 8329.5322 | F19: =1-E19/D19 -> 0.25246063 | G19: =SUM(G17:G18) -> 2813.0678
A21: SKUs Submitted for Conditional CSP | B21: 0
A23: (1) Total eligible spend is the full data provided by the customer
A24: (2) Benchmarked active Redbook SKUs
A25: (3) Savings do not reflect A) volume and manufacturer rebates, B) future CSPL adds, C) freight savings
A26: (4) Benchmark pricing valid for 60 days
A28: File Summary
B29: # SKU | C29: Spend $
A30: Total Provided | B30: =COUNT('Cust File'!$A:$A) -> 295 | C30: ='Cust File'!U1 -> 117597.23
A32: As per customer file
A33: SKU's meeting threshold | B33: =COUNTA('Item Detail'!$A:$A)-1+COUNTA(Excluded!$A:$A)-1 -> 295 | C33: =SUM('Item Detail'!V:V)+SUM(Excluded!U:U) -> 117597.23
A34: Excluded from benchmark analysis (code):
A35: Spend Not Associated with Graybar (NOT) | B35: =COUNTIF(Excluded!$V:$V,"NOT") -> 197 | C35: =SUMIF(Excluded!$V:$V,"NOT",Excluded!$U:$U) -> 91456.72
A36: OEM Material (OEM) | B36: =COUNTIF(Excluded!$V:$V,"OEM") -> 0 | C36: =SUMIF(Excluded!$V:$V,"OEM",Excluded!$U:$U) -> 0
A37: Need more information (CID) | B37: =COUNTIF(Excluded!$V:$V,"CID") -> 7 | C37: =SUMIF(Excluded!$V:$V,"CID",Excluded!$U:$U) -> 4037.71
A38: Items with zero spend (ZERO) | B38: =COUNTIF(Excluded!$V:$V,"ZERO") -> 0 | C38: =SUMIF(Excluded!$V:$V,"ZERO",Excluded!$U:$U) -> 0
A39: UOM issues (UOM) | B39: =COUNTIF(Excluded!$V:$V,"UOM") -> 0 | C39: =SUMIF(Excluded!$V:$V,"UOM",Excluded!$U:$U) -> 0
A40: Graybar potential sourcing (SOU) | B40: =COUNTIF(Excluded!$V:$V,"SOU") -> 0 | C40: =SUMIF(Excluded!$V:$V,"SOU",Excluded!$U:$U) -> 0
A41: Graybar active sourcing (FIND) | B41: =COUNTIF(Excluded!$V:$V,"FIND") -> 9 | C41: =SUMIF(Excluded!$V:$V,"FIND",Excluded!$U:$U) -> 1348.32
A42: Obsolete (OBS) | B42: =COUNTIF(Excluded!$V:$V,"OBS") -> 1 | C42: =SUMIF(Excluded!$V:$V,"OBS",Excluded!$U:$U) -> 76.33
A43: Capital Expenditure (CAPX) | B43: =COUNTIF(Excluded!$V:$V,"CAPX") -> 0 | C43: =SUMIF(Excluded!$V:$V,"CAPX",Excluded!$U:$U) -> 0
A44: Outliers (OUT) | B44: =COUNTIF(Excluded!$V:$V,"OUT") -> 0 | C44: =SUMIF(Excluded!$V:$V,"OUT",Excluded!$U:$U) -> 0
A45: No Bid - Allen Bradley (ANB) | B45: =COUNTIF(Excluded!$V:$V,"ANB") -> 13 | C45: =SUMIF(Excluded!$V:$V,"ANB",Excluded!$U:$U) -> 8768.48
A46: Tail Spend (TAIL) | B46: =COUNTIF(Excluded!$V:$V,"TAIL") -> 0 | C46: =SUMIF(Excluded!$V:$V,"TAIL",Excluded!$U:$U) -> 0
A47: No Material (NM) | B47: =COUNTIF(Excluded!$V:$V,"NM") -> 2 | C47: =SUMIF(Excluded!$V:$V,"NM",Excluded!$U:$U) -> 767.07
A48: Total Excluded (Excluded Tab) | B48: =SUM(B35:B47) -> 229 | C48: =SUM(C35:C47) -> 106454.63
...

Sheet Item Detail
A1: GLINE | B1: Project Name | C1: Sequence Number | D1: Location | E1: Customer Internal Part Number | F1: Transaction Date | G1: Distributor Name | H1: Distributor Part Number | I1: Item Description | J1: Manufacturer | K1: Manufacturer Part Number | L1: Other Notes 1 | M1: Other Notes 2 | N1: Other Notes 3 | O1: UOM | P1: UOM Qty | Q1: Qty | R1: Pack Price | S1: Unit price | T1: Total baseline units | U1: Extended Price Calculated | V1: Extended Price Provided | W1: true / false calculated to provided | X1: Savings $ | Y1: Savings % | Z1: Savings cat. | AA1: Act price | AB1: Act price per | AC1: Graybar extended price | AD1: Graybar unit price | AE1: Code | AF1: Xref Notes | AG1: NOTE | AH1: Graybar unit of measure | AI1: Graybar unit/pack | AJ1: Graybar item # | AK1: Manufacturer name | AL1: Mfr Prefix | AM1: Manufacturer number | AN1: Description1 | AO1: Product segment | AP1: Product family | AQ1: Pricing Structure | AR1: Core Item | AS1: Note 1: It is the customer’s responsibility to confirm form, fit and function prior to ordering. Graybar makes no guarantee the material will fit the customer’s application.
A2: 16 | B2: Pactiv_Multiple Suppliers Specialty PA | C2: 278 | F2: 44560 | G2: ELLIOTT ELECTRIC SUPPLY | I2: CONNECTOR,ELLIOTTELE,AH5369,CONN 20A 125 | J2: ELLIOTTELECTICAL | K2: AH5369 | L2: Hardware - 550440990 | O2: EA | P2: 1 | Q2: 10 | R2: 158.04 | S2: =R2/P2 -> 158.04 | T2: =Q2*P2 -> 10 | U2: =T2*S2 -> 1580.4 | V2: 1580.4 | W2: =V2=U2 -> TRUE | X2: =V2-AC2 -> 1396.9388 | Y2: =X2/V2 -> 0.88391469 | Z2: =IF(Y2<0,"Negative",IF(Y2=0,"Same",IF(Y2>0.3,"30+%",IF(Y2>0.2,"20-30%",IF(Y2>0.1,"10-20%",IF(Y2<=0.1,"0-10%")))))) -> 30+% | AA2: 18.346122 | AB2: 1 | AC2: =AA2/AB2*T2 -> 183.46122 | AD2: =AA2/AB2 -> 18.346122 | AE2: F | AH2: EA | AI2: 1 | AJ2: 95005496 | AK2: HUBBELL WIRING DEVICES | AL2: HBLPE | AM2: HBL5369C | AN2: CONN 20A 125V 5-20R B/W | AO2: BOXES, ENCLOSURES, F | AP2: STRAIGHT BLADE PLUGS AND CONNECTORS | AQ2: SCHEDULE OF DISCOUNTS
A3: 25 | B3: Pactiv_Multiple Suppliers Specialty PA | C3: 387 | F3: 44539 | G3: ELLIOTT ELECTRIC SUPPLY | I3: MISC,ELLIOTTELE,LT114,1 1-4METL/TNONUL50 | J3: ELLIOTTELECTICAL | K3: LT114 | L3: Hardware - 550440990 | O3: EA | P3: 20 | Q3: 20 | R3: 60.93 | S3: =R3/P3 -> 3.0465 | T3: =Q3*P3 -> 400 | U3: =T3*S3 -> 1218.6 | V3: 1218.6 | W3: =V3=U3 -> TRUE | X3: =V3-AC3 -> 127.2 | Y3: =X3/V3 -> 0.10438208 | Z3: =IF(Y3<0,"Negative",IF(Y3=0,"Same",IF(Y3>0.3,"30+%",IF(Y3>0.2,"20-30%",IF(Y3>0.1,"10-20%",IF(Y3<=0.1,"0-10%")))))) -> 10-20% | AA3: 272.85 | AB3: 100 | AC3: =AA3/AB3*T3 -> 1091.4 | AD3: =AA3/AB3 -> 2.7285 | AE3: E | AG3: ERROR IN UOM | AH3: EA | AI3: 1 | AJ3: 25183386 | AK3: GENERIC VENDOR-TUBPA | AL3: TUBPA | AM3: LT 1-1/4 GRY CUT REEL | AN3: NON-UL LIQUID TIGHT CONDUIT | AO3: CONDUIT & CHANNEL | AP3: METALLIC LIQUID TIGHT RACEWAY | AQ3: COMMODITY
A4: 31 | B4: Pactiv_Multiple Suppliers Specialty PA | C4: 485 | F4: 44560 | G4: ELLIOTT ELECTRIC SUPPLY | I4: MISC,ELLIOTTELE,CR20W,RECEP DUP 20 A 125 | J4: ELLIOTTELECTICAL | K4: CR20W | L4: Hardware - 550440990 | O4: EA | P4: 1 | Q4: 20 | R4: 49.46 | S4: =R4/P4 -> 49.46 | T4: =Q4*P4 -> 20 | U4: =T4*S4 -> 989.2 | V4: 989.2 | W4: =V4=U4 -> TRUE | X4: =V4-AC4 -> 964.22041 | Y4: =X4/V4 -> 0.97474768 | Z4: =IF(Y4<0,"Negative",IF(Y4=0,"Same",IF(Y4>0.3,"30+%",IF(Y4>0.2,"20-30%",IF(Y4>0.1,"10-20%",IF(Y4<=0.1,"0-10%")))))) -> 30+% | AA4: 1.2489796 | AB4: 1 | AC4: =AA4/AB4*T4 -> 24.979592 | AD4: =AA4/AB4 -> 1.2489796 | AE4: E | AH4: EA | AI4: 1 | AJ4: 90004681 | AK4: LEVITON MANUFACTURING COMPANY, INC | AL4: LEVPE | AM4: CR20-W | AN4: WHT DPLX RCPT-NEMA5-20R | AO4: BOXES, ENCLOSURES, F | AP4: ELECTRICAL RECEPTACLES - INCLUDES USB | AQ4: SCHEDULE OF DISCOUNTS
A5: 52 | B5: Pactiv_Multiple Suppliers Specialty PA | C5: 825 | F5: 44431 | G5: BORDER STATES INDUSTRIES INC | I5: MISC,BORDER STA,158215,SQD-9001KA1 N/O N | J5: BORDER STATES | K5: 158215 | L5: Other Repair Parts - 550990999 | O5: EA | P5: 1 | Q5: 12 | R5: 45.32 | S5: =R5/P5 -> 45.32 | T5: =Q5*P5 -> 12 | U5: =T5*S5 -> 543.84 | V5: 543.84 | W5: =V5=U5 -> TRUE | X5: =V5-AC5 -> 195.95755 | Y5: =X5/V5 -> 0.36032206 | Z5: =IF(Y5<0,"Negative",IF(Y5=0,"Same",IF(Y5>0.3,"30+%",IF(Y5>0.2,"20-30%",IF(Y5>0.1,"10-20%",IF(Y5<=0.1,"0-10%")))))) -> 30+% | AA5: 28.990204 | AB5: 1 | AC5: =AA5/AB5*T5 -> 347.88245 | AD5: =AA5/AB5 -> 28.990204 | AE5: E | AH5: EA | AI5: 1 | AJ5: 88247319 | AK5: SCHNEIDER ELECTRIC USA INC | AL5: SQDPA | AM5: 9001KA1 | AN5: 30MM CONTACT BLOCK 1N/O 1N/C | AO5: AUTOMATION CONTROL | AP5: PUSH BUTTONS, PILOT LIGHTS & SELECTOR SWITCHES | AQ5: SCHEDULE OF DISCOUNTS
A6: 67 | B6: Pactiv_Multiple Suppliers Specialty PA | C6: 1010 | F6: 44530 | G6: ALLIED ELECTRONICS INC | I6: SENSOR,P & F,#NBB5-18GM60-WO,PROXI. N/C | J6: HONEYWELL | K6: 973AA3XMB7TL | L6: Instrumentation - 550480990 | O6: EA | P6: 1 | Q6: 3 | R6: 137.98 | S6: =R6/P6 -> 137.98 | T6: =Q6*P6 -> 3 | U6: =T6*S6 -> 413.94 | V6: 413.94 | W6: =V6=U6 -> TRUE | X6: =V6-AC6 -> -59.006939 | Y6: =X6/V6 -> -0.1425495 | Z6: =IF(Y6<0,"Negative",IF(Y6=0,"Same",IF(Y6>0.3,"30+%",IF(Y6>0.2,"20-30%",IF(Y6>0.1,"10-20%",IF(Y6<=0.1,"0-10%")))))) -> Negative | AA6: 157.64898 | AB6: 1 | AC6: =AA6/AB6*T6 -> 472.94694 | AD6: =AA6/AB6 -> 157.64898 | AE6: F | AH6: EA | AI6: 1 | AJ6: NOF | AK6: PEPPREL & FUCHS | AL6: PPFPE | AM6: NBB5-18GM60-WO | AO6: AUTOMATION CONTROL | AQ6: COMMODITY
A7: 75 | B7: Pactiv_Multiple Suppliers Specialty PA | C7: 1143 | F7: 44298 | G7: WESCO DISTRIBUTION INC | I7: RECEPTACLE,HUBBELL,#HBL45105,F/ IRWIN BL | J7: HUBBELL | K7: HBL45105 | L7: Other Repair Parts - 550990999 | O7: EA | P7: 1 | Q7: 4 | R7: 89.96 | S7: =R7/P7 -> 89.96 | T7: =Q7*P7 -> 4 | U7: =T7*S7 -> 359.84 | V7: 359.84 | W7: =V7=U7 -> TRUE | X7: =V7-AC7 -> -245.22122 | Y7: =X7/V7 -> -0.68147294 | Z7: =IF(Y7<0,"Negative",IF(Y7=0,"Same",IF(Y7>0.3,"30+%",IF(Y7>0.2,"20-30%",IF(Y7>0.1,"10-20%",IF(Y7<=0.1,"0-10%")))))) -> Negative | AA7: 151.26531 | AB7: 1 | AC7: =AA7/AB7*T7 -> 605.06122 | AD7: =AA7/AB7 -> 151.26531 | AE7: E | AH7: EA | AI7: 1 | AJ7: 88126853 | AK7: HUBBELL WIRING DEVICES | AL7: HBLPE | AM7: HBL45105 | AN7: LKG RCPT VARILOAD 4P5W 30A 600V | AO7: BOXES, ENCLOSURES, F | AP7: ALL TURN LOCKING DEVICES | AQ7: SCHEDULE OF DISCOUNTS
A8: 88 | B8: Pactiv_Multiple Suppliers Specialty PA | C8: 1280 | F8: 44419 | G8: BORDER STATES INDUSTRIES INC | I8: MISC,BORDER STA,115262,50-UNPRINTED-2X 1 | J8: BORDER STATES | K8: 115262 | L8: Other Repair Parts - 550990999 | O8: EA | P8: 1 | Q8: 10 | R8: 30.85 | S8: =R8/P8 -> 30.85 | T8: =Q8*P8 -> 10 | U8: =T8*S8 -> 308.5 | V8: 308.5 | W8: =V8=U8 -> TRUE | X8: =V8-AC8 -> 93.953061 | Y8: =X8/V8 -> 0.30454801 | Z8: =IF(Y8<0,"Negative",IF(Y8=0,"Same",IF(Y8>0.3,"30+%",IF(Y8>0.2,"20-30%",IF(Y8>0.1,"10-20%",IF(Y8<=0.1,"0-10%")))))) -> 30+% | AA8: 21.454694 | AB8: 1 | AC8: =AA8/AB8*T8 -> 214.54694 | AD8: =AA8/AB8 -> 21.454694 | AE8: E | AH8: EA | AI8: 1 | AJ8: 88319020 | AK8: 3M CO. - ELECTRICAL MARKETS DIV. | AL8: MMMPE | AM8: 50-UNPRINTED-2X100FT | AN8: CORROSION PROTECTION TAPE | AO8: MRO | AP8: INSULATING MATERIAL, FIRE-STOP, TAPE & HEAT SHRINK | AQ8: SCHEDULE OF DISCOUNTS
A9: 91 | B9: Pactiv_Multiple Suppliers Specialty PA | C9: 1302 | F9: 44223 | G9: WESCO DISTRIBUTION INC | I9: LOCKOUT,HOFFMAN,#ASL6C,SAFETY W/CHA | J9: HOFFMAN | K9: ASL6C | L9: Other Repair Parts - 550990999 | O9: EA | P9: 1 | Q9: 16 | R9: 18.89 | S9: =R9/P9 -> 18.89 | T9: =Q9*P9 -> 16 | U9: =T9*S9 -> 302.24 | V9: 302.24 | W9: =V9=U9 -> TRUE | X9: =V9-AC9 -> -32.153469 | Y9: =X9/V9 -> -0.1063839 | Z9: =IF(Y9<0,"Negative",IF(Y9=0,"Same",IF(Y9>0.3,"30+%",IF(Y9>0.2,"20-30%",IF(Y9>0.1,"10-20%",IF(Y9<=0.1,"0-10%")))))) -> Negative | AA9: 20.899592 | AB9: 1 | AC9: =AA9/AB9*T9 -> 334.39347 | AD9: =AA9/AB9 -> 20.899592 | AE9: E | AH9: EA | AI9: 1 | AJ9: 88132577 | AK9: HOFFMAN ENCLOSURES, INC | AL9: HOFPA | AM9: ASL6C | AN9: SAFETY LOCKOUT CHAIN | AO9: BOXES, ENCLOSURES, F | AP9: ENCLOSURE ACCESSORIES | AQ9: SCHEDULE OF DISCOUNTS
A10: 99 | B10: Pactiv_Multiple Suppliers Specialty PA | C10: 1414 | F10: 44431 | G10: BORDER STATES INDUSTRIES INC | I10: MISC,BORDER STA,158158,SQD-9001KR1U UNIV | J10: BORDER STATES | K10: 158158 | L10: Other Repair Parts - 550990999 | O10: EA | P10: 1 | Q10: 6 | R10: 43.77 | S10: =R10/P10 -> 43.77 | T10: =Q10*P10 -> 6 | U10: =T10*S10 -> 262.62 | V10: 262.62 | W10: =V10=U10 -> TRUE | X10: =V10-AC10 -> 82.08 | Y10: =X10/V10 -> 0.31254284 | Z10: =IF(Y10<0,"Negative",IF(Y10=0,"Same",IF(Y10>0.3,"30+%",IF(Y10>0.2,"20-30%",IF(Y10>0.1,"10-20%",IF(Y10<=0.1,"0-10%")))))) -> 30+% | AA10: 30.09 | AB10: 1 | AC10: =AA10/AB10*T10 -> 180.54 | AD10: =AA10/AB10 -> 30.09 | AE10: E | AH10: EA | AI10: 1 | AJ10: 88247761 | AK10: SCHNEIDER ELECTRIC USA INC | AL10: SQDPA | AM10: 9001KR1U | AN10: 30MM PUSH BUTTON FULL GUARD | AO10: AUTOMATION CONTROL | AP10: PUSH BUTTONS, PILOT LIGHTS & SELECTOR SWITCHES | AQ10: NET
A11: 106 | B11: Pactiv_Multiple Suppliers Specialty PA | C11: 1501 | F11: 44539 | G11: ELLIOTT ELECTRIC SUPPLY | I11: MISC,ELLIOTTELE,LT1,1 MET L/T NO UL 100 | J11: ELLIOTTELECTICAL | K11: LT1 | L11: Hardware - 550440990 | O11: EA | P11: 1 | Q11: 10 | R11: 23.52 | S11: =R11/P11 -> 23.52 | T11: =Q11*P11 -> 10 | U11: =T11*S11 -> 235.2 | V11: 235.2 | W11: =V11=U11 -> TRUE | X11: =V11-AC11 -> 214.04808 | Y11: =X11/V11 -> 0.91006835 | Z11: =IF(Y11<0,"Negative",IF(Y11=0,"Same",IF(Y11>0.3,"30+%",IF(Y11>0.2,"20-30%",IF(Y11>0.1,"10-20%",IF(Y11<=0.1,"0-10%")))))) -> 30+% | AA11: 211.51923 | AB11: 100 | AC11: =AA11/AB11*T11 -> 21.151923 | AD11: =AA11/AB11 -> 2.1151923 | AE11: E | AH11: EA | AI11: 1 | AJ11: 25184887 | AK11: GENERIC VENDOR-TUBPA | AL11: TUBPA | AM11: LT 1 GRY CUT REEL | AN11: NON-UL LIQUID TIGHT CONDUIT | AO11: CONDUIT & CHANNEL | AP11: METALLIC LIQUID TIGHT RACEWAY | AQ11: COMMODITY
A12: 112 | B12: Pactiv_Multiple Suppliers Specialty PA | C12: 1544 | F12: 44482 | G12: ADDISON ELECTRIC INC | I12: Fuse,LITTLE FUSE,#JLS 45, JKS-45, A4J45 | J12: LITTLE FUSE | K12: JLS45JKS45A4J45 | L12: Hardware - 550440990 | O12: EA | P12: =1/10 -> 0.1 | Q12: 10 | R12: 22.28 | S12: =R12/P12 -> 222.8 | T12: =Q12*P12 -> 1 | U12: =T12*S12 -> 222.8 | V12: 222.8 | W12: =V12=U12 -> TRUE | X12: =V12-AC12 -> -18.974694 | Y12: =X12/V12 -> -0.085164694 | Z12: =IF(Y12<0,"Negative",IF(Y12=0,"Same",IF(Y12>0.3,"30+%",IF(Y12>0.2,"20-30%",IF(Y12>0.1,"10-20%",IF(Y12<=0.1,"0-10%")))))) -> Negative | AA12: 241.77469 | AB12: 1 | AC12: =AA12/AB12*T12 -> 241.77469 | AD12: =AA12/AB12 -> 241.77469 | AE12: E | AG12: ERROR IN UOM | AH12: EA | AI12: 1 | AJ12: 88051751 | AK12: COOPER BUSSMANN INC | AL12: BUSPA | AM12: JKS-450 | AN12: LIMITRON FAST ACTING FUSE CLASS J | AO12: MRO | AP12: LOW VOLTAGE, BRANCH CIRCUIT RATED FUSES | AQ12: SCHEDULE OF DISCOUNTS
A13: 114 | B13: Pactiv_Multiple Suppliers Specialty PA | C13: 1572 | F13: 44487 | G13: BORDER STATES INDUSTRIES INC | I13: MISC,BORDER STA,786135,THM -T17 COND BDY | J13: BORDER STATES | K13: 786135 | L13: Other Repair Parts - 550990999 | O13: EA | P13: 1 | Q13: 8 | R13: 26.93 | S13: =R13/P13 -> 26.93 | T13: =Q13*P13 -> 8 | U13: =T13*S13 -> 215.44 | V13: 215.44 | W13: =V13=U13 -> TRUE | X13: =V13-AC13 -> 96.4 | Y13: =X13/V13 -> 0.44745637 | Z13: =IF(Y13<0,"Negative",IF(Y13=0,"Same",IF(Y13>0.3,"30+%",IF(Y13>0.2,"20-30%",IF(Y13>0.1,"10-20%",IF(Y13<=0.1,"0-10%")))))) -> 30+% | AA13: 14.88 | AB13: 1 | AC13: =AA13/AB13*T13 -> 119.04 | AD13: =AA13/AB13 -> 14.88 | AE13: F | AH13: EA | AI13: 1 | AJ13: 88074765 | AK13: COOPER CROUSE-HINDS DIVISION | AL13: CRHPE | AM13: T17 | AN13: 1/2 T FORM 7 CNDT OUTLETBODY THRD RIGID | AO13: BOXES, ENCLOSURES, F | AP13: CONDUIT BODIES | AQ13: SCHEDULE OF DISCOUNTS | AR13: CORE
A14: 117 | B14: Pactiv_Multiple Suppliers Specialty PA | C14: 1595 | F14: 44495 | G14: AUTOMATIONDIRECT.COM INC | I14: PUSHBUTTON,AUTOMATION,#GCX1226-24L,22mm | J14: AUTOMATION | K14: GCX1226-24L | L14: Other Repair Parts - 550990999 | O14: EA | P14: =1/10 -> 0.1 | Q14: 10 | R14: 21.13 | S14: =R14/P14 -> 211.3 | T14: =Q14*P14 -> 1 | U14: =T14*S14 -> 211.3 | V14: 211.3 | W14: =V14=U14 -> TRUE | X14: =V14-AC14 -> 155.36667 | Y14: =X14/V14 -> 0.73528948 | Z14: =IF(Y14<0,"Negative",IF(Y14=0,"Same",IF(Y14>0.3,"30+%",IF(Y14>0.2,"20-30%",IF(Y14>0.1,"10-20%",IF(Y14<=0.1,"0-10%")))))) -> 30+% | AA14: 55.933333 | AB14: 1 | AC14: =AA14/AB14*T14 -> 55.933333 | AD14: =AA14/AB14 -> 55.933333 | AE14: DM | AG14: ERROR IN UOM | AH14: EA | AI14: 1 | AJ14: 99509354 | AK14: SCHNEIDER ELECTRIC USA INC | AL14: SQDPA | AM14: XB4BW34B5 | AN14: PUSHBUTTON LED 24V 22MM XB4 +OPTIONS | AO14: AUTOMATION CONTROL | AP14: PUSH BUTTONS, PILOT LIGHTS & SELECTOR SWITCHES | AQ14: SCHEDULE OF DISCOUNTS
A15: 120 | B15: Pactiv_Multiple Suppliers Specialty PA | C15: 1603 | F15: 44553 | G15: MIDCO ELECTRIC SUPPLY | I15: HARDWARE,HAMMOND IND,#1414PHE ,NEMA 12 H | J15: HAMMOND IND | K15: 1414PHE | L15: Hardware - 550440990 | O15: EA | P15: 1 | Q15: 4 | R15: 51.94 | S15: =R15/P15 -> 51.94 | T15: =Q15*P15 -> 4 | U15: =T15*S15 -> 207.76 | V15: 207.76 | W15: =V15=U15 -> TRUE | X15: =V15-AC15 -> -22.12 | Y15: =X15/V15 -> -0.106469 | Z15: =IF(Y15<0,"Negative",IF(Y15=0,"Same",IF(Y15>0.3,"30+%",IF(Y15>0.2,"20-30%",IF(Y15>0.1,"10-20%",IF(Y15<=0.1,"0-10%")))))) -> Negative | AA15: 57.47 | AB15: 1 | AC15: =AA15/AB15*T15 -> 229.88 | AD15: =AA15/AB15 -> 57.47 | AE15: F | AH15: EA | AI15: 1 | AJ15: 88131961 | AK15: HOFFMAN ENCLOSURES, INC | AL15: HOFPA | AM15: A606CH | AN15: J BOX TYPE 12 HINGED COVER | AO15: BOXES, ENCLOSURES, F | AQ15: NET
A16: 128 | B16: Pactiv_Multiple Suppliers Specialty PA | C16: 1663 | F16: 44545 | G16: MCMASTER CARR SUPPLY CO | I16: MISC,MCMASTER-C,3147T4,CURVED STRUT CHAN | J16: MCMASTER-CARR | K16: 3147T4 | L16: Hardware - 550440990 | O16: EA | P16: 10 | Q16: 1 | R16: 188.88 | S16: =R16/P16 -> 18.888 | T16: =Q16*P16 -> 10 | U16: =T16*S16 -> 188.88 | V16: 188.88 | W16: =V16=U16 -> TRUE | X16: =V16-AC16 -> 94.974776 | Y16: =X16/V16 -> 0.5028313 | Z16: =IF(Y16<0,"Negative",IF(Y16=0,"Same",IF(Y16>0.3,"30+%",IF(Y16>0.2,"20-30%",IF(Y16>0.1,"10-20%",IF(Y16<=0.1,"0-10%")))))) -> 30+% | AA16: 939.05224 | AB16: 100 | AC16: =AA16/AB16*T16 -> 93.905224 | AD16: =AA16/AB16 -> 9.3905224 | AE16: DM | AG16: ERROR IN UOM | AH16: EA | AI16: 1 | AJ16: 88035486 | AK16: COOPER B-LINE SYSTEMS | AL16: BLNPA | AM16: B22SH-120GLV | AN16: CHNL 1-5/8X1-5/8 9/16X1-1/8 SL HL 12GA | AO16: CONDUIT & CHANNEL | AP16: CHANNEL/STRUT | AQ16: COMMODITY | AR16: CORE
A17: 130 | B17: Pactiv_Multiple Suppliers Specialty PA | C17: 1667 | F17: 44505 | G17: REXEL USA INC | I17: BODY,HUBBELL,#HBL25414B,600VAC,30A,5-WIR | J17: HUBBELL | K17: 25414B | L17: Other Repair Parts - 550990999 | O17: EA | P17: 1 | Q17: 1 | R17: 188.16 | S17: =R17/P17 -> 188.16 | T17: =Q17*P17 -> 1 | U17: =T17*S17 -> 188.16 | V17: 188.16 | W17: =V17=U17 -> TRUE | X17: =V17-AC17 -> -125.47265 | Y17: =X17/V17 -> -0.66684021 | Z17: =IF(Y17<0,"Negative",IF(Y17=0,"Same",IF(Y17>0.3,"30+%",IF(Y17>0.2,"20-30%",IF(Y17>0.1,"10-20%",IF(Y17<=0.1,"0-10%")))))) -> Negative | AA17: 313.63265 | AB17: 1 | AC17: =AA17/AB17*T17 -> 313.63265 | AD17: =AA17/AB17 -> 313.63265 | AE17: E | AH17: EA | AI17: 1 | AJ17: 88126379 | AK17: HUBBELL WIRING DEVICES | AL17: HBLPE | AM17: HBL25414B | AN17: H/LOCK CONN 4P5W 30A 600V | AO17: BOXES, ENCLOSURES, F | AP17: ALL TURN LOCKING DEVICES | AQ17: SCHEDULE OF DISCOUNTS
A18: 134 | B18: Pactiv_Multiple Suppliers Specialty PA | C18: 1707 | F18: 44413 | G18: WESCO DISTRIBUTION INC | I18: HORN,FEDERAL SIGNAL,#350,VIBRATION HORN | J18: FEDERAL SIGNAL | K18: 350 | L18: Other Repair Parts - 550990999 | O18: EA | P18: 1 | Q18: 2 | R18: 89.13 | S18: =R18/P18 -> 89.13 | T18: =Q18*P18 -> 2 | U18: =T18*S18 -> 178.26 | V18: 178.26 | W18: =V18=U18 -> TRUE | X18: =V18-AC18 -> -44.56 | Y18: =X18/V18 -> -0.24997195 | Z18: =IF(Y18<0,"Negative",IF(Y18=0,"Same",IF(Y18>0.3,"30+%",IF(Y18>0.2,"20-30%",IF(Y18>0.1,"10-20%",IF(Y18<=0.1,"0-10%")))))) -> Negative | AA18: 111.41 | AB18: 1 | AC18: =AA18/AB18*T18 -> 222.82 | AD18: =AA18/AB18 -> 111.41 | AE18: E | AH18: EA | AI18: 1 | AJ18: 88095679 | AK18: FEDERAL SIGNAL CORP | AL18: FEDPA | AM18: 350-120-30 | AN18: HORN 120VAC | AO18: MRO | AP18: SIGNAL EQUIP SECURITY & EMERGENCY LIGHTS | AQ18: NET | AR18: CORE
A19: 135 | B19: Pactiv_Multiple Suppliers Specialty PA | C19: 1711 | F19: 44495 | G19: WESCO DISTRIBUTION INC | I19: TAPE,3M,#2520 ,VARNISHED CAMBRIC TAPE W/ | J19: 3M | K19: 2520 | L19: Hardware - 550440990 | O19: EA | P19: 1 | Q19: 5 | R19: 35.55 | S19: =R19/P19 -> 35.55 | T19: =Q19*P19 -> 5 | U19: =T19*S19 -> 177.75 | V19: 177.75 | W19: =V19=U19 -> TRUE | X19: =V19-AC19 -> -1.7561224 | Y19: =X19/V19 -> -0.0098797325 | Z19: =IF(Y19<0,"Negative",IF(Y19=0,"Same",IF(Y19>0.3,"30+%",IF(Y19>0.2,"20-30%",IF(Y19>0.1,"10-20%",IF(Y19<=0.1,"0-10%")))))) -> Negative | AA19: 35.901224 | AB19: 1 | AC19: =AA19/AB19*T19 -> 179.50612 | AD19: =AA19/AB19 -> 35.901224 | AE19: E | AH19: EA | AI19: 1 | AJ19: 88175896 | AK19: 3M CO. - ELECTRICAL MARKETS DIV. | AL19: MMMPE | AM19: 2520-3/4X60FT | AN19: VARNISHED CAMBRIC TAPE 3/4 X 60 | AO19: MRO | AP19: INSULATING MATERIAL, FIRE-STOP, TAPE & HEAT SHRINK | AQ19: SCHEDULE OF DISCOUNTS | AR19: CORE
A20: 137 | B20: Pactiv_Multiple Suppliers Specialty PA | C20: 1723 | F20: 44519 | G20: WESCO DISTRIBUTION INC | I20: GRIP,KELLEMS,#074-01-021,1",CORD GRIP | J20: KELLEMS DIV | K20: 07401021 | L20: Other Repair Parts - 550990999 | O20: EA | P20: 1 | Q20: 3 | R20: 58.65 | S20: =R20/P20 -> 58.65 | T20: =Q20*P20 -> 3 | U20: =T20*S20 -> 175.95 | V20: 175.95 | W20: =V20=U20 -> TRUE | X20: =V20-AC20 -> -54.028776 | Y20: =X20/V20 -> -0.30706891 | Z20: =IF(Y20<0,"Negative",IF(Y20=0,"Same",IF(Y20>0.3,"30+%",IF(Y20>0.2,"20-30%",IF(Y20>0.1,"10-20%",IF(Y20<=0.1,"0-10%")))))) -> Negative | AA20: 76.659592 | AB20: 1 | AC20: =AA20/AB20*T20 -> 229.97878 | AD20: =AA20/AB20 -> 76.659592 | AE20: E | AH20: EA | AI20: 1 | AJ20: 88147613 | AK20: HUBBELL WIRING DEVICES | AL20: HBLPE | AM20: 07401021 | AN20: STR MALE DCG .62-.751 W/MESH | AO20: BOXES, ENCLOSURES, F | AP20: SUPPORT GRIPS | AQ20: SCHEDULE OF DISCOUNTS
A21: 138 | B21: Pactiv_Multiple Suppliers Specialty PA | C21: 1727 | F21: 44326 | G21: WESCO DISTRIBUTION INC | I21: HORN, ALARM FEDERAL SIGNAL 350-120-30 | J21: GRAINGER PARTS OPERATIONS | K21: 4A967 | L21: Other Repair Parts - 550990999 | O21: EA | P21: 1 | Q21: 2 | R21: 87.29 | S21: =R21/P21 -> 87.29 | T21: =Q21*P21 -> 2 | U21: =T21*S21 -> 174.58 | V21: 174.58 | W21: =V21=U21 -> TRUE | X21: =V21-AC21 -> -48.24 | Y21: =X21/V21 -> -0.27632031 | Z21: =IF(Y21<0,"Negative",IF(Y21=0,"Same",IF(Y21>0.3,"30+%",IF(Y21>0.2,"20-30%",IF(Y21>0.1,"10-20%",IF(Y21<=0.1,"0-10%")))))) -> Negative | AA21: 111.41 | AB21: 1 | AC21: =AA21/AB21*T21 -> 222.82 | AD21: =AA21/AB21 -> 111.41 | AE21: E | AH21: EA | AI21: 1 | AJ21: 88095679 | AK21: FEDERAL SIGNAL CORP | AL21: FEDPA | AM21: 350-120-30 | AN21: HORN 120VAC | AO21: MRO | AP21: SIGNAL EQUIP SECURITY & EMERGENCY LIGHTS | AQ21: NET | AR21: CORE
A22: 140 | B22: Pactiv_Multiple Suppliers Specialty PA | C22: 1760 | F22: 44488 | G22: WESCO DISTRIBUTION INC | I22: CONNECTOR,EGS,#ST-50 ,1/2" SEALTITE CONN | J22: EGS | K22: ST50 | L22: Hardware - 550440990 | O22: EA | P22: 1 | Q22: 25 | R22: 6.65 | S22: =R22/P22 -> 6.65 | T22: =Q22*P22 -> 25 | U22: =T22*S22 -> 166.25 | V22: 166.25 | W22: =V22=U22 -> TRUE | X22: =V22-AC22 -> -87.362245 | Y22: =X22/V22 -> -0.52548719 | Z22: =IF(Y22<0,"Negative",IF(Y22=0,"Same",IF(Y22>0.3,"30+%",IF(Y22>0.2,"20-30%",IF(Y22>0.1,"10-20%",IF(Y22<=0.1,"0-10%")))))) -> Negative | AA22: 10.14449 | AB22: 1 | AC22: =AA22/AB22*T22 -> 253.61224 | AD22: =AA22/AB22 -> 10.14449 | AE22: F | AH22: EA | AI22: 1 | AJ22: 88073425 | AK22: COOPER CROUSE-HINDS DIVISION | AL22: CRHPE | AM22: LT50 | AN22: 1/2 STR L/T CONN | AO22: BOXES, ENCLOSURES, F | AP22: LIQUIDTIGHT FITTINGS | AQ22: SCHEDULE OF DISCOUNTS
A23: 142 | B23: Pactiv_Multiple Suppliers Specialty PA | C23: 1766 | F23: 44480 | G23: WESCO DISTRIBUTION INC | I23: Fuse, BUSS #FNQ-R-30 | J23: LITTLEFUSE | K23: KLDR30FNQR30ATQR30 | L23: Hardware - 550440990 | O23: EA | P23: 1 | Q23: 20 | R23: 8.19 | S23: =R23/P23 -> 8.19 | T23: =Q23*P23 -> 20 | U23: =T23*S23 -> 163.8 | V23: 163.8 | W23: =V23=U23 -> TRUE | X23: =V23-AC23 -> -31.4 | Y23: =X23/V23 -> -0.19169719 | Z23: =IF(Y23<0,"Negative",IF(Y23=0,"Same",IF(Y23>0.3,"30+%",IF(Y23>0.2,"20-30%",IF(Y23>0.1,"10-20%",IF(Y23<=0.1,"0-10%")))))) -> Negative | AA23: 9.76 | AB23: 1 | AC23: =AA23/AB23*T23 -> 195.2 | AD23: =AA23/AB23 -> 9.76 | AE23: E | AH23: EA | AI23: 1 | AJ23: 96072685 | AK23: COOPER BUSSMANN INC | AL23: BUSPA | AM23: FNQ-R-30 | AN23: CLASS CC TIME DELAY REJECTION FUSE | AO23: MRO | AP23: LOW VOLTAGE, BRANCH CIRCUIT RATED FUSES | AQ23: NET | AR23: CORE
A24: 145 | B24: Pactiv_Multiple Suppliers Specialty PA | C24: 1790 | F24: 44344 | G24: MCNAUGHTON-MCKAY ELECTRIC CO | I24: SH606MV B6 SINGLE LOCK SYS 1XPG1 | J24: THOMAS & BETTS | K24: SH606 | L24: Other Repair Parts - 550990999 | O24: EA | P24: 1 | Q24: 4 | R24: 39.12 | S24: =R24/P24 -> 39.12 | T24: =Q24*P24 -> 4 | U24: =T24*S24 -> 156.48 | V24: 156.48 | W24: =V24=U24 -> TRUE | X24: =V24-AC24 -> -50.35102 | Y24: =X24/V24 -> -0.32177288 | Z24: =IF(Y24<0,"Negative",IF(Y24=0,"Same",IF(Y24>0.3,"30+%",IF(Y24>0.2,"20-30%",IF(Y24>0.1,"10-20%",IF(Y24<=0.1,"0-10%")))))) -> Negative | AA24: 51.707755 | AB24: 1 | AC24: =AA24/AB24*T24 -> 206.83102 | AD24: =AA24/AB24 -> 51.707755 | AE24: E | AH24: EA | AI24: 1 | AJ24: 25446911 | AK24: ABB INSTALLATION PRODUCTS INC | AL24: TBCPE | AM24: SH606MV | AN24: B6 SINGLE LOCK SYS 1XPG13 5-1/2 | AO24: BOXES, ENCLOSURES, F | AP24: MECHNAICAL/COMPRESSION LUGS/CONNECTORS | AQ24: SCHEDULE OF DISCOUNTS
A25: 151 | B25: Pactiv_Multiple Suppliers Specialty PA | C25: 1848 | F25: 44482 | G25: WESCO DISTRIBUTION INC | I25: PLUG, ELECT.,HUBBLE,HBL27710,30A 3 PHASE | J25: HUBBLE | K25: HBL27710 | L25: Other Repair Parts - 550990999 | O25: EA | P25: 1 | Q25: 3 | R25: 47.61 | S25: =R25/P25 -> 47.61 | T25: =Q25*P25 -> 3 | U25: =T25*S25 -> 142.83 | V25: 142.83 | W25: =V25=U25 -> TRUE | X25: =V25-AC25 -> -15.790408 | Y25: =X25/V25 -> -0.11055386 | Z25: =IF(Y25<0,"Negative",IF(Y25=0,"Same",IF(Y25>0.3,"30+%",IF(Y25>0.2,"20-30%",IF(Y25>0.1,"10-20%",IF(Y25<=0.1,"0-10%")))))) -> Negative | AA25: 52.873469 | AB25: 1 | AC25: =AA25/AB25*T25 -> 158.62041 | AD25: =AA25/AB25 -> 52.873469 | AE25: E | AH25: EA | AI25: 1 | AJ25: 88126535 | AK25: HUBBELL WIRING DEVICES | AL25: HBLPE | AM25: HBL2771 | AN25: LKG PLUG 30A 3PH 347/600V L20-30P B/W | AO25: BOXES, ENCLOSURES, F | AP25: ALL TURN LOCKING DEVICES | AQ25: SCHEDULE OF DISCOUNTS
A26: 154 | B26: Pactiv_Multiple Suppliers Specialty PA | C26: 1867 | F26: 44546 | G26: MCMASTER CARR SUPPLY CO | I26: ELECTRICAL,MCMASTER CARR,#33145T31,UNIST | J26: MCMASTER CARR | K26: 33145T31 | L26: Hardware - 550440990 | O26: EA | P26: =1/4 -> 0.25 | Q26: 4 | R26: 34.41 | S26: =R26/P26 -> 137.64 | T26: =Q26*P26 -> 1 | U26: =T26*S26 -> 137.64 | V26: 137.64 | W26: =V26=U26 -> TRUE | X26: =V26-AC26 -> 16.058776 | Y26: =X26/V26 -> 0.1166723 | Z26: =IF(Y26<0,"Negative",IF(Y26=0,"Same",IF(Y26>0.3,"30+%",IF(Y26>0.2,"20-30%",IF(Y26>0.1,"10-20%",IF(Y26<=0.1,"0-10%")))))) -> 10-20% | AA26: 121.58122 | AB26: 1 | AC26: =AA26/AB26*T26 -> 121.58122 | AD26: =AA26/AB26 -> 121.58122 | AE26: DM | AG26: ERROR IN UOM | AH26: EA | AI26: 1 | AJ26: 25674915 | AK26: CAL-BRITE | AL26: CBDPA | AM26: S45800PB00 | AN26: SS304 POST BASE FOR 1-5/8 CHANNEL | AO26: CONDUIT & CHANNEL | AP26: CHANNEL/STRUT FITTINGS | AQ26: COMMODITY
A27: 156 | B27: Pactiv_Multiple Suppliers Specialty PA | C27: 1882 | F27: 44405 | G27: STEINER ELECTRIC COMPANY | I27: MISC,SQD,9001BWRY,PENDANT CONTROL STATIO | J27: SQD | K27: 9001BWRY | L27: Other Repair Parts - 550990999 | O27: EA | P27: 1 | Q27: 2 | R27: 66.87 | S27: =R27/P27 -> 66.87 | T27: =Q27*P27 -> 2 | U27: =T27*S27 -> 133.74 | V27: 133.74 | W27: =V27=U27 -> TRUE | X27: =V27-AC27 -> 63.446667 | Y27: =X27/V27 -> 0.47440307 | Z27: =IF(Y27<0,"Negative",IF(Y27=0,"Same",IF(Y27>0.3,"30+%",IF(Y27>0.2,"20-30%",IF(Y27>0.1,"10-20%",IF(Y27<=0.1,"0-10%")))))) -> 30+% | AA27: 35.146667 | AB27: 1 | AC27: =AA27/AB27*T27 -> 70.293333 | AD27: =AA27/AB27 -> 35.146667 | AE27: E | AH27: EA | AI27: 1 | AJ27: 22096215 | AK27: SCHNEIDER ELECTRIC USA INC | AL27: SQDPA | AM27: 9001BWRY | AN27: CONTROL STATION COVER+BOX T-BF+BW | AO27: AUTOMATION CONTROL | AP27: PUSH BUTTONS, PILOT LIGHTS & SELECTOR SWITCHES | AQ27: SCHEDULE OF DISCOUNTS
A28: 162 | B28: Pactiv_Multiple Suppliers Specialty PA | C28: 1954 | F28: 44308 | G28: WESCO DISTRIBUTION INC | I28: KNOB,SQUARE D,#9001-K-17R,RED MUSHROOM | J28: SQUARE D | K28: 9001K17R | L28: Other Repair Parts - 550990999 | O28: EA | P28: 1 | Q28: 2 | R28: 59.04 | S28: =R28/P28 -> 59.04 | T28: =Q28*P28 -> 2 | U28: =T28*S28 -> 118.08 | V28: 118.08 | W28: =V28=U28 -> TRUE | X28: =V28-AC28 -> 62.373333 | Y28: =X28/V28 -> 0.52822945 | Z28: =IF(Y28<0,"Negative",IF(Y28=0,"Same",IF(Y28>0.3,"30+%",IF(Y28>0.2,"20-30%",IF(Y28>0.1,"10-20%",IF(Y28<=0.1,"0-10%")))))) -> 30+% | AA28: 27.853333 | AB28: 1 | AC28: =AA28/AB28*T28 -> 55.706667 | AD28: =AA28/AB28 -> 27.853333 | AE28: E | AH28: EA | AI28: 1 | AJ28: 88247200 | AK28: SCHNEIDER ELECTRIC USA INC | AL28: SQDPA | AM28: 9001K17R | AN28: PUSHBUTTON MUSHROOM KNOB30MM TYPE K | AO28: AUTOMATION CONTROL | AP28: PUSH BUTTONS, PILOT LIGHTS & SELECTOR SWITCHES | AQ28: SCHEDULE OF DISCOUNTS
A29: 164 | B29: Pactiv_Multiple Suppliers Specialty PA | C29: 1963 | F29: 44421 | G29: WESCO DISTRIBUTION INC | I29: GRIP,KELLEMS,#074-01-017,3/4",CORD GRIP | J29: KELLEMS DIV | K29: 07401017 | L29: Other Repair Parts - 550990999 | O29: EA | P29: 1 | Q29: 2 | R29: 57.64 | S29: =R29/P29 -> 57.64 | T29: =Q29*P29 -> 2 | U29: =T29*S29 -> 115.28 | V29: 115.28 | W29: =V29=U29 -> TRUE | X29: =V29-AC29 -> -27.658776 | Y29: =X29/V29 -> -0.23992692 | Z29: =IF(Y29<0,"Negative",IF(Y29=0,"Same",IF(Y29>0.3,"30+%",IF(Y29>0.2,"20-30%",IF(Y29>0.1,"10-20%",IF(Y29<=0.1,"0-10%")))))) -> Negative | AA29: 71.469388 | AB29: 1 | AC29: =AA29/AB29*T29 -> 142.93878 | AD29: =AA29/AB29 -> 71.469388 | AE29: E | AH29: EA | AI29: 1 | AJ29: 88147610 | AK29: HUBBELL WIRING DEVICES | AL29: HBLPE | AM29: 07401017 | AN29: STR MALE DCG .50-.623/4 W/MESH | AO29: BOXES, ENCLOSURES, F | AP29: SUPPORT GRIPS | AQ29: SCHEDULE OF DISCOUNTS | AR29: CORE
A30: 167 | B30: Pactiv_Multiple Suppliers Specialty PA | C30: 1995 | F30: 44539 | G30: ELLIOTT ELECTRIC SUPPLY | I30: MISC,ELLIOTTELE,LT125,1 1-4LT STR STEEL | J30: ELLIOTTELECTICAL | K30: LT125 | L30: Hardware - 550440990 | O30: EA | P30: 1 | Q30: 3 | R30: 36.77 | S30: =R30/P30 -> 36.77 | T30: =Q30*P30 -> 3 | U30: =T30*S30 -> 110.31 | V30: 110.31 | W30: =V30=U30 -> TRUE | X30: =V30-AC30 -> 91.390457 | Y30: =X30/V30 -> 0.82848751 | Z30: =IF(Y30<0,"Negative",IF(Y30=0,"Same",IF(Y30>0.3,"30+%",IF(Y30>0.2,"20-30%",IF(Y30>0.1,"10-20%",IF(Y30<=0.1,"0-10%")))))) -> 30+% | AA30: 630.65143 | AB30: 100 | AC30: =AA30/AB30*T30 -> 18.919543 | AD30: =AA30/AB30 -> 6.3065143 | AE30: F | AH30: EA | AI30: 1 | AJ30: 88073396 | AK30: COOPER CROUSE-HINDS DIVISION | AL30: CRHPE | AM30: LT125 | AN30: 1-1/4 STR L/T CONN | AO30: BOXES, ENCLOSURES, F | AP30: LIQUIDTIGHT FITTINGS | AQ30: SCHEDULE OF DISCOUNTS
A31: 172 | B31: Pactiv_Multiple Suppliers Specialty PA | C31: 2051 | F31: 44214 | G31: WESCO DISTRIBUTION INC | I31: GRIP,RAIN,6-1/2"L,NON-INSULATED | J31: KELLEMS DIV | K31: 073031203 | L31: Other Repair Parts - 550990999 | O31: EA | P31: 1 | Q31: 6 | R31: 17.03 | S31: =R31/P31 -> 17.03 | T31: =Q31*P31 -> 6 | U31: =T31*S31 -> 102.18 | V31: 102.18 | W31: =V31=U31 -> TRUE | X31: =V31-AC31 -> -18.97102 | Y31: =X31/V31 -> -0.18566276 | Z31: =IF(Y31<0,"Negative",IF(Y31=0,"Same",IF(Y31>0.3,"30+%",IF(Y31>0.2,"20-30%",IF(Y31>0.1,"10-20%",IF(Y31<=0.1,"0-10%")))))) -> Negative | AA31: 20.191837 | AB31: 1 | AC31: =AA31/AB31*T31 -> 121.15102 | AD31: =AA31/AB31 -> 20.191837 | AE31: DM | AH31: EA | AI31: 1 | AJ31: 25962433 | AK31: HUBBELL WIRING DEVICES | AL31: HBLPE | AM31: 073031203A | AN31: D/T STRAIN RELF .54-.73 3/4 MOD | AO31: BOXES, ENCLOSURES, F | AP31: SUPPORT GRIPS | AQ31: SCHEDULE OF DISCOUNTS
A32: 173 | B32: Pactiv_Multiple Suppliers Specialty PA | C32: 2061 | F32: 44495 | G32: ADDISON ELECTRIC INC | I32: Fuse,LITTLE FUSE,#FLSR20, FLSR20ID,CLASS | J32: LITTLE FUSE | K32: FLSR20FLSR20ID | L32: Hardware - 550440990 | O32: EA | P32: 1 | Q32: 10 | R32: 10.09 | S32: =R32/P32 -> 10.09 | T32: =Q32*P32 -> 10 | U32: =T32*S32 -> 100.9 | V32: 100.9 | W32: =V32=U32 -> TRUE | X32: =V32-AC32 -> -65.353061 | Y32: =X32/V32 -> -0.6477013 | Z32: =IF(Y32<0,"Negative",IF(Y32=0,"Same",IF(Y32>0.3,"30+%",IF(Y32>0.2,"20-30%",IF(Y32>0.1,"10-20%",IF(Y32<=0.1,"0-10%")))))) -> Negative | AA32: 16.625306 | AB32: 1 | AC32: =AA32/AB32*T32 -> 166.25306 | AD32: =AA32/AB32 -> 16.625306 | AE32: E | AH32: EA | AI32: 1 | AJ32: 25438996 | AK32: COOPER BUSSMANN INC | AL32: BUSPA | AM32: FRS-R-20ID | AN32: FUSETRON DUAL-ELEMENT CLASS RK5 INDICATI | AO32: MRO | AP32: LOW VOLTAGE, BRANCH CIRCUIT RATED FUSES | AQ32: SCHEDULE OF DISCOUNTS
A33: 180 | B33: Pactiv_Multiple Suppliers Specialty PA | C33: 2083 | F33: 44431 | G33: BORDER STATES INDUSTRIES INC | I33: MISC,BORDER STA,158217,SQD-9001KA3 N/C C | J33: BORDER STATES | K33: 158217 | L33: Other Repair Parts - 550990999 | O33: EA | P33: 1 | Q33: 4 | R33: 24.39 | S33: =R33/P33 -> 24.39 | T33: =Q33*P33 -> 4 | U33: =T33*S33 -> 97.56 | V33: 97.56 | W33: =V33=U33 -> TRUE | X33: =V33-AC33 -> 39.329796 | Y33: =X33/V33 -> 0.40313444 | Z33: =IF(Y33<0,"Negative",IF(Y33=0,"Same",IF(Y33>0.3,"30+%",IF(Y33>0.2,"20-30%",IF(Y33>0.1,"10-20%",IF(Y33<=0.1,"0-10%")))))) -> 30+% | AA33: 14.557551 | AB33: 1 | AC33: =AA33/AB33*T33 -> 58.230204 | AD33: =AA33/AB33 -> 14.557551 | AE33: E | AH33: EA | AI33: 1 | AJ33: 88247321 | AK33: SCHNEIDER ELECTRIC USA INC | AL33: SQDPA | AM33: 9001KA3 | AN33: 30MM CONTACT BLOCK 1N/C | AO33: AUTOMATION CONTROL | AP33: PUSH BUTTONS, PILOT LIGHTS & SELECTOR SWITCHES | AQ33: SCHEDULE OF DISCOUNTS
A34: 185 | B34: Pactiv_Multiple Suppliers Specialty PA | C34: 2138 | F34: 44223 | G34: WESCO DISTRIBUTION INC | I34: INSULATOR,THOMAS + BETTS,#MSC 250 | J34: THOMAS + BETTS | K34: MSC250 | L34: Other Repair Parts - 550990999 | O34: EA | P34: 1 | Q34: 4 | R34: 22.6 | S34: =R34/P34 -> 22.6 | T34: =Q34*P34 -> 4 | U34: =T34*S34 -> 90.4 | V34: 90.4 | W34: =V34=U34 -> TRUE | X34: =V34-AC34 -> -33.907469 | Y34: =X34/V34 -> -0.37508263 | Z34: =IF(Y34<0,"Negative",IF(Y34=0,"Same",IF(Y34>0.3,"30+%",IF(Y34>0.2,"20-30%",IF(Y34>0.1,"10-20%",IF(Y34<=0.1,"0-10%")))))) -> Negative | AA34: 3107.6867 | AB34: 100 | AC34: =AA34/AB34*T34 -> 124.30747 | AD34: =AA34/AB34 -> 31.076867 | AE34: E | AH34: EA | AI34: 1 | AJ34: 88265855 | AK34: ABB INSTALLATION PRODUCTS INC | AL34: TBCPE | AM34: MSC250 | AN34: MTR STUB SPLICE INSULTR | AO34: POWER DISTRIBUTION | AP34: LINE SPLICES, GUY GRIPS, DEAD-ENDS, ETC. | AQ34: SCHEDULE OF DISCOUNTS
A35: 186 | B35: Pactiv_Multiple Suppliers Specialty PA | C35: 2151 | F35: 44497 | G35: ALLIED ELECTRONICS INC | I35: MISC,PEPPERL+FU,V31-WM-5MPVC,M8 FEMALE R | J35: PEPPERL+FUCHS AUTOMATION | K35: V31-WM-5MPVC | L35: Other Repair Parts - 550990999 | O35: EA | P35: 1 | Q35: 5 | R35: 17.67 | S35: =R35/P35 -> 17.67 | T35: =Q35*P35 -> 5 | U35: =T35*S35 -> 88.35 | V35: 88.35 | W35: =V35=U35 -> TRUE | X35: =V35-AC35 -> -6.0173469 | Y35: =X35/V35 -> -0.068108058 | Z35: =IF(Y35<0,"Negative",IF(Y35=0,"Same",IF(Y35>0.3,"30+%",IF(Y35>0.2,"20-30%",IF(Y35>0.1,"10-20%",IF(Y35<=0.1,"0-10%")))))) -> Negative | AA35: 18.873469 | AB35: 1 | AC35: =AA35/AB35*T35 -> 94.367347 | AD35: =AA35/AB35 -> 18.873469 | AE35: E | AH35: EA | AI35: 1 | AJ35: NOF | AK35: PEPPREL & FUCHS | AL35: PPFPE | AM35: V31-WM-5MPVC | AO35: AUTOMATION CONTROL | AQ35: COMMODITY
A36: 191 | B36: Pactiv_Multiple Suppliers Specialty PA | C36: 2203 | F36: 44522 | G36: STEINER ELECTRIC COMPANY | I36: ENCLOSURE,STEINER ELECTRIC CO,#A404CH , | J36: STEINER ELECTRIC CO | K36: A404CH | L36: Hardware - 550440990 | O36: EA | P36: 1 | Q36: 2 | R36: 40.44 | S36: =R36/P36 -> 40.44 | T36: =Q36*P36 -> 2 | U36: =T36*S36 -> 80.88 | V36: 80.88 | W36: =V36=U36 -> TRUE | X36: =V36-AC36 -> -45.66 | Y36: =X36/V36 -> -0.56454006 | Z36: =IF(Y36<0,"Negative",IF(Y36=0,"Same",IF(Y36>0.3,"30+%",IF(Y36>0.2,"20-30%",IF(Y36>0.1,"10-20%",IF(Y36<=0.1,"0-10%")))))) -> Negative | AA36: 63.27 | AB36: 1 | AC36: =AA36/AB36*T36 -> 126.54 | AD36: =AA36/AB36 -> 63.27 | AE36: E | AH36: EA | AI36: 1 | AJ36: 88131797 | AK36: HOFFMAN ENCLOSURES, INC | AL36: HOFPA | AM36: A404CH | AN36: J BOX TYPE 12 HINGED COVER | AO36: BOXES, ENCLOSURES, F | AP36: ENCLOSURES | AQ36: SCHEDULE OF DISCOUNTS
A37: 207 | B37: Pactiv_Multiple Suppliers Specialty PA | C37: 2269 | F37: 44348 | G37: WESCO DISTRIBUTION INC | I37: BODY,HUBBELL,#HBL4729-C,125VAC/DC,15A,CO | J37: HUBBELL | K37: HBL4760 | L37: Other Repair Parts - 550990999 | O37: EA | P37: 1 | Q37: 2 | R37: 36.93 | S37: =R37/P37 -> 36.93 | T37: =Q37*P37 -> 2 | U37: =T37*S37 -> 73.86 | V37: 73.86 | W37: =V37=U37 -> TRUE | X37: =V37-AC37 -> 15.157959 | Y37: =X37/V37 -> 0.20522555 | Z37: =IF(Y37<0,"Negative",IF(Y37=0,"Same",IF(Y37>0.3,"30+%",IF(Y37>0.2,"20-30%",IF(Y37>0.1,"10-20%",IF(Y37<=0.1,"0-10%")))))) -> 20-30% | AA37: 29.35102 | AB37: 1 | AC37: =AA37/AB37*T37 -> 58.702041 | AD37: =AA37/AB37 -> 29.35102 | AE37: E | AH37: EA | AI37: 1 | AJ37: 95005512 | AK37: HUBBELL WIRING DEVICES | AL37: HBLPE | AM37: HBL4729C | AN37: LKG CONN 15A 125V L5-15R B/W | AO37: BOXES, ENCLOSURES, F | AP37: ALL TURN LOCKING DEVICES | AQ37: SCHEDULE OF DISCOUNTS | AR37: CORE
A38: 209 | B38: Pactiv_Multiple Suppliers Specialty PA | C38: 2281 | F38: 44519 | G38: ADDISON ELECTRIC INC | I38: Fuse,LITTLE FUSE,#JLS 30, JKS-30, A4J30 | J38: LITTLE FUSE | K38: JLS30JKS30A4J30 | L38: Hardware - 550440990 | O38: EA | P38: =1/10 -> 0.1 | Q38: 10 | R38: 7.21 | S38: =R38/P38 -> 72.1 | T38: =Q38*P38 -> 1 | U38: =T38*S38 -> 72.1 | V38: 72.1 | W38: =V38=U38 -> TRUE | X38: =V38-AC38 -> -91.766122 | Y38: =X38/V38 -> -1.2727618 | Z38: =IF(Y38<0,"Negative",IF(Y38=0,"Same",IF(Y38>0.3,"30+%",IF(Y38>0.2,"20-30%",IF(Y38>0.1,"10-20%",IF(Y38<=0.1,"0-10%")))))) -> Negative | AA38: 163.86612 | AB38: 1 | AC38: =AA38/AB38*T38 -> 163.86612 | AD38: =AA38/AB38 -> 163.86612 | AE38: E | AG38: ERROR IN UOM | AH38: EA | AI38: 1 | AJ38: 88051744 | AK38: COOPER BUSSMANN INC | AL38: BUSPA | AM38: JKS-300 | AN38: LIMITRON FAST ACTING FUSE CLASS J | AO38: MRO | AP38: LOW VOLTAGE, BRANCH CIRCUIT RATED FUSES | AQ38: SCHEDULE OF DISCOUNTS
A39: 214 | B39: Pactiv_Multiple Suppliers Specialty PA | C39: 2301 | F39: 44245 | G39: WESCO DISTRIBUTION INC | I39: TAPE,3M,#05400741750,SCOTCHFIL PUTTY TAP | J39: 3M | K39: 05400741750 | L39: Other Repair Parts - 550990999 | O39: EA | P39: 1 | Q39: 5 | R39: 13.9 | S39: =R39/P39 -> 13.9 | T39: =Q39*P39 -> 5 | U39: =T39*S39 -> 69.5 | V39: 69.5 | W39: =V39=U39 -> TRUE | X39: =V39-AC39 -> 6.15 | Y39: =X39/V39 -> 0.088489209 | Z39: =IF(Y39<0,"Negative",IF(Y39=0,"Same",IF(Y39>0.3,"30+%",IF(Y39>0.2,"20-30%",IF(Y39>0.1,"10-20%",IF(Y39<=0.1,"0-10%")))))) -> 0-10% | AA39: 12.67 | AB39: 1 | AC39: =AA39/AB39*T39 -> 63.35 | AD39: =AA39/AB39 -> 12.67 | AE39: E | AH39: EA | AI39: 1 | AJ39: 88176855 | AK39: 3M CO. - ELECTRICAL MARKETS DIV. | AL39: MMMPE | AM39: SCOTCHFIL | AN39: INSULATION PUTTY 1 1/2 X60 | AO39: MRO | AP39: INSULATING MATERIAL, FIRE-STOP, TAPE & HEAT SHRINK | AQ39: NET | AR39: CORE
A40: 216 | B40: Pactiv_Multiple Suppliers Specialty PA | C40: 2303 | F40: 44497 | G40: ALLIED ELECTRONICS INC | I40: MISC,ALLIED,SS720,BLANK WALL PLATE | J40: ALLIED | K40: SS720 | L40: Other Repair Parts - 550990999 | O40: EA | P40: 1 | Q40: 10 | R40: 6.93 | S40: =R40/P40 -> 6.93 | T40: =Q40*P40 -> 10 | U40: =T40*S40 -> 69.3 | V40: 69.3 | W40: =V40=U40 -> TRUE | X40: =V40-AC40 -> 26.002041 | Y40: =X40/V40 -> 0.37520982 | Z40: =IF(Y40<0,"Negative",IF(Y40=0,"Same",IF(Y40>0.3,"30+%",IF(Y40>0.2,"20-30%",IF(Y40>0.1,"10-20%",IF(Y40<=0.1,"0-10%")))))) -> 30+% | AA40: 4.3297959 | AB40: 1 | AC40: =AA40/AB40*T40 -> 43.297959 | AD40: =AA40/AB40 -> 4.3297959 | AE40: E | AH40: EA | AI40: 1 | AJ40: 25081073 | AK40: HUBBELL WIRING DEVICES | AL40: HBLPE | AM40: SS720 | AN40: WALLPLATE 1-G 1.60 SS | AO40: BOXES, ENCLOSURES, F | AP40: RECEPTACLE WALL PLATES/COVERS | AQ40: SCHEDULE OF DISCOUNTS
...

Sheet Excluded
A1: GLINE | B1: Project Name | C1: Sequence Number | D1: Location | E1: Customer Internal Part Number | F1: Transaction Date | G1: Distributor Name | H1: Distributor Part Number | I1: Item Description | J1: Manufacturer | K1: Manufacturer Part Number | L1: Other Notes 1 | M1: Other Notes 2 | N1: Other Notes 3 | O1: UOM | P1: UOM Qty | Q1: Pack Price | R1: Qty | S1: Unit Price | T1: Total Baseline Units | U1: Extended Price | V1: CODE | W1: NOTES
A2: 1 | B2: Pactiv_Multiple Suppliers Specialty PA | C2: 29 | F2: 44475 | G2: D REYNOLDS CO LLC | I2: KIT,AB,ALBRSKH1DCFANRETROFITF10,PF 700H/ | J2: AB | K2: ALBRSKH1DCFANRETROFITF10 | L2: Hardware - 550440990 | O2: EA | P2: 1 | Q2: 6965.58 | R2: 1 | S2: 6965.58 | T2: 1 | U2: 6965.58 | V2: ANB | W2: Allen Bradley item that we have no access to, and cannot cross.
A3: 2 | B3: Pactiv_Multiple Suppliers Specialty PA | C3: 52 | F3: 44522 | G3: MCNAUGHTON MCKAY SOUTHEAST INC | I3: MISC,PRO-FACE,PROPFXGP4303TAD,GP-4000 OP | J3: PRO-FACE | K3: PROPFXGP4303TAD | L3: Other Repair Parts - 550990999 | O3: EA | P3: 1 | Q3: 2567.69 | R3: 2 | S3: 2567.69 | T3: 2 | U3: 5135.38 | V3: NOT | W3: Automation item we have no access to and cannot cross.
A4: 3 | B4: Pactiv_Multiple Suppliers Specialty PA | C4: 54 | F4: 44419 | G4: BORDER STATES INDUSTRIES INC | I4: MISC,BORDER STA,DM220KK 480D-480Y/277,IS | J4: BORDER STATES | K4: DM220KK 480D-480Y/277 | L4: Other Repair Parts - 550990999 | O4: EA | P4: 1 | Q4: 5053.5 | R4: 1 | S4: 5053.5 | T4: 1 | U4: 5053.5 | V4: NOT | W4: Automation item we have no access to and cannot cross.
A5: 4 | B5: Pactiv_Multiple Suppliers Specialty PA | C5: 69 | F5: 44509 | G5: EXTRUSION CONTROL & SUPPLY INC | I5: THERMOCOUPLE,NANMAC,#C8A3J, 4-1/4",TIP E | J5: NANMAC CORP | K5: C8A3J | L5: Instrumentation - 550480990 | O5: EA | P5: 1 | Q5: 661.45 | R5: 6 | S5: 661.45 | T5: 6 | U5: 3968.7 | V5: NOT | W5: Automation item we have no access to and cannot cross.
A6: 5 | B6: Pactiv_Multiple Suppliers Specialty PA | C6: 82 | F6: 44504 | G6: WESCO DISTRIBUTION INC | I6: CABLE,SNAP,#HD-CBF6,SNAP WIRE HARNESS | J6: SNAP | K6: #HD-CBF6 | L6: Instrumentation - 550480990 | O6: EA | P6: 1 | Q6: 183.4 | R6: 20 | S6: 183.4 | T6: 20 | U6: 3668 | V6: NOT | W6: Electronic item we have no access to and cannot cross.
A7: 6 | B7: Pactiv_Multiple Suppliers Specialty PA | C7: 94 | F7: 44202 | G7: ATLANTIC CORP OF WILMINGTON INC | I7: WIRE,ATLANTIC P,6050006,18'X12GA | J7: ATLANTIC PKG | K7: 6050006 | L7: Other Repair Parts - 550990999 | O7: EA | P7: 1 | Q7: 68.46 | R7: 50 | S7: 68.46 | T7: 50 | U7: 3423 | V7: CID | W7: Item does not have a full part number provided or a full description that would allow a part number to be determined.
A8: 7 | B8: Pactiv_Multiple Suppliers Specialty PA | C8: 145 | F8: 44470 | G8: AWC INC | I8: MISC,SIEMENS,6ES78221AE070YAS,1951251945 | J8: SIEMENS | K8: 6ES78221AE070YAS | L8: Other Repair Parts - 550990999 | O8: EA | P8: 1 | Q8: 2529.61 | R8: 1 | S8: 2529.61 | T8: 1 | U8: 2529.61 | V8: NOT | W8: Automation item we have no access to and cannot cross.
A9: 8 | B9: Pactiv_Multiple Suppliers Specialty PA | C9: 163 | F9: 44264 | G9: YUSHIN AMERICA INC | I9: CABLE,YUSHIN,20693580,CABLE TRAVERSE C-F | J9: YUSHIN | K9: 20693580 | L9: Other Repair Parts - 550990999 | O9: EA | P9: 1 | Q9: 1188.97 | R9: 2 | S9: 1188.97 | T9: 2 | U9: 2377.94 | V9: NOT | W9: Automation item we have no access to and cannot cross.
A10: 9 | B10: Pactiv_Multiple Suppliers Specialty PA | C10: 165 | F10: 44543 | G10: BORDER STATES INDUSTRIES INC | I10: MISC,BORDER STA,SFI-700-3/4,SIGHT FLOW I | J10: BORDER STATES | K10: SFI-700-3/4 | L10: Other Repair Parts - 550990999 | O10: EA | P10: 1 | Q10: 336 | R10: 7 | S10: 336 | T10: 7 | U10: 2352 | V10: NOT | W10: Automation item we have no access to and cannot cross.
A11: 10 | B11: Pactiv_Multiple Suppliers Specialty PA | C11: 170 | F11: 44271 | G11: RADWELL INTL INC | I11: CARD,EUROTHERM,#PC3000/AI/VERSION3/V4/99 | J11: EUROTHERM | K11: PC3000AIVERSION3V499103 | L11: Other Repair Parts - 550990999 | O11: EA | P11: 1 | Q11: 1154.41 | R11: 2 | S11: 1154.41 | T11: 2 | U11: 2308.82 | V11: NOT | W11: Automation item we have no access to and cannot cross.
A12: 11 | B12: Pactiv_Multiple Suppliers Specialty PA | C12: 212 | F12: 44389 | G12: WESCO DISTRIBUTION INC | I12: FRAME,WESTINGHOUSE,KD3400F,400A,BREAKER | J12: WESTINGHOUSE | K12: LA3400F | L12: Other Repair Parts - 550990999 | O12: EA | P12: 1 | Q12: 1961.43 | R12: 1 | S12: 1961.43 | T12: 1 | U12: 1961.43 | V12: NOT | W12: Automation item we have no access to and cannot cross.
A13: 12 | B13: Pactiv_Multiple Suppliers Specialty PA | C13: 237 | F13: 44518 | G13: RADWELL INTL INC | I13: ENCODER,BEI,#H25W-F67-SS-8GCC-7272-SM16/ | J13: BEI INDUSTRIAL ENCODER DIVISIO | K13: H25WF67SS8GCC7272SM1626S | L13: Other Repair Parts - 550990999 | O13: EA | P13: 1 | Q13: 1824.01 | R13: 1 | S13: 1824.01 | T13: 1 | U13: 1824.01 | V13: NOT | W13: Automation item we have no access to and cannot cross.
... A230: 295 | B230: Pactiv_Multiple Suppliers Specialty PA | C230: 2903 | F230: 44406 | G230: KEYENCE CORP OF AMERICA | I230: CABLE,KEYENCE,OP-99021,STANDARD AC CABLE | J230: KEYENCE | K230: OP-99021 | L230: Other Repair Parts - 550990999 | O230: EA | P230: 1 | Q230: 0.01 | R230: 1 | S230: 0.01 | T230: 1 | U230: 0.01 | V230: NOT | W230: Automation item we have no access to and cannot cross.

Sheet SegmentSummary
A1: Segment Summary
A2: Segment | B2: SKU Count | C2: Incumbent Spend | D2: Graybar Spend | E2: Savings $ | F2: Savings %
A3: AUTOMATION CONTROL | B3: =COUNTIF('Item Detail'!AO:AO,A3) -> 11 | C3: =SUMIF('Item Detail'!AO:AO,A3,'Item Detail'!V:V) -> 1934.87 | D3: =SUMIF('Item Detail'!AO:AO,A3,'Item Detail'!AC:AC) -> 1386.6469 | E3: =C3-D3 -> 548.22306 | F3: =IFERROR(E3/C3,0) -> 0.28333845
A4: BOXES, ENCLOSURES, F | B4: =COUNTIF('Item Detail'!AO:AO,A4) -> 39 | C4: =SUMIF('Item Detail'!AO:AO,A4,'Item Detail'!V:V) -> 5791.24 | D4: =SUMIF('Item Detail'!AO:AO,A4,'Item Detail'!AC:AC) -> 3760.2127 | E4: =C4-D4 -> 2031.0273 | F4: =IFERROR(E4/C4,0) -> 0.35070681
A5: CD CABLING | B5: =COUNTIF('Item Detail'!AO:AO,A5) -> 0 | C5: =SUMIF('Item Detail'!AO:AO,A5,'Item Detail'!V:V) -> 0 | D5: =SUMIF('Item Detail'!AO:AO,A5,'Item Detail'!AC:AC) -> 0 | E5: =C5-D5 -> 0 | F5: =IFERROR(E5/C5,0) -> 0
A6: CD CONNECTIVITY | B6: =COUNTIF('Item Detail'!AO:AO,A6) -> 0 | C6: =SUMIF('Item Detail'!AO:AO,A6,'Item Detail'!V:V) -> 0 | D6: =SUMIF('Item Detail'!AO:AO,A6,'Item Detail'!AC:AC) -> 0 | E6: =C6-D6 -> 0 | F6: =IFERROR(E6/C6,0) -> 0
A7: CD VOICE, ACTIVE COM | B7: =COUNTIF('Item Detail'!AO:AO,A7) -> 0 | C7: =SUMIF('Item Detail'!AO:AO,A7,'Item Detail'!V:V) -> 0 | D7: =SUMIF('Item Detail'!AO:AO,A7,'Item Detail'!AC:AC) -> 0 | E7: =C7-D7 -> 0 | F7: =IFERROR(E7/C7,0) -> 0
A8: CONDUIT & CHANNEL | B8: =COUNTIF('Item Detail'!AO:AO,A8) -> 4 | C8: =SUMIF('Item Detail'!AO:AO,A8,'Item Detail'!V:V) -> 1780.32 | D8: =SUMIF('Item Detail'!AO:AO,A8,'Item Detail'!AC:AC) -> 1328.0384 | E8: =C8-D8 -> 452.28163 | F8: =IFERROR(E8/C8,0) -> 0.25404513
A9: LIGHTING | B9: =COUNTIF('Item Detail'!AO:AO,A9) -> 0 | C9: =SUMIF('Item Detail'!AO:AO,A9,'Item Detail'!V:V) -> 0 | D9: =SUMIF('Item Detail'!AO:AO,A9,'Item Detail'!AC:AC) -> 0 | E9: =C9-D9 -> 0 | F9: =IFERROR(E9/C9,0) -> 0
A10: MRO | B10: =COUNTIF('Item Detail'!AO:AO,A10) -> 10 | C10: =SUMIF('Item Detail'!AO:AO,A10,'Item Detail'!V:V) -> 1479.71 | D10: =SUMIF('Item Detail'!AO:AO,A10,'Item Detail'!AC:AC) -> 1677.5369 | E10: =C10-D10 -> -197.82694 | F10: =IFERROR(E10/C10,0) -> -0.13369305
A11: POWER DISTRIBUTION | B11: =COUNTIF('Item Detail'!AO:AO,A11) -> 2 | C11: =SUMIF('Item Detail'!AO:AO,A11,'Item Detail'!V:V) -> 156.46 | D11: =SUMIF('Item Detail'!AO:AO,A11,'Item Detail'!AC:AC) -> 177.09726 | E11: =C11-D11 -> -20.637257 | F11: =IFERROR(E11/C11,0) -> -0.13190117
A12: Undefined | B12: =COUNTIF('Item Detail'!AO:AO,A12) -> 0 | C12: =SUMIF('Item Detail'!AO:AO,A12,'Item Detail'!V:V) -> 0 | D12: =SUMIF('Item Detail'!AO:AO,A12,'Item Detail'!AC:AC) -> 0 | E12: =C12-D12 -> 0 | F12: =IFERROR(E12/C12,0) -> 0
A13: WIRE & CABLE | B13: =COUNTIF('Item Detail'!AO:AO,A13) -> 0 | C13: =SUMIF('Item Detail'!AO:AO,A13,'Item Detail'!V:V) -> 0 | D13: =SUMIF('Item Detail'!AO:AO,A13,'Item Detail'!AC:AC) -> 0 | E13: =C13-D13 -> 0 | F13: =IFERROR(E13/C13,0) -> 0
A14: Total | B14: =SUM(B3:B13) -> 66 | C14: =SUM(C3:C13) -> 11142.6 | D14: =SUM(D3:D13) -> 8329.5322 | E14: =SUM(E3:E13) -> 2813.0678 | F14: =IFERROR(E14/C14,0) -> 0.25246063

Sheet Cust File
U1: =SUM(U3:U10779) -> 117597.23
A2: GLINE | B2: Project Name | C2: Sequence Number | D2: Location | E2: Customer Internal Part Number | F2: Transaction Date | G2: Distributor Name | H2: Distributor Part Number | I2: Item Description | J2: Manufacturer | K2: Manufacturer Part Number | L2: Other Notes 1 | M2: Other Notes 2 | N2: Other Notes 3 | O2: UOM | P2: UOM Qty | Q2: Pack Price | R2: Qty | S2: Unit Price | T2: Total Baseline Units | U2: Extended Price
A3: 1 | B3: Pactiv_Multiple Suppliers Specialty PA | C3: 29 | F3: 44475 | G3: D REYNOLDS CO LLC | I3: KIT,AB,ALBRSKH1DCFANRETROFITF10,PF 700H/ | J3: AB | K3: ALBRSKH1DCFANRETROFITF10 | L3: Hardware - 550440990 | O3: EA | P3: 1 | Q3: 6965.58 | R3: 1 | S3: 6965.58 | T3: 1 | U3: 6965.58
A4: 2 | B4: Pactiv_Multiple Suppliers Specialty PA | C4: 52 | F4: 44522 | G4: MCNAUGHTON MCKAY SOUTHEAST INC | I4: MISC,PRO-FACE,PROPFXGP4303TAD,GP-4000 OP | J4: PRO-FACE | K4: PROPFXGP4303TAD | L4: Other Repair Parts - 550990999 | O4: EA | P4: 1 | Q4: 2567.69 | R4: 2 | S4: 2567.69 | T4: 2 | U4: 5135.38
A5: 3 | B5: Pactiv_Multiple Suppliers Specialty PA | C5: 54 | F5: 44419 | G5: BORDER STATES INDUSTRIES INC | I5: MISC,BORDER STA,DM220KK 480D-480Y/277,IS | J5: BORDER STATES | K5: DM220KK 480D-480Y/277 | L5: Other Repair Parts - 550990999 | O5: EA | P5: 1 | Q5: 5053.5 | R5: 1 | S5: 5053.5 | T5: 1 | U5: 5053.5
A6: 4 | B6: Pactiv_Multiple Suppliers Specialty PA | C6: 69 | F6: 44509 | G6: EXTRUSION CONTROL & SUPPLY INC | I6: THERMOCOUPLE,NANMAC,#C8A3J, 4-1/4",TIP E | J6: NANMAC CORP | K6: C8A3J | L6: Instrumentation - 550480990 | O6: EA | P6: 1 | Q6: 661.45 | R6: 6 | S6: 661.45 | T6: 6 | U6: 3968.7
A7: 5 | B7: Pactiv_Multiple Suppliers Specialty PA | C7: 82 | F7: 44504 | G7: WESCO DISTRIBUTION INC | I7: CABLE,SNAP,#HD-CBF6,SNAP WIRE HARNESS | J7: SNAP | K7: #HD-CBF6 | L7: Instrumentation - 550480990 | O7: EA | P7: 1 | Q7: 183.4 | R7: 20 | S7: 183.4 | T7: 20 | U7: 3668
A8: 6 | B8: Pactiv_Multiple Suppliers Specialty PA | C8: 94 | F8: 44202 | G8: ATLANTIC CORP OF WILMINGTON INC | I8: WIRE,ATLANTIC P,6050006,18'X12GA | J8: ATLANTIC PKG | K8: 6050006 | L8: Other Repair Parts - 550990999 | O8: EA | P8: 1 | Q8: 68.46 | R8: 50 | S8: 68.46 | T8: 50 | U8: 3423
A9: 7 | B9: Pactiv_Multiple Suppliers Specialty PA | C9: 145 | F9: 44470 | G9: AWC INC | I9: MISC,SIEMENS,6ES78221AE070YAS,1951251945 | J9: SIEMENS | K9: 6ES78221AE070YAS | L9: Other Repair Parts - 550990999 | O9: EA | P9: 1 | Q9: 2529.61 | R9: 1 | S9: 2529.61 | T9: 1 | U9: 2529.61
A10: 8 | B10: Pactiv_Multiple Suppliers Specialty PA | C10: 163 | F10: 44264 | G10: YUSHIN AMERICA INC | I10: CABLE,YUSHIN,20693580,CABLE TRAVERSE C-F | J10: YUSHIN | K10: 20693580 | L10: Other Repair Parts - 550990999 | O10: EA | P10: 1 | Q10: 1188.97 | R10: 2 | S10: 1188.97 | T10: 2 | U10: 2377.94
A11: 9 | B11: Pactiv_Multiple Suppliers Specialty PA | C11: 165 | F11: 44543 | G11: BORDER STATES INDUSTRIES INC | I11: MISC,BORDER STA,SFI-700-3/4,SIGHT FLOW I | J11: BORDER STATES | K11: SFI-700-3/4 | L11: Other Repair Parts - 550990999 | O11: EA | P11: 1 | Q11: 336 | R11: 7 | S11: 336 | T11: 7 | U11: 2352
A12: 10 | B12: Pactiv_Multiple Suppliers Specialty PA | C12: 170 | F12: 44271 | G12: RADWELL INTL INC | I12: CARD,EUROTHERM,#PC3000/AI/VERSION3/V4/99 | J12: EUROTHERM | K12: PC3000AIVERSION3V499103 | L12: Other Repair Parts - 550990999 | O12: EA | P12: 1 | Q12: 1154.41 | R12: 2 | S12: 1154.41 | T12: 2 | U12: 2308.82
A13: 11 | B13: Pactiv_Multiple Suppliers Specialty PA | C13: 212 | F13: 44389 | G13: WESCO DISTRIBUTION INC | I13: FRAME,WESTINGHOUSE,KD3400F,400A,BREAKER | J13: WESTINGHOUSE | K13: LA3400F | L13: Other Repair Parts - 550990999 | O13: EA | P13: 1 | Q13: 1961.43 | R13: 1 | S13: 1961.43 | T13: 1 | U13: 1961.43
A14: 12 | B14: Pactiv_Multiple Suppliers Specialty PA | C14: 237 | F14: 44518 | G14: RADWELL INTL INC | I14: ENCODER,BEI,#H25W-F67-SS-8GCC-7272-SM16/ | J14: BEI INDUSTRIAL ENCODER DIVISIO | K14: H25WF67SS8GCC7272SM1626S | L14: Other Repair Parts - 550990999 | O14: EA | P14: 1 | Q14: 1824.01 | R14: 1 | S14: 1824.01 | T14: 1 | U14: 1824.01
... A297: 295 | B297: Pactiv_Multiple Suppliers Specialty PA | C297: 2903 | F297: 44406 | G297: KEYENCE CORP OF AMERICA | I297: CABLE,KEYENCE,OP-99021,STANDARD AC CABLE | J297: KEYENCE | K297: OP-99021 | L297: Other Repair Parts - 550990999 | O297: EA | P297: 1 | Q297: 0.01 | R297: 1 | S297: 0.01 | T297: 1 | U297: 0.01

Sheet Pricing Validity 
B2: Pricing provided as a component in this price request file is for quotations purposes only and is valid for 90 days from the date of submittal except for items impacted by changes in our costs due to volatile market fluctuations, which include but are not limited to copper and aluminum wire, metallic conduit, strut systems, channels and fittings, steel and zinc fittings and boxes, and all products containing polyvinyl chloride (PVC). Such products will be subject to escalation/de-escalation at time of shipment. All efforts will be made to hold our original price submittal.
