Workbook
Name lookup21: '[1]Location List.Confidential'!#REF!
Name lookup21: #REF!

Sheet Summary.Confidential
C1: Procurement Advisors
C2: Benchmark Summary
C3: Clearway Energy | H3: =TODAY() -> 44608
C4: 02/2021 - 01/2022
B6: Total Eligible Spend | C6: Benchmarked Current Spend | D6: Benchmarked % of Total | E6: PA Pricing | F6: Savings $ | G6: Savings | H6: Comments
A7: Graybar | B7: =C18 -> 14891.919 | C7: =SUMIF(ItemDetail.Confidential!$R:$R,">-9e100",ItemDetail.Confidential!$J:$J) -> 12984.419 | D7: =C7/B7 -> 0.87191039 | E7: =SUMIF(ItemDetail.Confidential!$R:$R,">-9e100",ItemDetail.Confidential!$Q:$Q) -> 12560.525 | F7: =C7-E7 -> 423.8936 | G7: =SUM(1-(E7/C7)) -> 0.032646329 | H7: Exact SKU benchmarking
A9: No. of SKUs | B9: Negative | C9: Same | D9: 0-10% | E9: 10-20% | F9: 20-30% | G9: 30+% | H9: Total | I9: Wtd. Avg.
A10: Total SKUs | B10: =COUNTIF(ItemDetail.Confidential!$P:$P,"Negative") -> 17 | C10: =COUNTIF(ItemDetail.Confidential!$P:$P,"Same") -> 0 | D10: =COUNTIF(ItemDetail.Confidential!$P:$P,"0-10%") -> 10 | E10: =COUNTIF(ItemDetail.Confidential!$P:$P,"10-20%") -> 13 | F10: =COUNTIF(ItemDetail.Confidential!$P:$P,"20-30%") -> 10 | G10: =COUNTIF(ItemDetail.Confidential!$P:$P,"30+%") -> 11 | H10: =SUM(B10:G10) -> 61 | I10: =G7 -> 0.032646329
A12: $ Spend | B12: Negative | C12: Same | D12: 0-10% | E12: 10-20% | F12: 20-30% | G12: 30+% | H12: Total
A13: 0 | B13: =SUMIF(ItemDetail.Confidential!$P:$P,"Negative",ItemDetail.Confidential!$J:$J) -> 7087.0359 | C13: =SUMIF(ItemDetail.Confidential!$P:$P,"Same",ItemDetail.Confidential!$J:$J) -> 0 | D13: =SUMIF(ItemDetail.Confidential!$P:$P,"0-10%",ItemDetail.Confidential!$J:$J) -> 1298.0752 | E13: =SUMIF(ItemDetail.Confidential!$P:$P,"10-20%",ItemDetail.Confidential!$J:$J) -> 1420.422 | F13: =SUMIF(ItemDetail.Confidential!$P:$P,"20-30%",ItemDetail.Confidential!$J:$J) -> 2280.5056 | G13: =SUMIF(ItemDetail.Confidential!$P:$P,"30+%",ItemDetail.Confidential!$J:$J) -> 898.38 | H13: =SUM(B13:G13) -> 12984.419
A14: PA | B14: =SUMIF(ItemDetail.Confidential!$P:$P,"Negative",ItemDetail.Confidential!$Q:$Q) -> 7890.0383 | C14: =SUMIF(ItemDetail.Confidential!$P:$P,"Same",ItemDetail.Confidential!$Q:$Q) -> 0 | D14: =SUMIF(ItemDetail.Confidential!$P:$P,"0-10%",ItemDetail.Confidential!$Q:$Q) -> 1193.4047 | E14: =SUMIF(ItemDetail.Confidential!$P:$P,"10-20%",ItemDetail.Confidential!$Q:$Q) -> 1220.012 | F14: =SUMIF(ItemDetail.Confidential!$P:$P,"20-30%",ItemDetail.Confidential!$Q:$Q) -> 1705.7801 | G14: =SUMIF(ItemDetail.Confidential!$P:$P,"30+%",ItemDetail.Confidential!$Q:$Q) -> 551.29 | H14: =SUM(B14:G14) -> 12560.525
A15: SKU Level Savings | B15: =B13-B14 -> -803.0024 | C15: =C13-C14 -> 0 | D15: =D13-D14 -> 104.6705 | E15: =E13-E14 -> 200.41 | F15: =F13-F14 -> 574.7255 | G15: =G13-G14 -> 347.09 | H15: =H13-H14 -> 423.8936
A17: As per customer file
A18: SKU's meeting threshold | B18: =COUNTA(ItemDetail.Confidential!$J:$J)-1+COUNTA(Excluded.Confidential!$J:$J)-1 -> 72 | C18: =SUM(ItemDetail.Confidential!J:J)+SUM(Excluded.Confidential!J:J) -> 14891.919
A19: Excluded | B19: # SKU | C19: Spend $
A20: Not on File (NOF) | B20: =COUNTIF(Excluded.Confidential!$N:$N, "*NOF*") -> 0 | C20: =SUMIF(Excluded.Confidential!$N:$N,"NOF",Excluded.Confidential!$J:$J) -> 0
A21: Capital Expenditure (CAPX) | B21: =COUNTIF(Excluded.Confidential!$N:$N, "*CAPX*") -> 0 | C21: =SUMIF(Excluded.Confidential!$N:$N,"CAPX",Excluded.Confidential!$J:$J) -> 0
A22: OEM (OEM) | B22: =COUNTIF(Excluded.Confidential!$N:$N, "*OEM*") -> 0 | C22: =SUMIF(Excluded.Confidential!$N:$N,"OEM",Excluded.Confidential!$J:$J) -> 0
A23: Obsolete (OBS) | B23: =COUNTIF(Excluded.Confidential!$N:$N, "*OBS*") -> 0 | C23: =SUMIF(Excluded.Confidential!$N:$N,"OBS",Excluded.Confidential!$J:$J) -> 0
A24: Graybar active Sourcing (FIND) | B24: =COUNTIF(Excluded.Confidential!$N:$N, "*FIND*") -> 6 | C24: =SUMIF(Excluded.Confidential!$N:$N,"FIND",Excluded.Confidential!$J:$J) -> 291.9
A25: Graybar potential sourcing (SOU) | B25: =COUNTIF(Excluded.Confidential!$N:$N, "*SOU*") -> 5 | C25: =SUMIF(Excluded.Confidential!$N:$N,"SOU",Excluded.Confidential!$J:$J) -> 1121.5
A26: Total Excluded (Excluded Tab) | B26: =SUM(B20:B25) -> 11 | C26: =SUM(C20:C25) -> 1413.4
A28: Other savings opportunities:
A29: Free Freight Benefit
A30: Paid freight Prior 12 months | B30: 148.77
A31: PA freight charges | B31: 0
A32: Annual Freight Savings Benefit | B32: =B30-B31 -> 148.77 | C32: estimate
A36: Note:
A37: (1) Total spend is data provided by Graybar
A38: (2) Benchmarked all SKUs except sourced items
A39: (3) Used company current price to compare against PA current price
A40: (4) Savings do not reflect (a) volume and manufacturer rebates, (b) CSPL alternatives and future CSPL adds
A41: (5) Benchmark pricing valid for 60 days
A42: (6) "Other Savings" numbers are projections based on historical spend and current agreements, actual numbers and percentages will change based of future spend patterns

Sheet Loc.Summ.Confidential
A1: Location Summary
A2: Location name | B2: # SKUs | C2: Current Ext. Price | D2: PA Ext. Price | E2: Savings $ | F2: Savings %
A3: Clearway Energy, Inc. MINNEAPOLIS MN | B3: 1 | C3: 115.7 | D3: 114.18 | E3: 1.52 | F3: =IFERROR(E3/C3,"") -> 0.013137424
A4: Clearway Energy, Inc. PITTSBURGH PA | B4: 11 | C4: 9025.31 | D4: 9099.96 | E4: -74.65 | F4: =IFERROR(E4/C4,"") -> -0.008271184
A5: Clearway Energy, Inc. HARRISBURG PA | B5: 49 | C5: 3843.4087 | D5: 3346.3851 | E5: 497.0236 | F5: =IFERROR(E5/C5,"") -> 0.12931844
A6: Grand Total | B6: 61 | C6: 12984.419 | D6: 12560.525 | E6: 423.8936 | F6: =IFERROR(E6/C6,"") -> 0.032646329
F7: =IFERROR(E7/C7,"")
F8: =IFERROR(E8/C8,"")
F9: =IFERROR(E9/C9,"")
F10: =IFERROR(E10/C10,"")
F11: =IFERROR(E11/C11,"")
F12: =IFERROR(E12/C12,"")
F13: =IFERROR(E13/C13,"")
F14: =IFERROR(E14/C14,"")
F15: =IFERROR(E15/C15,"")
F16: =IFERROR(E16/C16,"")
F17: =IFERROR(E17/C17,"")
F18: =IFERROR(E18/C18,"")
... F64: =IFERROR(E64/C64,"")

Sheet Segment.Confidential
A1: Segment Breakdown
A2: Segment | B2: # SKUs | C2: Total Current Spend | D2: PA Ext Price | E2: % of Total | F2: Savings $ | G2: Saving %
A3: AUTOMATION CONTROL | B3: =COUNTIF(ItemDetail.Confidential!$G:$G,A3) -> 3 | C3: =SUMIF(ItemDetail.Confidential!$G:$G,A3,ItemDetail.Confidential!$J:$J) -> 2182.23 | D3: =SUMIF(ItemDetail.Confidential!$G:$G,A3,ItemDetail.Confidential!$Q:$Q) -> 1669.07 | E3: =C3/$C$14 -> 0.16806528 | F3: =C3-D3 -> 513.16 | G3: =IFERROR(F3/C3,0) -> 0.23515395
A4: BOXES, ENCLOSURES, F | B4: =COUNTIF(ItemDetail.Confidential!$G:$G,A4) -> 25 | C4: =SUMIF(ItemDetail.Confidential!$G:$G,A4,ItemDetail.Confidential!$J:$J) -> 6760.1587 | D4: =SUMIF(ItemDetail.Confidential!$G:$G,A4,ItemDetail.Confidential!$Q:$Q) -> 7393.6051 | E4: =C4/$C$14 -> 0.52063622 | F4: =C4-D4 -> -633.4464 | G4: =IFERROR(F4/C4,0) -> -0.093702889
A5: CD CABLING | B5: =COUNTIF(ItemDetail.Confidential!$G:$G,A5) -> 1 | C5: =SUMIF(ItemDetail.Confidential!$G:$G,A5,ItemDetail.Confidential!$J:$J) -> 5.04 | D5: =SUMIF(ItemDetail.Confidential!$G:$G,A5,ItemDetail.Confidential!$Q:$Q) -> 3.42 | E5: =C5/$C$14 -> 0.00038815754 | F5: =C5-D5 -> 1.62 | G5: =IFERROR(F5/C5,0) -> 0.32142857
A6: CD CONNECTIVITY | B6: =COUNTIF(ItemDetail.Confidential!$G:$G,A6) -> 0 | C6: =SUMIF(ItemDetail.Confidential!$G:$G,A6,ItemDetail.Confidential!$J:$J) -> 0 | D6: =SUMIF(ItemDetail.Confidential!$G:$G,A6,ItemDetail.Confidential!$Q:$Q) -> 0 | E6: =C6/$C$14 -> 0 | F6: =C6-D6 -> 0 | G6: =IFERROR(F6/C6,0) -> 0
A7: CD VOICE, ACTIVE COM | B7: =COUNTIF(ItemDetail.Confidential!$G:$G,A7) -> 1 | C7: =SUMIF(ItemDetail.Confidential!$G:$G,A7,ItemDetail.Confidential!$J:$J) -> 115.7 | D7: =SUMIF(ItemDetail.Confidential!$G:$G,A7,ItemDetail.Confidential!$Q:$Q) -> 114.18 | E7: =C7/$C$14 -> 0.00891068 | F7: =C7-D7 -> 1.52 | G7: =IFERROR(F7/C7,0) -> 0.013137424
A8: CONDUIT & CHANNEL | B8: =COUNTIF(ItemDetail.Confidential!$G:$G,A8) -> 3 | C8: =SUMIF(ItemDetail.Confidential!$G:$G,A8,ItemDetail.Confidential!$J:$J) -> 318.11 | D8: =SUMIF(ItemDetail.Confidential!$G:$G,A8,ItemDetail.Confidential!$Q:$Q) -> 273.24 | E8: =C8/$C$14 -> 0.024499364 | F8: =C8-D8 -> 44.87 | G8: =IFERROR(F8/C8,0) -> 0.14105184
A9: LIGHTING | B9: =COUNTIF(ItemDetail.Confidential!$G:$G,A9) -> 4 | C9: =SUMIF(ItemDetail.Confidential!$G:$G,A9,ItemDetail.Confidential!$J:$J) -> 1060.2 | D9: =SUMIF(ItemDetail.Confidential!$G:$G,A9,ItemDetail.Confidential!$Q:$Q) -> 927.4 | E9: =C9/$C$14 -> 0.081651711 | F9: =C9-D9 -> 132.8 | G9: =IFERROR(F9/C9,0) -> 0.12525939
A10: MRO | B10: =COUNTIF(ItemDetail.Confidential!$G:$G,A10) -> 21 | C10: =SUMIF(ItemDetail.Confidential!$G:$G,A10,ItemDetail.Confidential!$J:$J) -> 1885.895 | D10: =SUMIF(ItemDetail.Confidential!$G:$G,A10,ItemDetail.Confidential!$Q:$Q) -> 1570.985 | E10: =C10/$C$14 -> 0.14524293 | F10: =C10-D10 -> 314.91 | G10: =IFERROR(F10/C10,0) -> 0.16698172
A11: POWER DISTRIBUTION | B11: =COUNTIF(ItemDetail.Confidential!$G:$G,A11) -> 1 | C11: =SUMIF(ItemDetail.Confidential!$G:$G,A11,ItemDetail.Confidential!$J:$J) -> 291.17 | D11: =SUMIF(ItemDetail.Confidential!$G:$G,A11,ItemDetail.Confidential!$Q:$Q) -> 309.07 | E11: =C11/$C$14 -> 0.02242457 | F11: =C11-D11 -> -17.9 | G11: =IFERROR(F11/C11,0) -> -0.061476114
A12: Undefined | B12: =COUNTIF(ItemDetail.Confidential!$G:$G,A12) -> 0 | C12: =SUMIF(ItemDetail.Confidential!$G:$G,A12,ItemDetail.Confidential!$J:$J) -> 0 | D12: =SUMIF(ItemDetail.Confidential!$G:$G,A12,ItemDetail.Confidential!$Q:$Q) -> 0 | E12: =C12/$C$14 -> 0 | F12: =C12-D12 -> 0 | G12: =IFERROR(F12/C12,0) -> 0
A13: WIRE & CABLE | B13: =COUNTIF(ItemDetail.Confidential!$G:$G,A13) -> 2 | C13: =SUMIF(ItemDetail.Confidential!$G:$G,A13,ItemDetail.Confidential!$J:$J) -> 365.915 | D13: =SUMIF(ItemDetail.Confidential!$G:$G,A13,ItemDetail.Confidential!$Q:$Q) -> 299.555 | E13: =C13/$C$14 -> 0.028181084 | F13: =C13-D13 -> 66.36 | G13: =IFERROR(F13/C13,0) -> 0.18135359
A14: Totals | B14: =SUM(B3:B13) -> 61 | C14: =SUM(C3:C13) -> 12984.419 | D14: =SUM(D3:D13) -> 12560.525 | F14: =SUM(F3:F13) -> 423.8936 | G14: =F14/C14 -> 0.032646329

Sheet ItemDetail.Confidential
A1: GLINE | B1: CUSTOMER NAME | C1: ITEM NUMBER | D1: Catalog Number | E1: ITEM DESCRIPTION | F1: BRAND NAME | G1: PRODUCT SEGMENT | H1: PRODUCT FAMILY | I1: MATERIAL CATEGORY | J1: Current Extended | K1: Current Price | L1: TRANSACTIONS | M1: QTY PURCHASED | N1: Savings $ | O1: Savings % | P1: Savings Cat. | Q1: PA Extended | R1: PA Price | S1: CSPL | T1: Notes | U1: Catalog Price | V1: Catalog Price UOM | W1: PURCHASE AMOUNT | X1: Per Each Price | Y1: Is this Better?
A2: 1 | B2: Clearway Energy, Inc. MINNEAPOLIS MN | C2: 22053355 | D2: LDB-3 | E2: ADVANCED LOOP DETECTOR | F2: VIKING ELECTRONICS INCORPORATED | G2: CD VOICE, ACTIVE COM | H2: Voice Security Notif | I2: CD VOICE, ACTIVE COM | J2: 115.7 | K2: 57.85 | L2: 2 | M2: 2 | N2: 1.52 | O2: 0.013137424 | P2: 0-10% | Q2: 114.18 | R2: 57.09 | T2: SCHEDULE OF DISCOUNT | U2: 70.9 | V2: 1 | W2: 107.69 | X2: 70.9 | Y2: TRUE
A3: 5 | B3: Clearway Energy, Inc. PITTSBURGH PA | C3: 88017157 | D3: ACP1034CD | E3: 100A CLAMP RING PLUG 3W4P ST2 | F3: APPLETON ELECTRIC | G3: BOXES, ENCLOSURES, F | H3: Pin & Sleeve | I3: BOXES, ENCLOSURES, F | J3: 6022.9 | K3: 602.29 | L3: 1 | M3: 10 | N3: -642.4 | O3: -0.10665958 | P3: Negative | Q3: 6665.3 | R3: 666.53 | T3: SCHEDULE OF DISCOUNT | U3: 1047.93 | V3: 1 | W3: 5142.2 | X3: 1047.93 | Y3: TRUE
A4: 6 | B4: Clearway Energy, Inc. PITTSBURGH PA | C4: 88052890 | D4: NOS-40 | E4: BUSS ONE TIME FUSE | F4: COOPER BUSSMANN INC | G4: MRO | H4: Branch Circuit Fuses | I4: MRO | J4: 59.82 | K4: 9.97 | L4: 2 | M4: 6 | N4: -40.68 | O4: -0.68004012 | P4: Negative | Q4: 100.5 | R4: 16.75 | T4: SCHEDULE OF DISCOUNT | U4: 40.69 | V4: 1 | W4: 48.24 | X4: 40.69 | Y4: TRUE
A5: 7 | B5: Clearway Energy, Inc. PITTSBURGH PA | C5: 88148040 | D5: G1050 | E5: NM POLYTUFF I GY 1/2 | F5: HUBBELL WIRING DEVICES | G5: CONDUIT & CHANNEL | H5: Non-Metallic Tubing | I5: CONDUIT & CHANNEL | J5: 105 | K5: 1.05 | L5: 1 | M5: 100 | N5: 40 | O5: 0.38095238 | P5: 30+% | Q5: 65 | R5: 0.65 | T5: SCHEDULE OF DISCOUNT | U5: 1.18 | V5: 1 | W5: 96 | X5: 1.18 | Y5: TRUE
A6: 8 | B6: Clearway Energy, Inc. PITTSBURGH PA | C6: 92042245 | D6: 35PAR36/H/FL30 | E6: HALOGEN LAMP | F6: CURRENT LIGHTING SOLUTIONS LLC | G6: LIGHTING | H6: Halogen Lamps | I6: LIGHTING | J6: 262.2 | K6: 21.85 | L6: 1 | M6: 12 | N6: 49.8 | O6: 0.18993135 | P6: 10-20% | Q6: 212.4 | R6: 17.7 | T6: SCHEDULE OF DISCOUNT | U6: 21.22 | V6: 1 | W6: 208.08 | X6: 21.22 | Y6: TRUE
A7: 14 | B7: Clearway Energy, Inc. PITTSBURGH PA | C7: 25563178 | D7: XY2CE3C010TK | E7: INACTIVE CABLE PULL SWITCH 300 VAC 10A | F7: SCHNEIDER ELECTRIC USA INC | G7: AUTOMATION CONTROL | H7: Automation & Cont | I7: AUTOMATION CONTROL | J7: 1675.8 | K7: 558.6 | L7: 3 | M7: 3 | N7: 427.95 | O7: 0.25537057 | P7: 20-30% | Q7: 1247.85 | R7: 415.95 | T7: SCHEDULE OF DISCOUNT | U7: 596.28 | V7: 1 | W7: 1652.07 | X7: 596.28 | Y7: TRUE
A8: 16 | B8: Clearway Energy, Inc. PITTSBURGH PA | C8: 88052111 | D8: KTK-4 | E8: LIMITRON FAST ACTING FUSE | F8: COOPER BUSSMANN INC | G8: MRO | H8: Supplementary Fuses | I8: MRO | J8: 54.48 | K8: 9.08 | L8: 1 | M8: 6 | N8: 1.2 | O8: 0.022026432 | P8: 0-10% | Q8: 53.28 | R8: 8.88 | T8: SCHEDULE OF DISCOUNT | U8: 27.57 | V8: 1 | W8: 46.14 | X8: 27.57 | Y8: TRUE
A9: 17 | B9: Clearway Energy, Inc. PITTSBURGH PA | C9: 93174138 | D9: LP-CC-1 | E9: LOW PEAK CC TIME DELAY | F9: COOPER BUSSMANN INC | G9: MRO | H9: Branch Circuit Fuses | I9: MRO | J9: 50.44 | K9: 12.61 | L9: 1 | M9: 4 | N9: 11.92 | O9: 0.23632038 | P9: 20-30% | Q9: 38.52 | R9: 9.63 | S9: CORE | T9: NET | U9: 29.94 | V9: 1 | W9: 45.04 | X9: 29.94 | Y9: TRUE
A10: 22 | B10: Clearway Energy, Inc. PITTSBURGH PA | C10: 90001839 | D10: TY164 | E10: 400FT 16-1/2G TIE WIRE | F10: L H DOTTIE CO | G10: MRO | H10: Wiring Acc & Ties | I10: MRO | J10: 112.88 | K10: 14.11 | L10: 1 | M10: 8 | N10: 44.16 | O10: 0.39121191 | P10: 30+% | Q10: 68.72 | R10: 8.59 | T10: SCHEDULE OF DISCOUNT | U10: 16.32 | V10: 1 | W10: 97.6 | X10: 16.32 | Y10: TRUE
A11: 23 | B11: Clearway Energy, Inc. PITTSBURGH PA | C11: 88284562 | D11: THHN-12-STR-GRN-500S | E11: THHN/THWN-2 19 STR 600V 90DEG CU | F11: GENERIC VENDOR WIRE-WYRPA | G11: WIRE & CABLE | H11: Bldng WYR -T-CU Crct | I11: WIRE & CABLE | J11: 285.12 | K11: 0.28512 | L11: 2 | M11: 1000 | N11: 61.3 | O11: 0.21499719 | P11: 20-30% | Q11: 223.82 | R11: 0.22382 | T11: SCHEDULE OF DISCOUNT | U11: 306.99 | V11: 1000 | W11: 270.51 | X11: 0.30699 | Y11: TRUE
A12: 24 | B12: Clearway Energy, Inc. PITTSBURGH PA | C12: 88176018 | D12: 5322 | E12: MOTOR LEAD SPLICING KIT (3 SPLICES/KIT) | F12: 3M CO. - ELECTRICAL MARKETS DIV. | G12: POWER DISTRIBUTION | H12: SplcngTermin&Elbws | I12: POWER DISTRIBUTION | J12: 291.17 | K12: 291.17 | L12: 1 | M12: 1 | N12: -17.9 | O12: -0.061476114 | P12: Negative | Q12: 309.07 | R12: 309.07 | T12: SCHEDULE OF DISCOUNT | U12: 392.56 | V12: 1 | W12: 219.25 | X12: 392.56 | Y12: TRUE
A13: 25 | B13: Clearway Energy, Inc. PITTSBURGH PA | C13: 88050707 | D13: FRS-R-1-4/10 | E13: FUSETRON DUAL ELEMENT FUSE CLASS RK5 | F13: COOPER BUSSMANN INC | G13: MRO | H13: Branch Circuit Fuses | I13: MRO | J13: 105.5 | K13: 10.55 | L13: 3 | M13: 10 | N13: -10 | O13: -0.09478673 | P13: Negative | Q13: 115.5 | R13: 11.55 | T13: SCHEDULE OF DISCOUNT | U13: 47.29 | V13: 1 | W13: 95.4 | X13: 47.29 | Y13: TRUE
A14: 26 | B14: Clearway Energy, Inc. HARRISBURG PA | C14: 26046047 | D14: LED14ET8/G/4/850 | E14: LED GLASS TUBE 4FT 14W 5000K | F14: CURRENT LIGHTING SOLUTIONS LLC | G14: LIGHTING | H14: LED Lamps & Systems | I14: LIGHTING | J14: 400.2 | K14: 6.67 | L14: 2 | M14: 60 | N14: 38.4 | O14: 0.095952024 | P14: 0-10% | Q14: 361.8 | R14: 6.03 | T14: SCHEDULE OF DISCOUNT | U14: 6.3 | V14: 1 | W14: 353.4 | X14: 6.3 | Y14: TRUE
A15: 27 | B15: Clearway Energy, Inc. HARRISBURG PA | C15: 26355384 | D15: 33+SUPER-3/4X76FT | E15: VINYL TAPE 3/4 X 76 | F15: 3M CO. - ELECTRICAL MARKETS DIV. | G15: MRO | H15: Insulating Material | I15: MRO | J15: 77.6 | K15: 7.76 | L15: 1 | M15: 10 | N15: 30.5 | O15: 0.39304124 | P15: 30+% | Q15: 47.1 | R15: 4.71 | S15: CORE | T15: NET | U15: 9.73 | V15: 1 | W15: 55.9 | X15: 9.73 | Y15: TRUE
A16: 28 | B16: Clearway Energy, Inc. HARRISBURG PA | C16: 88175835 | D16: 130C-1-1/2X30FT | E16: LINERLESS RUBBER TAPE 1 1/2 X 30 | F16: 3M CO. - ELECTRICAL MARKETS DIV. | G16: MRO | H16: Insulating Material | I16: MRO | J16: 171.65 | K16: 34.33 | L16: 1 | M16: 5 | N16: 24.85 | O16: 0.14477134 | P16: 10-20% | Q16: 146.8 | R16: 29.36 | T16: NET | U16: 48.12 | V16: 1 | W16: 141.45 | X16: 48.12 | Y16: TRUE
A17: 29 | B17: Clearway Energy, Inc. HARRISBURG PA | C17: 88175838 | D17: 130C-3/4X30FT | E17: LINERLESS RUBBER TAPE 3/4 X 30 | F17: 3M CO. - ELECTRICAL MARKETS DIV. | G17: MRO | H17: Insulating Material | I17: MRO | J17: 159.9 | K17: 15.99 | L17: 1 | M17: 10 | N17: 60.8 | O17: 0.38023765 | P17: 30+% | Q17: 99.1 | R17: 9.91 | S17: CORE | T17: NET | U17: 24.03 | V17: 1 | W17: 131.9 | X17: 24.03 | Y17: TRUE
A18: 30 | B18: Clearway Energy, Inc. HARRISBURG PA | C18: 88176158 | D18: 70-1X30FT | E18: SILICONE RUBBER TAPE 1 X 30 | F18: 3M CO. - ELECTRICAL MARKETS DIV. | G18: MRO | H18: Insulating Material | I18: MRO | J18: 332.35 | K18: 66.47 | L18: 1 | M18: 5 | N18: 37.2 | O18: 0.11193019 | P18: 10-20% | Q18: 295.15 | R18: 59.03 | T18: SCHEDULE OF DISCOUNT | U18: 114.99 | V18: 1 | W18: 253 | X18: 114.99 | Y18: TRUE
A19: 31 | B19: Clearway Energy, Inc. HARRISBURG PA | C19: 25081087 | D19: SS8 | E19: WALLPLATE 1-G DUPLEX RECEPTACLESS | F19: HUBBELL WIRING DEVICES | G19: BOXES, ENCLOSURES, F | H19: Rcptcle Wll Plts/Cvr | I19: BOXES, ENCLOSURES, F | J19: 2.12 | K19: 2.12 | L19: 1 | M19: 1 | N19: 0.96 | O19: 0.45283019 | P19: 30+% | Q19: 1.16 | R19: 1.16 | T19: SCHEDULE OF DISCOUNT | U19: 2.33 | V19: 1 | W19: 2.02 | X19: 2.33 | Y19: TRUE
A20: 32 | B20: Clearway Energy, Inc. HARRISBURG PA | C20: 88128229 | D20: CR20I | E20: DUP RCPT COMM GRD 20A 125V 5-20R IV | F20: HUBBELL WIRING DEVICES | G20: BOXES, ENCLOSURES, F | H20: Electric Receptacles | I20: BOXES, ENCLOSURES, F | J20: 2.42 | K20: 2.42 | L20: 1 | M20: 1 | N20: 0.37 | O20: 0.15289256 | P20: 10-20% | Q20: 2.05 | R20: 2.05 | T20: SCHEDULE OF DISCOUNT | U20: 2.46 | V20: 1 | W20: 2.33 | X20: 2.46 | Y20: TRUE
A21: 33 | B21: Clearway Energy, Inc. HARRISBURG PA | C21: 88131255 | D21: A1212CH | E21: J BOX TYPE 12 HINGED COVER | F21: HOFFMAN ENCLOSURES, INC | G21: BOXES, ENCLOSURES, F | H21: Enclosures | I21: BOXES, ENCLOSURES, F | J21: 160.99 | K21: 160.99 | L21: 1 | M21: 1 | N21: 47.71 | O21: 0.29635381 | P21: 20-30% | Q21: 113.28 | R21: 113.28 | S21: CORE | T21: NET | U21: 245.23 | V21: 1 | W21: 152.61 | X21: 245.23 | Y21: TRUE
A22: 34 | B22: Clearway Energy, Inc. HARRISBURG PA | C22: 88131284 | D22: A12P12 | E22: PANEL J BOX 10.75X10.88 | F22: HOFFMAN ENCLOSURES, INC | G22: BOXES, ENCLOSURES, F | H22: Enclosure Acces | I22: BOXES, ENCLOSURES, F | J22: 19.64 | K22: 19.64 | L22: 1 | M22: 1 | N22: 4.67 | O22: 0.23778004 | P22: 20-30% | Q22: 14.97 | R22: 14.97 | T22: SCHEDULE OF DISCOUNT | U22: 18.37 | V22: 1 | W22: 17.9 | X22: 18.37 | Y22: TRUE
A23: 35 | B23: Clearway Energy, Inc. HARRISBURG PA | C23: 88272942 | D23: 3/4-EMT | E23: 3/4-STEEL THINWALL CONDUIT | F23: GENERIC VENDOR-TUBPA | G23: CONDUIT & CHANNEL | H23: Rigid Metal Conduit | I23: CONDUIT & CHANNEL | J23: 135.56 | K23: 1.3556 | L23: 1 | M23: 100 | N23: -3.54 | O23: -0.026113898 | P23: Negative | Q23: 139.1 | R23: 1.391 | T23: COMMODITY | U23: 146.8 | V23: 100 | W23: 128.88 | X23: 1.468 | Y23: TRUE
A24: 36 | B24: Clearway Energy, Inc. HARRISBURG PA | C24: 94005349 | D24: BT3S-C0 | E24: BARB-TY 12IN .185 OUTDOOR | F24: PANDUIT CORP | G24: MRO | H24: Wiring Acc & Ties | I24: MRO | J24: 56 | K24: 0.28 | L24: 1 | M24: 200 | N24: 6.62 | O24: 0.11821429 | P24: 10-20% | Q24: 49.38 | R24: 0.2469 | T24: SCHEDULE OF DISCOUNT | U24: 51.32 | V24: 100 | W24: 52.34 | X24: 0.5132 | Y24: TRUE
A25: 37 | B25: Clearway Energy, Inc. HARRISBURG PA | C25: 94005350 | D25: BT4S-C0 | E25: NYLON CABLE TIE | F25: PANDUIT CORP | G25: MRO | H25: Wiring Acc & Ties | I25: MRO | J25: 31.23 | K25: 0.3123 | L25: 1 | M25: 100 | N25: 4.83 | O25: 0.15465898 | P25: 10-20% | Q25: 26.4 | R25: 0.264 | T25: NET | U25: 87.1 | V25: 100 | W25: 28.46 | X25: 0.871 | Y25: TRUE
A26: 38 | B26: Clearway Energy, Inc. HARRISBURG PA | C26: 94007543 | D26: BT5LH-L0 | E26: NYLON CABLE TIE | F26: PANDUIT CORP | G26: MRO | H26: Wiring Acc & Ties | I26: MRO | J26: 81.29 | K26: 0.8129 | L26: 1 | M26: 100 | N26: 26.08 | O26: 0.32082667 | P26: 30+% | Q26: 55.21 | R26: 0.5521 | T26: SCHEDULE OF DISCOUNT | U26: 120.84 | V26: 100 | W26: 76 | X26: 1.2084 | Y26: TRUE
A27: 39 | B27: Clearway Energy, Inc. HARRISBURG PA | C27: 97230814 | D27: TP7010 | E27: 1G WP BOX W/3 1/2 HUBS | F27: COOPER CROUSE-HINDS DIVISION | G27: BOXES, ENCLOSURES, F | H27: WP Boxes | I27: BOXES, ENCLOSURES, F | J27: 3.3652 | K27: 3.3652 | L27: 1 | M27: 1 | N27: 0.1705 | O27: 0.050665637 | P27: 0-10% | Q27: 3.1947 | R27: 3.1947 | T27: SCHEDULE OF DISCOUNT | U27: 1193.81 | V27: 100 | W27: 2.75 | X27: 11.9381 | Y27: TRUE
A28: 40 | B28: Clearway Energy, Inc. HARRISBURG PA | C28: 99477183 | D28: TP403 | E28: 4SQ 2-1/8D BOX 1/2 AND 3/4 KO | F28: COOPER CROUSE-HINDS DIVISION | G28: BOXES, ENCLOSURES, F | H28: 4Sq Bx,Rngs,Cvrs | I28: BOXES, ENCLOSURES, F | J28: 12.2946 | K28: 2.0491 | L28: 1 | M28: 6 | N28: 3.246 | O28: 0.26401835 | P28: 20-30% | Q28: 9.0486 | R28: 1.5081 | S28: CORE | T28: NET | U28: 1506.11 | V28: 100 | W28: 9.7 | X28: 15.0611 | Y28: TRUE
A29: 41 | B29: Clearway Energy, Inc. HARRISBURG PA | C29: 99894914 | D29: ECAT5-4PR-14-BLB | E29: CAT 5E 14FT BLUE | F29: LYNN ELECTRONICS CORP | G29: CD CABLING | H29: Sld&StrndCondPtchCrd | I29: CD CABLING | J29: 5.04 | K29: 5.04 | L29: 1 | M29: 1 | N29: 1.62 | O29: 0.32142857 | P29: 30+% | Q29: 3.42 | R29: 3.42 | T29: SCHEDULE OF DISCOUNT | U29: 5.84 | V29: 1 | W29: 3.18 | X29: 5.84 | Y29: TRUE
A30: 42 | B30: Clearway Energy, Inc. HARRISBURG PA | C30: 25146061 | D30: 9038CG36N5 | E30: FLOAT SWITCH 575VAC 1HP TYPE C OPTIONS | F30: SCHNEIDER ELECTRIC USA INC | G30: AUTOMATION CONTROL | H30: Automation & Cont | I30: AUTOMATION CONTROL | J30: 406.68 | K30: 406.68 | L30: 1 | M30: 1 | N30: 39.26 | O30: 0.096537818 | P30: 0-10% | Q30: 367.42 | R30: 367.42 | T30: SCHEDULE OF DISCOUNT | U30: 522.9 | V30: 1 | W30: 399.12 | X30: 522.9 | Y30: TRUE
A31: 43 | B31: Clearway Energy, Inc. HARRISBURG PA | C31: 25249854 | D31: M21-187-C-342 | E31: CART M21 B342 .187INX7FTPERMASLEEVE | F31: BRADY WORLDWIDE INCORPORATED | G31: MRO | H31: ID Products Labeling | I31: MRO | J31: 107.98 | K31: 53.99 | L31: 1 | M31: 2 | N31: -0.46 | O31: -0.0042600482 | P31: Negative | Q31: 108.44 | R31: 54.22 | T31: SCHEDULE OF DISCOUNT | U31: 62.12 | V31: 1 | W31: 103.98 | X31: 62.12 | Y31: TRUE
A32: 44 | B32: Clearway Energy, Inc. HARRISBURG PA | C32: 25249882 | D32: M21-750-427 | E32: CART M21 B427 0.75INX14FT SELF LAM | F32: BRADY WORLDWIDE INCORPORATED | G32: MRO | H32: ID Products Labeling | I32: MRO | J32: 63.98 | K32: 31.99 | L32: 1 | M32: 2 | N32: -0.5 | O32: -0.0078149422 | P32: Negative | Q32: 64.48 | R32: 32.24 | T32: SCHEDULE OF DISCOUNT | U32: 39.17 | V32: 1 | W32: 61.38 | X32: 39.17 | Y32: TRUE
A33: 45 | B33: Clearway Energy, Inc. HARRISBURG PA | C33: 25569603 | D33: ICE 125 32 17 02-CUT REEL | E33: 1 1/4 HDPE CORRUGATED INNERDUCT W/TAPE | F33: ENDOT INDUSTRIES INC | G33: CONDUIT & CHANNEL | H33: Specialty Raceway | I33: CONDUIT & CHANNEL | J33: 77.55 | K33: 0.7755 | L33: 3 | M33: 100 | N33: 8.41 | O33: 0.10844616 | P33: 10-20% | Q33: 69.14 | R33: 0.6914 | T33: SCHEDULE OF DISCOUNT | U33: 73.89 | V33: 100 | W33: 43.53 | X33: 0.7389 | Y33: TRUE
A34: 46 | B34: Clearway Energy, Inc. HARRISBURG PA | C34: 25712101 | D34: GFRST20I | E34: 20A COM SELF TEST GFR IVORY | F34: HUBBELL WIRING DEVICES | G34: BOXES, ENCLOSURES, F | H34: GFCI Receptacles | I34: BOXES, ENCLOSURES, F | J34: 15.44 | K34: 15.44 | L34: 1 | M34: 1 | N34: 1.94 | O34: 0.12564767 | P34: 10-20% | Q34: 13.5 | R34: 13.5 | T34: NET | U34: 30 | V34: 1 | W34: 14.51 | X34: 30 | Y34: TRUE
A35: 47 | B35: Clearway Energy, Inc. HARRISBURG PA | C35: 25846511 | D35: 5240 | E35: TRPRO SMALL MAINTENANCE POUCH | F35: KLEIN TOOLS INC | G35: MRO | H35: Tool Storage/Bags | I35: MRO | J35: 26.87 | K35: 26.87 | L35: 1 | M35: 1 | N35: 6.89 | O35: 0.2564198 | P35: 20-30% | Q35: 19.98 | R35: 19.98 | T35: SCHEDULE OF DISCOUNT | U35: 29.13 | V35: 1 | W35: 25.71 | X35: 29.13 | Y35: TRUE
A36: 48 | B36: Clearway Energy, Inc. HARRISBURG PA | C36: 25889114 | D36: LED15LS2/850 | E36: LED BRIGHT STIK 15W 5000K 2PK | F36: CURRENT LIGHTING SOLUTIONS LLC | G36: LIGHTING | H36: LED Lamps & Systems | I36: LIGHTING | J36: 124.2 | K36: 12.42 | L36: 1 | M36: 10 | N36: 12.2 | O36: 0.098228663 | P36: 0-10% | Q36: 112 | R36: 11.2 | T36: SCHEDULE OF DISCOUNT | U36: 16.37 | V36: 1 | W36: 115.2 | X36: 16.37 | Y36: TRUE
A37: 49 | B37: Clearway Energy, Inc. HARRISBURG PA | C37: 26046047 | D37: LED14ET8/G/4/850 | E37: LED GLASS TUBE 4FT 14W 5000K | F37: CURRENT LIGHTING SOLUTIONS LLC | G37: LIGHTING | H37: LED Lamps & Systems | I37: LIGHTING | J37: 273.6 | K37: 6.84 | L37: 1 | M37: 40 | N37: 32.4 | O37: 0.11842105 | P37: 10-20% | Q37: 241.2 | R37: 6.03 | T37: SCHEDULE OF DISCOUNT | U37: 6.3 | V37: 1 | W37: 260.4 | X37: 6.3 | Y37: TRUE
A38: 51 | B38: Clearway Energy, Inc. HARRISBURG PA | C38: 26355384 | D38: 33+SUPER-3/4X76FT | E38: VINYL TAPE 3/4 X 76 | F38: 3M CO. - ELECTRICAL MARKETS DIV. | G38: MRO | H38: Insulating Material | I38: MRO | J38: 80.1 | K38: 8.01 | L38: 1 | M38: 10 | N38: 33 | O38: 0.41198502 | P38: 30+% | Q38: 47.1 | R38: 4.71 | S38: CORE | T38: NET | U38: 9.73 | V38: 1 | W38: 72.8 | X38: 9.73 | Y38: TRUE
A39: 52 | B39: Clearway Energy, Inc. HARRISBURG PA | C39: 88050674 | D39: FRN-R-30 | E39: FUSETRON DUAL-ELEMENT CLASS RK5 | F39: COOPER BUSSMANN INC | G39: MRO | H39: Branch Circuit Fuses | I39: MRO | J39: 34.2 | K39: 3.42 | L39: 3 | M39: 10 | N39: 0.9 | O39: 0.026315789 | P39: 0-10% | Q39: 33.3 | R39: 3.33 | T39: SCHEDULE OF DISCOUNT | U39: 9.87 | V39: 1 | W39: 25.8 | X39: 9.87 | Y39: TRUE
A40: 53 | B40: Clearway Energy, Inc. HARRISBURG PA | C40: 88073427 | D40: LT5045 | E40: 1/2 45D L/T CONN | F40: COOPER CROUSE-HINDS DIVISION | G40: BOXES, ENCLOSURES, F | H40: LQDTIGHT Ftngs | I40: BOXES, ENCLOSURES, F | J40: 60.8875 | K40: 2.4355 | L40: 3 | M40: 25 | N40: -2.4125 | O40: -0.039622254 | P40: Negative | Q40: 63.3 | R40: 2.532 | S40: CORE | T40: NET | U40: 1352.35 | V40: 100 | W40: 58.37 | X40: 13.5235 | Y40: TRUE
...

Sheet Excluded.Confidential
A1: GLINE | B1: CUSTOMER NAME | C1: ITEM NUMBER | D1: Catalog Number | E1: ITEM DESCRIPTION | F1: BRAND NAME | G1: PRODUCT SEGMENT | H1: PRODUCT FAMILY | I1: MATERIAL CATEGORY | J1: PURCHASE AMOUNT | K1: TRANSACTIONS | L1: QTY PURCHASED | M1: CSPL | N1: Notes
A2: 2 | B2: Clearway Energy, Inc. MINNEAPOLIS MN | C2: 25060624 | D2: C-200 | E2: BASIC SGL ENTRY PHONE INTERFACE | F2: VIKING ELECTRONICS INCORPORATED | G2: CD VOICE, ACTIVE COM | H2: Voice Security Notif | I2: CD VOICE, ACTIVE COM | J2: 165 | K2: 1 | L2: 1 | M2: #N/A | N2: SOU
A3: 3 | B3: Clearway Energy, Inc. MINNEAPOLIS MN | C3: NOF ORT CATVHDWRE | D3: 802-L31-248PE | F3: ORTRONICS INCORPORATED | G3: CD VOICE, ACTIVE COM | H3: Othr Comm Products | I3: CD VOICE, ACTIVE COM | J3: 279.12 | K3: 1 | L3: 2 | M3: #N/A | N3: SOU
A4: 11 | B4: Clearway Energy, Inc. PITTSBURGH PA | C4: NOF GEN CURRENT | D4: NOF CURRENT LIGHTING SOLUTIONS LLC | F4: CURRENT LIGHTING SOLUTIONS LLC | G4: LIGHTING | H4: Fluorescent Lamps | I4: LIGHTING | J4: 70.18 | K4: 1 | L4: 1 | M4: #N/A | N4: SOU
A5: 12 | B5: Clearway Energy, Inc. PITTSBURGH PA | C5: NOF JBY SIGNLEQUIP | D5: MINIMUM CHARGE | F5: JASCO BATTERY | G5: MRO | H5: SgnlEquip&BldrsPrd | I5: MRO | J5: 12.29 | K5: 1 | L5: 1 | M5: #N/A | N5: FIND
A6: 13 | B6: Clearway Energy, Inc. PITTSBURGH PA | C6: NOF PP2 PORTABLE | D6: 44F7570 | F6: PORTABLE POWER SYSTEMS | G6: MRO | H6: Miscellaneous | I6: MRO | J6: 51.48 | K6: 1 | L6: 2 | M6: #N/A | N6: FIND
A7: 20 | B7: Clearway Energy, Inc. PITTSBURGH PA | C7: NOF JBY SIGNLEQUIP | D7: RB1270 | F7: JASCO BATTERY | G7: MRO | H7: SgnlEquip&BldrsPrd | I7: MRO | J7: 28.24 | K7: 1 | L7: 2 | M7: #N/A | N7: FIND
A8: 21 | B8: Clearway Energy, Inc. PITTSBURGH PA | C8: NOF JBY SIGNLEQUIP | D8: RB640 (LC-R064R5P) | F8: JASCO BATTERY | G8: MRO | H8: SgnlEquip&BldrsPrd | I8: MRO | J8: 5.88 | K8: 1 | L8: 1 | M8: #N/A | N8: FIND
A9: 78 | B9: Clearway Energy, Inc. HARRISBURG PA | C9: NOF RE2 RELAYCONTR | D9: RS-5 | F9: RELAY & CONTROL CORP | G9: MRO | H9: Miscellaneous | I9: MRO | J9: 169.77 | K9: 1 | L9: 1 | M9: #N/A | N9: FIND
A10: ZZ | B10: Clearway Energy, Inc. PITTSBURGH PA | C10: 25201915 | D10: RB1252 | E10: 12V 5AH SLA BATTERY F1 | F10: JASCO BATTERY | G10: MRO | H10: Builders Prodcts | I10: MRO | J10: 24.24 | K10: 1 | L10: 2 | M10: #N/A | N10: FIND
A11: ZZ | B11: Clearway Energy, Inc. PITTSBURGH PA | C11: 25689191 | D11: ELP U023 | E11: CHARGING BOARD 12V NI-CAD | F11: LITHONIA LIGHTING | G11: LIGHTING | H11: LghtFxtrs-Resid | I11: LIGHTING | J11: 607.2 | K11: 1 | L11: 5 | M11: #N/A | N11: SOU
A12: ZZ | B12: Clearway Energy, Inc. PITTSBURGH PA | C12: 99567462 | D12: ELP U012 | E12: 12V CHARGER BOARD | F12: LITHONIA LIGHTING | G12: LIGHTING | H12: Emergcy Power Backup | I12: LIGHTING | J12: 494.1 | K12: 1 | L12: 6 | M12: #N/A | N12: SOU

Sheet ItemDetail vs Historical
J1: 107.69 | M1: -6.49 | N1: -0.060265577 | P1: 114.18 | R1: 115.7
A2: GLINE | B2: CUSTOMER NAME | C2: ITEM NUMBER | D2: Catalog Number | E2: ITEM DESCRIPTION | F2: BRAND NAME | G2: PRODUCT SEGMENT | H2: PRODUCT FAMILY | I2: MATERIAL CATEGORY | J2: PURCHASE AMOUNT | K2: TRANSACTIONS | L2: QTY PURCHASED | M2: Savings $ | N2: Savings % | O2: Savings Cat. | P2: PA Extended | Q2: PA Price | R2: Current Extended | S2: Current Price | T2: Notes
A3: 1 | B3: Clearway Energy, Inc. MINNEAPOLIS MN | C3: 22053355 | D3: LDB-3 | E3: ADVANCED LOOP DETECTOR | F3: VIKING ELECTRONICS INCORPORATED | G3: CD VOICE, ACTIVE COM | H3: Voice Security Notif | I3: CD VOICE, ACTIVE COM | J3: 107.69 | K3: 2 | L3: 2 | M3: -6.49 | N3: -0.060265577 | O3: Negative | P3: 114.18 | Q3: 57.09 | R3: 115.7 | S3: 57.85 | T3: SCHEDULE OF DISCOUNT
A4: 5 | B4: Clearway Energy, Inc. PITTSBURGH PA | C4: 88017157 | D4: ACP1034CD | E4: 100A CLAMP RING PLUG 3W4P ST2 | F4: APPLETON ELECTRIC | G4: BOXES, ENCLOSURES, F | H4: Pin & Sleeve | I4: BOXES, ENCLOSURES, F | J4: 5142.2 | K4: 1 | L4: 10 | M4: -1523.1 | N4: -0.29619618 | O4: Negative | P4: 6665.3 | Q4: 666.53 | R4: 6022.9 | S4: 602.29 | T4: SCHEDULE OF DISCOUNT
A5: 6 | B5: Clearway Energy, Inc. PITTSBURGH PA | C5: 88052890 | D5: NOS-40 | E5: BUSS ONE TIME FUSE | F5: COOPER BUSSMANN INC | G5: MRO | H5: Branch Circuit Fuses | I5: MRO | J5: 48.24 | K5: 2 | L5: 6 | M5: -52.26 | N5: -1.0833333 | O5: Negative | P5: 100.5 | Q5: 16.75 | R5: 59.82 | S5: 9.97 | T5: SCHEDULE OF DISCOUNT
A6: 7 | B6: Clearway Energy, Inc. PITTSBURGH PA | C6: 88148040 | D6: G1050 | E6: NM POLYTUFF I GY 1/2 | F6: HUBBELL WIRING DEVICES | G6: CONDUIT & CHANNEL | H6: Non-Metallic Tubing | I6: CONDUIT & CHANNEL | J6: 96 | K6: 1 | L6: 100 | M6: 31 | N6: 0.32291667 | O6: 30+% | P6: 65 | Q6: 0.65 | R6: 105 | S6: 1.05 | T6: SCHEDULE OF DISCOUNT
A7: 8 | B7: Clearway Energy, Inc. PITTSBURGH PA | C7: 92042245 | D7: 35PAR36/H/FL30 | E7: HALOGEN LAMP | F7: CURRENT LIGHTING SOLUTIONS LLC | G7: LIGHTING | H7: Halogen Lamps | I7: LIGHTING | J7: 208.08 | K7: 1 | L7: 12 | M7: -4.32 | N7: -0.020761246 | O7: Negative | P7: 212.4 | Q7: 17.7 | R7: 262.2 | S7: 21.85 | T7: SCHEDULE OF DISCOUNT
A8: 14 | B8: Clearway Energy, Inc. PITTSBURGH PA | C8: 25563178 | D8: XY2CE3C010TK | E8: INACTIVE CABLE PULL SWITCH 300 VAC 10A | F8: SCHNEIDER ELECTRIC USA INC | G8: AUTOMATION CONTROL | H8: Automation & Cont | I8: AUTOMATION CONTROL | J8: 1652.07 | K8: 3 | L8: 3 | M8: 404.22 | N8: 0.24467486 | O8: 20-30% | P8: 1247.85 | Q8: 415.95 | R8: 1675.8 | S8: 558.6 | T8: SCHEDULE OF DISCOUNT
A9: 16 | B9: Clearway Energy, Inc. PITTSBURGH PA | C9: 88052111 | D9: KTK-4 | E9: LIMITRON FAST ACTING FUSE | F9: COOPER BUSSMANN INC | G9: MRO | H9: Supplementary Fuses | I9: MRO | J9: 46.14 | K9: 1 | L9: 6 | M9: -7.14 | N9: -0.15474642 | O9: Negative | P9: 53.28 | Q9: 8.88 | R9: 54.48 | S9: 9.08 | T9: SCHEDULE OF DISCOUNT
A10: 17 | B10: Clearway Energy, Inc. PITTSBURGH PA | C10: 93174138 | D10: LP-CC-1 | E10: LOW PEAK CC TIME DELAY | F10: COOPER BUSSMANN INC | G10: MRO | H10: Branch Circuit Fuses | I10: MRO | J10: 45.04 | K10: 1 | L10: 4 | M10: 6.52 | N10: 0.14476021 | O10: 10-20% | P10: 38.52 | Q10: 9.63 | R10: 50.44 | S10: 12.61 | T10: NET
A11: 22 | B11: Clearway Energy, Inc. PITTSBURGH PA | C11: 90001839 | D11: TY164 | E11: 400FT 16-1/2G TIE WIRE | F11: L H DOTTIE CO | G11: MRO | H11: Wiring Acc & Ties | I11: MRO | J11: 97.6 | K11: 1 | L11: 8 | M11: 28.88 | N11: 0.29590164 | O11: 20-30% | P11: 68.72 | Q11: 8.59 | R11: 112.88 | S11: 14.11 | T11: SCHEDULE OF DISCOUNT
A12: 23 | B12: Clearway Energy, Inc. PITTSBURGH PA | C12: 88284562 | D12: THHN-12-STR-GRN-500S | E12: THHN/THWN-2 19 STR 600V 90DEG CU | F12: GENERIC VENDOR WIRE-WYRPA | G12: WIRE & CABLE | H12: Bldng WYR -T-CU Crct | I12: WIRE & CABLE | J12: 270.51 | K12: 2 | L12: 1000 | M12: 46.69 | N12: 0.1725999 | O12: 10-20% | P12: 223.82 | Q12: 0.22382 | R12: 285.12 | S12: 0.28512 | T12: SCHEDULE OF DISCOUNT
A13: 24 | B13: Clearway Energy, Inc. PITTSBURGH PA | C13: 88176018 | D13: 5322 | E13: MOTOR LEAD SPLICING KIT (3 SPLICES/KIT) | F13: 3M CO. - ELECTRICAL MARKETS DIV. | G13: POWER DISTRIBUTION | H13: SplcngTermin&Elbws | I13: POWER DISTRIBUTION | J13: 219.25 | K13: 1 | L13: 1 | M13: -89.82 | N13: -0.40966933 | O13: Negative | P13: 309.07 | Q13: 309.07 | R13: 291.17 | S13: 291.17 | T13: SCHEDULE OF DISCOUNT
A14: 25 | B14: Clearway Energy, Inc. PITTSBURGH PA | C14: 88050707 | D14: FRS-R-1-4/10 | E14: FUSETRON DUAL ELEMENT FUSE CLASS RK5 | F14: COOPER BUSSMANN INC | G14: MRO | H14: Branch Circuit Fuses | I14: MRO | J14: 95.4 | K14: 3 | L14: 10 | M14: -20.1 | N14: -0.21069182 | O14: Negative | P14: 115.5 | Q14: 11.55 | R14: 105.5 | S14: 10.55 | T14: SCHEDULE OF DISCOUNT
... A63: 76 | B63: Clearway Energy, Inc. HARRISBURG PA | C63: 97215440 | D63: TP513 | E63: 4SQ 1/2D CVR W/GFCI RCPT | F63: COOPER CROUSE-HINDS DIVISION | G63: BOXES, ENCLOSURES, F | H63: 4Sq Bx,Rngs,Cvrs | I63: BOXES, ENCLOSURES, F | J63: 9.81 | K63: 1 | L63: 5 | M63: -2.812 | N63: -0.28664628 | O63: Negative | P63: 12.622 | Q63: 2.5244 | R63: 11.5195 | S63: 2.3039 | T63: SCHEDULE OF DISCOUNT
N64: #DIV/0! | O64: #DIV/0! | Q64: #DIV/0! | S64: #DIV/0!
N65: #DIV/0! | O65: #DIV/0! | Q65: #DIV/0! | S65: #DIV/0!
N66: #DIV/0! | O66: #DIV/0! | Q66: #DIV/0! | S66: #DIV/0!
N67: #DIV/0! | O67: #DIV/0! | Q67: #DIV/0! | S67: #DIV/0!
N68: #DIV/0! | O68: #DIV/0! | Q68: #DIV/0! | S68: #DIV/0!
N69: #DIV/0! | O69: #DIV/0! | Q69: #DIV/0! | S69: #DIV/0!
N70: #DIV/0! | O70: #DIV/0! | Q70: #DIV/0! | S70: #DIV/0!
N71: #DIV/0! | O71: #DIV/0! | Q71: #DIV/0! | S71: #DIV/0!
N72: #DIV/0! | O72: #DIV/0! | Q72: #DIV/0! | S72: #DIV/0!
N73: #DIV/0! | O73: #DIV/0! | Q73: #DIV/0! | S73: #DIV/0!
N74: #DIV/0! | O74: #DIV/0! | Q74: #DIV/0! | S74: #DIV/0!
N75: #DIV/0! | O75: #DIV/0! | Q75: #DIV/0! | S75: #DIV/0!
... N15000: #DIV/0! | O15000: #DIV/0! | Q15000: #DIV/0! | S15000: #DIV/0!
