Workbook

Sheet Sum by cat
A1: =Analysis!A1 -> McShea Contracting
A2: =Analysis!A2 -> Kissimmee, FL
A3: Summary by Category
H6: Imperial Supplies | M6: Vendor
I7: % of Spend | K7: % Difference | N7: % of Spend
D8: Cat | H8: Extension | I8: by Category | K8: vs. Vendor | M8: Extension | N8: by Category
B9: =IF(H9="","","category total:") -> category total: | D9: 1 | F9: Grade 8 Fasteners | H9: =IF(SUMIF(Analysis!H:H,D9,Analysis!P:P)=0,"",SUMIF(Analysis!H:H,D9,Analysis!P:P)) -> 24.4275 | I9: =IF(H9="","",H9/$H$28) -> 0.028040457 | K9: =IF(M9="","",(H9-M9)/M9) -> -0.53024038 | M9: =IF(SUMIF(Analysis!H:H,D9,Analysis!T:T)=0,"",SUMIF(Analysis!H:H,D9,Analysis!T:T)) -> 52 | N9: =IF(M9="","",M9/$M$28) -> 0.030496566
B10: =IF(H10="","","category total:") | D10: 2 | F10: Grade 5 Fasteners | H10: =IF(SUMIF(Analysis!H:H,D10,Analysis!P:P)=0,"",SUMIF(Analysis!H:H,D10,Analysis!P:P)) | I10: =IF(H10="","",H10/$H$28) | K10: =IF(M10="","",(H10-M10)/M10) | M10: =IF(SUMIF(Analysis!H:H,D10,Analysis!T:T)=0,"",SUMIF(Analysis!H:H,D10,Analysis!T:T)) | N10: =IF(M10="","",M10/$M$28)
B11: =IF(H11="","","category total:") -> category total: | D11: A | F11: Misc Threaded Fasteners | H11: =IF(SUMIF(Analysis!H:H,D11,Analysis!P:P)=0,"",SUMIF(Analysis!H:H,D11,Analysis!P:P)) -> 6.495 | I11: =IF(H11="","",H11/$H$28) -> 0.007455645 | K11: =IF(M11="","",(H11-M11)/M11) -> -0.71662304 | M11: =IF(SUMIF(Analysis!H:H,D11,Analysis!T:T)=0,"",SUMIF(Analysis!H:H,D11,Analysis!T:T)) -> 22.92 | N11: =IF(M11="","",M11/$M$28) -> 0.013441948
B12: =IF(H12="","","category total:") | D12: B | F12: Misc Hardware | H12: =IF(SUMIF(Analysis!H:H,D12,Analysis!P:P)=0,"",SUMIF(Analysis!H:H,D12,Analysis!P:P)) | I12: =IF(H12="","",H12/$H$28) | K12: =IF(M12="","",(H12-M12)/M12) | M12: =IF(SUMIF(Analysis!H:H,D12,Analysis!T:T)=0,"",SUMIF(Analysis!H:H,D12,Analysis!T:T)) | N12: =IF(M12="","",M12/$M$28)
B13: =IF(H13="","","category total:") | D13: C | F13: Rivets | H13: =IF(SUMIF(Analysis!H:H,D13,Analysis!P:P)=0,"",SUMIF(Analysis!H:H,D13,Analysis!P:P)) | I13: =IF(H13="","",H13/$H$28) | K13: =IF(M13="","",(H13-M13)/M13) | M13: =IF(SUMIF(Analysis!H:H,D13,Analysis!T:T)=0,"",SUMIF(Analysis!H:H,D13,Analysis!T:T)) | N13: =IF(M13="","",M13/$M$28)
B14: =IF(H14="","","category total:") | D14: D | F14: Vehicle Lighting | H14: =IF(SUMIF(Analysis!H:H,D14,Analysis!P:P)=0,"",SUMIF(Analysis!H:H,D14,Analysis!P:P)) | I14: =IF(H14="","",H14/$H$28) | K14: =IF(M14="","",(H14-M14)/M14) | M14: =IF(SUMIF(Analysis!H:H,D14,Analysis!T:T)=0,"",SUMIF(Analysis!H:H,D14,Analysis!T:T)) | N14: =IF(M14="","",M14/$M$28)
B15: =IF(H15="","","category total:") | D15: E | F15: Electrical Products | H15: =IF(SUMIF(Analysis!H:H,D15,Analysis!P:P)=0,"",SUMIF(Analysis!H:H,D15,Analysis!P:P)) | I15: =IF(H15="","",H15/$H$28) | K15: =IF(M15="","",(H15-M15)/M15) | M15: =IF(SUMIF(Analysis!H:H,D15,Analysis!T:T)=0,"",SUMIF(Analysis!H:H,D15,Analysis!T:T)) | N15: =IF(M15="","",M15/$M$28)
B16: =IF(H16="","","category total:") -> category total: | D16: F | F16: Tubing & Tubing Fittings | H16: =IF(SUMIF(Analysis!H:H,D16,Analysis!P:P)=0,"",SUMIF(Analysis!H:H,D16,Analysis!P:P)) -> 15.71 | I16: =IF(H16="","",H16/$H$28) -> 0.018033592 | K16: =IF(M16="","",(H16-M16)/M16) -> -0.50079441 | M16: =IF(SUMIF(Analysis!H:H,D16,Analysis!T:T)=0,"",SUMIF(Analysis!H:H,D16,Analysis!T:T)) -> 31.47 | N16: =IF(M16="","",M16/$M$28) -> 0.018456287
B17: =IF(H17="","","category total:") -> category total: | D17: G | F17: Air Brake Products | H17: =IF(SUMIF(Analysis!H:H,D17,Analysis!P:P)=0,"",SUMIF(Analysis!H:H,D17,Analysis!P:P)) -> 164.42 | I17: =IF(H17="","",H17/$H$28) -> 0.18873859 | K17: =IF(M17="","",(H17-M17)/M17) -> -0.18401985 | M17: =IF(SUMIF(Analysis!H:H,D17,Analysis!T:T)=0,"",SUMIF(Analysis!H:H,D17,Analysis!T:T)) -> 201.5 | N17: =IF(M17="","",M17/$M$28) -> 0.11817419
B18: =IF(H18="","","category total:") | D18: H | F18: Hose & Hose Ends | H18: =IF(SUMIF(Analysis!H:H,D18,Analysis!P:P)=0,"",SUMIF(Analysis!H:H,D18,Analysis!P:P)) | I18: =IF(H18="","",H18/$H$28) | K18: =IF(M18="","",(H18-M18)/M18) | M18: =IF(SUMIF(Analysis!H:H,D18,Analysis!T:T)=0,"",SUMIF(Analysis!H:H,D18,Analysis!T:T)) | N18: =IF(M18="","",M18/$M$28)
B19: =IF(H19="","","category total:") -> category total: | D19: I | F19: Cutting Tools | H19: =IF(SUMIF(Analysis!H:H,D19,Analysis!P:P)=0,"",SUMIF(Analysis!H:H,D19,Analysis!P:P)) -> 237.48 | I19: =IF(H19="","",H19/$H$28) -> 0.27260455 | K19: =IF(M19="","",(H19-M19)/M19) -> -0.71163163 | M19: =IF(SUMIF(Analysis!H:H,D19,Analysis!T:T)=0,"",SUMIF(Analysis!H:H,D19,Analysis!T:T)) -> 823.53 | N19: =IF(M19="","",M19/$M$28) -> 0.48297764
B20: =IF(H20="","","category total:") | D20: J | F20: Abrasives | H20: =IF(SUMIF(Analysis!H:H,D20,Analysis!P:P)=0,"",SUMIF(Analysis!H:H,D20,Analysis!P:P)) | I20: =IF(H20="","",H20/$H$28) | K20: =IF(M20="","",(H20-M20)/M20) | M20: =IF(SUMIF(Analysis!H:H,D20,Analysis!T:T)=0,"",SUMIF(Analysis!H:H,D20,Analysis!T:T)) | N20: =IF(M20="","",M20/$M$28)
B21: =IF(H21="","","category total:") | D21: K | F21: Safety Products | H21: =IF(SUMIF(Analysis!H:H,D21,Analysis!P:P)=0,"",SUMIF(Analysis!H:H,D21,Analysis!P:P)) | I21: =IF(H21="","",H21/$H$28) | K21: =IF(M21="","",(H21-M21)/M21) | M21: =IF(SUMIF(Analysis!H:H,D21,Analysis!T:T)=0,"",SUMIF(Analysis!H:H,D21,Analysis!T:T)) | N21: =IF(M21="","",M21/$M$28)
B22: =IF(H22="","","category total:") -> category total: | D22: L | F22: Paints & Chemicals | H22: =IF(SUMIF(Analysis!H:H,D22,Analysis!P:P)=0,"",SUMIF(Analysis!H:H,D22,Analysis!P:P)) -> 232.2595 | I22: =IF(H22="","",H22/$H$28) -> 0.26661191 | K22: =IF(M22="","",(H22-M22)/M22) -> -0.19427081 | M22: =IF(SUMIF(Analysis!H:H,D22,Analysis!T:T)=0,"",SUMIF(Analysis!H:H,D22,Analysis!T:T)) -> 288.26 | N22: =IF(M22="","",M22/$M$28) -> 0.16905654
... B24: =IF(H24="","","category total:") | D24: N | F24: Misc Vehicle Parts | H24: =IF(SUMIF(Analysis!H:H,D24,Analysis!P:P)=0,"",SUMIF(Analysis!H:H,D24,Analysis!P:P)) | I24: =IF(H24="","",H24/$H$28) | K24: =IF(M24="","",(H24-M24)/M24) | M24: =IF(SUMIF(Analysis!H:H,D24,Analysis!T:T)=0,"",SUMIF(Analysis!H:H,D24,Analysis!T:T)) | N24: =IF(M24="","",M24/$M$28)
B25: =IF(H25="","","category total:") -> category total: | D25: 1008 | F25: MRO Fasteners | H25: =IF(SUMIF(Analysis!H:H,D25,Analysis!P:P)=0,"",SUMIF(Analysis!H:H,D25,Analysis!P:P)) -> 50.75 | I25: =IF(H25="","",H25/$H$28) -> 0.058256194 | K25: =IF(M25="","",(H25-M25)/M25) -> -0.45383125 | M25: =IF(SUMIF(Analysis!H:H,D25,Analysis!T:T)=0,"",SUMIF(Analysis!H:H,D25,Analysis!T:T)) -> 92.92 | N25: =IF(M25="","",M25/$M$28) -> 0.054495018
B26: =IF(H26="","","category total:") -> category total: | D26: 1022 | F26: MRO Plumbing | H26: =IF(SUMIF(Analysis!H:H,D26,Analysis!P:P)=0,"",SUMIF(Analysis!H:H,D26,Analysis!P:P)) -> 48.24 | I26: =IF(H26="","",H26/$H$28) -> 0.055374952 | K26: =IF(M26="","",(H26-M26)/M26) -> -0.033653846 | M26: =IF(SUMIF(Analysis!H:H,D26,Analysis!T:T)=0,"",SUMIF(Analysis!H:H,D26,Analysis!T:T)) -> 49.92 | N26: =IF(M26="","",M26/$M$28) -> 0.029276704
B27: =IF(H27="","","category total:") -> category total: | D27: 1024 | F27: MRO Power Tools | H27: =IF(SUMIF(Analysis!H:H,D27,Analysis!P:P)=0,"",SUMIF(Analysis!H:H,D27,Analysis!P:P)) -> 91.37 | I27: =IF(H27="","",H27/$H$28) -> 0.10488411 | K27: =IF(M27="","",(H27-M27)/M27) -> -0.35921173 | M27: =IF(SUMIF(Analysis!H:H,D27,Analysis!T:T)=0,"",SUMIF(Analysis!H:H,D27,Analysis!T:T)) -> 142.59 | N27: =IF(M27="","",M27/$M$28) -> 0.083625103
F28: Overall Total | H28: =SUM(H9:H27) -> 871.152 | K28: =IFERROR((H28-M28)/M28,0) -> -0.48909337 | M28: =SUM(M9:M27) -> 1705.11

Sheet Sum by rank
A1: =Analysis!A1 -> McShea Contracting
A2: =Analysis!A2 -> Kissimmee, FL
A3: Summary by Rank
G8: Imperial Supplies | L8: Vendor
H9: % of Spend | J9: % of Difference | M9: % of Spend
D10: Rank | G10: Extension | H10: by Rank | J10: vs. Vendor | L10: Extension | M10: by Rank
D11: A | E11: =IF(L11="","","Rank") -> Rank | G11: =IF(SUMIF(Analysis!I:I,D11,Analysis!P:P)=0,"",SUMIF(Analysis!I:I,D11,Analysis!P:P)) -> 473.142 | H11: =IF(G11="","",G11/$G$15) -> 0.54312221 | J11: =IF(L11="","",(G11-L11)/L11) -> -0.39526068 | L11: =IF(SUMIF(Analysis!I:I,D11,Analysis!T:T)=0,"",SUMIF(Analysis!I:I,D11,Analysis!T:T)) -> 782.39 | M11: =IF(L11="","",L11/$L$15) -> 0.45885016
D12: B | E12: =IF(L12="","","Rank") -> Rank | G12: =IF(SUMIF(Analysis!I:I,D12,Analysis!P:P)=0,"",SUMIF(Analysis!I:I,D12,Analysis!P:P)) -> 117.48 | H12: =IF(G12="","",G12/$G$15) -> 0.13485592 | J12: =IF(L12="","",(G12-L12)/L12) -> -0.44311718 | L12: =IF(SUMIF(Analysis!I:I,D12,Analysis!T:T)=0,"",SUMIF(Analysis!I:I,D12,Analysis!T:T)) -> 210.96 | M12: =IF(L12="","",L12/$L$15) -> 0.12372222
D13: C | E13: =IF(L13="","","Rank") -> Rank | G13: =IF(SUMIF(Analysis!I:I,D13,Analysis!P:P)=0,"",SUMIF(Analysis!I:I,D13,Analysis!P:P)) -> 15.18 | H13: =IF(G13="","",G13/$G$15) -> 0.017425203 | J13: =IF(L13="","",(G13-L13)/L13) -> -0.70165094 | L13: =IF(SUMIF(Analysis!I:I,D13,Analysis!T:T)=0,"",SUMIF(Analysis!I:I,D13,Analysis!T:T)) -> 50.88 | M13: =IF(L13="","",L13/$L$15) -> 0.029839717
D14: D | E14: =IF(L14="","","Rank") -> Rank | G14: =IF(SUMIF(Analysis!I:I,D14,Analysis!P:P)=0,"",SUMIF(Analysis!I:I,D14,Analysis!P:P)) -> 265.35 | H14: =IF(G14="","",G14/$G$15) -> 0.30459667 | J14: =IF(L14="","",(G14-L14)/L14) -> -0.59848989 | L14: =IF(SUMIF(Analysis!I:I,D14,Analysis!T:T)=0,"",SUMIF(Analysis!I:I,D14,Analysis!T:T)) -> 660.88 | M14: =IF(L14="","",L14/$L$15) -> 0.3875879
E15: Overall Total | G15: =SUM(G11:G14) -> 871.152 | J15: =IFERROR((G15-L15)/L15,0) -> -0.48909337 | L15: =SUM(L11:L14) -> 1705.11

Sheet Analysis
A1: McShea Contracting
A2: Kissimmee, FL
A3: Analysis
B5: Vendor | C5: Vendor X-Info | F5: Imperial | L5: Vendor | N5: Imperial | R5: Vendor | V5: Imperial
B6: Item# | C6: Notes | D6: Qty | E6: UOM | F6: Part# | G6: Grp | H6: Cat | I6: Rnk | J6: Description | L6: Quantity | N6: Price/Unit | P6: Extension | R6: Price/Unit | T6: Extension | V6: BD Qty | W6: BD UOM
A7: APPLIED
A8: KISSIMMEE, FL
A9: INVOICE: 1516358166 2/21/22
B11: 101734069 | D11: 50 | E11: FT | F11: 90924 | G11: 199 | H11: G | I11: A | J11: 1/4 DOT AIR BRAKE TUBING | L11: 1 | N11: 0.44 | O11: FT | R11: 25.46 | S11: RL
F12: 90924 | G12: 199 | H12: G | I12: A | J12: Actual # of FT | L12: =D11*L11 -> 50 | N12: =IF(ISBLANK(V11),IF(O11="C",N11/100,N11),IF(O11="C",N11/100/V11,N11/V11)) -> 0.44 | O12: FT | P12: =(N12*L12) -> 22 | R12: =IF(S11="C",R11/D11/100,R11/D11) -> 0.5092 | S12: FT | T12: =R12*L12 -> 25.46
B14: 110357570 | C14: 12/PK | D14: 180 | E14: OZ | F14: 6536 | G14: 251 | H14: L | I14: A | J14: BRAKE CLEANE R 14 OZ NET | L14: 4 | N14: 2.38 | O14: EA | R14: 30.46 | S14: PK | V14: 14 | W14: OZ
F15: 6536 | G15: 251 | H15: L | I15: A | J15: Actual # of OZ | L15: =D14*L14 -> 720 | N15: =IF(ISBLANK(V14),IF(O14="C",N14/100,N14),IF(O14="C",N14/100/V14,N14/V14)) -> 0.17 | O15: OZ | P15: =(N15*L15) -> 122.4 | R15: =IF(S14="C",R14/D14/100,R14/D14) -> 0.16922222 | S15: OZ | T15: =R15*L15 -> 121.84
B17: 116758286 | C17: 12/PK | D17: 180 | E17: OZ | F17: 6502 | G17: 251 | H17: L | I17: A | J17: PENT LUBE W/ PTFE 10-1/2 | L17: 1 | N17: 3.76 | O17: EA | R17: 72.39 | S17: PK | V17: 10.5 | W17: OZ
F18: 6502 | G18: 251 | H18: L | I18: A | J18: Actual # of OZ | L18: =D17*L17 -> 180 | N18: =IF(ISBLANK(V17),IF(O17="C",N17/100,N17),IF(O17="C",N17/100/V17,N17/V17)) -> 0.35809524 | O18: OZ | P18: =(N18*L18) -> 64.457143 | R18: =IF(S17="C",R17/D17/100,R17/D17) -> 0.40216667 | S18: OZ | T18: =R18*L18 -> 72.39
B20: 116756643 | C20: 12/PK | D20: 216 | E20: OZ | F20: 6515 | G20: 251 | H20: L | I20: A | J20: BATTERY CLNR 12-3/4 OZ | L20: 1 | N20: 2.68 | O20: EA | R20: 94.03 | S20: PK | V20: 12.75 | W20: OZ
F21: 6515 | G21: 251 | H21: L | I21: A | J21: Actual # of OZ | L21: =D20*L20 -> 216 | N21: =IF(ISBLANK(V20),IF(O20="C",N20/100,N20),IF(O20="C",N20/100/V20,N20/V20)) -> 0.21019608 | O21: OZ | P21: =(N21*L21) -> 45.402353 | R21: =IF(S20="C",R20/D20/100,R20/D20) -> 0.43532407 | S21: OZ | T21: =R21*L21 -> 94.03
B23: 101707732 | D23: 100 | E23: PC | F23: 40150 | G23: 049 | H23: 1 | I23: A | J23: FN HEX 8 PL 1/4-20 | L23: 1 | N23: 2.18 | O23: C | R23: 5.23 | S23: PK
F24: 40150 | G24: 049 | H24: 1 | I24: A | J24: Actual # of PC | L24: =D23*L23 -> 100 | N24: =IF(ISBLANK(V23),IF(O23="C",N23/100,N23),IF(O23="C",N23/100/V23,N23/V23)) -> 0.0218 | O24: PC | P24: =(N24*L24) -> 2.18 | R24: =IF(S23="C",R23/D23/100,R23/D23) -> 0.0523 | S24: PC | T24: =R24*L24 -> 5.23
B26: 101734009 | D26: 75 | E26: PC | F26: 76014 | G26: 146 | H26: 1 | I26: A | J26: USS FLAT GR8 7/16 | L26: 1 | N26: 7.39 | O26: C | R26: 12.5 | S26: PK
F27: 76014 | G27: 146 | H27: 1 | I27: A | J27: Actual # of PC | L27: =D26*L26 -> 75 | N27: =IF(ISBLANK(V26),IF(O26="C",N26/100,N26),IF(O26="C",N26/100/V26,N26/V26)) -> 0.0739 | O27: PC | P27: =(N27*L27) -> 5.5425 | R27: =IF(S26="C",R26/D26/100,R26/D26) -> 0.16666667 | S27: PC | T27: =R27*L27 -> 12.5
B29: 101707213 | D29: 25 | E29: PC | F29: 16654 | G29: 026 | H29: 1 | I29: A | J29: HX CP PL USS 3/8X2-1/2 8 | L29: 1 | N29: 19.78 | O29: C | R29: 10.16 | S29: PK
F30: 16654 | G30: 026 | H30: 1 | I30: A | J30: Actual # of PC | L30: =D29*L29 -> 25 | N30: =IF(ISBLANK(V29),IF(O29="C",N29/100,N29),IF(O29="C",N29/100/V29,N29/V29)) -> 0.1978 | O30: PC | P30: =(N30*L30) -> 4.945 | R30: =IF(S29="C",R29/D29/100,R29/D29) -> 0.4064 | S30: PC | T30: =R30*L30 -> 10.16
B32: 101708147 | D32: 100 | E32: PC | F32: 16605 | G32: 026 | H32: 1 | I32: A | J32: HX CP PL USS 1/4X1-1/4 8 | L32: 1 | N32: 5.67 | O32: C | R32: 13.76 | S32: PK
F33: 16605 | G33: 026 | H33: 1 | I33: A | J33: Actual # of PC | L33: =D32*L32 -> 100 | N33: =IF(ISBLANK(V32),IF(O32="C",N32/100,N32),IF(O32="C",N32/100/V32,N32/V32)) -> 0.0567 | O33: PC | P33: 5.66 | R33: =IF(S32="C",R32/D32/100,R32/D32) -> 0.1376 | S33: PC | T33: =R33*L33 -> 13.76
B35: 101723700 | D35: 5 | E35: PC | F35: 16750 | G35: 026 | H35: 1 | I35: A | J35: HX CP PL USS 5/8X5 8 | L35: 1 | N35: 122 | O35: C | R35: 10.35 | S35: PK
F36: 16750 | G36: 026 | H36: 1 | I36: A | J36: Actual # of PC | L36: =D35*L35 -> 5 | N36: =IF(ISBLANK(V35),IF(O35="C",N35/100,N35),IF(O35="C",N35/100/V35,N35/V35)) -> 1.22 | O36: PC | P36: =(N36*L36) -> 6.1 | R36: =IF(S35="C",R35/D35/100,R35/D35) -> 2.07 | S36: PC | T36: =R36*L36 -> 10.35
B38: 116755234 | D38: 3 | E38: PC | F38: 98575 | G38: 302 | H38: F | I38: D | J38: GAL PIPE FIT 1-1/4XCLOSEN | L38: 1 | N38: 227 | O38: C | R38: 12.57 | S38: PK
F39: 98575 | G39: 302 | H39: F | I39: D | J39: Actual # of PC | L39: =D38*L38 -> 3 | N39: =IF(ISBLANK(V38),IF(O38="C",N38/100,N38),IF(O38="C",N38/100/V38,N38/V38)) -> 2.27 | O39: PC | P39: =(N39*L39) -> 6.81 | R39: =IF(S38="C",R38/D38/100,R38/D38) -> 4.19 | S39: PC | T39: =R39*L39 -> 12.57
B41: 116755191 | D41: 5 | E41: PC | F41: 98545 | G41: 302 | H41: F | I41: D | J41: GAL PIPE FIT 3/4X1-1/2 N | L41: 1 | N41: 112 | O41: C | R41: 11.44 | S41: PK
F42: 98545 | G42: 302 | H42: F | I42: D | J42: Actual # of PC | L42: =D41*L41 -> 5 | N42: =IF(ISBLANK(V41),IF(O41="C",N41/100,N41),IF(O41="C",N41/100/V41,N41/V41)) -> 1.12 | O42: PC | P42: =(N42*L42) -> 5.6 | R42: =IF(S41="C",R41/D41/100,R41/D41) -> 2.288 | S42: PC | T42: =R42*L42 -> 11.44
B44: 116755071 | D44: 2 | E44: PC | F44: 98515 | G44: 302 | H44: F | I44: D | J44: GAL PIPE FIT 1/4X3 N | L44: 1 | N44: 165 | O44: C | R44: 7.46 | S44: PK
F45: 98515 | G45: 302 | H45: F | I45: D | J45: Actual # of PC | L45: =D44*L44 -> 2 | N45: =IF(ISBLANK(V44),IF(O44="C",N44/100,N44),IF(O44="C",N44/100/V44,N44/V44)) -> 1.65 | O45: PC | P45: =(N45*L45) -> 3.3 | R45: =IF(S44="C",R44/D44/100,R44/D44) -> 3.73 | S45: PC | T45: =R45*L45 -> 7.46
B47: 101771795 | D47: 3 | E47: PC | F47: 928340-7 | G47: GRA | H47: 1022 | I47: D | J47: Merchant Coupling,3/4 | L47: 3 | N47: 536 | O47: C | R47: 16.64 | S47: PK
F48: 928340-7 | G48: GRA | H48: 1022 | I48: D | J48: Actual # of PC | L48: =D47*L47 -> 9 | N48: =IF(ISBLANK(V47),IF(O47="C",N47/100,N47),IF(O47="C",N47/100/V47,N47/V47)) -> 5.36 | O48: PC | P48: =(N48*L48) -> 48.24 | R48: =IF(S47="C",R47/D47/100,R47/D47) -> 5.5466667 | S48: PC | T48: =R48*L48 -> 49.92
B50: 101736767 | F50: 70684 | G50: 088 | H50: I | I50: D | J50: MASONRY DRIL 1/2X6 | L50: 6 | N50: 3.31 | O50: EA | P50: 19.86 | R50: 18.21 | S50: EA | T50: 109.26
B51: 101738489 | C51: 4 INCH* | F51: 70682 | G51: 088 | H51: I | I51: D | J51: MASONRY DRIL 3/8X6 | L51: 6 | N51: 2.64 | O51: EA | P51: 15.84 | R51: 13.67 | S51: EA | T51: 82.02
B52: 102698723 | F52: 917692-5 | G52: GRA | H52: 1024 | I52: D | J52: Masonry Bit, 5/16 In,4 In | L52: 1 | N52: 251 | O52: C | P52: 2.51 | R52: 12.69 | S52: EA | T52: 12.69
B53: 101745241 | F53: 70681 | G53: 088 | H53: I | I53: D | J53: MASONRY DRIL 5/16X6 | L53: 6 | N53: 2.12 | O53: EA | P53: 12.72 | R53: 14.73 | S53: EA | T53: 88.38
B54: 101745240 | F54: 931094-4 | G54: GRA | H54: 1024 | I54: D | J54: Hammer Drill Bit,SDS Plus, | L54: 6 | N54: 976 | O54: C | P54: 58.56 | R54: 12.69 | S54: EA | T54: 76.14
B55: 101737232 | F55: 70679 | G55: 088 | H55: I | I55: D | J55: MASONRY DRIL 1/4X6 | L55: 6 | N55: 1.81 | O55: EA | P55: 10.86 | R55: 10.72 | S55: EA | T55: 64.32
...

Sheet Price Variance
A1: McShea Contracting
A2: Multiple Locations
A3: Price Variance
C5: Vendor | D5: Vendor X-Info | G5: Imperial | J5: Vendor | L5: Imperial | P5: Vendor | T5: Imperial
A6: Location | B6: Invoice | C6: Item# | D6: Notes | E6: Qty | F6: UOM | G6: Part# | H6: Description | J6: Quantity | L6: Price/Unit | N6: Extension | P6: Price/Unit | R6: Extension | T6: BD Qty | U6: BD UOM
A7: KISSIMMEE, FL | B7: INVOICE: 1516358166 2/21/22 | C7: 116758286 | D7: 12/PK | E7: 180 | F7: OZ | G7: 6502 | H7: PENT LUBE W/ PTFE 10-1/2 | J7: 1 | L7: 3.76 | M7: EA | P7: 72.39 | Q7: PK | T7: 10.5 | U7: OZ
A8: KISSIMMEE, FL | B8: INVOICE: 1516358166 2/21/22 | G8: 6502 | H8: Actual # of OZ | J8: =E7*J7 -> 180 | L8: =IF(ISBLANK(T7),IF(M7="C",L7/100,L7),IF(M7="C",L7/100/T7,L7/T7)) -> 0.35809524 | M8: OZ | N8: =(L8*J8) -> 64.457143 | P8: =IF(Q7="C",P7/E7/100,P7/E7) -> 0.40216667 | Q8: OZ | R8: =P8*J8 -> 72.39
A9: LEHIGH ACRES, FL | B9: INVOICE: 7022638800 10/07/21 | C9: 116758286 | D9: 12 PK | E9: 180 | F9: OZ | G9: 6502 | H9: PENT LUBE W/ PTFE 10-1/2 | J9: 1 | L9: 3.76 | M9: EA | P9: 73.87 | Q9: PK | T9: 10.5 | U9: OZ
A10: LEHIGH ACRES, FL | B10: INVOICE: 7022638800 10/07/21 | G10: 6502 | H10: Actual # of OZ | J10: =E9*J9 -> 180 | L10: =IF(ISBLANK(T9),IF(M9="C",L9/100,L9),IF(M9="C",L9/100/T9,L9/T9)) -> 0.35809524 | M10: OZ | N10: =(L10*J10) -> 64.457143 | P10: =IF(Q9="C",P9/E9/100,P9/E9) -> 0.41038889 | Q10: OZ | R10: =P10*J10 -> 73.87
